[2016-10-07T20:14:31.874] Not running as root. Can't drop supplementary groups
[2016-10-07T20:14:31.874] error: Configured MailProg is invalid
[2016-10-07T20:14:31.874] slurmctld version 15.08.11 started on cluster cluster
[2016-10-07T20:14:31.876] layouts: no layout to initialize
[2016-10-07T20:14:32.071] layouts: loading entities/relations information
[2016-10-07T20:14:32.071] cons_res_gpu: select_p_node_init
[2016-10-07T20:14:32.071] cons_res_gpu: preparing for 1 partitions
[2016-10-07T20:14:32.072] gres/gpu: state for gpu-cluster-1
[2016-10-07T20:14:32.072]   gres_cnt found:TBD configured:8 avail:8 alloc:0
[2016-10-07T20:14:32.072]   gres_bit_alloc:NULL
[2016-10-07T20:14:32.072]   gres_used:(null)
[2016-10-07T20:14:32.072] gres/gpu: state for gpu-cluster-2
[2016-10-07T20:14:32.072]   gres_cnt found:TBD configured:8 avail:8 alloc:0
[2016-10-07T20:14:32.072]   gres_bit_alloc:NULL
[2016-10-07T20:14:32.072]   gres_used:(null)
[2016-10-07T20:14:32.072] gres/gpu: state for gpu-cluster-3
[2016-10-07T20:14:32.072]   gres_cnt found:TBD configured:8 avail:8 alloc:0
[2016-10-07T20:14:32.072]   gres_bit_alloc:NULL
[2016-10-07T20:14:32.072]   gres_used:(null)
[2016-10-07T20:14:32.072] gres/gpu: state for gpu-cluster-4
[2016-10-07T20:14:32.072]   gres_cnt found:TBD configured:8 avail:8 alloc:0
[2016-10-07T20:14:32.072]   gres_bit_alloc:NULL
[2016-10-07T20:14:32.072]   gres_used:(null)
[2016-10-07T20:14:32.072] Recovered state of 0 reservations
[2016-10-07T20:14:32.072] read_slurm_conf: backup_controller not specified.
[2016-10-07T20:14:32.072] cons_res_gpu: select_p_reconfigure
[2016-10-07T20:14:32.072] cons_res_gpu: select_p_node_init
[2016-10-07T20:14:32.072] cons_res_gpu: preparing for 1 partitions
[2016-10-07T20:14:32.073] Running as primary controller
[2016-10-07T20:14:32.073] Recovered information about 0 sicp jobs
[2016-10-07T20:14:35.536] gres/gpu: state for gpu-cluster-1
[2016-10-07T20:14:35.536]   gres_cnt found:8 configured:8 avail:8 alloc:0
[2016-10-07T20:14:35.536]   gres_bit_alloc:
[2016-10-07T20:14:35.536]   gres_used:(null)
[2016-10-07T20:14:35.536]   topo_cpus_bitmap[0]:0-7
[2016-10-07T20:14:35.536]   topo_gres_bitmap[0]:0-7
[2016-10-07T20:14:35.536]   topo_gres_cnt_alloc[0]:0
[2016-10-07T20:14:35.536]   topo_gres_cnt_avail[0]:8
[2016-10-07T20:14:35.536]   type[0]:tesla
[2016-10-07T20:14:36.077] SchedulerParameters=default_queue_depth=100,max_rpc_cnt=0,max_sched_time=2,partition_job_depth=0,sched_max_job_start=0,sched_min_interval=0
[2016-10-07T20:14:36.081] gres/gpu: state for gpu-cluster-1
[2016-10-07T20:14:36.082]   gres_cnt found:8 configured:8 avail:8 alloc:0
[2016-10-07T20:14:36.082]   gres_bit_alloc:
[2016-10-07T20:14:36.082]   gres_used:(null)
[2016-10-07T20:14:36.082]   topo_cpus_bitmap[0]:0-7
[2016-10-07T20:14:36.082]   topo_gres_bitmap[0]:0-7
[2016-10-07T20:14:36.082]   topo_gres_cnt_alloc[0]:0
[2016-10-07T20:14:36.082]   topo_gres_cnt_avail[0]:8
[2016-10-07T20:14:36.082]   type[0]:tesla
[2016-10-07T20:14:44.770] gres/gpu: state for gpu-cluster-2
[2016-10-07T20:14:44.770]   gres_cnt found:8 configured:8 avail:8 alloc:0
[2016-10-07T20:14:44.770]   gres_bit_alloc:
[2016-10-07T20:14:44.770]   gres_used:(null)
[2016-10-07T20:14:44.770]   topo_cpus_bitmap[0]:0-7
[2016-10-07T20:14:44.770]   topo_gres_bitmap[0]:0-7
[2016-10-07T20:14:44.770]   topo_gres_cnt_alloc[0]:0
[2016-10-07T20:14:44.770]   topo_gres_cnt_avail[0]:8
[2016-10-07T20:14:44.770]   type[0]:tesla
[2016-10-07T20:14:45.086] gres/gpu: state for gpu-cluster-2
[2016-10-07T20:14:45.086]   gres_cnt found:8 configured:8 avail:8 alloc:0
[2016-10-07T20:14:45.086]   gres_bit_alloc:
[2016-10-07T20:14:45.086]   gres_used:(null)
[2016-10-07T20:14:45.086]   topo_cpus_bitmap[0]:0-7
[2016-10-07T20:14:45.086]   topo_gres_bitmap[0]:0-7
[2016-10-07T20:14:45.086]   topo_gres_cnt_alloc[0]:0
[2016-10-07T20:14:45.086]   topo_gres_cnt_avail[0]:8
[2016-10-07T20:14:45.086]   type[0]:tesla
[2016-10-07T20:14:53.344] gres/gpu: state for gpu-cluster-3
[2016-10-07T20:14:53.345]   gres_cnt found:8 configured:8 avail:8 alloc:0
[2016-10-07T20:14:53.345]   gres_bit_alloc:
[2016-10-07T20:14:53.345]   gres_used:(null)
[2016-10-07T20:14:53.345]   topo_cpus_bitmap[0]:0-7
[2016-10-07T20:14:53.345]   topo_gres_bitmap[0]:0-7
[2016-10-07T20:14:53.345]   topo_gres_cnt_alloc[0]:0
[2016-10-07T20:14:53.345]   topo_gres_cnt_avail[0]:8
[2016-10-07T20:14:53.345]   type[0]:tesla
[2016-10-07T20:14:57.339] gres/gpu: state for gpu-cluster-4
[2016-10-07T20:14:57.339]   gres_cnt found:8 configured:8 avail:8 alloc:0
[2016-10-07T20:14:57.339]   gres_bit_alloc:
[2016-10-07T20:14:57.339]   gres_used:(null)
[2016-10-07T20:14:57.339]   topo_cpus_bitmap[0]:0-7
[2016-10-07T20:14:57.339]   topo_gres_bitmap[0]:0-7
[2016-10-07T20:14:57.339]   topo_gres_cnt_alloc[0]:0
[2016-10-07T20:14:57.339]   topo_gres_cnt_avail[0]:8
[2016-10-07T20:14:57.339]   type[0]:tesla
[2016-10-07T20:15:32.176] gres: gpu state for job 1828
[2016-10-07T20:15:32.176]   gres_cnt:8 node_cnt:0 type:(null)
[2016-10-07T20:15:32.177] _slurm_rpc_submit_batch_job JobId=1828 usec=855
[2016-10-07T20:15:32.177] job submit: job_id = 1828	time = 1475842532

[2016-10-07T20:15:32.182] gres: gpu state for job 1829
[2016-10-07T20:15:32.183]   gres_cnt:4 node_cnt:0 type:(null)
[2016-10-07T20:15:32.183] _slurm_rpc_submit_batch_job JobId=1829 usec=583
[2016-10-07T20:15:32.183] job submit: job_id = 1829	time = 1475842532

[2016-10-07T20:15:32.191] gres: gpu state for job 1830
[2016-10-07T20:15:32.191]   gres_cnt:6 node_cnt:0 type:(null)
[2016-10-07T20:15:32.191] _slurm_rpc_submit_batch_job JobId=1830 usec=576
[2016-10-07T20:15:32.192] job submit: job_id = 1830	time = 1475842532

[2016-10-07T20:15:32.198] gres: gpu state for job 1831
[2016-10-07T20:15:32.198]   gres_cnt:8 node_cnt:0 type:(null)
[2016-10-07T20:15:32.199] _slurm_rpc_submit_batch_job JobId=1831 usec=1008
[2016-10-07T20:15:32.200] job submit: job_id = 1831	time = 1475842532

[2016-10-07T20:15:32.206] gres: gpu state for job 1832
[2016-10-07T20:15:32.206]   gres_cnt:2 node_cnt:0 type:(null)
[2016-10-07T20:15:32.206] _slurm_rpc_submit_batch_job JobId=1832 usec=582
[2016-10-07T20:15:32.207] job submit: job_id = 1832	time = 1475842532

[2016-10-07T20:15:32.213] gres: gpu state for job 1833
[2016-10-07T20:15:32.213]   gres_cnt:3 node_cnt:0 type:(null)
[2016-10-07T20:15:32.214] _slurm_rpc_submit_batch_job JobId=1833 usec=588
[2016-10-07T20:15:32.214] job submit: job_id = 1833	time = 1475842532

[2016-10-07T20:15:32.221] gres: gpu state for job 1834
[2016-10-07T20:15:32.221]   gres_cnt:4 node_cnt:0 type:(null)
[2016-10-07T20:15:32.222] _slurm_rpc_submit_batch_job JobId=1834 usec=573
[2016-10-07T20:15:32.222] job submit: job_id = 1834	time = 1475842532

[2016-10-07T20:15:32.228] gres: gpu state for job 1835
[2016-10-07T20:15:32.228]   gres_cnt:2 node_cnt:0 type:(null)
[2016-10-07T20:15:32.228] _slurm_rpc_submit_batch_job JobId=1835 usec=583
[2016-10-07T20:15:32.229] job submit: job_id = 1835	time = 1475842532

[2016-10-07T20:15:32.235] gres: gpu state for job 1836
[2016-10-07T20:15:32.235]   gres_cnt:8 node_cnt:0 type:(null)
[2016-10-07T20:15:32.235] _slurm_rpc_submit_batch_job JobId=1836 usec=586
[2016-10-07T20:15:32.236] job submit: job_id = 1836	time = 1475842532

[2016-10-07T20:15:32.242] gres: gpu state for job 1837
[2016-10-07T20:15:32.243]   gres_cnt:5 node_cnt:0 type:(null)
[2016-10-07T20:15:32.243] _slurm_rpc_submit_batch_job JobId=1837 usec=584
[2016-10-07T20:15:32.243] job submit: job_id = 1837	time = 1475842532

[2016-10-07T20:15:32.250] gres: gpu state for job 1838
[2016-10-07T20:15:32.250]   gres_cnt:4 node_cnt:0 type:(null)
[2016-10-07T20:15:32.251] _slurm_rpc_submit_batch_job JobId=1838 usec=571
[2016-10-07T20:15:32.251] job submit: job_id = 1838	time = 1475842532

[2016-10-07T20:15:32.258] gres: gpu state for job 1839
[2016-10-07T20:15:32.258]   gres_cnt:1 node_cnt:0 type:(null)
[2016-10-07T20:15:32.258] _slurm_rpc_submit_batch_job JobId=1839 usec=581
[2016-10-07T20:15:32.259] job submit: job_id = 1839	time = 1475842532

[2016-10-07T20:15:32.264] gres: gpu state for job 1840
[2016-10-07T20:15:32.264]   gres_cnt:2 node_cnt:0 type:(null)
[2016-10-07T20:15:32.265] _slurm_rpc_submit_batch_job JobId=1840 usec=588
[2016-10-07T20:15:32.265] job submit: job_id = 1840	time = 1475842532

[2016-10-07T20:15:32.271] gres: gpu state for job 1841
[2016-10-07T20:15:32.272]   gres_cnt:7 node_cnt:0 type:(null)
[2016-10-07T20:15:32.272] _slurm_rpc_submit_batch_job JobId=1841 usec=580
[2016-10-07T20:15:32.273] job submit: job_id = 1841	time = 1475842532

[2016-10-07T20:15:32.280] gres: gpu state for job 1842
[2016-10-07T20:15:32.280]   gres_cnt:6 node_cnt:0 type:(null)
[2016-10-07T20:15:32.280] _slurm_rpc_submit_batch_job JobId=1842 usec=583
[2016-10-07T20:15:32.281] job submit: job_id = 1842	time = 1475842532

[2016-10-07T20:15:32.288] gres: gpu state for job 1843
[2016-10-07T20:15:32.288]   gres_cnt:2 node_cnt:0 type:(null)
[2016-10-07T20:15:32.288] _slurm_rpc_submit_batch_job JobId=1843 usec=576
[2016-10-07T20:15:32.289] job submit: job_id = 1843	time = 1475842532

[2016-10-07T20:15:32.295] gres: gpu state for job 1844
[2016-10-07T20:15:32.295]   gres_cnt:7 node_cnt:0 type:(null)
[2016-10-07T20:15:32.296] _slurm_rpc_submit_batch_job JobId=1844 usec=572
[2016-10-07T20:15:32.296] job submit: job_id = 1844	time = 1475842532

[2016-10-07T20:15:32.302] gres: gpu state for job 1845
[2016-10-07T20:15:32.302]   gres_cnt:8 node_cnt:0 type:(null)
[2016-10-07T20:15:32.303] _slurm_rpc_submit_batch_job JobId=1845 usec=578
[2016-10-07T20:15:32.303] job submit: job_id = 1845	time = 1475842532

[2016-10-07T20:15:32.310] gres: gpu state for job 1846
[2016-10-07T20:15:32.310]   gres_cnt:6 node_cnt:0 type:(null)
[2016-10-07T20:15:32.310] _slurm_rpc_submit_batch_job JobId=1846 usec=576
[2016-10-07T20:15:32.311] job submit: job_id = 1846	time = 1475842532

[2016-10-07T20:15:32.317] gres: gpu state for job 1847
[2016-10-07T20:15:32.317]   gres_cnt:7 node_cnt:0 type:(null)
[2016-10-07T20:15:32.318] _slurm_rpc_submit_batch_job JobId=1847 usec=598
[2016-10-07T20:15:32.318] job submit: job_id = 1847	time = 1475842532

[2016-10-07T20:15:32.324] gres: gpu state for job 1848
[2016-10-07T20:15:32.324]   gres_cnt:4 node_cnt:0 type:(null)
[2016-10-07T20:15:32.324] _slurm_rpc_submit_batch_job JobId=1848 usec=577
[2016-10-07T20:15:32.325] job submit: job_id = 1848	time = 1475842532

[2016-10-07T20:15:32.331] gres: gpu state for job 1849
[2016-10-07T20:15:32.331]   gres_cnt:6 node_cnt:0 type:(null)
[2016-10-07T20:15:32.332] _slurm_rpc_submit_batch_job JobId=1849 usec=641
[2016-10-07T20:15:32.332] job submit: job_id = 1849	time = 1475842532

[2016-10-07T20:15:32.340] gres: gpu state for job 1850
[2016-10-07T20:15:32.340]   gres_cnt:1 node_cnt:0 type:(null)
[2016-10-07T20:15:32.340] _slurm_rpc_submit_batch_job JobId=1850 usec=589
[2016-10-07T20:15:32.341] job submit: job_id = 1850	time = 1475842532

[2016-10-07T20:15:32.348] gres: gpu state for job 1851
[2016-10-07T20:15:32.348]   gres_cnt:6 node_cnt:0 type:(null)
[2016-10-07T20:15:32.348] _slurm_rpc_submit_batch_job JobId=1851 usec=570
[2016-10-07T20:15:32.349] job submit: job_id = 1851	time = 1475842532

[2016-10-07T20:15:32.356] gres: gpu state for job 1852
[2016-10-07T20:15:32.356]   gres_cnt:4 node_cnt:0 type:(null)
[2016-10-07T20:15:32.356] _slurm_rpc_submit_batch_job JobId=1852 usec=585
[2016-10-07T20:15:32.357] job submit: job_id = 1852	time = 1475842532

[2016-10-07T20:15:32.363] gres: gpu state for job 1853
[2016-10-07T20:15:32.363]   gres_cnt:2 node_cnt:0 type:(null)
[2016-10-07T20:15:32.363] _slurm_rpc_submit_batch_job JobId=1853 usec=583
[2016-10-07T20:15:32.364] job submit: job_id = 1853	time = 1475842532

[2016-10-07T20:15:32.371] gres: gpu state for job 1854
[2016-10-07T20:15:32.371]   gres_cnt:8 node_cnt:0 type:(null)
[2016-10-07T20:15:32.371] _slurm_rpc_submit_batch_job JobId=1854 usec=575
[2016-10-07T20:15:32.372] job submit: job_id = 1854	time = 1475842532

[2016-10-07T20:15:32.378] gres: gpu state for job 1855
[2016-10-07T20:15:32.378]   gres_cnt:3 node_cnt:0 type:(null)
[2016-10-07T20:15:32.379] _slurm_rpc_submit_batch_job JobId=1855 usec=581
[2016-10-07T20:15:32.379] job submit: job_id = 1855	time = 1475842532

[2016-10-07T20:15:32.385] gres: gpu state for job 1856
[2016-10-07T20:15:32.385]   gres_cnt:5 node_cnt:0 type:(null)
[2016-10-07T20:15:32.386] _slurm_rpc_submit_batch_job JobId=1856 usec=592
[2016-10-07T20:15:32.386] job submit: job_id = 1856	time = 1475842532

[2016-10-07T20:15:32.393] gres: gpu state for job 1857
[2016-10-07T20:15:32.393]   gres_cnt:7 node_cnt:0 type:(null)
[2016-10-07T20:15:32.393] _slurm_rpc_submit_batch_job JobId=1857 usec=639
[2016-10-07T20:15:32.394] job submit: job_id = 1857	time = 1475842532

[2016-10-07T20:15:32.400] gres: gpu state for job 1858
[2016-10-07T20:15:32.400]   gres_cnt:5 node_cnt:0 type:(null)
[2016-10-07T20:15:32.401] _slurm_rpc_submit_batch_job JobId=1858 usec=614
[2016-10-07T20:15:32.401] job submit: job_id = 1858	time = 1475842532

[2016-10-07T20:15:32.407] gres: gpu state for job 1859
[2016-10-07T20:15:32.407]   gres_cnt:7 node_cnt:0 type:(null)
[2016-10-07T20:15:32.408] _slurm_rpc_submit_batch_job JobId=1859 usec=572
[2016-10-07T20:15:32.408] job submit: job_id = 1859	time = 1475842532

[2016-10-07T20:15:32.414] gres: gpu state for job 1860
[2016-10-07T20:15:32.415]   gres_cnt:5 node_cnt:0 type:(null)
[2016-10-07T20:15:32.415] _slurm_rpc_submit_batch_job JobId=1860 usec=576
[2016-10-07T20:15:32.415] job submit: job_id = 1860	time = 1475842532

[2016-10-07T20:15:32.421] gres: gpu state for job 1861
[2016-10-07T20:15:32.421]   gres_cnt:3 node_cnt:0 type:(null)
[2016-10-07T20:15:32.422] _slurm_rpc_submit_batch_job JobId=1861 usec=568
[2016-10-07T20:15:32.422] job submit: job_id = 1861	time = 1475842532

[2016-10-07T20:15:32.429] gres: gpu state for job 1862
[2016-10-07T20:15:32.429]   gres_cnt:8 node_cnt:0 type:(null)
[2016-10-07T20:15:32.429] _slurm_rpc_submit_batch_job JobId=1862 usec=568
[2016-10-07T20:15:32.430] job submit: job_id = 1862	time = 1475842532

[2016-10-07T20:15:32.437] gres: gpu state for job 1863
[2016-10-07T20:15:32.437]   gres_cnt:5 node_cnt:0 type:(null)
[2016-10-07T20:15:32.437] _slurm_rpc_submit_batch_job JobId=1863 usec=582
[2016-10-07T20:15:32.438] job submit: job_id = 1863	time = 1475842532

[2016-10-07T20:15:32.443] gres: gpu state for job 1864
[2016-10-07T20:15:32.444]   gres_cnt:1 node_cnt:0 type:(null)
[2016-10-07T20:15:32.444] _slurm_rpc_submit_batch_job JobId=1864 usec=580
[2016-10-07T20:15:32.444] job submit: job_id = 1864	time = 1475842532

[2016-10-07T20:15:32.450] gres: gpu state for job 1865
[2016-10-07T20:15:32.450]   gres_cnt:6 node_cnt:0 type:(null)
[2016-10-07T20:15:32.451] _slurm_rpc_submit_batch_job JobId=1865 usec=573
[2016-10-07T20:15:32.451] job submit: job_id = 1865	time = 1475842532

[2016-10-07T20:15:32.458] gres: gpu state for job 1866
[2016-10-07T20:15:32.458]   gres_cnt:5 node_cnt:0 type:(null)
[2016-10-07T20:15:32.458] _slurm_rpc_submit_batch_job JobId=1866 usec=582
[2016-10-07T20:15:32.459] job submit: job_id = 1866	time = 1475842532

[2016-10-07T20:15:32.465] gres: gpu state for job 1867
[2016-10-07T20:15:32.465]   gres_cnt:8 node_cnt:0 type:(null)
[2016-10-07T20:15:32.466] _slurm_rpc_submit_batch_job JobId=1867 usec=574
[2016-10-07T20:15:32.466] job submit: job_id = 1867	time = 1475842532

[2016-10-07T20:15:32.473] gres: gpu state for job 1868
[2016-10-07T20:15:32.473]   gres_cnt:5 node_cnt:0 type:(null)
[2016-10-07T20:15:32.473] _slurm_rpc_submit_batch_job JobId=1868 usec=566
[2016-10-07T20:15:32.474] job submit: job_id = 1868	time = 1475842532

[2016-10-07T20:15:32.480] gres: gpu state for job 1869
[2016-10-07T20:15:32.480]   gres_cnt:6 node_cnt:0 type:(null)
[2016-10-07T20:15:32.480] _slurm_rpc_submit_batch_job JobId=1869 usec=578
[2016-10-07T20:15:32.481] job submit: job_id = 1869	time = 1475842532

[2016-10-07T20:15:32.488] gres: gpu state for job 1870
[2016-10-07T20:15:32.488]   gres_cnt:7 node_cnt:0 type:(null)
[2016-10-07T20:15:32.488] _slurm_rpc_submit_batch_job JobId=1870 usec=580
[2016-10-07T20:15:32.489] job submit: job_id = 1870	time = 1475842532

[2016-10-07T20:15:32.496] gres: gpu state for job 1871
[2016-10-07T20:15:32.496]   gres_cnt:6 node_cnt:0 type:(null)
[2016-10-07T20:15:32.497] _slurm_rpc_submit_batch_job JobId=1871 usec=606
[2016-10-07T20:15:32.497] job submit: job_id = 1871	time = 1475842532

[2016-10-07T20:15:32.503] gres: gpu state for job 1872
[2016-10-07T20:15:32.503]   gres_cnt:8 node_cnt:0 type:(null)
[2016-10-07T20:15:32.504] _slurm_rpc_submit_batch_job JobId=1872 usec=580
[2016-10-07T20:15:32.504] job submit: job_id = 1872	time = 1475842532

[2016-10-07T20:15:32.510] gres: gpu state for job 1873
[2016-10-07T20:15:32.510]   gres_cnt:1 node_cnt:0 type:(null)
[2016-10-07T20:15:32.511] _slurm_rpc_submit_batch_job JobId=1873 usec=589
[2016-10-07T20:15:32.511] job submit: job_id = 1873	time = 1475842532

[2016-10-07T20:15:32.517] gres: gpu state for job 1874
[2016-10-07T20:15:32.517]   gres_cnt:7 node_cnt:0 type:(null)
[2016-10-07T20:15:32.518] _slurm_rpc_submit_batch_job JobId=1874 usec=578
[2016-10-07T20:15:32.518] job submit: job_id = 1874	time = 1475842532

[2016-10-07T20:15:32.525] gres: gpu state for job 1875
[2016-10-07T20:15:32.525]   gres_cnt:3 node_cnt:0 type:(null)
[2016-10-07T20:15:32.525] _slurm_rpc_submit_batch_job JobId=1875 usec=607
[2016-10-07T20:15:32.526] job submit: job_id = 1875	time = 1475842532

[2016-10-07T20:15:32.532] gres: gpu state for job 1876
[2016-10-07T20:15:32.532]   gres_cnt:4 node_cnt:0 type:(null)
[2016-10-07T20:15:32.533] _slurm_rpc_submit_batch_job JobId=1876 usec=620
[2016-10-07T20:15:32.533] job submit: job_id = 1876	time = 1475842532

[2016-10-07T20:15:32.539] gres: gpu state for job 1877
[2016-10-07T20:15:32.539]   gres_cnt:5 node_cnt:0 type:(null)
[2016-10-07T20:15:32.540] _slurm_rpc_submit_batch_job JobId=1877 usec=574
[2016-10-07T20:15:32.540] job submit: job_id = 1877	time = 1475842532

[2016-10-07T20:15:32.546] gres: gpu state for job 1878
[2016-10-07T20:15:32.546]   gres_cnt:5 node_cnt:0 type:(null)
[2016-10-07T20:15:32.547] _slurm_rpc_submit_batch_job JobId=1878 usec=576
[2016-10-07T20:15:32.547] job submit: job_id = 1878	time = 1475842532

[2016-10-07T20:15:32.553] gres: gpu state for job 1879
[2016-10-07T20:15:32.553]   gres_cnt:6 node_cnt:0 type:(null)
[2016-10-07T20:15:32.554] _slurm_rpc_submit_batch_job JobId=1879 usec=593
[2016-10-07T20:15:32.554] job submit: job_id = 1879	time = 1475842532

[2016-10-07T20:15:32.561] gres: gpu state for job 1880
[2016-10-07T20:15:32.561]   gres_cnt:3 node_cnt:0 type:(null)
[2016-10-07T20:15:32.561] _slurm_rpc_submit_batch_job JobId=1880 usec=581
[2016-10-07T20:15:32.562] job submit: job_id = 1880	time = 1475842532

[2016-10-07T20:15:32.569] gres: gpu state for job 1881
[2016-10-07T20:15:32.569]   gres_cnt:2 node_cnt:0 type:(null)
[2016-10-07T20:15:32.569] _slurm_rpc_submit_batch_job JobId=1881 usec=588
[2016-10-07T20:15:32.570] job submit: job_id = 1881	time = 1475842532

[2016-10-07T20:15:32.576] gres: gpu state for job 1882
[2016-10-07T20:15:32.576]   gres_cnt:5 node_cnt:0 type:(null)
[2016-10-07T20:15:32.576] _slurm_rpc_submit_batch_job JobId=1882 usec=583
[2016-10-07T20:15:32.577] job submit: job_id = 1882	time = 1475842532

[2016-10-07T20:15:32.583] gres: gpu state for job 1883
[2016-10-07T20:15:32.583]   gres_cnt:2 node_cnt:0 type:(null)
[2016-10-07T20:15:32.583] _slurm_rpc_submit_batch_job JobId=1883 usec=578
[2016-10-07T20:15:32.584] job submit: job_id = 1883	time = 1475842532

[2016-10-07T20:15:32.590] gres: gpu state for job 1884
[2016-10-07T20:15:32.590]   gres_cnt:6 node_cnt:0 type:(null)
[2016-10-07T20:15:32.591] _slurm_rpc_submit_batch_job JobId=1884 usec=577
[2016-10-07T20:15:32.591] job submit: job_id = 1884	time = 1475842532

[2016-10-07T20:15:32.598] gres: gpu state for job 1885
[2016-10-07T20:15:32.598]   gres_cnt:2 node_cnt:0 type:(null)
[2016-10-07T20:15:32.599] _slurm_rpc_submit_batch_job JobId=1885 usec=568
[2016-10-07T20:15:32.599] job submit: job_id = 1885	time = 1475842532

[2016-10-07T20:15:32.606] gres: gpu state for job 1886
[2016-10-07T20:15:32.606]   gres_cnt:6 node_cnt:0 type:(null)
[2016-10-07T20:15:32.606] _slurm_rpc_submit_batch_job JobId=1886 usec=590
[2016-10-07T20:15:32.607] job submit: job_id = 1886	time = 1475842532

[2016-10-07T20:15:32.612] gres: gpu state for job 1887
[2016-10-07T20:15:32.612]   gres_cnt:8 node_cnt:0 type:(null)
[2016-10-07T20:15:32.613] _slurm_rpc_submit_batch_job JobId=1887 usec=596
[2016-10-07T20:15:32.613] job submit: job_id = 1887	time = 1475842532

[2016-10-07T20:15:32.619] gres: gpu state for job 1888
[2016-10-07T20:15:32.620]   gres_cnt:2 node_cnt:0 type:(null)
[2016-10-07T20:15:32.620] _slurm_rpc_submit_batch_job JobId=1888 usec=590
[2016-10-07T20:15:32.621] job submit: job_id = 1888	time = 1475842532

[2016-10-07T20:15:32.628] gres: gpu state for job 1889
[2016-10-07T20:15:32.628]   gres_cnt:5 node_cnt:0 type:(null)
[2016-10-07T20:15:32.628] _slurm_rpc_submit_batch_job JobId=1889 usec=584
[2016-10-07T20:15:32.629] job submit: job_id = 1889	time = 1475842532

[2016-10-07T20:15:32.636] gres: gpu state for job 1890
[2016-10-07T20:15:32.636]   gres_cnt:7 node_cnt:0 type:(null)
[2016-10-07T20:15:32.636] _slurm_rpc_submit_batch_job JobId=1890 usec=574
[2016-10-07T20:15:32.637] job submit: job_id = 1890	time = 1475842532

[2016-10-07T20:15:32.643] gres: gpu state for job 1891
[2016-10-07T20:15:32.643]   gres_cnt:7 node_cnt:0 type:(null)
[2016-10-07T20:15:32.644] _slurm_rpc_submit_batch_job JobId=1891 usec=577
[2016-10-07T20:15:32.644] job submit: job_id = 1891	time = 1475842532

[2016-10-07T20:15:32.650] gres: gpu state for job 1892
[2016-10-07T20:15:32.650]   gres_cnt:7 node_cnt:0 type:(null)
[2016-10-07T20:15:32.651] _slurm_rpc_submit_batch_job JobId=1892 usec=572
[2016-10-07T20:15:32.651] job submit: job_id = 1892	time = 1475842532

[2016-10-07T20:15:32.658] gres: gpu state for job 1893
[2016-10-07T20:15:32.658]   gres_cnt:1 node_cnt:0 type:(null)
[2016-10-07T20:15:32.658] _slurm_rpc_submit_batch_job JobId=1893 usec=597
[2016-10-07T20:15:32.659] job submit: job_id = 1893	time = 1475842532

[2016-10-07T20:15:32.666] gres: gpu state for job 1894
[2016-10-07T20:15:32.666]   gres_cnt:3 node_cnt:0 type:(null)
[2016-10-07T20:15:32.666] _slurm_rpc_submit_batch_job JobId=1894 usec=569
[2016-10-07T20:15:32.667] job submit: job_id = 1894	time = 1475842532

[2016-10-07T20:15:32.672] gres: gpu state for job 1895
[2016-10-07T20:15:32.672]   gres_cnt:7 node_cnt:0 type:(null)
[2016-10-07T20:15:32.673] _slurm_rpc_submit_batch_job JobId=1895 usec=598
[2016-10-07T20:15:32.673] job submit: job_id = 1895	time = 1475842532

[2016-10-07T20:15:32.679] gres: gpu state for job 1896
[2016-10-07T20:15:32.679]   gres_cnt:8 node_cnt:0 type:(null)
[2016-10-07T20:15:32.680] _slurm_rpc_submit_batch_job JobId=1896 usec=566
[2016-10-07T20:15:32.680] job submit: job_id = 1896	time = 1475842532

[2016-10-07T20:15:32.687] gres: gpu state for job 1897
[2016-10-07T20:15:32.687]   gres_cnt:7 node_cnt:0 type:(null)
[2016-10-07T20:15:32.687] _slurm_rpc_submit_batch_job JobId=1897 usec=587
[2016-10-07T20:15:32.688] job submit: job_id = 1897	time = 1475842532

[2016-10-07T20:15:32.694] gres: gpu state for job 1898
[2016-10-07T20:15:32.694]   gres_cnt:5 node_cnt:0 type:(null)
[2016-10-07T20:15:32.695] _slurm_rpc_submit_batch_job JobId=1898 usec=587
[2016-10-07T20:15:32.695] job submit: job_id = 1898	time = 1475842532

[2016-10-07T20:15:32.702] gres: gpu state for job 1899
[2016-10-07T20:15:32.702]   gres_cnt:1 node_cnt:0 type:(null)
[2016-10-07T20:15:32.702] _slurm_rpc_submit_batch_job JobId=1899 usec=587
[2016-10-07T20:15:32.703] job submit: job_id = 1899	time = 1475842532

[2016-10-07T20:15:32.708] gres: gpu state for job 1900
[2016-10-07T20:15:32.708]   gres_cnt:2 node_cnt:0 type:(null)
[2016-10-07T20:15:32.709] _slurm_rpc_submit_batch_job JobId=1900 usec=612
[2016-10-07T20:15:32.709] job submit: job_id = 1900	time = 1475842532

[2016-10-07T20:15:32.716] gres: gpu state for job 1901
[2016-10-07T20:15:32.716]   gres_cnt:6 node_cnt:0 type:(null)
[2016-10-07T20:15:32.716] _slurm_rpc_submit_batch_job JobId=1901 usec=582
[2016-10-07T20:15:32.717] job submit: job_id = 1901	time = 1475842532

[2016-10-07T20:15:32.724] gres: gpu state for job 1902
[2016-10-07T20:15:32.724]   gres_cnt:4 node_cnt:0 type:(null)
[2016-10-07T20:15:32.724] _slurm_rpc_submit_batch_job JobId=1902 usec=578
[2016-10-07T20:15:32.725] job submit: job_id = 1902	time = 1475842532

[2016-10-07T20:15:32.731] gres: gpu state for job 1903
[2016-10-07T20:15:32.731]   gres_cnt:8 node_cnt:0 type:(null)
[2016-10-07T20:15:32.732] _slurm_rpc_submit_batch_job JobId=1903 usec=592
[2016-10-07T20:15:32.732] job submit: job_id = 1903	time = 1475842532

[2016-10-07T20:15:32.738] gres: gpu state for job 1904
[2016-10-07T20:15:32.739]   gres_cnt:1 node_cnt:0 type:(null)
[2016-10-07T20:15:32.739] _slurm_rpc_submit_batch_job JobId=1904 usec=572
[2016-10-07T20:15:32.740] job submit: job_id = 1904	time = 1475842532

[2016-10-07T20:15:32.745] gres: gpu state for job 1905
[2016-10-07T20:15:32.745]   gres_cnt:1 node_cnt:0 type:(null)
[2016-10-07T20:15:32.746] _slurm_rpc_submit_batch_job JobId=1905 usec=585
[2016-10-07T20:15:32.746] job submit: job_id = 1905	time = 1475842532

[2016-10-07T20:15:32.753] gres: gpu state for job 1906
[2016-10-07T20:15:32.753]   gres_cnt:2 node_cnt:0 type:(null)
[2016-10-07T20:15:32.753] _slurm_rpc_submit_batch_job JobId=1906 usec=579
[2016-10-07T20:15:32.754] job submit: job_id = 1906	time = 1475842532

[2016-10-07T20:15:32.760] gres: gpu state for job 1907
[2016-10-07T20:15:32.760]   gres_cnt:8 node_cnt:0 type:(null)
[2016-10-07T20:15:32.761] _slurm_rpc_submit_batch_job JobId=1907 usec=633
[2016-10-07T20:15:32.761] job submit: job_id = 1907	time = 1475842532

[2016-10-07T20:15:32.767] gres: gpu state for job 1908
[2016-10-07T20:15:32.768]   gres_cnt:5 node_cnt:0 type:(null)
[2016-10-07T20:15:32.768] _slurm_rpc_submit_batch_job JobId=1908 usec=581
[2016-10-07T20:15:32.768] job submit: job_id = 1908	time = 1475842532

[2016-10-07T20:15:32.774] gres: gpu state for job 1909
[2016-10-07T20:15:32.774]   gres_cnt:2 node_cnt:0 type:(null)
[2016-10-07T20:15:32.775] _slurm_rpc_submit_batch_job JobId=1909 usec=585
[2016-10-07T20:15:32.775] job submit: job_id = 1909	time = 1475842532

[2016-10-07T20:15:32.781] gres: gpu state for job 1910
[2016-10-07T20:15:32.782]   gres_cnt:5 node_cnt:0 type:(null)
[2016-10-07T20:15:32.782] _slurm_rpc_submit_batch_job JobId=1910 usec=565
[2016-10-07T20:15:32.782] job submit: job_id = 1910	time = 1475842532

[2016-10-07T20:15:32.789] gres: gpu state for job 1911
[2016-10-07T20:15:32.789]   gres_cnt:8 node_cnt:0 type:(null)
[2016-10-07T20:15:32.789] _slurm_rpc_submit_batch_job JobId=1911 usec=580
[2016-10-07T20:15:32.790] job submit: job_id = 1911	time = 1475842532

[2016-10-07T20:15:32.797] gres: gpu state for job 1912
[2016-10-07T20:15:32.797]   gres_cnt:8 node_cnt:0 type:(null)
[2016-10-07T20:15:32.797] _slurm_rpc_submit_batch_job JobId=1912 usec=570
[2016-10-07T20:15:32.798] job submit: job_id = 1912	time = 1475842532

[2016-10-07T20:15:32.804] gres: gpu state for job 1913
[2016-10-07T20:15:32.804]   gres_cnt:4 node_cnt:0 type:(null)
[2016-10-07T20:15:32.804] _slurm_rpc_submit_batch_job JobId=1913 usec=576
[2016-10-07T20:15:32.805] job submit: job_id = 1913	time = 1475842532

[2016-10-07T20:15:32.811] gres: gpu state for job 1914
[2016-10-07T20:15:32.811]   gres_cnt:2 node_cnt:0 type:(null)
[2016-10-07T20:15:32.811] _slurm_rpc_submit_batch_job JobId=1914 usec=565
[2016-10-07T20:15:32.812] job submit: job_id = 1914	time = 1475842532

[2016-10-07T20:15:32.818] gres: gpu state for job 1915
[2016-10-07T20:15:32.818]   gres_cnt:5 node_cnt:0 type:(null)
[2016-10-07T20:15:32.819] _slurm_rpc_submit_batch_job JobId=1915 usec=589
[2016-10-07T20:15:32.819] job submit: job_id = 1915	time = 1475842532

[2016-10-07T20:15:32.826] gres: gpu state for job 1916
[2016-10-07T20:15:32.826]   gres_cnt:6 node_cnt:0 type:(null)
[2016-10-07T20:15:32.827] _slurm_rpc_submit_batch_job JobId=1916 usec=579
[2016-10-07T20:15:32.827] job submit: job_id = 1916	time = 1475842532

[2016-10-07T20:15:32.834] gres: gpu state for job 1917
[2016-10-07T20:15:32.834]   gres_cnt:6 node_cnt:0 type:(null)
[2016-10-07T20:15:32.834] _slurm_rpc_submit_batch_job JobId=1917 usec=571
[2016-10-07T20:15:32.835] job submit: job_id = 1917	time = 1475842532

[2016-10-07T20:15:32.840] gres: gpu state for job 1918
[2016-10-07T20:15:32.840]   gres_cnt:7 node_cnt:0 type:(null)
[2016-10-07T20:15:32.841] _slurm_rpc_submit_batch_job JobId=1918 usec=594
[2016-10-07T20:15:32.841] job submit: job_id = 1918	time = 1475842532

[2016-10-07T20:15:32.847] gres: gpu state for job 1919
[2016-10-07T20:15:32.848]   gres_cnt:6 node_cnt:0 type:(null)
[2016-10-07T20:15:32.848] _slurm_rpc_submit_batch_job JobId=1919 usec=571
[2016-10-07T20:15:32.849] job submit: job_id = 1919	time = 1475842532

[2016-10-07T20:15:32.855] gres: gpu state for job 1920
[2016-10-07T20:15:32.855]   gres_cnt:8 node_cnt:0 type:(null)
[2016-10-07T20:15:32.856] _slurm_rpc_submit_batch_job JobId=1920 usec=586
[2016-10-07T20:15:32.856] job submit: job_id = 1920	time = 1475842532

[2016-10-07T20:15:32.863] gres: gpu state for job 1921
[2016-10-07T20:15:32.863]   gres_cnt:5 node_cnt:0 type:(null)
[2016-10-07T20:15:32.863] _slurm_rpc_submit_batch_job JobId=1921 usec=588
[2016-10-07T20:15:32.864] job submit: job_id = 1921	time = 1475842532

[2016-10-07T20:15:32.870] gres: gpu state for job 1922
[2016-10-07T20:15:32.870]   gres_cnt:8 node_cnt:0 type:(null)
[2016-10-07T20:15:32.871] _slurm_rpc_submit_batch_job JobId=1922 usec=571
[2016-10-07T20:15:32.871] job submit: job_id = 1922	time = 1475842532

[2016-10-07T20:15:32.877] gres: gpu state for job 1923
[2016-10-07T20:15:32.877]   gres_cnt:4 node_cnt:0 type:(null)
[2016-10-07T20:15:32.877] _slurm_rpc_submit_batch_job JobId=1923 usec=576
[2016-10-07T20:15:32.878] job submit: job_id = 1923	time = 1475842532

[2016-10-07T20:15:32.884] gres: gpu state for job 1924
[2016-10-07T20:15:32.884]   gres_cnt:4 node_cnt:0 type:(null)
[2016-10-07T20:15:32.885] _slurm_rpc_submit_batch_job JobId=1924 usec=635
[2016-10-07T20:15:32.885] job submit: job_id = 1924	time = 1475842532

[2016-10-07T20:15:32.892] gres: gpu state for job 1925
[2016-10-07T20:15:32.892]   gres_cnt:2 node_cnt:0 type:(null)
[2016-10-07T20:15:32.893] _slurm_rpc_submit_batch_job JobId=1925 usec=599
[2016-10-07T20:15:32.893] job submit: job_id = 1925	time = 1475842532

[2016-10-07T20:15:32.899] gres: gpu state for job 1926
[2016-10-07T20:15:32.899]   gres_cnt:8 node_cnt:0 type:(null)
[2016-10-07T20:15:32.900] _slurm_rpc_submit_batch_job JobId=1926 usec=571
[2016-10-07T20:15:32.900] job submit: job_id = 1926	time = 1475842532

[2016-10-07T20:15:32.906] gres: gpu state for job 1927
[2016-10-07T20:15:32.906]   gres_cnt:8 node_cnt:0 type:(null)
[2016-10-07T20:15:32.907] _slurm_rpc_submit_batch_job JobId=1927 usec=580
[2016-10-07T20:15:32.907] job submit: job_id = 1927	time = 1475842532

[2016-10-07T20:15:33.072] gres: gpu state for job 1828
[2016-10-07T20:15:33.072]   gres_cnt:8 node_cnt:1 type:(null)
[2016-10-07T20:15:33.072]   gres_bit_step_alloc:NULL
[2016-10-07T20:15:33.072]   gres_cnt_step_alloc:NULL
[2016-10-07T20:15:33.072]   gres_bit_alloc[0]:0-7
[2016-10-07T20:15:33.072] backfill: Started JobId=1828 in partition on gpu-cluster-1
[2016-10-07T20:15:33.072] job start: job_id = 1828	time = 1475842533

[2016-10-07T20:15:33.073] gres: gpu state for job 1829
[2016-10-07T20:15:33.073]   gres_cnt:4 node_cnt:1 type:(null)
[2016-10-07T20:15:33.073]   gres_bit_step_alloc:NULL
[2016-10-07T20:15:33.073]   gres_cnt_step_alloc:NULL
[2016-10-07T20:15:33.073]   gres_bit_alloc[0]:0-3
[2016-10-07T20:15:33.073] backfill: Started JobId=1829 in partition on gpu-cluster-1
[2016-10-07T20:15:33.074] job start: job_id = 1829	time = 1475842533

[2016-10-07T20:15:33.074] gres: gpu state for job 1830
[2016-10-07T20:15:33.074]   gres_cnt:6 node_cnt:2 type:(null)
[2016-10-07T20:15:33.074]   gres_bit_step_alloc:NULL
[2016-10-07T20:15:33.074]   gres_cnt_step_alloc:NULL
[2016-10-07T20:15:33.074]   gres_bit_alloc[0]:4-7
[2016-10-07T20:15:33.074]   gres_bit_alloc[1]:0-1
[2016-10-07T20:15:33.074] backfill: Started JobId=1830 in partition on gpu-cluster-1
[2016-10-07T20:15:33.075] job start: job_id = 1830	time = 1475842533

[2016-10-07T20:15:33.075] gres: gpu state for job 1831
[2016-10-07T20:15:33.075]   gres_cnt:8 node_cnt:2 type:(null)
[2016-10-07T20:15:33.075]   gres_bit_step_alloc:NULL
[2016-10-07T20:15:33.075]   gres_cnt_step_alloc:NULL
[2016-10-07T20:15:33.075]   gres_bit_alloc[0]:2-7
[2016-10-07T20:15:33.075]   gres_bit_alloc[1]:0-1
[2016-10-07T20:15:33.075] backfill: Started JobId=1831 in partition on gpu-cluster-1
[2016-10-07T20:15:33.076] job start: job_id = 1831	time = 1475842533

[2016-10-07T20:15:33.076] gres: gpu state for job 1832
[2016-10-07T20:15:33.076]   gres_cnt:2 node_cnt:1 type:(null)
[2016-10-07T20:15:33.076]   gres_bit_step_alloc:NULL
[2016-10-07T20:15:33.077]   gres_cnt_step_alloc:NULL
[2016-10-07T20:15:33.077]   gres_bit_alloc[0]:2-3
[2016-10-07T20:15:33.077] backfill: Started JobId=1832 in partition on gpu-cluster-1
[2016-10-07T20:15:33.077] job start: job_id = 1832	time = 1475842533

[2016-10-07T20:15:33.077] gres: gpu state for job 1833
[2016-10-07T20:15:33.078]   gres_cnt:3 node_cnt:1 type:(null)
[2016-10-07T20:15:33.078]   gres_bit_step_alloc:NULL
[2016-10-07T20:15:33.078]   gres_cnt_step_alloc:NULL
[2016-10-07T20:15:33.078]   gres_bit_alloc[0]:4-6
[2016-10-07T20:15:33.078] backfill: Started JobId=1833 in partition on gpu-cluster-1
[2016-10-07T20:15:33.078] job start: job_id = 1833	time = 1475842533

[2016-10-07T20:15:33.080] gres: gpu state for job 1839
[2016-10-07T20:15:33.080]   gres_cnt:1 node_cnt:1 type:(null)
[2016-10-07T20:15:33.080]   gres_bit_step_alloc:NULL
[2016-10-07T20:15:33.080]   gres_cnt_step_alloc:NULL
[2016-10-07T20:15:33.080]   gres_bit_alloc[0]:7
[2016-10-07T20:15:33.080] backfill: Started JobId=1839 in partition on gpu-cluster-1
[2016-10-07T20:15:33.081] job start: job_id = 1839	time = 1475842533

[2016-10-07T20:15:33.607] job_complete: JobID=1831 State=0x1 NodeCnt=1 WEXITSTATUS 255
[2016-10-07T20:15:33.607] job end: job_id = 1831	time = 1475842533

[2016-10-07T20:15:33.607] job_complete: JobID=1831 State=0x8005 NodeCnt=1 done
[2016-10-07T20:15:33.612] gres: gpu state for job 1834
[2016-10-07T20:15:33.612]   gres_cnt:4 node_cnt:1 type:(null)
[2016-10-07T20:15:33.612]   gres_bit_step_alloc:NULL
[2016-10-07T20:15:33.612]   gres_cnt_step_alloc:NULL
[2016-10-07T20:15:33.612]   gres_bit_alloc[0]:2-5
[2016-10-07T20:15:33.612] sched: Allocate JobID=1834 NodeList=gpu-cluster-1 #CPUs=1 Partition=partition
[2016-10-07T20:15:33.612] job start: job_id = 1834	time = 1475842533

[2016-10-07T20:15:33.613] gres: gpu state for job 1835
[2016-10-07T20:15:33.613]   gres_cnt:2 node_cnt:1 type:(null)
[2016-10-07T20:15:33.613]   gres_bit_step_alloc:NULL
[2016-10-07T20:15:33.613]   gres_cnt_step_alloc:NULL
[2016-10-07T20:15:33.613]   gres_bit_alloc[0]:6-7
[2016-10-07T20:15:33.613] sched: Allocate JobID=1835 NodeList=gpu-cluster-1 #CPUs=1 Partition=partition
[2016-10-07T20:15:33.613] job start: job_id = 1835	time = 1475842533

[2016-10-07T20:15:33.649] job_complete: JobID=1832 State=0x1 NodeCnt=1 WEXITSTATUS 255
[2016-10-07T20:15:33.649] job end: job_id = 1832	time = 1475842533

[2016-10-07T20:15:33.649] job_complete: JobID=1832 State=0x8005 NodeCnt=1 done
[2016-10-07T20:15:33.650] job_complete: JobID=1839 State=0x1 NodeCnt=1 WEXITSTATUS 255
[2016-10-07T20:15:33.650] job end: job_id = 1839	time = 1475842533

[2016-10-07T20:15:33.650] job_complete: JobID=1839 State=0x8005 NodeCnt=1 done
[2016-10-07T20:15:33.654] job_complete: JobID=1833 State=0x1 NodeCnt=1 WEXITSTATUS 255
[2016-10-07T20:15:33.654] job end: job_id = 1833	time = 1475842533

[2016-10-07T20:15:33.655] job_complete: JobID=1833 State=0x8005 NodeCnt=1 done
[2016-10-07T20:15:33.655] gres: gpu state for job 1836
[2016-10-07T20:15:33.655]   gres_cnt:8 node_cnt:1 type:(null)
[2016-10-07T20:15:33.655]   gres_bit_step_alloc:NULL
[2016-10-07T20:15:33.655]   gres_cnt_step_alloc:NULL
[2016-10-07T20:15:33.655]   gres_bit_alloc[0]:0-7
[2016-10-07T20:15:33.655] sched: Allocate JobID=1836 NodeList=gpu-cluster-2 #CPUs=1 Partition=partition
[2016-10-07T20:15:33.655] job start: job_id = 1836	time = 1475842533

[2016-10-07T20:15:33.664] job_complete: JobID=1836 State=0x1 NodeCnt=1 WEXITSTATUS 1
[2016-10-07T20:15:33.664] job end: job_id = 1836	time = 1475842533

[2016-10-07T20:15:33.664] job_complete: JobID=1836 State=0x8005 NodeCnt=1 done
[2016-10-07T20:15:33.669] gres: gpu state for job 1837
[2016-10-07T20:15:33.669]   gres_cnt:5 node_cnt:1 type:(null)
[2016-10-07T20:15:33.669]   gres_bit_step_alloc:NULL
[2016-10-07T20:15:33.669]   gres_cnt_step_alloc:NULL
[2016-10-07T20:15:33.669]   gres_bit_alloc[0]:0-4
[2016-10-07T20:15:33.670] sched: Allocate JobID=1837 NodeList=gpu-cluster-1 #CPUs=1 Partition=partition
[2016-10-07T20:15:33.670] job start: job_id = 1837	time = 1475842533

[2016-10-07T20:15:33.806] job_complete: JobID=1829 State=0x1 NodeCnt=1 WEXITSTATUS 255
[2016-10-07T20:15:33.806] job end: job_id = 1829	time = 1475842533

[2016-10-07T20:15:33.806] job_complete: JobID=1829 State=0x8005 NodeCnt=1 done
[2016-10-07T20:15:33.811] gres: gpu state for job 1838
[2016-10-07T20:15:33.811]   gres_cnt:4 node_cnt:1 type:(null)
[2016-10-07T20:15:33.811]   gres_bit_step_alloc:NULL
[2016-10-07T20:15:33.811]   gres_cnt_step_alloc:NULL
[2016-10-07T20:15:33.811]   gres_bit_alloc[0]:0-3
[2016-10-07T20:15:33.811] sched: Allocate JobID=1838 NodeList=gpu-cluster-1 #CPUs=1 Partition=partition
[2016-10-07T20:15:33.812] job start: job_id = 1838	time = 1475842533

[2016-10-07T20:15:33.812] gres: gpu state for job 1840
[2016-10-07T20:15:33.812]   gres_cnt:2 node_cnt:1 type:(null)
[2016-10-07T20:15:33.812]   gres_bit_step_alloc:NULL
[2016-10-07T20:15:33.812]   gres_cnt_step_alloc:NULL
[2016-10-07T20:15:33.812]   gres_bit_alloc[0]:5-6
[2016-10-07T20:15:33.812] sched: Allocate JobID=1840 NodeList=gpu-cluster-1 #CPUs=1 Partition=partition
[2016-10-07T20:15:33.812] job start: job_id = 1840	time = 1475842533

[2016-10-07T20:15:33.873] job_complete: JobID=1830 State=0x1 NodeCnt=1 WEXITSTATUS 255
[2016-10-07T20:15:33.873] job end: job_id = 1830	time = 1475842533

[2016-10-07T20:15:33.873] job_complete: JobID=1830 State=0x8005 NodeCnt=1 done
[2016-10-07T20:15:33.878] gres: gpu state for job 1841
[2016-10-07T20:15:33.878]   gres_cnt:7 node_cnt:3 type:(null)
[2016-10-07T20:15:33.878]   gres_bit_step_alloc:NULL
[2016-10-07T20:15:33.878]   gres_cnt_step_alloc:NULL
[2016-10-07T20:15:33.878]   gres_bit_alloc[0]:4-7
[2016-10-07T20:15:33.878]   gres_bit_alloc[1]:0-1
[2016-10-07T20:15:33.878]   gres_bit_alloc[2]:7
[2016-10-07T20:15:33.878] sched: Allocate JobID=1841 NodeList=gpu-cluster-1 #CPUs=1 Partition=partition
[2016-10-07T20:15:33.879] job start: job_id = 1841	time = 1475842533

[2016-10-07T20:15:34.241] job_complete: JobID=1837 State=0x1 NodeCnt=1 WEXITSTATUS 255
[2016-10-07T20:15:34.241] job end: job_id = 1837	time = 1475842534

[2016-10-07T20:15:34.241] job_complete: JobID=1837 State=0x8005 NodeCnt=1 done
[2016-10-07T20:15:34.357] job_complete: JobID=1840 State=0x1 NodeCnt=1 WEXITSTATUS 255
[2016-10-07T20:15:34.357] job end: job_id = 1840	time = 1475842534

[2016-10-07T20:15:34.357] job_complete: JobID=1840 State=0x8005 NodeCnt=1 done
[2016-10-07T20:15:34.363] gres: gpu state for job 1842
[2016-10-07T20:15:34.363]   gres_cnt:6 node_cnt:1 type:(null)
[2016-10-07T20:15:34.363]   gres_bit_step_alloc:NULL
[2016-10-07T20:15:34.363]   gres_cnt_step_alloc:NULL
[2016-10-07T20:15:34.363]   gres_bit_alloc[0]:0-5
[2016-10-07T20:15:34.363] sched: Allocate JobID=1842 NodeList=gpu-cluster-1 #CPUs=1 Partition=partition
[2016-10-07T20:15:34.363] job start: job_id = 1842	time = 1475842534

[2016-10-07T20:15:34.396] job_complete: JobID=1841 State=0x1 NodeCnt=1 WEXITSTATUS 255
[2016-10-07T20:15:34.397] job end: job_id = 1841	time = 1475842534

[2016-10-07T20:15:34.397] job_complete: JobID=1841 State=0x8005 NodeCnt=1 done
[2016-10-07T20:15:34.402] gres: gpu state for job 1843
[2016-10-07T20:15:34.402]   gres_cnt:2 node_cnt:1 type:(null)
[2016-10-07T20:15:34.402]   gres_bit_step_alloc:NULL
[2016-10-07T20:15:34.402]   gres_cnt_step_alloc:NULL
[2016-10-07T20:15:34.402]   gres_bit_alloc[0]:4-5
[2016-10-07T20:15:34.402] sched: Allocate JobID=1843 NodeList=gpu-cluster-1 #CPUs=1 Partition=partition
[2016-10-07T20:15:34.402] job start: job_id = 1843	time = 1475842534

[2016-10-07T20:15:34.486] job_complete: JobID=1834 State=0x1 NodeCnt=1 WEXITSTATUS 255
[2016-10-07T20:15:34.486] job end: job_id = 1834	time = 1475842534

[2016-10-07T20:15:34.486] job_complete: JobID=1834 State=0x8005 NodeCnt=1 done
[2016-10-07T20:15:34.492] gres: gpu state for job 1844
[2016-10-07T20:15:34.492]   gres_cnt:7 node_cnt:2 type:(null)
[2016-10-07T20:15:34.492]   gres_bit_step_alloc:NULL
[2016-10-07T20:15:34.492]   gres_cnt_step_alloc:NULL
[2016-10-07T20:15:34.492]   gres_bit_alloc[0]:6-7
[2016-10-07T20:15:34.492]   gres_bit_alloc[1]:0-4
[2016-10-07T20:15:34.492] sched: Allocate JobID=1844 NodeList=gpu-cluster-1 #CPUs=1 Partition=partition
[2016-10-07T20:15:34.492] job start: job_id = 1844	time = 1475842534

[2016-10-07T20:15:34.502] job_complete: JobID=1835 State=0x1 NodeCnt=1 WEXITSTATUS 255
[2016-10-07T20:15:34.502] job end: job_id = 1835	time = 1475842534

[2016-10-07T20:15:34.502] job_complete: JobID=1835 State=0x8005 NodeCnt=1 done
[2016-10-07T20:15:34.622] job_complete: JobID=1838 State=0x1 NodeCnt=1 WEXITSTATUS 255
[2016-10-07T20:15:34.622] job end: job_id = 1838	time = 1475842534

[2016-10-07T20:15:34.622] job_complete: JobID=1838 State=0x8005 NodeCnt=1 done
[2016-10-07T20:15:34.628] gres: gpu state for job 1845
[2016-10-07T20:15:34.628]   gres_cnt:8 node_cnt:3 type:(null)
[2016-10-07T20:15:34.628]   gres_bit_step_alloc:NULL
[2016-10-07T20:15:34.628]   gres_cnt_step_alloc:NULL
[2016-10-07T20:15:34.628]   gres_bit_alloc[0]:0-3
[2016-10-07T20:15:34.628]   gres_bit_alloc[1]:5-7
[2016-10-07T20:15:34.628]   gres_bit_alloc[2]:6
[2016-10-07T20:15:34.628] sched: Allocate JobID=1845 NodeList=gpu-cluster-1 #CPUs=1 Partition=partition
[2016-10-07T20:15:34.628] job start: job_id = 1845	time = 1475842534

[2016-10-07T20:15:34.935] job_complete: JobID=1842 State=0x1 NodeCnt=1 WEXITSTATUS 255
[2016-10-07T20:15:34.935] job end: job_id = 1842	time = 1475842534

[2016-10-07T20:15:34.935] job_complete: JobID=1842 State=0x8005 NodeCnt=1 done
[2016-10-07T20:15:34.940] gres: gpu state for job 1846
[2016-10-07T20:15:34.940]   gres_cnt:6 node_cnt:1 type:(null)
[2016-10-07T20:15:34.940]   gres_bit_step_alloc:NULL
[2016-10-07T20:15:34.940]   gres_cnt_step_alloc:NULL
[2016-10-07T20:15:34.940]   gres_bit_alloc[0]:0-5
[2016-10-07T20:15:34.940] sched: Allocate JobID=1846 NodeList=gpu-cluster-1 #CPUs=1 Partition=partition
[2016-10-07T20:15:34.941] job start: job_id = 1846	time = 1475842534

[2016-10-07T20:15:35.095] job_complete: JobID=1845 State=0x1 NodeCnt=1 WEXITSTATUS 255
[2016-10-07T20:15:35.095] job end: job_id = 1845	time = 1475842535

[2016-10-07T20:15:35.095] job_complete: JobID=1845 State=0x8005 NodeCnt=1 done
[2016-10-07T20:15:35.101] gres: gpu state for job 1847
[2016-10-07T20:15:35.101]   gres_cnt:7 node_cnt:2 type:(null)
[2016-10-07T20:15:35.101]   gres_bit_step_alloc:NULL
[2016-10-07T20:15:35.101]   gres_cnt_step_alloc:NULL
[2016-10-07T20:15:35.101]   gres_bit_alloc[0]:0-3
[2016-10-07T20:15:35.101]   gres_bit_alloc[1]:5-7
[2016-10-07T20:15:35.101] sched: Allocate JobID=1847 NodeList=gpu-cluster-1 #CPUs=1 Partition=partition
[2016-10-07T20:15:35.101] job start: job_id = 1847	time = 1475842535

[2016-10-07T20:15:35.201] job_complete: JobID=1843 State=0x1 NodeCnt=1 WEXITSTATUS 255
[2016-10-07T20:15:35.201] job end: job_id = 1843	time = 1475842535

[2016-10-07T20:15:35.201] job_complete: JobID=1843 State=0x8005 NodeCnt=1 done
[2016-10-07T20:15:35.207] gres: gpu state for job 1848
[2016-10-07T20:15:35.207]   gres_cnt:4 node_cnt:2 type:(null)
[2016-10-07T20:15:35.207]   gres_bit_step_alloc:NULL
[2016-10-07T20:15:35.207]   gres_cnt_step_alloc:NULL
[2016-10-07T20:15:35.207]   gres_bit_alloc[0]:4-5
[2016-10-07T20:15:35.207]   gres_bit_alloc[1]:6-7
[2016-10-07T20:15:35.207] sched: Allocate JobID=1848 NodeList=gpu-cluster-1 #CPUs=1 Partition=partition
[2016-10-07T20:15:35.207] job start: job_id = 1848	time = 1475842535

[2016-10-07T20:15:35.342] job_complete: JobID=1844 State=0x1 NodeCnt=1 WEXITSTATUS 255
[2016-10-07T20:15:35.342] job end: job_id = 1844	time = 1475842535

[2016-10-07T20:15:35.342] job_complete: JobID=1844 State=0x8005 NodeCnt=1 done
[2016-10-07T20:15:35.347] gres: gpu state for job 1849
[2016-10-07T20:15:35.347]   gres_cnt:6 node_cnt:2 type:(null)
[2016-10-07T20:15:35.347]   gres_bit_step_alloc:NULL
[2016-10-07T20:15:35.347]   gres_cnt_step_alloc:NULL
[2016-10-07T20:15:35.347]   gres_bit_alloc[0]:6-7
[2016-10-07T20:15:35.347]   gres_bit_alloc[1]:0-3
[2016-10-07T20:15:35.347] sched: Allocate JobID=1849 NodeList=gpu-cluster-1 #CPUs=1 Partition=partition
[2016-10-07T20:15:35.347] job start: job_id = 1849	time = 1475842535

[2016-10-07T20:15:35.348] gres: gpu state for job 1850
[2016-10-07T20:15:35.348]   gres_cnt:1 node_cnt:1 type:(null)
[2016-10-07T20:15:35.348]   gres_bit_step_alloc:NULL
[2016-10-07T20:15:35.348]   gres_cnt_step_alloc:NULL
[2016-10-07T20:15:35.348]   gres_bit_alloc[0]:4
[2016-10-07T20:15:35.348] sched: Allocate JobID=1850 NodeList=gpu-cluster-1 #CPUs=1 Partition=partition
[2016-10-07T20:15:35.349] job start: job_id = 1850	time = 1475842535

[2016-10-07T20:15:35.424] job_complete: JobID=1846 State=0x1 NodeCnt=1 WEXITSTATUS 255
[2016-10-07T20:15:35.424] job end: job_id = 1846	time = 1475842535

[2016-10-07T20:15:35.425] job_complete: JobID=1846 State=0x8005 NodeCnt=1 done
[2016-10-07T20:15:35.431] gres: gpu state for job 1851
[2016-10-07T20:15:35.431]   gres_cnt:6 node_cnt:1 type:(null)
[2016-10-07T20:15:35.431]   gres_bit_step_alloc:NULL
[2016-10-07T20:15:35.431]   gres_cnt_step_alloc:NULL
[2016-10-07T20:15:35.431]   gres_bit_alloc[0]:0-5
[2016-10-07T20:15:35.431] sched: Allocate JobID=1851 NodeList=gpu-cluster-1 #CPUs=1 Partition=partition
[2016-10-07T20:15:35.432] job start: job_id = 1851	time = 1475842535

[2016-10-07T20:15:35.764] job_complete: JobID=1847 State=0x1 NodeCnt=1 WEXITSTATUS 255
[2016-10-07T20:15:35.764] job end: job_id = 1847	time = 1475842535

[2016-10-07T20:15:35.764] job_complete: JobID=1847 State=0x8005 NodeCnt=1 done
[2016-10-07T20:15:35.770] gres: gpu state for job 1852
[2016-10-07T20:15:35.770]   gres_cnt:4 node_cnt:1 type:(null)
[2016-10-07T20:15:35.770]   gres_bit_step_alloc:NULL
[2016-10-07T20:15:35.770]   gres_cnt_step_alloc:NULL
[2016-10-07T20:15:35.770]   gres_bit_alloc[0]:0-3
[2016-10-07T20:15:35.770] sched: Allocate JobID=1852 NodeList=gpu-cluster-1 #CPUs=1 Partition=partition
[2016-10-07T20:15:35.770] job start: job_id = 1852	time = 1475842535

[2016-10-07T20:15:35.770] gres: gpu state for job 1853
[2016-10-07T20:15:35.770]   gres_cnt:2 node_cnt:1 type:(null)
[2016-10-07T20:15:35.770]   gres_bit_step_alloc:NULL
[2016-10-07T20:15:35.770]   gres_cnt_step_alloc:NULL
[2016-10-07T20:15:35.770]   gres_bit_alloc[0]:5-6
[2016-10-07T20:15:35.770] sched: Allocate JobID=1853 NodeList=gpu-cluster-1 #CPUs=1 Partition=partition
[2016-10-07T20:15:35.770] job start: job_id = 1853	time = 1475842535

[2016-10-07T20:15:35.778] job_complete: JobID=1848 State=0x1 NodeCnt=1 WEXITSTATUS 255
[2016-10-07T20:15:35.778] job end: job_id = 1848	time = 1475842535

[2016-10-07T20:15:35.778] job_complete: JobID=1848 State=0x8005 NodeCnt=1 done
[2016-10-07T20:15:35.923] job_complete: JobID=1851 State=0x1 NodeCnt=1 WEXITSTATUS 255
[2016-10-07T20:15:35.923] job end: job_id = 1851	time = 1475842535

[2016-10-07T20:15:35.923] job_complete: JobID=1851 State=0x8005 NodeCnt=1 done
[2016-10-07T20:15:35.928] gres: gpu state for job 1854
[2016-10-07T20:15:35.928]   gres_cnt:8 node_cnt:3 type:(null)
[2016-10-07T20:15:35.928]   gres_bit_step_alloc:NULL
[2016-10-07T20:15:35.928]   gres_cnt_step_alloc:NULL
[2016-10-07T20:15:35.928]   gres_bit_alloc[0]:4-5
[2016-10-07T20:15:35.928]   gres_bit_alloc[1]:7
[2016-10-07T20:15:35.928]   gres_bit_alloc[2]:0-4
[2016-10-07T20:15:35.928] sched: Allocate JobID=1854 NodeList=gpu-cluster-1 #CPUs=1 Partition=partition
[2016-10-07T20:15:35.929] job start: job_id = 1854	time = 1475842535

[2016-10-07T20:15:35.929] gres: gpu state for job 1855
[2016-10-07T20:15:35.929]   gres_cnt:3 node_cnt:1 type:(null)
[2016-10-07T20:15:35.929]   gres_bit_step_alloc:NULL
[2016-10-07T20:15:35.929]   gres_cnt_step_alloc:NULL
[2016-10-07T20:15:35.929]   gres_bit_alloc[0]:5-7
[2016-10-07T20:15:35.929] sched: Allocate JobID=1855 NodeList=gpu-cluster-1 #CPUs=1 Partition=partition
[2016-10-07T20:15:35.929] job start: job_id = 1855	time = 1475842535

[2016-10-07T20:15:36.166] job_complete: JobID=1849 State=0x1 NodeCnt=1 WEXITSTATUS 255
[2016-10-07T20:15:36.166] job end: job_id = 1849	time = 1475842536

[2016-10-07T20:15:36.166] job_complete: JobID=1849 State=0x8005 NodeCnt=1 done
[2016-10-07T20:15:36.171] gres: gpu state for job 1856
[2016-10-07T20:15:36.171]   gres_cnt:5 node_cnt:2 type:(null)
[2016-10-07T20:15:36.171]   gres_bit_step_alloc:NULL
[2016-10-07T20:15:36.171]   gres_cnt_step_alloc:NULL
[2016-10-07T20:15:36.171]   gres_bit_alloc[0]:6-7
[2016-10-07T20:15:36.171]   gres_bit_alloc[1]:0-2
[2016-10-07T20:15:36.171] sched: Allocate JobID=1856 NodeList=gpu-cluster-1 #CPUs=1 Partition=partition
[2016-10-07T20:15:36.172] job start: job_id = 1856	time = 1475842536

[2016-10-07T20:15:36.200] job_complete: JobID=1850 State=0x1 NodeCnt=1 WEXITSTATUS 255
[2016-10-07T20:15:36.201] job end: job_id = 1850	time = 1475842536

[2016-10-07T20:15:36.201] job_complete: JobID=1850 State=0x8005 NodeCnt=1 done
[2016-10-07T20:15:36.285] job_complete: JobID=1854 State=0x1 NodeCnt=1 WEXITSTATUS 255
[2016-10-07T20:15:36.285] job end: job_id = 1854	time = 1475842536

[2016-10-07T20:15:36.285] job_complete: JobID=1854 State=0x8005 NodeCnt=1 done
[2016-10-07T20:15:36.291] gres: gpu state for job 1857
[2016-10-07T20:15:36.291]   gres_cnt:7 node_cnt:3 type:(null)
[2016-10-07T20:15:36.291]   gres_bit_step_alloc:NULL
[2016-10-07T20:15:36.291]   gres_cnt_step_alloc:NULL
[2016-10-07T20:15:36.291]   gres_bit_alloc[0]:4-5
[2016-10-07T20:15:36.291]   gres_bit_alloc[1]:3-4,7
[2016-10-07T20:15:36.291]   gres_bit_alloc[2]:0-1
[2016-10-07T20:15:36.291] sched: Allocate JobID=1857 NodeList=gpu-cluster-1 #CPUs=1 Partition=partition
[2016-10-07T20:15:36.291] job start: job_id = 1857	time = 1475842536

[2016-10-07T20:15:36.416] job_complete: JobID=1852 State=0x1 NodeCnt=1 WEXITSTATUS 255
[2016-10-07T20:15:36.416] job end: job_id = 1852	time = 1475842536

[2016-10-07T20:15:36.416] job_complete: JobID=1852 State=0x8005 NodeCnt=1 done
[2016-10-07T20:15:36.421] gres: gpu state for job 1858
[2016-10-07T20:15:36.421]   gres_cnt:5 node_cnt:2 type:(null)
[2016-10-07T20:15:36.421]   gres_bit_step_alloc:NULL
[2016-10-07T20:15:36.421]   gres_cnt_step_alloc:NULL
[2016-10-07T20:15:36.421]   gres_bit_alloc[0]:0-3
[2016-10-07T20:15:36.421]   gres_bit_alloc[1]:2
[2016-10-07T20:15:36.421] sched: Allocate JobID=1858 NodeList=gpu-cluster-1 #CPUs=1 Partition=partition
[2016-10-07T20:15:36.422] job start: job_id = 1858	time = 1475842536

[2016-10-07T20:15:36.482] job_complete: JobID=1853 State=0x1 NodeCnt=1 WEXITSTATUS 255
[2016-10-07T20:15:36.482] job end: job_id = 1853	time = 1475842536

[2016-10-07T20:15:36.482] job_complete: JobID=1853 State=0x8005 NodeCnt=1 done
[2016-10-07T20:15:36.565] job_complete: JobID=1855 State=0x1 NodeCnt=1 WEXITSTATUS 255
[2016-10-07T20:15:36.565] job end: job_id = 1855	time = 1475842536

[2016-10-07T20:15:36.565] job_complete: JobID=1855 State=0x8005 NodeCnt=1 done
[2016-10-07T20:15:36.571] gres: gpu state for job 1859
[2016-10-07T20:15:36.571]   gres_cnt:7 node_cnt:2 type:(null)
[2016-10-07T20:15:36.571]   gres_bit_step_alloc:NULL
[2016-10-07T20:15:36.571]   gres_cnt_step_alloc:NULL
[2016-10-07T20:15:36.571]   gres_bit_alloc[0]:5-6
[2016-10-07T20:15:36.571]   gres_bit_alloc[1]:3-7
[2016-10-07T20:15:36.571] sched: Allocate JobID=1859 NodeList=gpu-cluster-1 #CPUs=1 Partition=partition
[2016-10-07T20:15:36.571] job start: job_id = 1859	time = 1475842536

[2016-10-07T20:15:36.750] job_complete: JobID=1857 State=0x1 NodeCnt=1 WEXITSTATUS 255
[2016-10-07T20:15:36.750] job end: job_id = 1857	time = 1475842536

[2016-10-07T20:15:36.750] job_complete: JobID=1857 State=0x8005 NodeCnt=1 done
[2016-10-07T20:15:36.755] gres: gpu state for job 1860
[2016-10-07T20:15:36.755]   gres_cnt:5 node_cnt:2 type:(null)
[2016-10-07T20:15:36.755]   gres_bit_step_alloc:NULL
[2016-10-07T20:15:36.755]   gres_cnt_step_alloc:NULL
[2016-10-07T20:15:36.755]   gres_bit_alloc[0]:4-5
[2016-10-07T20:15:36.755]   gres_bit_alloc[1]:3-4,7
[2016-10-07T20:15:36.755] sched: Allocate JobID=1860 NodeList=gpu-cluster-1 #CPUs=1 Partition=partition
[2016-10-07T20:15:36.755] job start: job_id = 1860	time = 1475842536

[2016-10-07T20:15:36.794] job_complete: JobID=1858 State=0x1 NodeCnt=1 WEXITSTATUS 255
[2016-10-07T20:15:36.794] job end: job_id = 1858	time = 1475842536

[2016-10-07T20:15:36.794] job_complete: JobID=1858 State=0x8005 NodeCnt=1 done
[2016-10-07T20:15:36.799] gres: gpu state for job 1861
[2016-10-07T20:15:36.799]   gres_cnt:3 node_cnt:1 type:(null)
[2016-10-07T20:15:36.799]   gres_bit_step_alloc:NULL
[2016-10-07T20:15:36.799]   gres_cnt_step_alloc:NULL
[2016-10-07T20:15:36.799]   gres_bit_alloc[0]:0-2
[2016-10-07T20:15:36.799] sched: Allocate JobID=1861 NodeList=gpu-cluster-1 #CPUs=1 Partition=partition
[2016-10-07T20:15:36.799] job start: job_id = 1861	time = 1475842536

[2016-10-07T20:15:36.910] job_complete: JobID=1856 State=0x1 NodeCnt=1 WEXITSTATUS 255
[2016-10-07T20:15:36.910] job end: job_id = 1856	time = 1475842536

[2016-10-07T20:15:36.910] job_complete: JobID=1856 State=0x8005 NodeCnt=1 done
[2016-10-07T20:15:36.915] gres: gpu state for job 1862
[2016-10-07T20:15:36.915]   gres_cnt:8 node_cnt:3 type:(null)
[2016-10-07T20:15:36.915]   gres_bit_step_alloc:NULL
[2016-10-07T20:15:36.915]   gres_cnt_step_alloc:NULL
[2016-10-07T20:15:36.915]   gres_bit_alloc[0]:3,6-7
[2016-10-07T20:15:36.915]   gres_bit_alloc[1]:0-2
[2016-10-07T20:15:36.915]   gres_bit_alloc[2]:0-1
[2016-10-07T20:15:36.915] sched: Allocate JobID=1862 NodeList=gpu-cluster-1 #CPUs=1 Partition=partition
[2016-10-07T20:15:36.916] job start: job_id = 1862	time = 1475842536

[2016-10-07T20:15:37.073] job_complete: JobID=1859 State=0x1 NodeCnt=1 WEXITSTATUS 255
[2016-10-07T20:15:37.073] job end: job_id = 1859	time = 1475842537

[2016-10-07T20:15:37.073] job_complete: JobID=1859 State=0x8005 NodeCnt=1 done
[2016-10-07T20:15:37.078] gres: gpu state for job 1863
[2016-10-07T20:15:37.078]   gres_cnt:5 node_cnt:2 type:(null)
[2016-10-07T20:15:37.078]   gres_bit_step_alloc:NULL
[2016-10-07T20:15:37.078]   gres_cnt_step_alloc:NULL
[2016-10-07T20:15:37.078]   gres_bit_alloc[0]:5-6
[2016-10-07T20:15:37.078]   gres_bit_alloc[1]:2-4
[2016-10-07T20:15:37.078] sched: Allocate JobID=1863 NodeList=gpu-cluster-1 #CPUs=1 Partition=partition
[2016-10-07T20:15:37.079] job start: job_id = 1863	time = 1475842537

[2016-10-07T20:15:37.079] gres: gpu state for job 1864
[2016-10-07T20:15:37.079]   gres_cnt:1 node_cnt:1 type:(null)
[2016-10-07T20:15:37.079]   gres_bit_step_alloc:NULL
[2016-10-07T20:15:37.079]   gres_cnt_step_alloc:NULL
[2016-10-07T20:15:37.079]   gres_bit_alloc[0]:5
[2016-10-07T20:15:37.079] sched: Allocate JobID=1864 NodeList=gpu-cluster-1 #CPUs=1 Partition=partition
[2016-10-07T20:15:37.079] job start: job_id = 1864	time = 1475842537

[2016-10-07T20:15:37.356] job_complete: JobID=1862 State=0x1 NodeCnt=1 WEXITSTATUS 255
[2016-10-07T20:15:37.356] job end: job_id = 1862	time = 1475842537

[2016-10-07T20:15:37.356] job_complete: JobID=1862 State=0x8005 NodeCnt=1 done
[2016-10-07T20:15:37.361] gres: gpu state for job 1865
[2016-10-07T20:15:37.361]   gres_cnt:6 node_cnt:2 type:(null)
[2016-10-07T20:15:37.361]   gres_bit_step_alloc:NULL
[2016-10-07T20:15:37.361]   gres_cnt_step_alloc:NULL
[2016-10-07T20:15:37.361]   gres_bit_alloc[0]:3,6-7
[2016-10-07T20:15:37.361]   gres_bit_alloc[1]:0-2
[2016-10-07T20:15:37.361] sched: Allocate JobID=1865 NodeList=gpu-cluster-1 #CPUs=1 Partition=partition
[2016-10-07T20:15:37.362] job start: job_id = 1865	time = 1475842537

[2016-10-07T20:15:37.462] job_complete: JobID=1860 State=0x1 NodeCnt=1 WEXITSTATUS 255
[2016-10-07T20:15:37.462] job end: job_id = 1860	time = 1475842537

[2016-10-07T20:15:37.462] job_complete: JobID=1860 State=0x8005 NodeCnt=1 done
[2016-10-07T20:15:37.467] gres: gpu state for job 1866
[2016-10-07T20:15:37.467]   gres_cnt:5 node_cnt:2 type:(null)
[2016-10-07T20:15:37.467]   gres_bit_step_alloc:NULL
[2016-10-07T20:15:37.467]   gres_cnt_step_alloc:NULL
[2016-10-07T20:15:37.467]   gres_bit_alloc[0]:4-5
[2016-10-07T20:15:37.467]   gres_bit_alloc[1]:3-4,7
[2016-10-07T20:15:37.467] sched: Allocate JobID=1866 NodeList=gpu-cluster-1 #CPUs=1 Partition=partition
[2016-10-07T20:15:37.468] job start: job_id = 1866	time = 1475842537

[2016-10-07T20:15:37.504] job_complete: JobID=1864 State=0x1 NodeCnt=1 WEXITSTATUS 255
[2016-10-07T20:15:37.504] job end: job_id = 1864	time = 1475842537

[2016-10-07T20:15:37.504] job_complete: JobID=1864 State=0x8005 NodeCnt=1 done
[2016-10-07T20:15:37.505] job_complete: JobID=1863 State=0x1 NodeCnt=1 WEXITSTATUS 255
[2016-10-07T20:15:37.505] job end: job_id = 1863	time = 1475842537

[2016-10-07T20:15:37.505] job_complete: JobID=1863 State=0x8005 NodeCnt=1 done
[2016-10-07T20:15:37.509] gres: gpu state for job 1867
[2016-10-07T20:15:37.509]   gres_cnt:8 node_cnt:2 type:(null)
[2016-10-07T20:15:37.509]   gres_bit_step_alloc:NULL
[2016-10-07T20:15:37.509]   gres_cnt_step_alloc:NULL
[2016-10-07T20:15:37.509]   gres_bit_alloc[0]:5-6
[2016-10-07T20:15:37.509]   gres_bit_alloc[1]:0-5
[2016-10-07T20:15:37.509] sched: Allocate JobID=1867 NodeList=gpu-cluster-1 #CPUs=1 Partition=partition
[2016-10-07T20:15:37.509] job start: job_id = 1867	time = 1475842537

[2016-10-07T20:15:37.525] job_complete: JobID=1861 State=0x1 NodeCnt=1 WEXITSTATUS 255
[2016-10-07T20:15:37.525] job end: job_id = 1861	time = 1475842537

[2016-10-07T20:15:37.525] job_complete: JobID=1861 State=0x8005 NodeCnt=1 done
[2016-10-07T20:15:37.530] gres: gpu state for job 1868
[2016-10-07T20:15:37.530]   gres_cnt:5 node_cnt:2 type:(null)
[2016-10-07T20:15:37.530]   gres_bit_step_alloc:NULL
[2016-10-07T20:15:37.530]   gres_cnt_step_alloc:NULL
[2016-10-07T20:15:37.530]   gres_bit_alloc[0]:0-2
[2016-10-07T20:15:37.530]   gres_bit_alloc[1]:6-7
[2016-10-07T20:15:37.530] sched: Allocate JobID=1868 NodeList=gpu-cluster-1 #CPUs=1 Partition=partition
[2016-10-07T20:15:37.530] job start: job_id = 1868	time = 1475842537

[2016-10-07T20:15:38.025] job_complete: JobID=1868 State=0x1 NodeCnt=1 WEXITSTATUS 255
[2016-10-07T20:15:38.025] job end: job_id = 1868	time = 1475842538

[2016-10-07T20:15:38.025] job_complete: JobID=1868 State=0x8005 NodeCnt=1 done
[2016-10-07T20:15:38.082] job_complete: JobID=1867 State=0x1 NodeCnt=1 WEXITSTATUS 255
[2016-10-07T20:15:38.082] job end: job_id = 1867	time = 1475842538

[2016-10-07T20:15:38.082] job_complete: JobID=1867 State=0x8005 NodeCnt=1 done
[2016-10-07T20:15:38.088] gres: gpu state for job 1869
[2016-10-07T20:15:38.088]   gres_cnt:6 node_cnt:3 type:(null)
[2016-10-07T20:15:38.088]   gres_bit_step_alloc:NULL
[2016-10-07T20:15:38.088]   gres_cnt_step_alloc:NULL
[2016-10-07T20:15:38.088]   gres_bit_alloc[0]:0-2
[2016-10-07T20:15:38.088]   gres_bit_alloc[1]:5-6
[2016-10-07T20:15:38.088]   gres_bit_alloc[2]:0
[2016-10-07T20:15:38.088] sched: Allocate JobID=1869 NodeList=gpu-cluster-1 #CPUs=1 Partition=partition
[2016-10-07T20:15:38.088] job start: job_id = 1869	time = 1475842538

[2016-10-07T20:15:38.088] gres: gpu state for job 1870
[2016-10-07T20:15:38.088]   gres_cnt:7 node_cnt:1 type:(null)
[2016-10-07T20:15:38.088]   gres_bit_step_alloc:NULL
[2016-10-07T20:15:38.088]   gres_cnt_step_alloc:NULL
[2016-10-07T20:15:38.088]   gres_bit_alloc[0]:1-7
[2016-10-07T20:15:38.088] sched: Allocate JobID=1870 NodeList=gpu-cluster-1 #CPUs=1 Partition=partition
[2016-10-07T20:15:38.088] job start: job_id = 1870	time = 1475842538

[2016-10-07T20:15:38.131] job_complete: JobID=1865 State=0x1 NodeCnt=1 WEXITSTATUS 255
[2016-10-07T20:15:38.131] job end: job_id = 1865	time = 1475842538

[2016-10-07T20:15:38.131] job_complete: JobID=1865 State=0x8005 NodeCnt=1 done
[2016-10-07T20:15:38.137] gres: gpu state for job 1871
[2016-10-07T20:15:38.137]   gres_cnt:6 node_cnt:2 type:(null)
[2016-10-07T20:15:38.137]   gres_bit_step_alloc:NULL
[2016-10-07T20:15:38.137]   gres_cnt_step_alloc:NULL
[2016-10-07T20:15:38.137]   gres_bit_alloc[0]:3,6-7
[2016-10-07T20:15:38.137]   gres_bit_alloc[1]:0-2
[2016-10-07T20:15:38.137] sched: Allocate JobID=1871 NodeList=gpu-cluster-1 #CPUs=1 Partition=partition
[2016-10-07T20:15:38.137] job start: job_id = 1871	time = 1475842538

[2016-10-07T20:15:38.261] job_complete: JobID=1866 State=0x1 NodeCnt=1 WEXITSTATUS 255
[2016-10-07T20:15:38.261] job end: job_id = 1866	time = 1475842538

[2016-10-07T20:15:38.261] job_complete: JobID=1866 State=0x8005 NodeCnt=1 done
[2016-10-07T20:15:38.577] job_complete: JobID=1869 State=0x1 NodeCnt=1 WEXITSTATUS 255
[2016-10-07T20:15:38.577] job end: job_id = 1869	time = 1475842538

[2016-10-07T20:15:38.577] job_complete: JobID=1869 State=0x8005 NodeCnt=1 done
[2016-10-07T20:15:38.583] gres: gpu state for job 1872
[2016-10-07T20:15:38.583]   gres_cnt:8 node_cnt:2 type:(null)
[2016-10-07T20:15:38.583]   gres_bit_step_alloc:NULL
[2016-10-07T20:15:38.583]   gres_cnt_step_alloc:NULL
[2016-10-07T20:15:38.583]   gres_bit_alloc[0]:0-2,4-5
[2016-10-07T20:15:38.583]   gres_bit_alloc[1]:3-5
[2016-10-07T20:15:38.583] sched: Allocate JobID=1872 NodeList=gpu-cluster-1 #CPUs=1 Partition=partition
[2016-10-07T20:15:38.583] job start: job_id = 1872	time = 1475842538

[2016-10-07T20:15:38.583] gres: gpu state for job 1873
[2016-10-07T20:15:38.583]   gres_cnt:1 node_cnt:1 type:(null)
[2016-10-07T20:15:38.583]   gres_bit_step_alloc:NULL
[2016-10-07T20:15:38.583]   gres_cnt_step_alloc:NULL
[2016-10-07T20:15:38.583]   gres_bit_alloc[0]:6
[2016-10-07T20:15:38.583] sched: Allocate JobID=1873 NodeList=gpu-cluster-1 #CPUs=1 Partition=partition
[2016-10-07T20:15:38.583] job start: job_id = 1873	time = 1475842538

[2016-10-07T20:15:38.583] job_complete: JobID=1870 State=0x1 NodeCnt=1 WEXITSTATUS 255
[2016-10-07T20:15:38.583] job end: job_id = 1870	time = 1475842538

[2016-10-07T20:15:38.583] job_complete: JobID=1870 State=0x8005 NodeCnt=1 done
[2016-10-07T20:15:38.588] gres: gpu state for job 1874
[2016-10-07T20:15:38.588]   gres_cnt:7 node_cnt:2 type:(null)
[2016-10-07T20:15:38.588]   gres_bit_step_alloc:NULL
[2016-10-07T20:15:38.588]   gres_cnt_step_alloc:NULL
[2016-10-07T20:15:38.588]   gres_bit_alloc[0]:7
[2016-10-07T20:15:38.588]   gres_bit_alloc[1]:0-5
[2016-10-07T20:15:38.588] sched: Allocate JobID=1874 NodeList=gpu-cluster-1 #CPUs=1 Partition=partition
[2016-10-07T20:15:38.588] job start: job_id = 1874	time = 1475842538

[2016-10-07T20:15:38.805] job_complete: JobID=1871 State=0x1 NodeCnt=1 WEXITSTATUS 255
[2016-10-07T20:15:38.805] job end: job_id = 1871	time = 1475842538

[2016-10-07T20:15:38.805] job_complete: JobID=1871 State=0x8005 NodeCnt=1 done
[2016-10-07T20:15:38.810] gres: gpu state for job 1875
[2016-10-07T20:15:38.810]   gres_cnt:3 node_cnt:1 type:(null)
[2016-10-07T20:15:38.810]   gres_bit_step_alloc:NULL
[2016-10-07T20:15:38.810]   gres_cnt_step_alloc:NULL
[2016-10-07T20:15:38.810]   gres_bit_alloc[0]:3,6-7
[2016-10-07T20:15:38.810] sched: Allocate JobID=1875 NodeList=gpu-cluster-1 #CPUs=1 Partition=partition
[2016-10-07T20:15:38.811] job start: job_id = 1875	time = 1475842538

[2016-10-07T20:15:38.811] gres: gpu state for job 1876
[2016-10-07T20:15:38.811]   gres_cnt:4 node_cnt:2 type:(null)
[2016-10-07T20:15:38.811]   gres_bit_step_alloc:NULL
[2016-10-07T20:15:38.811]   gres_cnt_step_alloc:NULL
[2016-10-07T20:15:38.811]   gres_bit_alloc[0]:0-2
[2016-10-07T20:15:38.811]   gres_bit_alloc[1]:6
[2016-10-07T20:15:38.811] sched: Allocate JobID=1876 NodeList=gpu-cluster-1 #CPUs=1 Partition=partition
[2016-10-07T20:15:38.811] job start: job_id = 1876	time = 1475842538

[2016-10-07T20:15:39.119] job_complete: JobID=1874 State=0x1 NodeCnt=1 WEXITSTATUS 255
[2016-10-07T20:15:39.119] job end: job_id = 1874	time = 1475842539

[2016-10-07T20:15:39.119] job_complete: JobID=1874 State=0x8005 NodeCnt=1 done
[2016-10-07T20:15:39.124] gres: gpu state for job 1877
[2016-10-07T20:15:39.124]   gres_cnt:5 node_cnt:2 type:(null)
[2016-10-07T20:15:39.124]   gres_bit_step_alloc:NULL
[2016-10-07T20:15:39.124]   gres_cnt_step_alloc:NULL
[2016-10-07T20:15:39.124]   gres_bit_alloc[0]:7
[2016-10-07T20:15:39.124]   gres_bit_alloc[1]:0-3
[2016-10-07T20:15:39.124] sched: Allocate JobID=1877 NodeList=gpu-cluster-1 #CPUs=1 Partition=partition
[2016-10-07T20:15:39.125] job start: job_id = 1877	time = 1475842539

[2016-10-07T20:15:39.202] job_complete: JobID=1876 State=0x1 NodeCnt=1 WEXITSTATUS 255
[2016-10-07T20:15:39.202] job end: job_id = 1876	time = 1475842539

[2016-10-07T20:15:39.202] job_complete: JobID=1876 State=0x8005 NodeCnt=1 done
[2016-10-07T20:15:39.207] gres: gpu state for job 1878
[2016-10-07T20:15:39.207]   gres_cnt:5 node_cnt:2 type:(null)
[2016-10-07T20:15:39.207]   gres_bit_step_alloc:NULL
[2016-10-07T20:15:39.207]   gres_cnt_step_alloc:NULL
[2016-10-07T20:15:39.207]   gres_bit_alloc[0]:0-2
[2016-10-07T20:15:39.207]   gres_bit_alloc[1]:4-5
[2016-10-07T20:15:39.207] sched: Allocate JobID=1878 NodeList=gpu-cluster-1 #CPUs=1 Partition=partition
[2016-10-07T20:15:39.208] job start: job_id = 1878	time = 1475842539

[2016-10-07T20:15:39.374] job_complete: JobID=1872 State=0x1 NodeCnt=1 WEXITSTATUS 255
[2016-10-07T20:15:39.374] job end: job_id = 1872	time = 1475842539

[2016-10-07T20:15:39.374] job_complete: JobID=1872 State=0x8005 NodeCnt=1 done
[2016-10-07T20:15:39.379] gres: gpu state for job 1879
[2016-10-07T20:15:39.379]   gres_cnt:6 node_cnt:2 type:(null)
[2016-10-07T20:15:39.379]   gres_bit_step_alloc:NULL
[2016-10-07T20:15:39.379]   gres_cnt_step_alloc:NULL
[2016-10-07T20:15:39.379]   gres_bit_alloc[0]:0-2,4-5
[2016-10-07T20:15:39.379]   gres_bit_alloc[1]:3
[2016-10-07T20:15:39.379] sched: Allocate JobID=1879 NodeList=gpu-cluster-1 #CPUs=1 Partition=partition
[2016-10-07T20:15:39.380] job start: job_id = 1879	time = 1475842539

[2016-10-07T20:15:39.380] gres: gpu state for job 1880
[2016-10-07T20:15:39.380]   gres_cnt:3 node_cnt:2 type:(null)
[2016-10-07T20:15:39.380]   gres_bit_step_alloc:NULL
[2016-10-07T20:15:39.380]   gres_cnt_step_alloc:NULL
[2016-10-07T20:15:39.380]   gres_bit_alloc[0]:4-5
[2016-10-07T20:15:39.380]   gres_bit_alloc[1]:6
[2016-10-07T20:15:39.380] sched: Allocate JobID=1880 NodeList=gpu-cluster-1 #CPUs=1 Partition=partition
[2016-10-07T20:15:39.380] job start: job_id = 1880	time = 1475842539

[2016-10-07T20:15:39.404] job_complete: JobID=1873 State=0x1 NodeCnt=1 WEXITSTATUS 255
[2016-10-07T20:15:39.404] job end: job_id = 1873	time = 1475842539

[2016-10-07T20:15:39.404] job_complete: JobID=1873 State=0x8005 NodeCnt=1 done
[2016-10-07T20:15:39.409] gres: gpu state for job 1881
[2016-10-07T20:15:39.409]   gres_cnt:2 node_cnt:2 type:(null)
[2016-10-07T20:15:39.409]   gres_bit_step_alloc:NULL
[2016-10-07T20:15:39.409]   gres_cnt_step_alloc:NULL
[2016-10-07T20:15:39.409]   gres_bit_alloc[0]:6
[2016-10-07T20:15:39.409]   gres_bit_alloc[1]:7
[2016-10-07T20:15:39.409] sched: Allocate JobID=1881 NodeList=gpu-cluster-1 #CPUs=1 Partition=partition
[2016-10-07T20:15:39.409] job start: job_id = 1881	time = 1475842539

[2016-10-07T20:15:39.472] job_complete: JobID=1877 State=0x1 NodeCnt=1 WEXITSTATUS 255
[2016-10-07T20:15:39.472] job end: job_id = 1877	time = 1475842539

[2016-10-07T20:15:39.472] job_complete: JobID=1877 State=0x8005 NodeCnt=1 done
[2016-10-07T20:15:39.477] gres: gpu state for job 1882
[2016-10-07T20:15:39.477]   gres_cnt:5 node_cnt:2 type:(null)
[2016-10-07T20:15:39.477]   gres_bit_step_alloc:NULL
[2016-10-07T20:15:39.477]   gres_cnt_step_alloc:NULL
[2016-10-07T20:15:39.477]   gres_bit_alloc[0]:7
[2016-10-07T20:15:39.477]   gres_bit_alloc[1]:0-3
[2016-10-07T20:15:39.477] sched: Allocate JobID=1882 NodeList=gpu-cluster-1 #CPUs=1 Partition=partition
[2016-10-07T20:15:39.477] job start: job_id = 1882	time = 1475842539

[2016-10-07T20:15:39.534] job_complete: JobID=1875 State=0x1 NodeCnt=1 WEXITSTATUS 255
[2016-10-07T20:15:39.534] job end: job_id = 1875	time = 1475842539

[2016-10-07T20:15:39.534] job_complete: JobID=1875 State=0x8005 NodeCnt=1 done
[2016-10-07T20:15:39.540] gres: gpu state for job 1883
[2016-10-07T20:15:39.540]   gres_cnt:2 node_cnt:1 type:(null)
[2016-10-07T20:15:39.540]   gres_bit_step_alloc:NULL
[2016-10-07T20:15:39.540]   gres_cnt_step_alloc:NULL
[2016-10-07T20:15:39.540]   gres_bit_alloc[0]:3,6
[2016-10-07T20:15:39.540] sched: Allocate JobID=1883 NodeList=gpu-cluster-1 #CPUs=1 Partition=partition
[2016-10-07T20:15:39.540] job start: job_id = 1883	time = 1475842539

[2016-10-07T20:15:39.799] job_complete: JobID=1878 State=0x1 NodeCnt=1 WEXITSTATUS 255
[2016-10-07T20:15:39.799] job end: job_id = 1878	time = 1475842539

[2016-10-07T20:15:39.799] job_complete: JobID=1878 State=0x8005 NodeCnt=1 done
[2016-10-07T20:15:39.804] gres: gpu state for job 1884
[2016-10-07T20:15:39.804]   gres_cnt:6 node_cnt:3 type:(null)
[2016-10-07T20:15:39.804]   gres_bit_step_alloc:NULL
[2016-10-07T20:15:39.804]   gres_cnt_step_alloc:NULL
[2016-10-07T20:15:39.804]   gres_bit_alloc[0]:7
[2016-10-07T20:15:39.804]   gres_bit_alloc[1]:0-2
[2016-10-07T20:15:39.804]   gres_bit_alloc[2]:4-5
[2016-10-07T20:15:39.804] sched: Allocate JobID=1884 NodeList=gpu-cluster-1 #CPUs=1 Partition=partition
[2016-10-07T20:15:39.804] job start: job_id = 1884	time = 1475842539

[2016-10-07T20:15:39.859] job_complete: JobID=1880 State=0x1 NodeCnt=1 WEXITSTATUS 255
[2016-10-07T20:15:39.859] job end: job_id = 1880	time = 1475842539

[2016-10-07T20:15:39.859] job_complete: JobID=1880 State=0x8005 NodeCnt=1 done
[2016-10-07T20:15:39.864] gres: gpu state for job 1885
[2016-10-07T20:15:39.864]   gres_cnt:2 node_cnt:1 type:(null)
[2016-10-07T20:15:39.864]   gres_bit_step_alloc:NULL
[2016-10-07T20:15:39.864]   gres_cnt_step_alloc:NULL
[2016-10-07T20:15:39.864]   gres_bit_alloc[0]:4-5
[2016-10-07T20:15:39.864] sched: Allocate JobID=1885 NodeList=gpu-cluster-1 #CPUs=1 Partition=partition
[2016-10-07T20:15:39.865] job start: job_id = 1885	time = 1475842539

[2016-10-07T20:15:40.109] job_complete: JobID=1882 State=0x1 NodeCnt=1 WEXITSTATUS 255
[2016-10-07T20:15:40.109] job end: job_id = 1882	time = 1475842540

[2016-10-07T20:15:40.109] job_complete: JobID=1882 State=0x8005 NodeCnt=1 done
[2016-10-07T20:15:40.114] gres: gpu state for job 1886
[2016-10-07T20:15:40.114]   gres_cnt:6 node_cnt:2 type:(null)
[2016-10-07T20:15:40.114]   gres_bit_step_alloc:NULL
[2016-10-07T20:15:40.114]   gres_cnt_step_alloc:NULL
[2016-10-07T20:15:40.114]   gres_bit_alloc[0]:7
[2016-10-07T20:15:40.114]   gres_bit_alloc[1]:0-3,6
[2016-10-07T20:15:40.114] sched: Allocate JobID=1886 NodeList=gpu-cluster-1 #CPUs=1 Partition=partition
[2016-10-07T20:15:40.115] job start: job_id = 1886	time = 1475842540

[2016-10-07T20:15:40.116] job_complete: JobID=1881 State=0x1 NodeCnt=1 WEXITSTATUS 255
[2016-10-07T20:15:40.116] job end: job_id = 1881	time = 1475842540

[2016-10-07T20:15:40.116] job_complete: JobID=1881 State=0x8005 NodeCnt=1 done
[2016-10-07T20:15:40.124] job_complete: JobID=1879 State=0x1 NodeCnt=1 WEXITSTATUS 255
[2016-10-07T20:15:40.124] job end: job_id = 1879	time = 1475842540

[2016-10-07T20:15:40.124] job_complete: JobID=1879 State=0x8005 NodeCnt=1 done
[2016-10-07T20:15:40.130] gres: gpu state for job 1887
[2016-10-07T20:15:40.130]   gres_cnt:8 node_cnt:3 type:(null)
[2016-10-07T20:15:40.130]   gres_bit_step_alloc:NULL
[2016-10-07T20:15:40.130]   gres_cnt_step_alloc:NULL
[2016-10-07T20:15:40.130]   gres_bit_alloc[0]:0-2,4-5
[2016-10-07T20:15:40.130]   gres_bit_alloc[1]:3,6
[2016-10-07T20:15:40.130]   gres_bit_alloc[2]:7
[2016-10-07T20:15:40.130] sched: Allocate JobID=1887 NodeList=gpu-cluster-1 #CPUs=1 Partition=partition
[2016-10-07T20:15:40.130] job start: job_id = 1887	time = 1475842540

[2016-10-07T20:15:40.186] job_complete: JobID=1884 State=0x1 NodeCnt=1 WEXITSTATUS 255
[2016-10-07T20:15:40.186] job end: job_id = 1884	time = 1475842540

[2016-10-07T20:15:40.186] job_complete: JobID=1884 State=0x8005 NodeCnt=1 done
[2016-10-07T20:15:40.192] gres: gpu state for job 1888
[2016-10-07T20:15:40.192]   gres_cnt:2 node_cnt:2 type:(null)
[2016-10-07T20:15:40.192]   gres_bit_step_alloc:NULL
[2016-10-07T20:15:40.192]   gres_cnt_step_alloc:NULL
[2016-10-07T20:15:40.192]   gres_bit_alloc[0]:7
[2016-10-07T20:15:40.192]   gres_bit_alloc[1]:0
[2016-10-07T20:15:40.192] sched: Allocate JobID=1888 NodeList=gpu-cluster-1 #CPUs=1 Partition=partition
[2016-10-07T20:15:40.192] job start: job_id = 1888	time = 1475842540

[2016-10-07T20:15:40.362] job_complete: JobID=1883 State=0x1 NodeCnt=1 WEXITSTATUS 255
[2016-10-07T20:15:40.362] job end: job_id = 1883	time = 1475842540

[2016-10-07T20:15:40.362] job_complete: JobID=1883 State=0x8005 NodeCnt=1 done
[2016-10-07T20:15:40.368] gres: gpu state for job 1889
[2016-10-07T20:15:40.368]   gres_cnt:5 node_cnt:3 type:(null)
[2016-10-07T20:15:40.368]   gres_bit_step_alloc:NULL
[2016-10-07T20:15:40.368]   gres_cnt_step_alloc:NULL
[2016-10-07T20:15:40.368]   gres_bit_alloc[0]:3,6
[2016-10-07T20:15:40.368]   gres_bit_alloc[1]:1-2
[2016-10-07T20:15:40.368]   gres_bit_alloc[2]:4
[2016-10-07T20:15:40.368] sched: Allocate JobID=1889 NodeList=gpu-cluster-1 #CPUs=1 Partition=partition
[2016-10-07T20:15:40.368] job start: job_id = 1889	time = 1475842540

[2016-10-07T20:15:40.444] job_complete: JobID=1885 State=0x1 NodeCnt=1 WEXITSTATUS 255
[2016-10-07T20:15:40.444] job end: job_id = 1885	time = 1475842540

[2016-10-07T20:15:40.444] job_complete: JobID=1885 State=0x8005 NodeCnt=1 done
[2016-10-07T20:15:40.715] job_complete: JobID=1886 State=0x1 NodeCnt=1 WEXITSTATUS 255
[2016-10-07T20:15:40.715] job end: job_id = 1886	time = 1475842540

[2016-10-07T20:15:40.715] job_complete: JobID=1886 State=0x8005 NodeCnt=1 done
[2016-10-07T20:15:40.720] gres: gpu state for job 1890
[2016-10-07T20:15:40.721]   gres_cnt:7 node_cnt:2 type:(null)
[2016-10-07T20:15:40.721]   gres_bit_step_alloc:NULL
[2016-10-07T20:15:40.721]   gres_cnt_step_alloc:NULL
[2016-10-07T20:15:40.721]   gres_bit_alloc[0]:4-5,7
[2016-10-07T20:15:40.721]   gres_bit_alloc[1]:0-3
[2016-10-07T20:15:40.721] sched: Allocate JobID=1890 NodeList=gpu-cluster-1 #CPUs=1 Partition=partition
[2016-10-07T20:15:40.721] job start: job_id = 1890	time = 1475842540

[2016-10-07T20:15:40.748] job_complete: JobID=1887 State=0x1 NodeCnt=1 WEXITSTATUS 255
[2016-10-07T20:15:40.748] job end: job_id = 1887	time = 1475842540

[2016-10-07T20:15:40.748] job_complete: JobID=1887 State=0x8005 NodeCnt=1 done
[2016-10-07T20:15:40.753] gres: gpu state for job 1891
[2016-10-07T20:15:40.753]   gres_cnt:7 node_cnt:2 type:(null)
[2016-10-07T20:15:40.753]   gres_bit_step_alloc:NULL
[2016-10-07T20:15:40.753]   gres_cnt_step_alloc:NULL
[2016-10-07T20:15:40.753]   gres_bit_alloc[0]:0-2,4-5
[2016-10-07T20:15:40.753]   gres_bit_alloc[1]:3,6
[2016-10-07T20:15:40.753] sched: Allocate JobID=1891 NodeList=gpu-cluster-1 #CPUs=1 Partition=partition
[2016-10-07T20:15:40.753] job start: job_id = 1891	time = 1475842540

[2016-10-07T20:15:40.767] job_complete: JobID=1889 State=0x1 NodeCnt=1 WEXITSTATUS 255
[2016-10-07T20:15:40.767] job end: job_id = 1889	time = 1475842540

[2016-10-07T20:15:40.767] job_complete: JobID=1889 State=0x8005 NodeCnt=1 done
[2016-10-07T20:15:40.772] gres: gpu state for job 1892
[2016-10-07T20:15:40.772]   gres_cnt:7 node_cnt:3 type:(null)
[2016-10-07T20:15:40.772]   gres_bit_step_alloc:NULL
[2016-10-07T20:15:40.772]   gres_cnt_step_alloc:NULL
[2016-10-07T20:15:40.772]   gres_bit_alloc[0]:3,6
[2016-10-07T20:15:40.772]   gres_bit_alloc[1]:1-2
[2016-10-07T20:15:40.772]   gres_bit_alloc[2]:4-6
[2016-10-07T20:15:40.772] sched: Allocate JobID=1892 NodeList=gpu-cluster-1 #CPUs=1 Partition=partition
[2016-10-07T20:15:40.772] job start: job_id = 1892	time = 1475842540

[2016-10-07T20:15:40.773] gres: gpu state for job 1893
[2016-10-07T20:15:40.773]   gres_cnt:1 node_cnt:1 type:(null)
[2016-10-07T20:15:40.773]   gres_bit_step_alloc:NULL
[2016-10-07T20:15:40.773]   gres_cnt_step_alloc:NULL
[2016-10-07T20:15:40.773]   gres_bit_alloc[0]:7
[2016-10-07T20:15:40.773] sched: Allocate JobID=1893 NodeList=gpu-cluster-1 #CPUs=1 Partition=partition
[2016-10-07T20:15:40.773] job start: job_id = 1893	time = 1475842540

[2016-10-07T20:15:41.004] job_complete: JobID=1888 State=0x1 NodeCnt=1 WEXITSTATUS 255
[2016-10-07T20:15:41.004] job end: job_id = 1888	time = 1475842540

[2016-10-07T20:15:41.004] job_complete: JobID=1888 State=0x8005 NodeCnt=1 done
[2016-10-07T20:15:41.135] job_complete: JobID=1890 State=0x1 NodeCnt=1 WEXITSTATUS 255
[2016-10-07T20:15:41.135] job end: job_id = 1890	time = 1475842541

[2016-10-07T20:15:41.135] job_complete: JobID=1890 State=0x8005 NodeCnt=1 done
[2016-10-07T20:15:41.140] gres: gpu state for job 1894
[2016-10-07T20:15:41.140]   gres_cnt:3 node_cnt:2 type:(null)
[2016-10-07T20:15:41.140]   gres_bit_step_alloc:NULL
[2016-10-07T20:15:41.140]   gres_cnt_step_alloc:NULL
[2016-10-07T20:15:41.140]   gres_bit_alloc[0]:7
[2016-10-07T20:15:41.140]   gres_bit_alloc[1]:0,4
[2016-10-07T20:15:41.140] sched: Allocate JobID=1894 NodeList=gpu-cluster-1 #CPUs=1 Partition=partition
[2016-10-07T20:15:41.140] job start: job_id = 1894	time = 1475842541

[2016-10-07T20:15:41.282] job_complete: JobID=1893 State=0x1 NodeCnt=1 WEXITSTATUS 255
[2016-10-07T20:15:41.282] job end: job_id = 1893	time = 1475842541

[2016-10-07T20:15:41.282] job_complete: JobID=1893 State=0x8005 NodeCnt=1 done
[2016-10-07T20:15:41.287] gres: gpu state for job 1895
[2016-10-07T20:15:41.287]   gres_cnt:7 node_cnt:2 type:(null)
[2016-10-07T20:15:41.287]   gres_bit_step_alloc:NULL
[2016-10-07T20:15:41.287]   gres_cnt_step_alloc:NULL
[2016-10-07T20:15:41.287]   gres_bit_alloc[0]:5,7
[2016-10-07T20:15:41.287]   gres_bit_alloc[1]:0-3,7
[2016-10-07T20:15:41.287] sched: Allocate JobID=1895 NodeList=gpu-cluster-1 #CPUs=1 Partition=partition
[2016-10-07T20:15:41.287] job start: job_id = 1895	time = 1475842541

[2016-10-07T20:15:41.322] job_complete: JobID=1892 State=0x1 NodeCnt=1 WEXITSTATUS 255
[2016-10-07T20:15:41.322] job end: job_id = 1892	time = 1475842541

[2016-10-07T20:15:41.322] job_complete: JobID=1892 State=0x8005 NodeCnt=1 done
[2016-10-07T20:15:41.552] job_complete: JobID=1891 State=0x1 NodeCnt=1 WEXITSTATUS 255
[2016-10-07T20:15:41.552] job end: job_id = 1891	time = 1475842541

[2016-10-07T20:15:41.552] job_complete: JobID=1891 State=0x8005 NodeCnt=1 done
[2016-10-07T20:15:41.557] gres: gpu state for job 1896
[2016-10-07T20:15:41.557]   gres_cnt:8 node_cnt:2 type:(null)
[2016-10-07T20:15:41.557]   gres_bit_step_alloc:NULL
[2016-10-07T20:15:41.557]   gres_cnt_step_alloc:NULL
[2016-10-07T20:15:41.557]   gres_bit_alloc[0]:0-6
[2016-10-07T20:15:41.557]   gres_bit_alloc[1]:1
[2016-10-07T20:15:41.557] sched: Allocate JobID=1896 NodeList=gpu-cluster-1 #CPUs=1 Partition=partition
[2016-10-07T20:15:41.557] job start: job_id = 1896	time = 1475842541

[2016-10-07T20:15:41.656] job_complete: JobID=1895 State=0x1 NodeCnt=1 WEXITSTATUS 255
[2016-10-07T20:15:41.657] job end: job_id = 1895	time = 1475842541

[2016-10-07T20:15:41.657] job_complete: JobID=1895 State=0x8005 NodeCnt=1 done
[2016-10-07T20:15:41.662] gres: gpu state for job 1897
[2016-10-07T20:15:41.662]   gres_cnt:7 node_cnt:2 type:(null)
[2016-10-07T20:15:41.662]   gres_bit_step_alloc:NULL
[2016-10-07T20:15:41.662]   gres_cnt_step_alloc:NULL
[2016-10-07T20:15:41.662]   gres_bit_alloc[0]:2-3,5-7
[2016-10-07T20:15:41.662]   gres_bit_alloc[1]:0-1
[2016-10-07T20:15:41.662] sched: Allocate JobID=1897 NodeList=gpu-cluster-1 #CPUs=1 Partition=partition
[2016-10-07T20:15:41.662] job start: job_id = 1897	time = 1475842541

[2016-10-07T20:15:41.662] gres: gpu state for job 1898
[2016-10-07T20:15:41.662]   gres_cnt:5 node_cnt:1 type:(null)
[2016-10-07T20:15:41.662]   gres_bit_step_alloc:NULL
[2016-10-07T20:15:41.662]   gres_cnt_step_alloc:NULL
[2016-10-07T20:15:41.662]   gres_bit_alloc[0]:2-6
[2016-10-07T20:15:41.662] sched: Allocate JobID=1898 NodeList=gpu-cluster-1 #CPUs=1 Partition=partition
[2016-10-07T20:15:41.662] job start: job_id = 1898	time = 1475842541

[2016-10-07T20:15:41.662] gres: gpu state for job 1899
[2016-10-07T20:15:41.662]   gres_cnt:1 node_cnt:1 type:(null)
[2016-10-07T20:15:41.662]   gres_bit_step_alloc:NULL
[2016-10-07T20:15:41.662]   gres_cnt_step_alloc:NULL
[2016-10-07T20:15:41.662]   gres_bit_alloc[0]:7
[2016-10-07T20:15:41.662] sched: Allocate JobID=1899 NodeList=gpu-cluster-1 #CPUs=1 Partition=partition
[2016-10-07T20:15:41.663] job start: job_id = 1899	time = 1475842541

[2016-10-07T20:15:41.862] job_complete: JobID=1894 State=0x1 NodeCnt=1 WEXITSTATUS 255
[2016-10-07T20:15:41.862] job end: job_id = 1894	time = 1475842541

[2016-10-07T20:15:41.862] job_complete: JobID=1894 State=0x8005 NodeCnt=1 done
[2016-10-07T20:15:41.867] gres: gpu state for job 1900
[2016-10-07T20:15:41.867]   gres_cnt:2 node_cnt:2 type:(null)
[2016-10-07T20:15:41.867]   gres_bit_step_alloc:NULL
[2016-10-07T20:15:41.867]   gres_cnt_step_alloc:NULL
[2016-10-07T20:15:41.867]   gres_bit_alloc[0]:7
[2016-10-07T20:15:41.867]   gres_bit_alloc[1]:0
[2016-10-07T20:15:41.867] sched: Allocate JobID=1900 NodeList=gpu-cluster-1 #CPUs=1 Partition=partition
[2016-10-07T20:15:41.868] job start: job_id = 1900	time = 1475842541

[2016-10-07T20:15:42.121] job_complete: JobID=1899 State=0x1 NodeCnt=1 WEXITSTATUS 255
[2016-10-07T20:15:42.121] job end: job_id = 1899	time = 1475842542

[2016-10-07T20:15:42.121] job_complete: JobID=1899 State=0x8005 NodeCnt=1 done
[2016-10-07T20:15:42.128] job_complete: JobID=1898 State=0x1 NodeCnt=1 WEXITSTATUS 255
[2016-10-07T20:15:42.128] job end: job_id = 1898	time = 1475842542

[2016-10-07T20:15:42.128] job_complete: JobID=1898 State=0x8005 NodeCnt=1 done
[2016-10-07T20:15:42.133] gres: gpu state for job 1901
[2016-10-07T20:15:42.133]   gres_cnt:6 node_cnt:2 type:(null)
[2016-10-07T20:15:42.133]   gres_bit_step_alloc:NULL
[2016-10-07T20:15:42.133]   gres_cnt_step_alloc:NULL
[2016-10-07T20:15:42.133]   gres_bit_alloc[0]:4
[2016-10-07T20:15:42.133]   gres_bit_alloc[1]:2-6
[2016-10-07T20:15:42.133] sched: Allocate JobID=1901 NodeList=gpu-cluster-1 #CPUs=1 Partition=partition
[2016-10-07T20:15:42.133] job start: job_id = 1901	time = 1475842542

[2016-10-07T20:15:42.157] job_complete: JobID=1897 State=0x1 NodeCnt=1 WEXITSTATUS 255
[2016-10-07T20:15:42.157] job end: job_id = 1897	time = 1475842542

[2016-10-07T20:15:42.157] job_complete: JobID=1897 State=0x8005 NodeCnt=1 done
[2016-10-07T20:15:42.162] gres: gpu state for job 1902
[2016-10-07T20:15:42.162]   gres_cnt:4 node_cnt:1 type:(null)
[2016-10-07T20:15:42.162]   gres_bit_step_alloc:NULL
[2016-10-07T20:15:42.162]   gres_cnt_step_alloc:NULL
[2016-10-07T20:15:42.162]   gres_bit_alloc[0]:2-3,5-6
[2016-10-07T20:15:42.162] sched: Allocate JobID=1902 NodeList=gpu-cluster-1 #CPUs=1 Partition=partition
[2016-10-07T20:15:42.162] job start: job_id = 1902	time = 1475842542

[2016-10-07T20:15:42.186] job_complete: JobID=1896 State=0x1 NodeCnt=1 WEXITSTATUS 255
[2016-10-07T20:15:42.186] job end: job_id = 1896	time = 1475842542

[2016-10-07T20:15:42.186] job_complete: JobID=1896 State=0x8005 NodeCnt=1 done
[2016-10-07T20:15:42.191] gres: gpu state for job 1903
[2016-10-07T20:15:42.191]   gres_cnt:8 node_cnt:2 type:(null)
[2016-10-07T20:15:42.192]   gres_bit_step_alloc:NULL
[2016-10-07T20:15:42.192]   gres_cnt_step_alloc:NULL
[2016-10-07T20:15:42.192]   gres_bit_alloc[0]:0-6
[2016-10-07T20:15:42.192]   gres_bit_alloc[1]:1
[2016-10-07T20:15:42.192] sched: Allocate JobID=1903 NodeList=gpu-cluster-1 #CPUs=1 Partition=partition
[2016-10-07T20:15:42.192] job start: job_id = 1903	time = 1475842542

[2016-10-07T20:15:42.192] gres: gpu state for job 1904
[2016-10-07T20:15:42.192]   gres_cnt:1 node_cnt:1 type:(null)
[2016-10-07T20:15:42.192]   gres_bit_step_alloc:NULL
[2016-10-07T20:15:42.192]   gres_cnt_step_alloc:NULL
[2016-10-07T20:15:42.192]   gres_bit_alloc[0]:7
[2016-10-07T20:15:42.192] sched: Allocate JobID=1904 NodeList=gpu-cluster-1 #CPUs=1 Partition=partition
[2016-10-07T20:15:42.192] job start: job_id = 1904	time = 1475842542

[2016-10-07T20:15:42.192] gres: gpu state for job 1905
[2016-10-07T20:15:42.192]   gres_cnt:1 node_cnt:1 type:(null)
[2016-10-07T20:15:42.192]   gres_bit_step_alloc:NULL
[2016-10-07T20:15:42.192]   gres_cnt_step_alloc:NULL
[2016-10-07T20:15:42.192]   gres_bit_alloc[0]:0
[2016-10-07T20:15:42.192] sched: Allocate JobID=1905 NodeList=gpu-cluster-1 #CPUs=1 Partition=partition
[2016-10-07T20:15:42.193] job start: job_id = 1905	time = 1475842542

[2016-10-07T20:15:42.193] gres: gpu state for job 1906
[2016-10-07T20:15:42.193]   gres_cnt:2 node_cnt:1 type:(null)
[2016-10-07T20:15:42.193]   gres_bit_step_alloc:NULL
[2016-10-07T20:15:42.193]   gres_cnt_step_alloc:NULL
[2016-10-07T20:15:42.193]   gres_bit_alloc[0]:1,7
[2016-10-07T20:15:42.193] sched: Allocate JobID=1906 NodeList=gpu-cluster-1 #CPUs=1 Partition=partition
[2016-10-07T20:15:42.193] job start: job_id = 1906	time = 1475842542

[2016-10-07T20:15:42.486] job_complete: JobID=1900 State=0x1 NodeCnt=1 WEXITSTATUS 255
[2016-10-07T20:15:42.486] job end: job_id = 1900	time = 1475842542

[2016-10-07T20:15:42.486] job_complete: JobID=1900 State=0x8005 NodeCnt=1 done
[2016-10-07T20:15:42.778] job_complete: JobID=1901 State=0x1 NodeCnt=1 WEXITSTATUS 255
[2016-10-07T20:15:42.778] job end: job_id = 1901	time = 1475842542

[2016-10-07T20:15:42.778] job_complete: JobID=1901 State=0x8005 NodeCnt=1 done
[2016-10-07T20:15:42.783] gres: gpu state for job 1907
[2016-10-07T20:15:42.783]   gres_cnt:8 node_cnt:3 type:(null)
[2016-10-07T20:15:42.783]   gres_bit_step_alloc:NULL
[2016-10-07T20:15:42.783]   gres_cnt_step_alloc:NULL
[2016-10-07T20:15:42.783]   gres_bit_alloc[0]:7
[2016-10-07T20:15:42.783]   gres_bit_alloc[1]:0,4
[2016-10-07T20:15:42.783]   gres_bit_alloc[2]:2-6
[2016-10-07T20:15:42.783] sched: Allocate JobID=1907 NodeList=gpu-cluster-1 #CPUs=1 Partition=partition
[2016-10-07T20:15:42.783] job start: job_id = 1907	time = 1475842542

[2016-10-07T20:15:42.850] job_complete: JobID=1905 State=0x1 NodeCnt=1 WEXITSTATUS 255
[2016-10-07T20:15:42.850] job end: job_id = 1905	time = 1475842542

[2016-10-07T20:15:42.850] job_complete: JobID=1905 State=0x8005 NodeCnt=1 done
[2016-10-07T20:15:42.859] job_complete: JobID=1906 State=0x1 NodeCnt=1 WEXITSTATUS 255
[2016-10-07T20:15:42.859] job end: job_id = 1906	time = 1475842542

[2016-10-07T20:15:42.859] job_complete: JobID=1906 State=0x8005 NodeCnt=1 done
[2016-10-07T20:15:43.045] job_complete: JobID=1903 State=0x1 NodeCnt=1 WEXITSTATUS 255
[2016-10-07T20:15:43.045] job end: job_id = 1903	time = 1475842543

[2016-10-07T20:15:43.045] job_complete: JobID=1903 State=0x8005 NodeCnt=1 done
[2016-10-07T20:15:43.051] gres: gpu state for job 1908
[2016-10-07T20:15:43.051]   gres_cnt:5 node_cnt:1 type:(null)
[2016-10-07T20:15:43.051]   gres_bit_step_alloc:NULL
[2016-10-07T20:15:43.051]   gres_cnt_step_alloc:NULL
[2016-10-07T20:15:43.051]   gres_bit_alloc[0]:0-4
[2016-10-07T20:15:43.051] sched: Allocate JobID=1908 NodeList=gpu-cluster-1 #CPUs=1 Partition=partition
[2016-10-07T20:15:43.051] job start: job_id = 1908	time = 1475842543

[2016-10-07T20:15:43.051] gres: gpu state for job 1909
[2016-10-07T20:15:43.051]   gres_cnt:2 node_cnt:1 type:(null)
[2016-10-07T20:15:43.051]   gres_bit_step_alloc:NULL
[2016-10-07T20:15:43.051]   gres_cnt_step_alloc:NULL
[2016-10-07T20:15:43.051]   gres_bit_alloc[0]:5-6
[2016-10-07T20:15:43.051] sched: Allocate JobID=1909 NodeList=gpu-cluster-1 #CPUs=1 Partition=partition
[2016-10-07T20:15:43.051] job start: job_id = 1909	time = 1475842543

[2016-10-07T20:15:43.115] job_complete: JobID=1904 State=0x1 NodeCnt=1 WEXITSTATUS 255
[2016-10-07T20:15:43.115] job end: job_id = 1904	time = 1475842543

[2016-10-07T20:15:43.115] job_complete: JobID=1904 State=0x8005 NodeCnt=1 done
[2016-10-07T20:15:43.119] job_complete: JobID=1902 State=0x1 NodeCnt=1 WEXITSTATUS 255
[2016-10-07T20:15:43.119] job end: job_id = 1902	time = 1475842543

[2016-10-07T20:15:43.119] job_complete: JobID=1902 State=0x8005 NodeCnt=1 done
[2016-10-07T20:15:43.120] gres: gpu state for job 1910
[2016-10-07T20:15:43.120]   gres_cnt:5 node_cnt:1 type:(null)
[2016-10-07T20:15:43.120]   gres_bit_step_alloc:NULL
[2016-10-07T20:15:43.120]   gres_cnt_step_alloc:NULL
[2016-10-07T20:15:43.120]   gres_bit_alloc[0]:1-3,5-6
[2016-10-07T20:15:43.120] sched: Allocate JobID=1910 NodeList=gpu-cluster-2 #CPUs=1 Partition=partition
[2016-10-07T20:15:43.120] job start: job_id = 1910	time = 1475842543

[2016-10-07T20:15:43.138] job_complete: JobID=1910 State=0x1 NodeCnt=1 WEXITSTATUS 1
[2016-10-07T20:15:43.138] job end: job_id = 1910	time = 1475842543

[2016-10-07T20:15:43.138] job_complete: JobID=1910 State=0x8005 NodeCnt=1 done
[2016-10-07T20:15:43.143] gres: gpu state for job 1911
[2016-10-07T20:15:43.143]   gres_cnt:8 node_cnt:2 type:(null)
[2016-10-07T20:15:43.143]   gres_bit_step_alloc:NULL
[2016-10-07T20:15:43.143]   gres_cnt_step_alloc:NULL
[2016-10-07T20:15:43.143]   gres_bit_alloc[0]:1-3,5-7
[2016-10-07T20:15:43.143]   gres_bit_alloc[1]:0-1
[2016-10-07T20:15:43.143] sched: Allocate JobID=1911 NodeList=gpu-cluster-1 #CPUs=1 Partition=partition
[2016-10-07T20:15:43.144] job start: job_id = 1911	time = 1475842543

[2016-10-07T20:15:43.218] job_complete: JobID=1907 State=0x1 NodeCnt=1 WEXITSTATUS 255
[2016-10-07T20:15:43.218] job end: job_id = 1907	time = 1475842543

[2016-10-07T20:15:43.218] job_complete: JobID=1907 State=0x8005 NodeCnt=1 done
[2016-10-07T20:15:43.224] gres: gpu state for job 1912
[2016-10-07T20:15:43.224]   gres_cnt:8 node_cnt:3 type:(null)
[2016-10-07T20:15:43.224]   gres_bit_step_alloc:NULL
[2016-10-07T20:15:43.224]   gres_cnt_step_alloc:NULL
[2016-10-07T20:15:43.224]   gres_bit_alloc[0]:7
[2016-10-07T20:15:43.224]   gres_bit_alloc[1]:0,4
[2016-10-07T20:15:43.224]   gres_bit_alloc[2]:2-6
[2016-10-07T20:15:43.224] sched: Allocate JobID=1912 NodeList=gpu-cluster-1 #CPUs=1 Partition=partition
[2016-10-07T20:15:43.224] job start: job_id = 1912	time = 1475842543

[2016-10-07T20:15:43.736] job_complete: JobID=1909 State=0x1 NodeCnt=1 WEXITSTATUS 255
[2016-10-07T20:15:43.736] job end: job_id = 1909	time = 1475842543

[2016-10-07T20:15:43.736] job_complete: JobID=1909 State=0x8005 NodeCnt=1 done
[2016-10-07T20:15:43.736] job_complete: JobID=1911 State=0x1 NodeCnt=1 WEXITSTATUS 255
[2016-10-07T20:15:43.736] job end: job_id = 1911	time = 1475842543

[2016-10-07T20:15:43.736] job_complete: JobID=1911 State=0x8005 NodeCnt=1 done
[2016-10-07T20:15:43.741] gres: gpu state for job 1913
[2016-10-07T20:15:43.741]   gres_cnt:4 node_cnt:2 type:(null)
[2016-10-07T20:15:43.741]   gres_bit_step_alloc:NULL
[2016-10-07T20:15:43.741]   gres_cnt_step_alloc:NULL
[2016-10-07T20:15:43.741]   gres_bit_alloc[0]:5-6
[2016-10-07T20:15:43.741]   gres_bit_alloc[1]:1-2
[2016-10-07T20:15:43.741] sched: Allocate JobID=1913 NodeList=gpu-cluster-1 #CPUs=1 Partition=partition
[2016-10-07T20:15:43.741] job start: job_id = 1913	time = 1475842543

[2016-10-07T20:15:43.741] gres: gpu state for job 1914
[2016-10-07T20:15:43.741]   gres_cnt:2 node_cnt:1 type:(null)
[2016-10-07T20:15:43.741]   gres_bit_step_alloc:NULL
[2016-10-07T20:15:43.741]   gres_cnt_step_alloc:NULL
[2016-10-07T20:15:43.741]   gres_bit_alloc[0]:3,5
[2016-10-07T20:15:43.741] sched: Allocate JobID=1914 NodeList=gpu-cluster-1 #CPUs=1 Partition=partition
[2016-10-07T20:15:43.742] job start: job_id = 1914	time = 1475842543

[2016-10-07T20:15:43.742] gres: gpu state for job 1915
[2016-10-07T20:15:43.742]   gres_cnt:5 node_cnt:2 type:(null)
[2016-10-07T20:15:43.742]   gres_bit_step_alloc:NULL
[2016-10-07T20:15:43.742]   gres_cnt_step_alloc:NULL
[2016-10-07T20:15:43.742]   gres_bit_alloc[0]:6-7
[2016-10-07T20:15:43.742]   gres_bit_alloc[1]:0-1,7
[2016-10-07T20:15:43.742] sched: Allocate JobID=1915 NodeList=gpu-cluster-1 #CPUs=1 Partition=partition
[2016-10-07T20:15:43.742] job start: job_id = 1915	time = 1475842543

[2016-10-07T20:15:43.742] job_complete: JobID=1912 State=0x1 NodeCnt=1 WEXITSTATUS 255
[2016-10-07T20:15:43.742] job end: job_id = 1912	time = 1475842543

[2016-10-07T20:15:43.742] job_complete: JobID=1912 State=0x8005 NodeCnt=1 done
[2016-10-07T20:15:43.747] gres: gpu state for job 1916
[2016-10-07T20:15:43.747]   gres_cnt:6 node_cnt:3 type:(null)
[2016-10-07T20:15:43.747]   gres_bit_step_alloc:NULL
[2016-10-07T20:15:43.747]   gres_cnt_step_alloc:NULL
[2016-10-07T20:15:43.747]   gres_bit_alloc[0]:7
[2016-10-07T20:15:43.747]   gres_bit_alloc[1]:0,4
[2016-10-07T20:15:43.747]   gres_bit_alloc[2]:2-4
[2016-10-07T20:15:43.747] sched: Allocate JobID=1916 NodeList=gpu-cluster-1 #CPUs=1 Partition=partition
[2016-10-07T20:15:43.747] job start: job_id = 1916	time = 1475842543

[2016-10-07T20:15:43.770] job_complete: JobID=1908 State=0x1 NodeCnt=1 WEXITSTATUS 255
[2016-10-07T20:15:43.770] job end: job_id = 1908	time = 1475842543

[2016-10-07T20:15:43.770] job_complete: JobID=1908 State=0x8005 NodeCnt=1 done
[2016-10-07T20:15:43.775] gres: gpu state for job 1917
[2016-10-07T20:15:43.775]   gres_cnt:6 node_cnt:2 type:(null)
[2016-10-07T20:15:43.775]   gres_bit_step_alloc:NULL
[2016-10-07T20:15:43.775]   gres_cnt_step_alloc:NULL
[2016-10-07T20:15:43.775]   gres_bit_alloc[0]:0-4
[2016-10-07T20:15:43.775]   gres_bit_alloc[1]:5
[2016-10-07T20:15:43.775] sched: Allocate JobID=1917 NodeList=gpu-cluster-1 #CPUs=1 Partition=partition
[2016-10-07T20:15:43.775] job start: job_id = 1917	time = 1475842543

[2016-10-07T20:15:44.386] job_complete: JobID=1915 State=0x1 NodeCnt=1 WEXITSTATUS 255
[2016-10-07T20:15:44.386] job end: job_id = 1915	time = 1475842544

[2016-10-07T20:15:44.386] job_complete: JobID=1915 State=0x8005 NodeCnt=1 done
[2016-10-07T20:15:44.398] job_complete: JobID=1917 State=0x1 NodeCnt=1 WEXITSTATUS 255
[2016-10-07T20:15:44.398] job end: job_id = 1917	time = 1475842544

[2016-10-07T20:15:44.398] job_complete: JobID=1917 State=0x8005 NodeCnt=1 done
[2016-10-07T20:15:44.403] gres: gpu state for job 1918
[2016-10-07T20:15:44.403]   gres_cnt:7 node_cnt:2 type:(null)
[2016-10-07T20:15:44.403]   gres_bit_step_alloc:NULL
[2016-10-07T20:15:44.403]   gres_cnt_step_alloc:NULL
[2016-10-07T20:15:44.403]   gres_bit_alloc[0]:0-4
[2016-10-07T20:15:44.403]   gres_bit_alloc[1]:6-7
[2016-10-07T20:15:44.403] sched: Allocate JobID=1918 NodeList=gpu-cluster-1 #CPUs=1 Partition=partition
[2016-10-07T20:15:44.403] job start: job_id = 1918	time = 1475842544

[2016-10-07T20:15:44.423] job_complete: JobID=1916 State=0x1 NodeCnt=1 WEXITSTATUS 255
[2016-10-07T20:15:44.423] job end: job_id = 1916	time = 1475842544

[2016-10-07T20:15:44.423] job_complete: JobID=1916 State=0x8005 NodeCnt=1 done
[2016-10-07T20:15:44.428] gres: gpu state for job 1919
[2016-10-07T20:15:44.428]   gres_cnt:6 node_cnt:3 type:(null)
[2016-10-07T20:15:44.428]   gres_bit_step_alloc:NULL
[2016-10-07T20:15:44.428]   gres_cnt_step_alloc:NULL
[2016-10-07T20:15:44.428]   gres_bit_alloc[0]:7
[2016-10-07T20:15:44.428]   gres_bit_alloc[1]:0,4
[2016-10-07T20:15:44.428]   gres_bit_alloc[2]:0-2
[2016-10-07T20:15:44.428] sched: Allocate JobID=1919 NodeList=gpu-cluster-1 #CPUs=1 Partition=partition
[2016-10-07T20:15:44.428] job start: job_id = 1919	time = 1475842544

[2016-10-07T20:15:44.634] job_complete: JobID=1913 State=0x1 NodeCnt=1 WEXITSTATUS 255
[2016-10-07T20:15:44.634] job end: job_id = 1913	time = 1475842544

[2016-10-07T20:15:44.634] job_complete: JobID=1913 State=0x8005 NodeCnt=1 done
[2016-10-07T20:15:44.634] job_complete: JobID=1914 State=0x1 NodeCnt=1 WEXITSTATUS 255
[2016-10-07T20:15:44.634] job end: job_id = 1914	time = 1475842544

[2016-10-07T20:15:44.634] job_complete: JobID=1914 State=0x8005 NodeCnt=1 done
[2016-10-07T20:15:44.639] gres: gpu state for job 1920
[2016-10-07T20:15:44.639]   gres_cnt:8 node_cnt:3 type:(null)
[2016-10-07T20:15:44.639]   gres_bit_step_alloc:NULL
[2016-10-07T20:15:44.639]   gres_cnt_step_alloc:NULL
[2016-10-07T20:15:44.639]   gres_bit_alloc[0]:5-6
[2016-10-07T20:15:44.639]   gres_bit_alloc[1]:1-3,5
[2016-10-07T20:15:44.639]   gres_bit_alloc[2]:3-4
[2016-10-07T20:15:44.640] sched: Allocate JobID=1920 NodeList=gpu-cluster-1 #CPUs=1 Partition=partition
[2016-10-07T20:15:44.640] job start: job_id = 1920	time = 1475842544

[2016-10-07T20:15:44.969] job_complete: JobID=1919 State=0x1 NodeCnt=1 WEXITSTATUS 255
[2016-10-07T20:15:44.969] job end: job_id = 1919	time = 1475842544

[2016-10-07T20:15:44.969] job_complete: JobID=1919 State=0x8005 NodeCnt=1 done
[2016-10-07T20:15:44.974] gres: gpu state for job 1921
[2016-10-07T20:15:44.974]   gres_cnt:5 node_cnt:3 type:(null)
[2016-10-07T20:15:44.974]   gres_bit_step_alloc:NULL
[2016-10-07T20:15:44.974]   gres_cnt_step_alloc:NULL
[2016-10-07T20:15:44.974]   gres_bit_alloc[0]:7
[2016-10-07T20:15:44.974]   gres_bit_alloc[1]:0,4
[2016-10-07T20:15:44.974]   gres_bit_alloc[2]:0-1
[2016-10-07T20:15:44.974] sched: Allocate JobID=1921 NodeList=gpu-cluster-1 #CPUs=1 Partition=partition
[2016-10-07T20:15:44.974] job start: job_id = 1921	time = 1475842544

[2016-10-07T20:15:45.078] job_complete: JobID=1920 State=0x1 NodeCnt=1 WEXITSTATUS 255
[2016-10-07T20:15:45.078] job end: job_id = 1920	time = 1475842545

[2016-10-07T20:15:45.078] job_complete: JobID=1920 State=0x8005 NodeCnt=1 done
[2016-10-07T20:15:45.083] gres: gpu state for job 1922
[2016-10-07T20:15:45.083]   gres_cnt:8 node_cnt:3 type:(null)
[2016-10-07T20:15:45.083]   gres_bit_step_alloc:NULL
[2016-10-07T20:15:45.083]   gres_cnt_step_alloc:NULL
[2016-10-07T20:15:45.083]   gres_bit_alloc[0]:5-6
[2016-10-07T20:15:45.083]   gres_bit_alloc[1]:1-3,5
[2016-10-07T20:15:45.083]   gres_bit_alloc[2]:2-3
[2016-10-07T20:15:45.083] sched: Allocate JobID=1922 NodeList=gpu-cluster-1 #CPUs=1 Partition=partition
[2016-10-07T20:15:45.083] job start: job_id = 1922	time = 1475842545

[2016-10-07T20:15:45.083] gres: gpu state for job 1923
[2016-10-07T20:15:45.083]   gres_cnt:4 node_cnt:1 type:(null)
[2016-10-07T20:15:45.083]   gres_bit_step_alloc:NULL
[2016-10-07T20:15:45.083]   gres_cnt_step_alloc:NULL
[2016-10-07T20:15:45.083]   gres_bit_alloc[0]:4-7
[2016-10-07T20:15:45.083] sched: Allocate JobID=1923 NodeList=gpu-cluster-1 #CPUs=1 Partition=partition
[2016-10-07T20:15:45.084] job start: job_id = 1923	time = 1475842545

[2016-10-07T20:15:45.180] job_complete: JobID=1918 State=0x1 NodeCnt=1 WEXITSTATUS 255
[2016-10-07T20:15:45.180] job end: job_id = 1918	time = 1475842545

[2016-10-07T20:15:45.180] job_complete: JobID=1918 State=0x8005 NodeCnt=1 done
[2016-10-07T20:15:45.185] gres: gpu state for job 1924
[2016-10-07T20:15:45.185]   gres_cnt:4 node_cnt:1 type:(null)
[2016-10-07T20:15:45.185]   gres_bit_step_alloc:NULL
[2016-10-07T20:15:45.185]   gres_cnt_step_alloc:NULL
[2016-10-07T20:15:45.185]   gres_bit_alloc[0]:0-3
[2016-10-07T20:15:45.185] sched: Allocate JobID=1924 NodeList=gpu-cluster-1 #CPUs=1 Partition=partition
[2016-10-07T20:15:45.185] job start: job_id = 1924	time = 1475842545

[2016-10-07T20:15:45.186] gres: gpu state for job 1925
[2016-10-07T20:15:45.186]   gres_cnt:2 node_cnt:2 type:(null)
[2016-10-07T20:15:45.186]   gres_bit_step_alloc:NULL
[2016-10-07T20:15:45.186]   gres_cnt_step_alloc:NULL
[2016-10-07T20:15:45.186]   gres_bit_alloc[0]:4
[2016-10-07T20:15:45.186]   gres_bit_alloc[1]:6
[2016-10-07T20:15:45.186] sched: Allocate JobID=1925 NodeList=gpu-cluster-1 #CPUs=1 Partition=partition
[2016-10-07T20:15:45.186] job start: job_id = 1925	time = 1475842545

[2016-10-07T20:15:45.329] job_complete: JobID=1921 State=0x1 NodeCnt=1 WEXITSTATUS 255
[2016-10-07T20:15:45.329] job end: job_id = 1921	time = 1475842545

[2016-10-07T20:15:45.329] job_complete: JobID=1921 State=0x8005 NodeCnt=1 done
[2016-10-07T20:15:45.502] job_complete: JobID=1923 State=0x1 NodeCnt=1 WEXITSTATUS 255
[2016-10-07T20:15:45.502] job end: job_id = 1923	time = 1475842545

[2016-10-07T20:15:45.502] job_complete: JobID=1923 State=0x8005 NodeCnt=1 done
[2016-10-07T20:15:45.507] gres: gpu state for job 1926
[2016-10-07T20:15:45.507]   gres_cnt:8 node_cnt:3 type:(null)
[2016-10-07T20:15:45.507]   gres_bit_step_alloc:NULL
[2016-10-07T20:15:45.507]   gres_cnt_step_alloc:NULL
[2016-10-07T20:15:45.507]   gres_bit_alloc[0]:7
[2016-10-07T20:15:45.507]   gres_bit_alloc[1]:0,4,7
[2016-10-07T20:15:45.507]   gres_bit_alloc[2]:0-1,4-5
[2016-10-07T20:15:45.507] sched: Allocate JobID=1926 NodeList=gpu-cluster-1 #CPUs=1 Partition=partition
[2016-10-07T20:15:45.508] job start: job_id = 1926	time = 1475842545

[2016-10-07T20:15:45.580] job_complete: JobID=1922 State=0x1 NodeCnt=1 WEXITSTATUS 255
[2016-10-07T20:15:45.580] job end: job_id = 1922	time = 1475842545

[2016-10-07T20:15:45.580] job_complete: JobID=1922 State=0x8005 NodeCnt=1 done
[2016-10-07T20:15:45.585] gres: gpu state for job 1927
[2016-10-07T20:15:45.586]   gres_cnt:8 node_cnt:3 type:(null)
[2016-10-07T20:15:45.586]   gres_bit_step_alloc:NULL
[2016-10-07T20:15:45.586]   gres_cnt_step_alloc:NULL
[2016-10-07T20:15:45.586]   gres_bit_alloc[0]:5-6
[2016-10-07T20:15:45.586]   gres_bit_alloc[1]:1-3,5
[2016-10-07T20:15:45.586]   gres_bit_alloc[2]:2-3
[2016-10-07T20:15:45.586] sched: Allocate JobID=1927 NodeList=gpu-cluster-1 #CPUs=1 Partition=partition
[2016-10-07T20:15:45.586] job start: job_id = 1927	time = 1475842545

[2016-10-07T20:15:45.830] job_complete: JobID=1924 State=0x1 NodeCnt=1 WEXITSTATUS 255
[2016-10-07T20:15:45.830] job end: job_id = 1924	time = 1475842545

[2016-10-07T20:15:45.830] job_complete: JobID=1924 State=0x8005 NodeCnt=1 done
[2016-10-07T20:15:45.902] job_complete: JobID=1925 State=0x1 NodeCnt=1 WEXITSTATUS 255
[2016-10-07T20:15:45.903] job end: job_id = 1925	time = 1475842545

[2016-10-07T20:15:45.903] job_complete: JobID=1925 State=0x8005 NodeCnt=1 done
[2016-10-07T20:15:45.906] job_complete: JobID=1927 State=0x1 NodeCnt=1 WEXITSTATUS 255
[2016-10-07T20:15:45.906] job end: job_id = 1927	time = 1475842545

[2016-10-07T20:15:45.906] job_complete: JobID=1927 State=0x8005 NodeCnt=1 done
[2016-10-07T20:15:45.958] job_complete: JobID=1926 State=0x1 NodeCnt=1 WEXITSTATUS 255
[2016-10-07T20:15:45.958] job end: job_id = 1926	time = 1475842545

[2016-10-07T20:15:45.958] job_complete: JobID=1926 State=0x8005 NodeCnt=1 done
[2016-10-07T20:15:49.869] job_complete: JobID=1828 State=0x1 NodeCnt=1 WEXITSTATUS 255
[2016-10-07T20:15:49.869] job end: job_id = 1828	time = 1475842549

[2016-10-07T20:15:49.870] job_complete: JobID=1828 State=0x8005 NodeCnt=1 done
[2016-10-07T20:17:21.870] gres: gpu state for job 1928
[2016-10-07T20:17:21.870]   gres_cnt:1 node_cnt:0 type:(null)
[2016-10-07T20:17:21.871] _slurm_rpc_submit_batch_job JobId=1928 usec=694
[2016-10-07T20:17:21.871] job submit: job_id = 1928	time = 1475842641

[2016-10-07T20:17:22.103] gres: gpu state for job 1928
[2016-10-07T20:17:22.103]   gres_cnt:1 node_cnt:1 type:(null)
[2016-10-07T20:17:22.103]   gres_bit_step_alloc:NULL
[2016-10-07T20:17:22.103]   gres_cnt_step_alloc:NULL
[2016-10-07T20:17:22.103]   gres_bit_alloc[0]:0
[2016-10-07T20:17:22.103] backfill: Started JobId=1928 in partition on gpu-cluster-1
[2016-10-07T20:17:22.104] job start: job_id = 1928	time = 1475842642

[2016-10-07T20:17:22.360] job_complete: JobID=1928 State=0x1 NodeCnt=1 WEXITSTATUS 255
[2016-10-07T20:17:22.360] job end: job_id = 1928	time = 1475842642

[2016-10-07T20:17:22.360] job_complete: JobID=1928 State=0x8005 NodeCnt=1 done
[2016-10-07T20:18:33.788] gres: gpu state for job 1929
[2016-10-07T20:18:33.788]   gres_cnt:2 node_cnt:0 type:(null)
[2016-10-07T20:18:33.788] _slurm_rpc_submit_batch_job JobId=1929 usec=675
[2016-10-07T20:18:33.789] job submit: job_id = 1929	time = 1475842713

[2016-10-07T20:18:35.321] gres: gpu state for job 1929
[2016-10-07T20:18:35.321]   gres_cnt:2 node_cnt:1 type:(null)
[2016-10-07T20:18:35.321]   gres_bit_step_alloc:NULL
[2016-10-07T20:18:35.321]   gres_cnt_step_alloc:NULL
[2016-10-07T20:18:35.321]   gres_bit_alloc[0]:0-1
[2016-10-07T20:18:35.322] sched: Allocate JobID=1929 NodeList=gpu-cluster-1 #CPUs=2 Partition=partition
[2016-10-07T20:18:35.322] job start: job_id = 1929	time = 1475842715

[2016-10-07T20:18:36.807] job_complete: JobID=1929 State=0x1 NodeCnt=1 WEXITSTATUS 0
[2016-10-07T20:18:36.807] job end: job_id = 1929	time = 1475842716

[2016-10-07T20:18:36.807] job_complete: JobID=1929 State=0x8003 NodeCnt=1 done
[2016-10-07T20:19:32.448] error: Nodes gpu-cluster-[3-4] not responding
[2016-10-07T20:19:57.722] gres: gpu state for job 1930
[2016-10-07T20:19:57.722]   gres_cnt:8 node_cnt:0 type:(null)
[2016-10-07T20:19:57.723] _slurm_rpc_submit_batch_job JobId=1930 usec=683
[2016-10-07T20:19:57.723] job submit: job_id = 1930	time = 1475842797

[2016-10-07T20:19:57.728] gres: gpu state for job 1931
[2016-10-07T20:19:57.728]   gres_cnt:4 node_cnt:0 type:(null)
[2016-10-07T20:19:57.729] _slurm_rpc_submit_batch_job JobId=1931 usec=589
[2016-10-07T20:19:57.729] job submit: job_id = 1931	time = 1475842797

[2016-10-07T20:19:57.735] gres: gpu state for job 1932
[2016-10-07T20:19:57.735]   gres_cnt:6 node_cnt:0 type:(null)
[2016-10-07T20:19:57.735] _slurm_rpc_submit_batch_job JobId=1932 usec=587
[2016-10-07T20:19:57.736] job submit: job_id = 1932	time = 1475842797

[2016-10-07T20:19:57.743] gres: gpu state for job 1933
[2016-10-07T20:19:57.743]   gres_cnt:8 node_cnt:0 type:(null)
[2016-10-07T20:19:57.744] _slurm_rpc_submit_batch_job JobId=1933 usec=587
[2016-10-07T20:19:57.744] job submit: job_id = 1933	time = 1475842797

[2016-10-07T20:19:57.751] gres: gpu state for job 1934
[2016-10-07T20:19:57.751]   gres_cnt:2 node_cnt:0 type:(null)
[2016-10-07T20:19:57.751] _slurm_rpc_submit_batch_job JobId=1934 usec=596
[2016-10-07T20:19:57.752] job submit: job_id = 1934	time = 1475842797

[2016-10-07T20:19:57.759] gres: gpu state for job 1935
[2016-10-07T20:19:57.759]   gres_cnt:3 node_cnt:0 type:(null)
[2016-10-07T20:19:57.759] _slurm_rpc_submit_batch_job JobId=1935 usec=602
[2016-10-07T20:19:57.760] job submit: job_id = 1935	time = 1475842797

[2016-10-07T20:19:57.766] gres: gpu state for job 1936
[2016-10-07T20:19:57.766]   gres_cnt:4 node_cnt:0 type:(null)
[2016-10-07T20:19:57.766] _slurm_rpc_submit_batch_job JobId=1936 usec=598
[2016-10-07T20:19:57.767] job submit: job_id = 1936	time = 1475842797

[2016-10-07T20:19:57.773] gres: gpu state for job 1937
[2016-10-07T20:19:57.773]   gres_cnt:2 node_cnt:0 type:(null)
[2016-10-07T20:19:57.774] _slurm_rpc_submit_batch_job JobId=1937 usec=592
[2016-10-07T20:19:57.774] job submit: job_id = 1937	time = 1475842797

[2016-10-07T20:19:57.781] gres: gpu state for job 1938
[2016-10-07T20:19:57.781]   gres_cnt:8 node_cnt:0 type:(null)
[2016-10-07T20:19:57.781] _slurm_rpc_submit_batch_job JobId=1938 usec=590
[2016-10-07T20:19:57.782] job submit: job_id = 1938	time = 1475842797

[2016-10-07T20:19:57.788] gres: gpu state for job 1939
[2016-10-07T20:19:57.788]   gres_cnt:5 node_cnt:0 type:(null)
[2016-10-07T20:19:57.788] _slurm_rpc_submit_batch_job JobId=1939 usec=605
[2016-10-07T20:19:57.789] job submit: job_id = 1939	time = 1475842797

[2016-10-07T20:19:57.795] gres: gpu state for job 1940
[2016-10-07T20:19:57.795]   gres_cnt:4 node_cnt:0 type:(null)
[2016-10-07T20:19:57.795] _slurm_rpc_submit_batch_job JobId=1940 usec=585
[2016-10-07T20:19:57.796] job submit: job_id = 1940	time = 1475842797

[2016-10-07T20:19:57.803] gres: gpu state for job 1941
[2016-10-07T20:19:57.803]   gres_cnt:1 node_cnt:0 type:(null)
[2016-10-07T20:19:57.803] _slurm_rpc_submit_batch_job JobId=1941 usec=584
[2016-10-07T20:19:57.804] job submit: job_id = 1941	time = 1475842797

[2016-10-07T20:19:57.811] gres: gpu state for job 1942
[2016-10-07T20:19:57.811]   gres_cnt:2 node_cnt:0 type:(null)
[2016-10-07T20:19:57.811] _slurm_rpc_submit_batch_job JobId=1942 usec=591
[2016-10-07T20:19:57.812] job submit: job_id = 1942	time = 1475842797

[2016-10-07T20:19:57.818] gres: gpu state for job 1943
[2016-10-07T20:19:57.818]   gres_cnt:7 node_cnt:0 type:(null)
[2016-10-07T20:19:57.819] _slurm_rpc_submit_batch_job JobId=1943 usec=583
[2016-10-07T20:19:57.819] job submit: job_id = 1943	time = 1475842797

[2016-10-07T20:19:57.825] gres: gpu state for job 1944
[2016-10-07T20:19:57.825]   gres_cnt:6 node_cnt:0 type:(null)
[2016-10-07T20:19:57.825] _slurm_rpc_submit_batch_job JobId=1944 usec=564
[2016-10-07T20:19:57.826] job submit: job_id = 1944	time = 1475842797

[2016-10-07T20:19:57.832] gres: gpu state for job 1945
[2016-10-07T20:19:57.832]   gres_cnt:2 node_cnt:0 type:(null)
[2016-10-07T20:19:57.832] _slurm_rpc_submit_batch_job JobId=1945 usec=585
[2016-10-07T20:19:57.833] job submit: job_id = 1945	time = 1475842797

[2016-10-07T20:19:57.839] gres: gpu state for job 1946
[2016-10-07T20:19:57.839]   gres_cnt:7 node_cnt:0 type:(null)
[2016-10-07T20:19:57.840] _slurm_rpc_submit_batch_job JobId=1946 usec=590
[2016-10-07T20:19:57.840] job submit: job_id = 1946	time = 1475842797

[2016-10-07T20:19:57.847] gres: gpu state for job 1947
[2016-10-07T20:19:57.847]   gres_cnt:8 node_cnt:0 type:(null)
[2016-10-07T20:19:57.847] _slurm_rpc_submit_batch_job JobId=1947 usec=574
[2016-10-07T20:19:57.848] job submit: job_id = 1947	time = 1475842797

[2016-10-07T20:19:57.854] gres: gpu state for job 1948
[2016-10-07T20:19:57.854]   gres_cnt:6 node_cnt:0 type:(null)
[2016-10-07T20:19:57.855] _slurm_rpc_submit_batch_job JobId=1948 usec=581
[2016-10-07T20:19:57.855] job submit: job_id = 1948	time = 1475842797

[2016-10-07T20:19:57.861] gres: gpu state for job 1949
[2016-10-07T20:19:57.861]   gres_cnt:7 node_cnt:0 type:(null)
[2016-10-07T20:19:57.861] _slurm_rpc_submit_batch_job JobId=1949 usec=577
[2016-10-07T20:19:57.862] job submit: job_id = 1949	time = 1475842797

[2016-10-07T20:19:57.868] gres: gpu state for job 1950
[2016-10-07T20:19:57.868]   gres_cnt:4 node_cnt:0 type:(null)
[2016-10-07T20:19:57.868] _slurm_rpc_submit_batch_job JobId=1950 usec=597
[2016-10-07T20:19:57.869] job submit: job_id = 1950	time = 1475842797

[2016-10-07T20:19:57.875] gres: gpu state for job 1951
[2016-10-07T20:19:57.875]   gres_cnt:6 node_cnt:0 type:(null)
[2016-10-07T20:19:57.876] _slurm_rpc_submit_batch_job JobId=1951 usec=592
[2016-10-07T20:19:57.876] job submit: job_id = 1951	time = 1475842797

[2016-10-07T20:19:57.883] gres: gpu state for job 1952
[2016-10-07T20:19:57.883]   gres_cnt:1 node_cnt:0 type:(null)
[2016-10-07T20:19:57.883] _slurm_rpc_submit_batch_job JobId=1952 usec=696
[2016-10-07T20:19:57.884] job submit: job_id = 1952	time = 1475842797

[2016-10-07T20:19:57.891] gres: gpu state for job 1953
[2016-10-07T20:19:57.892]   gres_cnt:6 node_cnt:0 type:(null)
[2016-10-07T20:19:57.892] _slurm_rpc_submit_batch_job JobId=1953 usec=1268
[2016-10-07T20:19:57.893] job submit: job_id = 1953	time = 1475842797

[2016-10-07T20:19:57.898] gres: gpu state for job 1954
[2016-10-07T20:19:57.899]   gres_cnt:4 node_cnt:0 type:(null)
[2016-10-07T20:19:57.899] _slurm_rpc_submit_batch_job JobId=1954 usec=608
[2016-10-07T20:19:57.900] job submit: job_id = 1954	time = 1475842797

[2016-10-07T20:19:57.908] gres: gpu state for job 1955
[2016-10-07T20:19:57.908]   gres_cnt:2 node_cnt:0 type:(null)
[2016-10-07T20:19:57.908] _slurm_rpc_submit_batch_job JobId=1955 usec=593
[2016-10-07T20:19:57.909] job submit: job_id = 1955	time = 1475842797

[2016-10-07T20:19:57.916] gres: gpu state for job 1956
[2016-10-07T20:19:57.916]   gres_cnt:8 node_cnt:0 type:(null)
[2016-10-07T20:19:57.917] _slurm_rpc_submit_batch_job JobId=1956 usec=641
[2016-10-07T20:19:57.917] job submit: job_id = 1956	time = 1475842797

[2016-10-07T20:19:57.924] gres: gpu state for job 1957
[2016-10-07T20:19:57.924]   gres_cnt:3 node_cnt:0 type:(null)
[2016-10-07T20:19:57.925] _slurm_rpc_submit_batch_job JobId=1957 usec=614
[2016-10-07T20:19:57.925] job submit: job_id = 1957	time = 1475842797

[2016-10-07T20:19:57.932] gres: gpu state for job 1958
[2016-10-07T20:19:57.932]   gres_cnt:5 node_cnt:0 type:(null)
[2016-10-07T20:19:57.932] _slurm_rpc_submit_batch_job JobId=1958 usec=602
[2016-10-07T20:19:57.933] job submit: job_id = 1958	time = 1475842797

[2016-10-07T20:19:57.939] gres: gpu state for job 1959
[2016-10-07T20:19:57.939]   gres_cnt:7 node_cnt:0 type:(null)
[2016-10-07T20:19:57.940] _slurm_rpc_submit_batch_job JobId=1959 usec=593
[2016-10-07T20:19:57.940] job submit: job_id = 1959	time = 1475842797

[2016-10-07T20:19:57.947] gres: gpu state for job 1960
[2016-10-07T20:19:57.947]   gres_cnt:5 node_cnt:0 type:(null)
[2016-10-07T20:19:57.947] _slurm_rpc_submit_batch_job JobId=1960 usec=593
[2016-10-07T20:19:57.948] job submit: job_id = 1960	time = 1475842797

[2016-10-07T20:19:57.958] gres: gpu state for job 1961
[2016-10-07T20:19:57.958]   gres_cnt:7 node_cnt:0 type:(null)
[2016-10-07T20:19:57.959] _slurm_rpc_submit_batch_job JobId=1961 usec=578
[2016-10-07T20:19:57.959] job submit: job_id = 1961	time = 1475842797

[2016-10-07T20:19:57.969] gres: gpu state for job 1962
[2016-10-07T20:19:57.969]   gres_cnt:5 node_cnt:0 type:(null)
[2016-10-07T20:19:57.969] _slurm_rpc_submit_batch_job JobId=1962 usec=588
[2016-10-07T20:19:57.970] job submit: job_id = 1962	time = 1475842797

[2016-10-07T20:19:57.977] gres: gpu state for job 1963
[2016-10-07T20:19:57.977]   gres_cnt:3 node_cnt:0 type:(null)
[2016-10-07T20:19:57.977] _slurm_rpc_submit_batch_job JobId=1963 usec=600
[2016-10-07T20:19:57.978] job submit: job_id = 1963	time = 1475842797

[2016-10-07T20:19:57.983] gres: gpu state for job 1964
[2016-10-07T20:19:57.983]   gres_cnt:8 node_cnt:0 type:(null)
[2016-10-07T20:19:57.984] _slurm_rpc_submit_batch_job JobId=1964 usec=587
[2016-10-07T20:19:57.984] job submit: job_id = 1964	time = 1475842797

[2016-10-07T20:19:57.991] gres: gpu state for job 1965
[2016-10-07T20:19:57.991]   gres_cnt:5 node_cnt:0 type:(null)
[2016-10-07T20:19:57.992] _slurm_rpc_submit_batch_job JobId=1965 usec=592
[2016-10-07T20:19:57.992] job submit: job_id = 1965	time = 1475842797

[2016-10-07T20:19:57.999] gres: gpu state for job 1966
[2016-10-07T20:19:57.999]   gres_cnt:1 node_cnt:0 type:(null)
[2016-10-07T20:19:57.999] _slurm_rpc_submit_batch_job JobId=1966 usec=598
[2016-10-07T20:19:58.000] job submit: job_id = 1966	time = 1475842797

[2016-10-07T20:19:58.007] gres: gpu state for job 1967
[2016-10-07T20:19:58.007]   gres_cnt:6 node_cnt:0 type:(null)
[2016-10-07T20:19:58.007] _slurm_rpc_submit_batch_job JobId=1967 usec=608
[2016-10-07T20:19:58.008] job submit: job_id = 1967	time = 1475842798

[2016-10-07T20:19:58.016] gres: gpu state for job 1968
[2016-10-07T20:19:58.016]   gres_cnt:5 node_cnt:0 type:(null)
[2016-10-07T20:19:58.016] _slurm_rpc_submit_batch_job JobId=1968 usec=590
[2016-10-07T20:19:58.017] job submit: job_id = 1968	time = 1475842798

[2016-10-07T20:19:58.025] gres: gpu state for job 1969
[2016-10-07T20:19:58.025]   gres_cnt:8 node_cnt:0 type:(null)
[2016-10-07T20:19:58.026] _slurm_rpc_submit_batch_job JobId=1969 usec=583
[2016-10-07T20:19:58.026] job submit: job_id = 1969	time = 1475842798

[2016-10-07T20:19:58.034] gres: gpu state for job 1970
[2016-10-07T20:19:58.034]   gres_cnt:5 node_cnt:0 type:(null)
[2016-10-07T20:19:58.035] _slurm_rpc_submit_batch_job JobId=1970 usec=583
[2016-10-07T20:19:58.035] job submit: job_id = 1970	time = 1475842798

[2016-10-07T20:19:58.046] gres: gpu state for job 1971
[2016-10-07T20:19:58.046]   gres_cnt:6 node_cnt:0 type:(null)
[2016-10-07T20:19:58.046] _slurm_rpc_submit_batch_job JobId=1971 usec=576
[2016-10-07T20:19:58.047] job submit: job_id = 1971	time = 1475842798

[2016-10-07T20:19:58.057] gres: gpu state for job 1972
[2016-10-07T20:19:58.057]   gres_cnt:7 node_cnt:0 type:(null)
[2016-10-07T20:19:58.058] _slurm_rpc_submit_batch_job JobId=1972 usec=578
[2016-10-07T20:19:58.058] job submit: job_id = 1972	time = 1475842798

[2016-10-07T20:19:58.067] gres: gpu state for job 1973
[2016-10-07T20:19:58.067]   gres_cnt:6 node_cnt:0 type:(null)
[2016-10-07T20:19:58.067] _slurm_rpc_submit_batch_job JobId=1973 usec=582
[2016-10-07T20:19:58.068] job submit: job_id = 1973	time = 1475842798

[2016-10-07T20:19:58.078] gres: gpu state for job 1974
[2016-10-07T20:19:58.078]   gres_cnt:8 node_cnt:0 type:(null)
[2016-10-07T20:19:58.078] _slurm_rpc_submit_batch_job JobId=1974 usec=582
[2016-10-07T20:19:58.079] job submit: job_id = 1974	time = 1475842798

[2016-10-07T20:19:58.087] gres: gpu state for job 1975
[2016-10-07T20:19:58.087]   gres_cnt:1 node_cnt:0 type:(null)
[2016-10-07T20:19:58.088] _slurm_rpc_submit_batch_job JobId=1975 usec=576
[2016-10-07T20:19:58.088] job submit: job_id = 1975	time = 1475842798

[2016-10-07T20:19:58.097] gres: gpu state for job 1976
[2016-10-07T20:19:58.097]   gres_cnt:7 node_cnt:0 type:(null)
[2016-10-07T20:19:58.097] _slurm_rpc_submit_batch_job JobId=1976 usec=576
[2016-10-07T20:19:58.098] job submit: job_id = 1976	time = 1475842798

[2016-10-07T20:19:58.106] gres: gpu state for job 1977
[2016-10-07T20:19:58.106]   gres_cnt:3 node_cnt:0 type:(null)
[2016-10-07T20:19:58.107] _slurm_rpc_submit_batch_job JobId=1977 usec=578
[2016-10-07T20:19:58.107] job submit: job_id = 1977	time = 1475842798

[2016-10-07T20:19:58.109] gres: gpu state for job 1930
[2016-10-07T20:19:58.109]   gres_cnt:8 node_cnt:1 type:(null)
[2016-10-07T20:19:58.109]   gres_bit_step_alloc:NULL
[2016-10-07T20:19:58.109]   gres_cnt_step_alloc:NULL
[2016-10-07T20:19:58.109]   gres_bit_alloc[0]:0-7
[2016-10-07T20:19:58.109] backfill: Started JobId=1930 in partition on gpu-cluster-1
[2016-10-07T20:19:58.109] job start: job_id = 1930	time = 1475842798

[2016-10-07T20:19:58.110] gres: gpu state for job 1931
[2016-10-07T20:19:58.110]   gres_cnt:4 node_cnt:1 type:(null)
[2016-10-07T20:19:58.110]   gres_bit_step_alloc:NULL
[2016-10-07T20:19:58.110]   gres_cnt_step_alloc:NULL
[2016-10-07T20:19:58.110]   gres_bit_alloc[0]:0-3
[2016-10-07T20:19:58.110] backfill: Started JobId=1931 in partition on gpu-cluster-1
[2016-10-07T20:19:58.110] job start: job_id = 1931	time = 1475842798

[2016-10-07T20:19:58.111] gres: gpu state for job 1932
[2016-10-07T20:19:58.111]   gres_cnt:6 node_cnt:2 type:(null)
[2016-10-07T20:19:58.111]   gres_bit_step_alloc:NULL
[2016-10-07T20:19:58.111]   gres_cnt_step_alloc:NULL
[2016-10-07T20:19:58.111]   gres_bit_alloc[0]:4-7
[2016-10-07T20:19:58.111]   gres_bit_alloc[1]:0-1
[2016-10-07T20:19:58.111] backfill: Started JobId=1932 in partition on gpu-cluster-1
[2016-10-07T20:19:58.111] job start: job_id = 1932	time = 1475842798

[2016-10-07T20:19:58.112] gres: gpu state for job 1933
[2016-10-07T20:19:58.112]   gres_cnt:8 node_cnt:2 type:(null)
[2016-10-07T20:19:58.112]   gres_bit_step_alloc:NULL
[2016-10-07T20:19:58.112]   gres_cnt_step_alloc:NULL
[2016-10-07T20:19:58.112]   gres_bit_alloc[0]:2-7
[2016-10-07T20:19:58.112]   gres_bit_alloc[1]:0-1
[2016-10-07T20:19:58.112] backfill: Started JobId=1933 in partition on gpu-cluster-1
[2016-10-07T20:19:58.112] job start: job_id = 1933	time = 1475842798

[2016-10-07T20:19:58.113] gres: gpu state for job 1934
[2016-10-07T20:19:58.113]   gres_cnt:2 node_cnt:1 type:(null)
[2016-10-07T20:19:58.113]   gres_bit_step_alloc:NULL
[2016-10-07T20:19:58.113]   gres_cnt_step_alloc:NULL
[2016-10-07T20:19:58.113]   gres_bit_alloc[0]:2-3
[2016-10-07T20:19:58.113] backfill: Started JobId=1934 in partition on gpu-cluster-1
[2016-10-07T20:19:58.113] job start: job_id = 1934	time = 1475842798

[2016-10-07T20:19:58.114] gres: gpu state for job 1935
[2016-10-07T20:19:58.114]   gres_cnt:3 node_cnt:1 type:(null)
[2016-10-07T20:19:58.114]   gres_bit_step_alloc:NULL
[2016-10-07T20:19:58.114]   gres_cnt_step_alloc:NULL
[2016-10-07T20:19:58.114]   gres_bit_alloc[0]:4-6
[2016-10-07T20:19:58.114] backfill: Started JobId=1935 in partition on gpu-cluster-1
[2016-10-07T20:19:58.114] job start: job_id = 1935	time = 1475842798

[2016-10-07T20:19:58.116] gres: gpu state for job 1941
[2016-10-07T20:19:58.116]   gres_cnt:1 node_cnt:1 type:(null)
[2016-10-07T20:19:58.116]   gres_bit_step_alloc:NULL
[2016-10-07T20:19:58.116]   gres_cnt_step_alloc:NULL
[2016-10-07T20:19:58.116]   gres_bit_alloc[0]:7
[2016-10-07T20:19:58.116] backfill: Started JobId=1941 in partition on gpu-cluster-1
[2016-10-07T20:19:58.117] job start: job_id = 1941	time = 1475842798

[2016-10-07T20:19:58.121] gres: gpu state for job 1978
[2016-10-07T20:19:58.121]   gres_cnt:4 node_cnt:0 type:(null)
[2016-10-07T20:19:58.122] _slurm_rpc_submit_batch_job JobId=1978 usec=867
[2016-10-07T20:19:58.122] job submit: job_id = 1978	time = 1475842798

[2016-10-07T20:19:58.131] gres: gpu state for job 1979
[2016-10-07T20:19:58.131]   gres_cnt:5 node_cnt:0 type:(null)
[2016-10-07T20:19:58.131] _slurm_rpc_submit_batch_job JobId=1979 usec=588
[2016-10-07T20:19:58.132] job submit: job_id = 1979	time = 1475842798

[2016-10-07T20:19:58.140] gres: gpu state for job 1980
[2016-10-07T20:19:58.140]   gres_cnt:5 node_cnt:0 type:(null)
[2016-10-07T20:19:58.140] _slurm_rpc_submit_batch_job JobId=1980 usec=585
[2016-10-07T20:19:58.141] job submit: job_id = 1980	time = 1475842798

[2016-10-07T20:19:58.147] gres: gpu state for job 1981
[2016-10-07T20:19:58.147]   gres_cnt:6 node_cnt:0 type:(null)
[2016-10-07T20:19:58.147] _slurm_rpc_submit_batch_job JobId=1981 usec=431
[2016-10-07T20:19:58.147] job submit: job_id = 1981	time = 1475842798

[2016-10-07T20:19:58.155] gres: gpu state for job 1982
[2016-10-07T20:19:58.155]   gres_cnt:3 node_cnt:0 type:(null)
[2016-10-07T20:19:58.155] _slurm_rpc_submit_batch_job JobId=1982 usec=261
[2016-10-07T20:19:58.155] job submit: job_id = 1982	time = 1475842798

[2016-10-07T20:19:58.161] gres: gpu state for job 1983
[2016-10-07T20:19:58.161]   gres_cnt:2 node_cnt:0 type:(null)
[2016-10-07T20:19:58.161] _slurm_rpc_submit_batch_job JobId=1983 usec=269
[2016-10-07T20:19:58.161] job submit: job_id = 1983	time = 1475842798

[2016-10-07T20:19:58.169] gres: gpu state for job 1984
[2016-10-07T20:19:58.169]   gres_cnt:5 node_cnt:0 type:(null)
[2016-10-07T20:19:58.169] _slurm_rpc_submit_batch_job JobId=1984 usec=417
[2016-10-07T20:19:58.170] job submit: job_id = 1984	time = 1475842798

[2016-10-07T20:19:58.179] gres: gpu state for job 1985
[2016-10-07T20:19:58.179]   gres_cnt:2 node_cnt:0 type:(null)
[2016-10-07T20:19:58.180] _slurm_rpc_submit_batch_job JobId=1985 usec=610
[2016-10-07T20:19:58.180] job submit: job_id = 1985	time = 1475842798

[2016-10-07T20:19:58.187] gres: gpu state for job 1986
[2016-10-07T20:19:58.187]   gres_cnt:6 node_cnt:0 type:(null)
[2016-10-07T20:19:58.188] _slurm_rpc_submit_batch_job JobId=1986 usec=577
[2016-10-07T20:19:58.188] job submit: job_id = 1986	time = 1475842798

[2016-10-07T20:19:58.199] gres: gpu state for job 1987
[2016-10-07T20:19:58.199]   gres_cnt:2 node_cnt:0 type:(null)
[2016-10-07T20:19:58.199] _slurm_rpc_submit_batch_job JobId=1987 usec=406
[2016-10-07T20:19:58.199] job submit: job_id = 1987	time = 1475842798

[2016-10-07T20:19:58.210] gres: gpu state for job 1988
[2016-10-07T20:19:58.210]   gres_cnt:6 node_cnt:0 type:(null)
[2016-10-07T20:19:58.210] _slurm_rpc_submit_batch_job JobId=1988 usec=541
[2016-10-07T20:19:58.211] job submit: job_id = 1988	time = 1475842798

[2016-10-07T20:19:58.219] gres: gpu state for job 1989
[2016-10-07T20:19:58.219]   gres_cnt:8 node_cnt:0 type:(null)
[2016-10-07T20:19:58.220] _slurm_rpc_submit_batch_job JobId=1989 usec=636
[2016-10-07T20:19:58.220] job submit: job_id = 1989	time = 1475842798

[2016-10-07T20:19:58.231] gres: gpu state for job 1990
[2016-10-07T20:19:58.231]   gres_cnt:2 node_cnt:0 type:(null)
[2016-10-07T20:19:58.231] _slurm_rpc_submit_batch_job JobId=1990 usec=589
[2016-10-07T20:19:58.232] job submit: job_id = 1990	time = 1475842798

[2016-10-07T20:19:58.241] gres: gpu state for job 1991
[2016-10-07T20:19:58.241]   gres_cnt:5 node_cnt:0 type:(null)
[2016-10-07T20:19:58.242] _slurm_rpc_submit_batch_job JobId=1991 usec=584
[2016-10-07T20:19:58.242] job submit: job_id = 1991	time = 1475842798

[2016-10-07T20:19:58.250] gres: gpu state for job 1992
[2016-10-07T20:19:58.250]   gres_cnt:7 node_cnt:0 type:(null)
[2016-10-07T20:19:58.250] _slurm_rpc_submit_batch_job JobId=1992 usec=587
[2016-10-07T20:19:58.251] job submit: job_id = 1992	time = 1475842798

[2016-10-07T20:19:58.258] gres: gpu state for job 1993
[2016-10-07T20:19:58.258]   gres_cnt:7 node_cnt:0 type:(null)
[2016-10-07T20:19:58.258] _slurm_rpc_submit_batch_job JobId=1993 usec=596
[2016-10-07T20:19:58.259] job submit: job_id = 1993	time = 1475842798

[2016-10-07T20:19:58.266] gres: gpu state for job 1994
[2016-10-07T20:19:58.266]   gres_cnt:7 node_cnt:0 type:(null)
[2016-10-07T20:19:58.266] _slurm_rpc_submit_batch_job JobId=1994 usec=580
[2016-10-07T20:19:58.267] job submit: job_id = 1994	time = 1475842798

[2016-10-07T20:19:58.276] gres: gpu state for job 1995
[2016-10-07T20:19:58.276]   gres_cnt:1 node_cnt:0 type:(null)
[2016-10-07T20:19:58.277] _slurm_rpc_submit_batch_job JobId=1995 usec=640
[2016-10-07T20:19:58.277] job submit: job_id = 1995	time = 1475842798

[2016-10-07T20:19:58.287] gres: gpu state for job 1996
[2016-10-07T20:19:58.287]   gres_cnt:3 node_cnt:0 type:(null)
[2016-10-07T20:19:58.287] _slurm_rpc_submit_batch_job JobId=1996 usec=593
[2016-10-07T20:19:58.288] job submit: job_id = 1996	time = 1475842798

[2016-10-07T20:19:58.298] gres: gpu state for job 1997
[2016-10-07T20:19:58.298]   gres_cnt:7 node_cnt:0 type:(null)
[2016-10-07T20:19:58.299] _slurm_rpc_submit_batch_job JobId=1997 usec=583
[2016-10-07T20:19:58.299] job submit: job_id = 1997	time = 1475842798

[2016-10-07T20:19:58.309] gres: gpu state for job 1998
[2016-10-07T20:19:58.309]   gres_cnt:8 node_cnt:0 type:(null)
[2016-10-07T20:19:58.309] _slurm_rpc_submit_batch_job JobId=1998 usec=581
[2016-10-07T20:19:58.310] job submit: job_id = 1998	time = 1475842798

[2016-10-07T20:19:58.316] gres: gpu state for job 1999
[2016-10-07T20:19:58.316]   gres_cnt:7 node_cnt:0 type:(null)
[2016-10-07T20:19:58.317] _slurm_rpc_submit_batch_job JobId=1999 usec=603
[2016-10-07T20:19:58.317] job submit: job_id = 1999	time = 1475842798

[2016-10-07T20:19:58.323] gres: gpu state for job 2000
[2016-10-07T20:19:58.323]   gres_cnt:5 node_cnt:0 type:(null)
[2016-10-07T20:19:58.324] _slurm_rpc_submit_batch_job JobId=2000 usec=580
[2016-10-07T20:19:58.324] job submit: job_id = 2000	time = 1475842798

[2016-10-07T20:19:58.331] gres: gpu state for job 2001
[2016-10-07T20:19:58.331]   gres_cnt:1 node_cnt:0 type:(null)
[2016-10-07T20:19:58.331] _slurm_rpc_submit_batch_job JobId=2001 usec=602
[2016-10-07T20:19:58.332] job submit: job_id = 2001	time = 1475842798

[2016-10-07T20:19:58.342] gres: gpu state for job 2002
[2016-10-07T20:19:58.342]   gres_cnt:2 node_cnt:0 type:(null)
[2016-10-07T20:19:58.343] _slurm_rpc_submit_batch_job JobId=2002 usec=601
[2016-10-07T20:19:58.343] job submit: job_id = 2002	time = 1475842798

[2016-10-07T20:19:58.350] gres: gpu state for job 2003
[2016-10-07T20:19:58.350]   gres_cnt:6 node_cnt:0 type:(null)
[2016-10-07T20:19:58.350] _slurm_rpc_submit_batch_job JobId=2003 usec=610
[2016-10-07T20:19:58.351] job submit: job_id = 2003	time = 1475842798

[2016-10-07T20:19:58.357] gres: gpu state for job 2004
[2016-10-07T20:19:58.357]   gres_cnt:4 node_cnt:0 type:(null)
[2016-10-07T20:19:58.357] _slurm_rpc_submit_batch_job JobId=2004 usec=579
[2016-10-07T20:19:58.358] job submit: job_id = 2004	time = 1475842798

[2016-10-07T20:19:58.364] gres: gpu state for job 2005
[2016-10-07T20:19:58.364]   gres_cnt:8 node_cnt:0 type:(null)
[2016-10-07T20:19:58.365] _slurm_rpc_submit_batch_job JobId=2005 usec=641
[2016-10-07T20:19:58.365] job submit: job_id = 2005	time = 1475842798

[2016-10-07T20:19:58.372] gres: gpu state for job 2006
[2016-10-07T20:19:58.372]   gres_cnt:1 node_cnt:0 type:(null)
[2016-10-07T20:19:58.372] _slurm_rpc_submit_batch_job JobId=2006 usec=582
[2016-10-07T20:19:58.373] job submit: job_id = 2006	time = 1475842798

[2016-10-07T20:19:58.381] gres: gpu state for job 2007
[2016-10-07T20:19:58.381]   gres_cnt:1 node_cnt:0 type:(null)
[2016-10-07T20:19:58.381] _slurm_rpc_submit_batch_job JobId=2007 usec=577
[2016-10-07T20:19:58.382] job submit: job_id = 2007	time = 1475842798

[2016-10-07T20:19:58.389] gres: gpu state for job 2008
[2016-10-07T20:19:58.389]   gres_cnt:2 node_cnt:0 type:(null)
[2016-10-07T20:19:58.389] _slurm_rpc_submit_batch_job JobId=2008 usec=579
[2016-10-07T20:19:58.390] job submit: job_id = 2008	time = 1475842798

[2016-10-07T20:19:58.400] gres: gpu state for job 2009
[2016-10-07T20:19:58.400]   gres_cnt:8 node_cnt:0 type:(null)
[2016-10-07T20:19:58.400] _slurm_rpc_submit_batch_job JobId=2009 usec=588
[2016-10-07T20:19:58.401] job submit: job_id = 2009	time = 1475842798

[2016-10-07T20:19:58.407] gres: gpu state for job 2010
[2016-10-07T20:19:58.407]   gres_cnt:5 node_cnt:0 type:(null)
[2016-10-07T20:19:58.407] _slurm_rpc_submit_batch_job JobId=2010 usec=421
[2016-10-07T20:19:58.408] job submit: job_id = 2010	time = 1475842798

[2016-10-07T20:19:58.413] gres: gpu state for job 2011
[2016-10-07T20:19:58.413]   gres_cnt:2 node_cnt:0 type:(null)
[2016-10-07T20:19:58.413] _slurm_rpc_submit_batch_job JobId=2011 usec=361
[2016-10-07T20:19:58.414] job submit: job_id = 2011	time = 1475842798

[2016-10-07T20:19:58.419] gres: gpu state for job 2012
[2016-10-07T20:19:58.419]   gres_cnt:5 node_cnt:0 type:(null)
[2016-10-07T20:19:58.419] _slurm_rpc_submit_batch_job JobId=2012 usec=343
[2016-10-07T20:19:58.420] job submit: job_id = 2012	time = 1475842798

[2016-10-07T20:19:58.432] gres: gpu state for job 2013
[2016-10-07T20:19:58.432]   gres_cnt:8 node_cnt:0 type:(null)
[2016-10-07T20:19:58.433] _slurm_rpc_submit_batch_job JobId=2013 usec=633
[2016-10-07T20:19:58.433] job submit: job_id = 2013	time = 1475842798

[2016-10-07T20:19:58.438] gres: gpu state for job 2014
[2016-10-07T20:19:58.438]   gres_cnt:8 node_cnt:0 type:(null)
[2016-10-07T20:19:58.438] _slurm_rpc_submit_batch_job JobId=2014 usec=574
[2016-10-07T20:19:58.439] job submit: job_id = 2014	time = 1475842798

[2016-10-07T20:19:58.445] gres: gpu state for job 2015
[2016-10-07T20:19:58.445]   gres_cnt:4 node_cnt:0 type:(null)
[2016-10-07T20:19:58.446] _slurm_rpc_submit_batch_job JobId=2015 usec=583
[2016-10-07T20:19:58.446] job submit: job_id = 2015	time = 1475842798

[2016-10-07T20:19:58.454] gres: gpu state for job 2016
[2016-10-07T20:19:58.454]   gres_cnt:2 node_cnt:0 type:(null)
[2016-10-07T20:19:58.455] _slurm_rpc_submit_batch_job JobId=2016 usec=577
[2016-10-07T20:19:58.455] job submit: job_id = 2016	time = 1475842798

[2016-10-07T20:19:58.462] gres: gpu state for job 2017
[2016-10-07T20:19:58.462]   gres_cnt:5 node_cnt:0 type:(null)
[2016-10-07T20:19:58.462] _slurm_rpc_submit_batch_job JobId=2017 usec=578
[2016-10-07T20:19:58.462] job submit: job_id = 2017	time = 1475842798

[2016-10-07T20:19:58.469] gres: gpu state for job 2018
[2016-10-07T20:19:58.469]   gres_cnt:6 node_cnt:0 type:(null)
[2016-10-07T20:19:58.470] _slurm_rpc_submit_batch_job JobId=2018 usec=582
[2016-10-07T20:19:58.470] job submit: job_id = 2018	time = 1475842798

[2016-10-07T20:19:58.477] gres: gpu state for job 2019
[2016-10-07T20:19:58.477]   gres_cnt:6 node_cnt:0 type:(null)
[2016-10-07T20:19:58.477] _slurm_rpc_submit_batch_job JobId=2019 usec=364
[2016-10-07T20:19:58.478] job submit: job_id = 2019	time = 1475842798

[2016-10-07T20:19:58.483] gres: gpu state for job 2020
[2016-10-07T20:19:58.483]   gres_cnt:7 node_cnt:0 type:(null)
[2016-10-07T20:19:58.484] _slurm_rpc_submit_batch_job JobId=2020 usec=319
[2016-10-07T20:19:58.484] job submit: job_id = 2020	time = 1475842798

[2016-10-07T20:19:58.490] gres: gpu state for job 2021
[2016-10-07T20:19:58.490]   gres_cnt:6 node_cnt:0 type:(null)
[2016-10-07T20:19:58.490] _slurm_rpc_submit_batch_job JobId=2021 usec=259
[2016-10-07T20:19:58.490] job submit: job_id = 2021	time = 1475842798

[2016-10-07T20:19:58.495] gres: gpu state for job 2022
[2016-10-07T20:19:58.495]   gres_cnt:8 node_cnt:0 type:(null)
[2016-10-07T20:19:58.495] _slurm_rpc_submit_batch_job JobId=2022 usec=244
[2016-10-07T20:19:58.495] job submit: job_id = 2022	time = 1475842798

[2016-10-07T20:19:58.501] gres: gpu state for job 2023
[2016-10-07T20:19:58.501]   gres_cnt:5 node_cnt:0 type:(null)
[2016-10-07T20:19:58.501] _slurm_rpc_submit_batch_job JobId=2023 usec=253
[2016-10-07T20:19:58.501] job submit: job_id = 2023	time = 1475842798

[2016-10-07T20:19:58.506] gres: gpu state for job 2024
[2016-10-07T20:19:58.506]   gres_cnt:8 node_cnt:0 type:(null)
[2016-10-07T20:19:58.506] _slurm_rpc_submit_batch_job JobId=2024 usec=320
[2016-10-07T20:19:58.506] job submit: job_id = 2024	time = 1475842798

[2016-10-07T20:19:58.511] gres: gpu state for job 2025
[2016-10-07T20:19:58.511]   gres_cnt:4 node_cnt:0 type:(null)
[2016-10-07T20:19:58.511] _slurm_rpc_submit_batch_job JobId=2025 usec=266
[2016-10-07T20:19:58.511] job submit: job_id = 2025	time = 1475842798

[2016-10-07T20:19:58.516] gres: gpu state for job 2026
[2016-10-07T20:19:58.516]   gres_cnt:4 node_cnt:0 type:(null)
[2016-10-07T20:19:58.516] _slurm_rpc_submit_batch_job JobId=2026 usec=277
[2016-10-07T20:19:58.516] job submit: job_id = 2026	time = 1475842798

[2016-10-07T20:19:58.521] gres: gpu state for job 2027
[2016-10-07T20:19:58.521]   gres_cnt:2 node_cnt:0 type:(null)
[2016-10-07T20:19:58.521] _slurm_rpc_submit_batch_job JobId=2027 usec=250
[2016-10-07T20:19:58.521] job submit: job_id = 2027	time = 1475842798

[2016-10-07T20:19:58.525] gres: gpu state for job 2028
[2016-10-07T20:19:58.525]   gres_cnt:8 node_cnt:0 type:(null)
[2016-10-07T20:19:58.525] _slurm_rpc_submit_batch_job JobId=2028 usec=251
[2016-10-07T20:19:58.526] job submit: job_id = 2028	time = 1475842798

[2016-10-07T20:19:58.530] gres: gpu state for job 2029
[2016-10-07T20:19:58.530]   gres_cnt:8 node_cnt:0 type:(null)
[2016-10-07T20:19:58.530] _slurm_rpc_submit_batch_job JobId=2029 usec=246
[2016-10-07T20:19:58.530] job submit: job_id = 2029	time = 1475842798

[2016-10-07T20:20:13.184] job_complete: JobID=1931 State=0x1 NodeCnt=1 WEXITSTATUS 0
[2016-10-07T20:20:13.185] job end: job_id = 1931	time = 1475842813

[2016-10-07T20:20:13.185] job_complete: JobID=1931 State=0x8003 NodeCnt=1 done
[2016-10-07T20:20:13.190] gres: gpu state for job 1936
[2016-10-07T20:20:13.190]   gres_cnt:4 node_cnt:1 type:(null)
[2016-10-07T20:20:13.190]   gres_bit_step_alloc:NULL
[2016-10-07T20:20:13.190]   gres_cnt_step_alloc:NULL
[2016-10-07T20:20:13.190]   gres_bit_alloc[0]:0-3
[2016-10-07T20:20:13.190] sched: Allocate JobID=1936 NodeList=gpu-cluster-1 #CPUs=1 Partition=partition
[2016-10-07T20:20:13.190] job start: job_id = 1936	time = 1475842813

[2016-10-07T20:20:13.832] job_complete: JobID=1934 State=0x1 NodeCnt=1 WEXITSTATUS 0
[2016-10-07T20:20:13.832] job end: job_id = 1934	time = 1475842813

[2016-10-07T20:20:13.832] job_complete: JobID=1934 State=0x8003 NodeCnt=1 done
[2016-10-07T20:20:13.838] gres: gpu state for job 1937
[2016-10-07T20:20:13.838]   gres_cnt:2 node_cnt:1 type:(null)
[2016-10-07T20:20:13.838]   gres_bit_step_alloc:NULL
[2016-10-07T20:20:13.838]   gres_cnt_step_alloc:NULL
[2016-10-07T20:20:13.838]   gres_bit_alloc[0]:2-3
[2016-10-07T20:20:13.838] sched: Allocate JobID=1937 NodeList=gpu-cluster-1 #CPUs=1 Partition=partition
[2016-10-07T20:20:13.838] job start: job_id = 1937	time = 1475842813

[2016-10-07T20:20:15.075] job_complete: JobID=1932 State=0x1 NodeCnt=1 WEXITSTATUS 0
[2016-10-07T20:20:15.075] job end: job_id = 1932	time = 1475842815

[2016-10-07T20:20:15.075] job_complete: JobID=1932 State=0x8003 NodeCnt=1 done
[2016-10-07T20:20:16.332] job_complete: JobID=1930 State=0x1 NodeCnt=1 WEXITSTATUS 255
[2016-10-07T20:20:16.332] job end: job_id = 1930	time = 1475842816

[2016-10-07T20:20:16.332] job_complete: JobID=1930 State=0x8005 NodeCnt=1 done
[2016-10-07T20:20:16.337] gres: gpu state for job 1938
[2016-10-07T20:20:16.337]   gres_cnt:8 node_cnt:1 type:(null)
[2016-10-07T20:20:16.337]   gres_bit_step_alloc:NULL
[2016-10-07T20:20:16.337]   gres_cnt_step_alloc:NULL
[2016-10-07T20:20:16.337]   gres_bit_alloc[0]:0-7
[2016-10-07T20:20:16.337] sched: Allocate JobID=1938 NodeList=gpu-cluster-1 #CPUs=1 Partition=partition
[2016-10-07T20:20:16.337] job start: job_id = 1938	time = 1475842816

[2016-10-07T20:20:16.338] gres: gpu state for job 1939
[2016-10-07T20:20:16.338]   gres_cnt:5 node_cnt:2 type:(null)
[2016-10-07T20:20:16.338]   gres_bit_step_alloc:NULL
[2016-10-07T20:20:16.338]   gres_cnt_step_alloc:NULL
[2016-10-07T20:20:16.338]   gres_bit_alloc[0]:4-7
[2016-10-07T20:20:16.338]   gres_bit_alloc[1]:0
[2016-10-07T20:20:16.338] sched: Allocate JobID=1939 NodeList=gpu-cluster-1 #CPUs=1 Partition=partition
[2016-10-07T20:20:16.338] job start: job_id = 1939	time = 1475842816

[2016-10-07T20:20:16.573] job_complete: JobID=1937 State=0x1 NodeCnt=1 WEXITSTATUS 0
[2016-10-07T20:20:16.573] job end: job_id = 1937	time = 1475842816

[2016-10-07T20:20:16.573] job_complete: JobID=1937 State=0x8003 NodeCnt=1 done
[2016-10-07T20:20:16.952] job_complete: JobID=1933 State=0x1 NodeCnt=1 WEXITSTATUS 0
[2016-10-07T20:20:16.952] job end: job_id = 1933	time = 1475842816

[2016-10-07T20:20:16.952] job_complete: JobID=1933 State=0x8003 NodeCnt=1 done
[2016-10-07T20:20:16.958] gres: gpu state for job 1940
[2016-10-07T20:20:16.958]   gres_cnt:4 node_cnt:1 type:(null)
[2016-10-07T20:20:16.958]   gres_bit_step_alloc:NULL
[2016-10-07T20:20:16.958]   gres_cnt_step_alloc:NULL
[2016-10-07T20:20:16.958]   gres_bit_alloc[0]:1-4
[2016-10-07T20:20:16.958] sched: Allocate JobID=1940 NodeList=gpu-cluster-1 #CPUs=1 Partition=partition
[2016-10-07T20:20:16.958] job start: job_id = 1940	time = 1475842816

[2016-10-07T20:20:16.958] gres: gpu state for job 1942
[2016-10-07T20:20:16.958]   gres_cnt:2 node_cnt:1 type:(null)
[2016-10-07T20:20:16.958]   gres_bit_step_alloc:NULL
[2016-10-07T20:20:16.958]   gres_cnt_step_alloc:NULL
[2016-10-07T20:20:16.958]   gres_bit_alloc[0]:5-6
[2016-10-07T20:20:16.958] sched: Allocate JobID=1942 NodeList=gpu-cluster-1 #CPUs=1 Partition=partition
[2016-10-07T20:20:16.958] job start: job_id = 1942	time = 1475842816

[2016-10-07T20:20:20.352] job_complete: JobID=1938 State=0x1 NodeCnt=1 WEXITSTATUS 0
[2016-10-07T20:20:20.352] job end: job_id = 1938	time = 1475842820

[2016-10-07T20:20:20.352] job_complete: JobID=1938 State=0x8003 NodeCnt=1 done
[2016-10-07T20:20:20.358] gres: gpu state for job 1943
[2016-10-07T20:20:20.358]   gres_cnt:7 node_cnt:1 type:(null)
[2016-10-07T20:20:20.358]   gres_bit_step_alloc:NULL
[2016-10-07T20:20:20.358]   gres_cnt_step_alloc:NULL
[2016-10-07T20:20:20.358]   gres_bit_alloc[0]:0-6
[2016-10-07T20:20:20.358] sched: Allocate JobID=1943 NodeList=gpu-cluster-1 #CPUs=1 Partition=partition
[2016-10-07T20:20:20.358] job start: job_id = 1943	time = 1475842820

[2016-10-07T20:20:20.358] gres: gpu state for job 1944
[2016-10-07T20:20:20.358]   gres_cnt:6 node_cnt:3 type:(null)
[2016-10-07T20:20:20.358]   gres_bit_step_alloc:NULL
[2016-10-07T20:20:20.358]   gres_cnt_step_alloc:NULL
[2016-10-07T20:20:20.358]   gres_bit_alloc[0]:7
[2016-10-07T20:20:20.358]   gres_bit_alloc[1]:7
[2016-10-07T20:20:20.358]   gres_bit_alloc[2]:0-3
[2016-10-07T20:20:20.358] sched: Allocate JobID=1944 NodeList=gpu-cluster-1 #CPUs=1 Partition=partition
[2016-10-07T20:20:20.359] job start: job_id = 1944	time = 1475842820

[2016-10-07T20:20:22.741] job_complete: JobID=1936 State=0x1 NodeCnt=1 WEXITSTATUS 0
[2016-10-07T20:20:22.741] job end: job_id = 1936	time = 1475842822

[2016-10-07T20:20:22.742] job_complete: JobID=1936 State=0x8003 NodeCnt=1 done
[2016-10-07T20:20:22.747] gres: gpu state for job 1945
[2016-10-07T20:20:22.747]   gres_cnt:2 node_cnt:1 type:(null)
[2016-10-07T20:20:22.747]   gres_bit_step_alloc:NULL
[2016-10-07T20:20:22.747]   gres_cnt_step_alloc:NULL
[2016-10-07T20:20:22.747]   gres_bit_alloc[0]:0-1
[2016-10-07T20:20:22.747] sched: Allocate JobID=1945 NodeList=gpu-cluster-1 #CPUs=1 Partition=partition
[2016-10-07T20:20:22.748] job start: job_id = 1945	time = 1475842822

[2016-10-07T20:20:23.933] job_complete: JobID=1943 State=0x1 NodeCnt=1 WEXITSTATUS 0
[2016-10-07T20:20:23.933] job end: job_id = 1943	time = 1475842823

[2016-10-07T20:20:23.933] job_complete: JobID=1943 State=0x8003 NodeCnt=1 done
[2016-10-07T20:20:23.939] gres: gpu state for job 1946
[2016-10-07T20:20:23.939]   gres_cnt:7 node_cnt:1 type:(null)
[2016-10-07T20:20:23.939]   gres_bit_step_alloc:NULL
[2016-10-07T20:20:23.939]   gres_cnt_step_alloc:NULL
[2016-10-07T20:20:23.939]   gres_bit_alloc[0]:0-6
[2016-10-07T20:20:23.939] sched: Allocate JobID=1946 NodeList=gpu-cluster-1 #CPUs=1 Partition=partition
[2016-10-07T20:20:23.939] job start: job_id = 1946	time = 1475842823

[2016-10-07T20:20:26.092] job_complete: JobID=1945 State=0x1 NodeCnt=1 WEXITSTATUS 0
[2016-10-07T20:20:26.092] job end: job_id = 1945	time = 1475842826

[2016-10-07T20:20:26.092] job_complete: JobID=1945 State=0x8003 NodeCnt=1 done
[2016-10-07T20:20:27.350] job_complete: JobID=1946 State=0x1 NodeCnt=1 WEXITSTATUS 0
[2016-10-07T20:20:27.350] job end: job_id = 1946	time = 1475842827

[2016-10-07T20:20:27.350] job_complete: JobID=1946 State=0x8003 NodeCnt=1 done
[2016-10-07T20:20:27.356] gres: gpu state for job 1947
[2016-10-07T20:20:27.356]   gres_cnt:8 node_cnt:2 type:(null)
[2016-10-07T20:20:27.356]   gres_bit_step_alloc:NULL
[2016-10-07T20:20:27.356]   gres_cnt_step_alloc:NULL
[2016-10-07T20:20:27.356]   gres_bit_alloc[0]:0-6
[2016-10-07T20:20:27.356]   gres_bit_alloc[1]:0
[2016-10-07T20:20:27.356] sched: Allocate JobID=1947 NodeList=gpu-cluster-1 #CPUs=1 Partition=partition
[2016-10-07T20:20:27.356] job start: job_id = 1947	time = 1475842827

[2016-10-07T20:20:28.121] gres: gpu state for job 1952
[2016-10-07T20:20:28.121]   gres_cnt:1 node_cnt:1 type:(null)
[2016-10-07T20:20:28.121]   gres_bit_step_alloc:NULL
[2016-10-07T20:20:28.121]   gres_cnt_step_alloc:NULL
[2016-10-07T20:20:28.121]   gres_bit_alloc[0]:1
[2016-10-07T20:20:28.121] backfill: Started JobId=1952 in partition on gpu-cluster-1
[2016-10-07T20:20:28.121] job start: job_id = 1952	time = 1475842828

[2016-10-07T20:20:28.122] gres: gpu state for job 1955
[2016-10-07T20:20:28.122]   gres_cnt:2 node_cnt:1 type:(null)
[2016-10-07T20:20:28.122]   gres_bit_step_alloc:NULL
[2016-10-07T20:20:28.122]   gres_cnt_step_alloc:NULL
[2016-10-07T20:20:28.122]   gres_bit_alloc[0]:2-3
[2016-10-07T20:20:28.122] backfill: Started JobId=1955 in partition on gpu-cluster-2
[2016-10-07T20:20:28.122] job start: job_id = 1955	time = 1475842828

[2016-10-07T20:20:30.315] job_complete: JobID=1947 State=0x1 NodeCnt=1 WEXITSTATUS 255
[2016-10-07T20:20:30.315] job end: job_id = 1947	time = 1475842830

[2016-10-07T20:20:30.315] job_complete: JobID=1947 State=0x8005 NodeCnt=1 done
[2016-10-07T20:20:30.321] gres: gpu state for job 1948
[2016-10-07T20:20:30.321]   gres_cnt:6 node_cnt:1 type:(null)
[2016-10-07T20:20:30.321]   gres_bit_step_alloc:NULL
[2016-10-07T20:20:30.321]   gres_cnt_step_alloc:NULL
[2016-10-07T20:20:30.321]   gres_bit_alloc[0]:0-5
[2016-10-07T20:20:30.321] sched: Allocate JobID=1948 NodeList=gpu-cluster-1 #CPUs=1 Partition=partition
[2016-10-07T20:20:30.321] job start: job_id = 1948	time = 1475842830

[2016-10-07T20:20:31.137] job_complete: JobID=1955 State=0x1 NodeCnt=1 WEXITSTATUS 0
[2016-10-07T20:20:31.137] job end: job_id = 1955	time = 1475842831

[2016-10-07T20:20:31.137] job_complete: JobID=1955 State=0x8003 NodeCnt=1 done
[2016-10-07T20:20:32.945] job_complete: JobID=1940 State=0x1 NodeCnt=1 WEXITSTATUS 0
[2016-10-07T20:20:32.945] job end: job_id = 1940	time = 1475842832

[2016-10-07T20:20:32.945] job_complete: JobID=1940 State=0x8003 NodeCnt=1 done
[2016-10-07T20:20:32.951] gres: gpu state for job 1949
[2016-10-07T20:20:32.951]   gres_cnt:7 node_cnt:3 type:(null)
[2016-10-07T20:20:32.951]   gres_bit_step_alloc:NULL
[2016-10-07T20:20:32.951]   gres_cnt_step_alloc:NULL
[2016-10-07T20:20:32.951]   gres_bit_alloc[0]:6
[2016-10-07T20:20:32.951]   gres_bit_alloc[1]:0,2-3
[2016-10-07T20:20:32.951]   gres_bit_alloc[2]:1-3
[2016-10-07T20:20:32.951] sched: Allocate JobID=1949 NodeList=gpu-cluster-1 #CPUs=1 Partition=partition
[2016-10-07T20:20:32.951] job start: job_id = 1949	time = 1475842832

[2016-10-07T20:20:33.747] job_complete: JobID=1948 State=0x1 NodeCnt=1 WEXITSTATUS 0
[2016-10-07T20:20:33.747] job end: job_id = 1948	time = 1475842833

[2016-10-07T20:20:33.747] job_complete: JobID=1948 State=0x8003 NodeCnt=1 done
[2016-10-07T20:20:33.753] gres: gpu state for job 1950
[2016-10-07T20:20:33.753]   gres_cnt:4 node_cnt:1 type:(null)
[2016-10-07T20:20:33.753]   gres_bit_step_alloc:NULL
[2016-10-07T20:20:33.753]   gres_cnt_step_alloc:NULL
[2016-10-07T20:20:33.753]   gres_bit_alloc[0]:0-3
[2016-10-07T20:20:33.753] sched: Allocate JobID=1950 NodeList=gpu-cluster-1 #CPUs=1 Partition=partition
[2016-10-07T20:20:33.753] job start: job_id = 1950	time = 1475842833

[2016-10-07T20:20:36.892] job_complete: JobID=1949 State=0x1 NodeCnt=1 WEXITSTATUS 0
[2016-10-07T20:20:36.892] job end: job_id = 1949	time = 1475842836

[2016-10-07T20:20:36.892] job_complete: JobID=1949 State=0x8003 NodeCnt=1 done
[2016-10-07T20:20:36.897] gres: gpu state for job 1951
[2016-10-07T20:20:36.897]   gres_cnt:6 node_cnt:2 type:(null)
[2016-10-07T20:20:36.897]   gres_bit_step_alloc:NULL
[2016-10-07T20:20:36.897]   gres_cnt_step_alloc:NULL
[2016-10-07T20:20:36.897]   gres_bit_alloc[0]:4-6
[2016-10-07T20:20:36.897]   gres_bit_alloc[1]:0,2-3
[2016-10-07T20:20:36.897] sched: Allocate JobID=1951 NodeList=gpu-cluster-1 #CPUs=1 Partition=partition
[2016-10-07T20:20:36.897] job start: job_id = 1951	time = 1475842836

[2016-10-07T20:20:58.129] gres: gpu state for job 1954
[2016-10-07T20:20:58.129]   gres_cnt:4 node_cnt:1 type:(null)
[2016-10-07T20:20:58.129]   gres_bit_step_alloc:NULL
[2016-10-07T20:20:58.129]   gres_cnt_step_alloc:NULL
[2016-10-07T20:20:58.129]   gres_bit_alloc[0]:1-4
[2016-10-07T20:20:58.129] backfill: Started JobId=1954 in partition on gpu-cluster-2
[2016-10-07T20:20:58.129] job start: job_id = 1954	time = 1475842858

[2016-10-07T20:21:04.268] job_complete: JobID=1954 State=0x1 NodeCnt=1 WEXITSTATUS 0
[2016-10-07T20:21:04.268] job end: job_id = 1954	time = 1475842864

[2016-10-07T20:21:04.268] job_complete: JobID=1954 State=0x8003 NodeCnt=1 done
[2016-10-07T20:21:28.136] gres: gpu state for job 1957
[2016-10-07T20:21:28.136]   gres_cnt:3 node_cnt:1 type:(null)
[2016-10-07T20:21:28.136]   gres_bit_step_alloc:NULL
[2016-10-07T20:21:28.136]   gres_cnt_step_alloc:NULL
[2016-10-07T20:21:28.136]   gres_bit_alloc[0]:1-3
[2016-10-07T20:21:28.136] backfill: Started JobId=1957 in partition on gpu-cluster-2
[2016-10-07T20:21:28.136] job start: job_id = 1957	time = 1475842888

[2016-10-07T20:21:28.137] gres: gpu state for job 1966
[2016-10-07T20:21:28.137]   gres_cnt:1 node_cnt:1 type:(null)
[2016-10-07T20:21:28.137]   gres_bit_step_alloc:NULL
[2016-10-07T20:21:28.137]   gres_cnt_step_alloc:NULL
[2016-10-07T20:21:28.137]   gres_bit_alloc[0]:4
[2016-10-07T20:21:28.137] backfill: Started JobId=1966 in partition on gpu-cluster-2
[2016-10-07T20:21:28.137] job start: job_id = 1966	time = 1475842888

[2016-10-07T20:21:31.829] job_complete: JobID=1957 State=0x1 NodeCnt=1 WEXITSTATUS 0
[2016-10-07T20:21:31.829] job end: job_id = 1957	time = 1475842891

[2016-10-07T20:21:31.829] job_complete: JobID=1957 State=0x8003 NodeCnt=1 done
[2016-10-07T20:21:45.985] job_complete: JobID=1944 State=0x1 NodeCnt=1 WEXITSTATUS 255
[2016-10-07T20:21:45.985] job end: job_id = 1944	time = 1475842905

[2016-10-07T20:21:45.985] job_complete: JobID=1944 State=0x8005 NodeCnt=1 done
[2016-10-07T20:21:45.991] gres: gpu state for job 1953
[2016-10-07T20:21:45.991]   gres_cnt:6 node_cnt:3 type:(null)
[2016-10-07T20:21:45.991]   gres_bit_step_alloc:NULL
[2016-10-07T20:21:45.991]   gres_cnt_step_alloc:NULL
[2016-10-07T20:21:45.991]   gres_bit_alloc[0]:7
[2016-10-07T20:21:45.991]   gres_bit_alloc[1]:1-3,7
[2016-10-07T20:21:45.991]   gres_bit_alloc[2]:0
[2016-10-07T20:21:45.991] sched: Allocate JobID=1953 NodeList=gpu-cluster-1 #CPUs=1 Partition=partition
[2016-10-07T20:21:45.991] job start: job_id = 1953	time = 1475842905

[2016-10-07T20:21:49.985] job_complete: JobID=1953 State=0x1 NodeCnt=1 WEXITSTATUS 0
[2016-10-07T20:21:49.986] job end: job_id = 1953	time = 1475842909

[2016-10-07T20:21:49.986] job_complete: JobID=1953 State=0x8003 NodeCnt=1 done
[2016-10-07T20:21:49.991] gres: gpu state for job 1956
[2016-10-07T20:21:49.991]   gres_cnt:8 node_cnt:3 type:(null)
[2016-10-07T20:21:49.991]   gres_bit_step_alloc:NULL
[2016-10-07T20:21:49.991]   gres_cnt_step_alloc:NULL
[2016-10-07T20:21:49.991]   gres_bit_alloc[0]:7
[2016-10-07T20:21:49.991]   gres_bit_alloc[1]:1-3,7
[2016-10-07T20:21:49.991]   gres_bit_alloc[2]:0-2
[2016-10-07T20:21:49.991] sched: Allocate JobID=1956 NodeList=gpu-cluster-1 #CPUs=1 Partition=partition
[2016-10-07T20:21:49.991] job start: job_id = 1956	time = 1475842909

[2016-10-07T20:21:54.427] job_complete: JobID=1951 State=0x1 NodeCnt=1 WEXITSTATUS 255
[2016-10-07T20:21:54.427] job end: job_id = 1951	time = 1475842914

[2016-10-07T20:21:54.427] job_complete: JobID=1951 State=0x8005 NodeCnt=1 done
[2016-10-07T20:21:54.432] gres: gpu state for job 1958
[2016-10-07T20:21:54.432]   gres_cnt:5 node_cnt:2 type:(null)
[2016-10-07T20:21:54.432]   gres_bit_step_alloc:NULL
[2016-10-07T20:21:54.432]   gres_cnt_step_alloc:NULL
[2016-10-07T20:21:54.432]   gres_bit_alloc[0]:4-6
[2016-10-07T20:21:54.432]   gres_bit_alloc[1]:0,2
[2016-10-07T20:21:54.432] sched: Allocate JobID=1958 NodeList=gpu-cluster-1 #CPUs=1 Partition=partition
[2016-10-07T20:21:54.432] job start: job_id = 1958	time = 1475842914

[2016-10-07T20:21:58.144] gres: gpu state for job 1975
[2016-10-07T20:21:58.144]   gres_cnt:1 node_cnt:1 type:(null)
[2016-10-07T20:21:58.144]   gres_bit_step_alloc:NULL
[2016-10-07T20:21:58.144]   gres_cnt_step_alloc:NULL
[2016-10-07T20:21:58.144]   gres_bit_alloc[0]:3
[2016-10-07T20:21:58.144] backfill: Started JobId=1975 in partition on gpu-cluster-2
[2016-10-07T20:21:58.144] job start: job_id = 1975	time = 1475842918

[2016-10-07T20:21:58.145] gres: gpu state for job 1995
[2016-10-07T20:21:58.145]   gres_cnt:1 node_cnt:1 type:(null)
[2016-10-07T20:21:58.145]   gres_bit_step_alloc:NULL
[2016-10-07T20:21:58.145]   gres_cnt_step_alloc:NULL
[2016-10-07T20:21:58.145]   gres_bit_alloc[0]:3
[2016-10-07T20:21:58.145] backfill: Started JobId=1995 in partition on gpu-cluster-2
[2016-10-07T20:21:58.146] job start: job_id = 1995	time = 1475842918

[2016-10-07T20:21:59.488] job_complete: JobID=1958 State=0x1 NodeCnt=1 WEXITSTATUS 255
[2016-10-07T20:21:59.488] job end: job_id = 1958	time = 1475842919

[2016-10-07T20:21:59.488] job_complete: JobID=1958 State=0x8005 NodeCnt=1 done
[2016-10-07T20:22:00.815] job_complete: JobID=1975 State=0x1 NodeCnt=1 WEXITSTATUS 0
[2016-10-07T20:22:00.815] job end: job_id = 1975	time = 1475842920

[2016-10-07T20:22:00.815] job_complete: JobID=1975 State=0x8003 NodeCnt=1 done
[2016-10-07T20:22:10.493] job_complete: JobID=1956 State=0x1 NodeCnt=1 WEXITSTATUS 255
[2016-10-07T20:22:10.493] job end: job_id = 1956	time = 1475842930

[2016-10-07T20:22:10.493] job_complete: JobID=1956 State=0x8005 NodeCnt=1 done
[2016-10-07T20:22:10.498] gres: gpu state for job 1959
[2016-10-07T20:22:10.498]   gres_cnt:7 node_cnt:2 type:(null)
[2016-10-07T20:22:10.498]   gres_bit_step_alloc:NULL
[2016-10-07T20:22:10.498]   gres_cnt_step_alloc:NULL
[2016-10-07T20:22:10.498]   gres_bit_alloc[0]:4-7
[2016-10-07T20:22:10.498]   gres_bit_alloc[1]:0,2-3
[2016-10-07T20:22:10.498] sched: Allocate JobID=1959 NodeList=gpu-cluster-1 #CPUs=1 Partition=partition
[2016-10-07T20:22:10.499] job start: job_id = 1959	time = 1475842930

[2016-10-07T20:22:10.499] gres: gpu state for job 1960
[2016-10-07T20:22:10.499]   gres_cnt:5 node_cnt:2 type:(null)
[2016-10-07T20:22:10.499]   gres_bit_step_alloc:NULL
[2016-10-07T20:22:10.499]   gres_cnt_step_alloc:NULL
[2016-10-07T20:22:10.499]   gres_bit_alloc[0]:1-3,7
[2016-10-07T20:22:10.499]   gres_bit_alloc[1]:0
[2016-10-07T20:22:10.499] sched: Allocate JobID=1960 NodeList=gpu-cluster-1 #CPUs=1 Partition=partition
[2016-10-07T20:22:10.499] job start: job_id = 1960	time = 1475842930

[2016-10-07T20:22:14.141] job_complete: JobID=1959 State=0x1 NodeCnt=1 WEXITSTATUS 0
[2016-10-07T20:22:14.141] job end: job_id = 1959	time = 1475842934

[2016-10-07T20:22:14.142] job_complete: JobID=1959 State=0x8003 NodeCnt=1 done
[2016-10-07T20:22:14.147] gres: gpu state for job 1961
[2016-10-07T20:22:14.147]   gres_cnt:7 node_cnt:2 type:(null)
[2016-10-07T20:22:14.147]   gres_bit_step_alloc:NULL
[2016-10-07T20:22:14.147]   gres_cnt_step_alloc:NULL
[2016-10-07T20:22:14.147]   gres_bit_alloc[0]:4-7
[2016-10-07T20:22:14.147]   gres_bit_alloc[1]:0,2-3
[2016-10-07T20:22:14.147] sched: Allocate JobID=1961 NodeList=gpu-cluster-1 #CPUs=1 Partition=partition
[2016-10-07T20:22:14.147] job start: job_id = 1961	time = 1475842934

[2016-10-07T20:22:14.521] job_complete: JobID=1960 State=0x1 NodeCnt=1 WEXITSTATUS 0
[2016-10-07T20:22:14.521] job end: job_id = 1960	time = 1475842934

[2016-10-07T20:22:14.521] job_complete: JobID=1960 State=0x8003 NodeCnt=1 done
[2016-10-07T20:22:14.526] gres: gpu state for job 1962
[2016-10-07T20:22:14.526]   gres_cnt:5 node_cnt:2 type:(null)
[2016-10-07T20:22:14.526]   gres_bit_step_alloc:NULL
[2016-10-07T20:22:14.526]   gres_cnt_step_alloc:NULL
[2016-10-07T20:22:14.526]   gres_bit_alloc[0]:1-3,7
[2016-10-07T20:22:14.526]   gres_bit_alloc[1]:0
[2016-10-07T20:22:14.526] sched: Allocate JobID=1962 NodeList=gpu-cluster-1 #CPUs=1 Partition=partition
[2016-10-07T20:22:14.526] job start: job_id = 1962	time = 1475842934

[2016-10-07T20:22:28.150] gres: gpu state for job 1983
[2016-10-07T20:22:28.150]   gres_cnt:2 node_cnt:1 type:(null)
[2016-10-07T20:22:28.150]   gres_bit_step_alloc:NULL
[2016-10-07T20:22:28.150]   gres_cnt_step_alloc:NULL
[2016-10-07T20:22:28.150]   gres_bit_alloc[0]:1-2
[2016-10-07T20:22:28.150] backfill: Started JobId=1983 in partition on gpu-cluster-2
[2016-10-07T20:22:28.150] job start: job_id = 1983	time = 1475842948

[2016-10-07T20:22:30.588] job_complete: JobID=1983 State=0x1 NodeCnt=1 WEXITSTATUS 0
[2016-10-07T20:22:30.746] job end: job_id = 1983	time = 1475842950

[2016-10-07T20:22:30.746] job_complete: JobID=1983 State=0x8003 NodeCnt=1 done
[2016-10-07T20:22:58.155] gres: gpu state for job 1985
[2016-10-07T20:22:58.155]   gres_cnt:2 node_cnt:1 type:(null)
[2016-10-07T20:22:58.155]   gres_bit_step_alloc:NULL
[2016-10-07T20:22:58.155]   gres_cnt_step_alloc:NULL
[2016-10-07T20:22:58.155]   gres_bit_alloc[0]:1-2
[2016-10-07T20:22:58.155] backfill: Started JobId=1985 in partition on gpu-cluster-2
[2016-10-07T20:22:58.155] job start: job_id = 1985	time = 1475842978

[2016-10-07T20:23:00.829] job_complete: JobID=1985 State=0x1 NodeCnt=1 WEXITSTATUS 0
[2016-10-07T20:23:00.829] job end: job_id = 1985	time = 1475842980

[2016-10-07T20:23:00.829] job_complete: JobID=1985 State=0x8003 NodeCnt=1 done
[2016-10-07T20:23:28.162] gres: gpu state for job 1987
[2016-10-07T20:23:28.162]   gres_cnt:2 node_cnt:1 type:(null)
[2016-10-07T20:23:28.162]   gres_bit_step_alloc:NULL
[2016-10-07T20:23:28.162]   gres_cnt_step_alloc:NULL
[2016-10-07T20:23:28.162]   gres_bit_alloc[0]:1-2
[2016-10-07T20:23:28.162] backfill: Started JobId=1987 in partition on gpu-cluster-2
[2016-10-07T20:23:28.162] job start: job_id = 1987	time = 1475843008

[2016-10-07T20:23:29.972] job_complete: JobID=1961 State=0x1 NodeCnt=1 WEXITSTATUS 255
[2016-10-07T20:23:29.972] job end: job_id = 1961	time = 1475843009

[2016-10-07T20:23:29.972] job_complete: JobID=1961 State=0x8005 NodeCnt=1 done
[2016-10-07T20:23:29.977] gres: gpu state for job 1963
[2016-10-07T20:23:29.977]   gres_cnt:3 node_cnt:1 type:(null)
[2016-10-07T20:23:29.977]   gres_bit_step_alloc:NULL
[2016-10-07T20:23:29.977]   gres_cnt_step_alloc:NULL
[2016-10-07T20:23:29.977]   gres_bit_alloc[0]:4-6
[2016-10-07T20:23:29.977] sched: Allocate JobID=1963 NodeList=gpu-cluster-1 #CPUs=1 Partition=partition
[2016-10-07T20:23:29.978] job start: job_id = 1963	time = 1475843009

[2016-10-07T20:23:31.934] job_complete: JobID=1963 State=0x1 NodeCnt=1 WEXITSTATUS 0
[2016-10-07T20:23:31.934] job end: job_id = 1963	time = 1475843011

[2016-10-07T20:23:31.934] job_complete: JobID=1963 State=0x8003 NodeCnt=1 done
[2016-10-07T20:23:58.167] gres: gpu state for job 1965
[2016-10-07T20:23:58.167]   gres_cnt:5 node_cnt:2 type:(null)
[2016-10-07T20:23:58.167]   gres_bit_step_alloc:NULL
[2016-10-07T20:23:58.167]   gres_cnt_step_alloc:NULL
[2016-10-07T20:23:58.167]   gres_bit_alloc[0]:4-7
[2016-10-07T20:23:58.167]   gres_bit_alloc[1]:0
[2016-10-07T20:23:58.167] backfill: Started JobId=1965 in partition on gpu-cluster-1
[2016-10-07T20:23:58.167] job start: job_id = 1965	time = 1475843038

[2016-10-07T20:23:58.169] gres: gpu state for job 1990
[2016-10-07T20:23:58.169]   gres_cnt:2 node_cnt:1 type:(null)
[2016-10-07T20:23:58.169]   gres_bit_step_alloc:NULL
[2016-10-07T20:23:58.169]   gres_cnt_step_alloc:NULL
[2016-10-07T20:23:58.169]   gres_bit_alloc[0]:2-3
[2016-10-07T20:23:58.169] backfill: Started JobId=1990 in partition on gpu-cluster-2
[2016-10-07T20:23:58.169] job start: job_id = 1990	time = 1475843038

[2016-10-07T20:24:01.132] job_complete: JobID=1990 State=0x1 NodeCnt=1 WEXITSTATUS 0
[2016-10-07T20:24:01.132] job end: job_id = 1990	time = 1475843041

[2016-10-07T20:24:01.133] job_complete: JobID=1990 State=0x8003 NodeCnt=1 done
[2016-10-07T20:24:01.455] job_complete: JobID=1965 State=0x1 NodeCnt=1 WEXITSTATUS 255
[2016-10-07T20:24:01.455] job end: job_id = 1965	time = 1475843041

[2016-10-07T20:24:01.455] job_complete: JobID=1965 State=0x8005 NodeCnt=1 done
[2016-10-07T20:24:13.760] job_complete: JobID=1939 State=0x1 NodeCnt=1 WEXITSTATUS 255
[2016-10-07T20:24:13.760] job end: job_id = 1939	time = 1475843053

[2016-10-07T20:24:13.760] job_complete: JobID=1939 State=0x8005 NodeCnt=1 done
[2016-10-07T20:24:13.765] gres: gpu state for job 1964
[2016-10-07T20:24:13.765]   gres_cnt:8 node_cnt:2 type:(null)
[2016-10-07T20:24:13.765]   gres_bit_step_alloc:NULL
[2016-10-07T20:24:13.765]   gres_cnt_step_alloc:NULL
[2016-10-07T20:24:13.765]   gres_bit_alloc[0]:4-7
[2016-10-07T20:24:13.765]   gres_bit_alloc[1]:0,2-4
[2016-10-07T20:24:13.765] sched: Allocate JobID=1964 NodeList=gpu-cluster-1 #CPUs=1 Partition=partition
[2016-10-07T20:24:13.765] job start: job_id = 1964	time = 1475843053

[2016-10-07T20:24:28.173] gres: gpu state for job 1977
[2016-10-07T20:24:28.173]   gres_cnt:3 node_cnt:1 type:(null)
[2016-10-07T20:24:28.173]   gres_bit_step_alloc:NULL
[2016-10-07T20:24:28.173]   gres_cnt_step_alloc:NULL
[2016-10-07T20:24:28.173]   gres_bit_alloc[0]:5-7
[2016-10-07T20:24:28.173] backfill: Started JobId=1977 in partition on gpu-cluster-1
[2016-10-07T20:24:28.173] job start: job_id = 1977	time = 1475843068

[2016-10-07T20:24:28.175] gres: gpu state for job 2001
[2016-10-07T20:24:28.175]   gres_cnt:1 node_cnt:1 type:(null)
[2016-10-07T20:24:28.175]   gres_bit_step_alloc:NULL
[2016-10-07T20:24:28.175]   gres_cnt_step_alloc:NULL
[2016-10-07T20:24:28.175]   gres_bit_alloc[0]:0
[2016-10-07T20:24:28.175] backfill: Started JobId=2001 in partition on gpu-cluster-2
[2016-10-07T20:24:28.175] job start: job_id = 2001	time = 1475843068

[2016-10-07T20:24:30.744] job_complete: JobID=2001 State=0x1 NodeCnt=1 WEXITSTATUS 0
[2016-10-07T20:24:30.744] job end: job_id = 2001	time = 1475843070

[2016-10-07T20:24:30.744] job_complete: JobID=2001 State=0x8003 NodeCnt=1 done
[2016-10-07T20:24:31.997] job_complete: JobID=1964 State=0x1 NodeCnt=1 WEXITSTATUS 255
[2016-10-07T20:24:31.997] job end: job_id = 1964	time = 1475843071

[2016-10-07T20:24:31.997] job_complete: JobID=1964 State=0x8005 NodeCnt=1 done
[2016-10-07T20:24:32.003] gres: gpu state for job 1967
[2016-10-07T20:24:32.003]   gres_cnt:6 node_cnt:2 type:(null)
[2016-10-07T20:24:32.003]   gres_bit_step_alloc:NULL
[2016-10-07T20:24:32.003]   gres_cnt_step_alloc:NULL
[2016-10-07T20:24:32.003]   gres_bit_alloc[0]:4-7
[2016-10-07T20:24:32.003]   gres_bit_alloc[1]:0,2
[2016-10-07T20:24:32.003] sched: Allocate JobID=1967 NodeList=gpu-cluster-1 #CPUs=1 Partition=partition
[2016-10-07T20:24:32.003] job start: job_id = 1967	time = 1475843071

[2016-10-07T20:24:36.041] job_complete: JobID=1967 State=0x1 NodeCnt=1 WEXITSTATUS 0
[2016-10-07T20:24:36.041] job end: job_id = 1967	time = 1475843076

[2016-10-07T20:24:36.041] job_complete: JobID=1967 State=0x8003 NodeCnt=1 done
[2016-10-07T20:24:36.047] gres: gpu state for job 1968
[2016-10-07T20:24:36.047]   gres_cnt:5 node_cnt:2 type:(null)
[2016-10-07T20:24:36.047]   gres_bit_step_alloc:NULL
[2016-10-07T20:24:36.047]   gres_cnt_step_alloc:NULL
[2016-10-07T20:24:36.047]   gres_bit_alloc[0]:4-7
[2016-10-07T20:24:36.047]   gres_bit_alloc[1]:0
[2016-10-07T20:24:36.047] sched: Allocate JobID=1968 NodeList=gpu-cluster-1 #CPUs=1 Partition=partition
[2016-10-07T20:24:36.047] job start: job_id = 1968	time = 1475843076

[2016-10-07T20:24:40.851] job_complete: JobID=1968 State=0x1 NodeCnt=1 WEXITSTATUS 255
[2016-10-07T20:24:40.851] job end: job_id = 1968	time = 1475843080

[2016-10-07T20:24:40.852] job_complete: JobID=1968 State=0x8005 NodeCnt=1 done
[2016-10-07T20:24:40.857] gres: gpu state for job 1969
[2016-10-07T20:24:40.857]   gres_cnt:8 node_cnt:2 type:(null)
[2016-10-07T20:24:40.857]   gres_bit_step_alloc:NULL
[2016-10-07T20:24:40.857]   gres_cnt_step_alloc:NULL
[2016-10-07T20:24:40.857]   gres_bit_alloc[0]:4-7
[2016-10-07T20:24:40.857]   gres_bit_alloc[1]:0,2-4
[2016-10-07T20:24:40.857] sched: Allocate JobID=1969 NodeList=gpu-cluster-1 #CPUs=1 Partition=partition
[2016-10-07T20:24:40.857] job start: job_id = 1969	time = 1475843080

[2016-10-07T20:24:58.181] gres: gpu state for job 2006
[2016-10-07T20:24:58.181]   gres_cnt:1 node_cnt:1 type:(null)
[2016-10-07T20:24:58.181]   gres_bit_step_alloc:NULL
[2016-10-07T20:24:58.181]   gres_cnt_step_alloc:NULL
[2016-10-07T20:24:58.181]   gres_bit_alloc[0]:0
[2016-10-07T20:24:58.181] backfill: Started JobId=2006 in partition on gpu-cluster-2
[2016-10-07T20:24:58.182] job start: job_id = 2006	time = 1475843098

[2016-10-07T20:25:00.928] job_complete: JobID=1969 State=0x1 NodeCnt=1 WEXITSTATUS 255
[2016-10-07T20:25:00.928] job end: job_id = 1969	time = 1475843100

[2016-10-07T20:25:00.928] job_complete: JobID=1969 State=0x8005 NodeCnt=1 done
[2016-10-07T20:25:00.937] gres: gpu state for job 1970
[2016-10-07T20:25:00.937]   gres_cnt:5 node_cnt:2 type:(null)
[2016-10-07T20:25:00.937]   gres_bit_step_alloc:NULL
[2016-10-07T20:25:00.937]   gres_cnt_step_alloc:NULL
[2016-10-07T20:25:00.937]   gres_bit_alloc[0]:4-7
[2016-10-07T20:25:00.937]   gres_bit_alloc[1]:0
[2016-10-07T20:25:00.937] sched: Allocate JobID=1970 NodeList=gpu-cluster-1 #CPUs=1 Partition=partition
[2016-10-07T20:25:00.937] job start: job_id = 1970	time = 1475843100

[2016-10-07T20:25:04.321] job_complete: JobID=1970 State=0x1 NodeCnt=1 WEXITSTATUS 0
[2016-10-07T20:25:04.321] job end: job_id = 1970	time = 1475843104

[2016-10-07T20:25:04.321] job_complete: JobID=1970 State=0x8003 NodeCnt=1 done
[2016-10-07T20:25:04.327] gres: gpu state for job 1971
[2016-10-07T20:25:04.327]   gres_cnt:6 node_cnt:2 type:(null)
[2016-10-07T20:25:04.327]   gres_bit_step_alloc:NULL
[2016-10-07T20:25:04.327]   gres_cnt_step_alloc:NULL
[2016-10-07T20:25:04.327]   gres_bit_alloc[0]:4-7
[2016-10-07T20:25:04.327]   gres_bit_alloc[1]:0,2
[2016-10-07T20:25:04.327] sched: Allocate JobID=1971 NodeList=gpu-cluster-1 #CPUs=1 Partition=partition
[2016-10-07T20:25:04.327] job start: job_id = 1971	time = 1475843104

[2016-10-07T20:25:28.186] gres: gpu state for job 2002
[2016-10-07T20:25:28.186]   gres_cnt:2 node_cnt:1 type:(null)
[2016-10-07T20:25:28.186]   gres_bit_step_alloc:NULL
[2016-10-07T20:25:28.186]   gres_cnt_step_alloc:NULL
[2016-10-07T20:25:28.186]   gres_bit_alloc[0]:3-4
[2016-10-07T20:25:28.186] backfill: Started JobId=2002 in partition on gpu-cluster-2
[2016-10-07T20:25:28.187] job start: job_id = 2002	time = 1475843128

[2016-10-07T20:26:13.791] job_complete: JobID=1962 State=0x1 NodeCnt=1 WEXITSTATUS 255
[2016-10-07T20:26:13.791] job end: job_id = 1962	time = 1475843173

[2016-10-07T20:26:13.791] job_complete: JobID=1962 State=0x8005 NodeCnt=1 done
[2016-10-07T20:26:19.695] job_complete: JobID=1971 State=0x1 NodeCnt=1 WEXITSTATUS 255
[2016-10-07T20:26:19.695] job end: job_id = 1971	time = 1475843179

[2016-10-07T20:26:19.695] job_complete: JobID=1971 State=0x8005 NodeCnt=1 done
[2016-10-07T20:26:19.700] gres: gpu state for job 1972
[2016-10-07T20:26:19.700]   gres_cnt:7 node_cnt:3 type:(null)
[2016-10-07T20:26:19.700]   gres_bit_step_alloc:NULL
[2016-10-07T20:26:19.700]   gres_cnt_step_alloc:NULL
[2016-10-07T20:26:19.700]   gres_bit_alloc[0]:4-7
[2016-10-07T20:26:19.700]   gres_bit_alloc[1]:0,2
[2016-10-07T20:26:19.700]   gres_bit_alloc[2]:1
[2016-10-07T20:26:19.700] sched: Allocate JobID=1972 NodeList=gpu-cluster-1 #CPUs=1 Partition=partition
[2016-10-07T20:26:19.701] job start: job_id = 1972	time = 1475843179

[2016-10-07T20:26:23.851] job_complete: JobID=1972 State=0x1 NodeCnt=1 WEXITSTATUS 255
[2016-10-07T20:26:23.851] job end: job_id = 1972	time = 1475843183

[2016-10-07T20:26:23.851] job_complete: JobID=1972 State=0x8005 NodeCnt=1 done
[2016-10-07T20:26:23.856] gres: gpu state for job 1973
[2016-10-07T20:26:23.856]   gres_cnt:6 node_cnt:2 type:(null)
[2016-10-07T20:26:23.856]   gres_bit_step_alloc:NULL
[2016-10-07T20:26:23.856]   gres_cnt_step_alloc:NULL
[2016-10-07T20:26:23.856]   gres_bit_alloc[0]:4-7
[2016-10-07T20:26:23.856]   gres_bit_alloc[1]:0,2
[2016-10-07T20:26:23.856] sched: Allocate JobID=1973 NodeList=gpu-cluster-1 #CPUs=1 Partition=partition
[2016-10-07T20:26:23.856] job start: job_id = 1973	time = 1475843183

[2016-10-07T20:26:28.106] job_complete: JobID=1973 State=0x1 NodeCnt=1 WEXITSTATUS 255
[2016-10-07T20:26:28.106] job end: job_id = 1973	time = 1475843188

[2016-10-07T20:26:28.106] job_complete: JobID=1973 State=0x8005 NodeCnt=1 done
[2016-10-07T20:26:28.111] gres: gpu state for job 1974
[2016-10-07T20:26:28.111]   gres_cnt:8 node_cnt:3 type:(null)
[2016-10-07T20:26:28.111]   gres_bit_step_alloc:NULL
[2016-10-07T20:26:28.111]   gres_cnt_step_alloc:NULL
[2016-10-07T20:26:28.111]   gres_bit_alloc[0]:4-7
[2016-10-07T20:26:28.111]   gres_bit_alloc[1]:0,2
[2016-10-07T20:26:28.111]   gres_bit_alloc[2]:1-2
[2016-10-07T20:26:28.111] sched: Allocate JobID=1974 NodeList=gpu-cluster-1 #CPUs=1 Partition=partition
[2016-10-07T20:26:28.112] job start: job_id = 1974	time = 1475843188

[2016-10-07T20:26:28.194] gres: gpu state for job 1982
[2016-10-07T20:26:28.194]   gres_cnt:3 node_cnt:2 type:(null)
[2016-10-07T20:26:28.194]   gres_bit_step_alloc:NULL
[2016-10-07T20:26:28.194]   gres_cnt_step_alloc:NULL
[2016-10-07T20:26:28.194]   gres_bit_alloc[0]:3,7
[2016-10-07T20:26:28.194]   gres_bit_alloc[1]:0
[2016-10-07T20:26:28.194] backfill: Started JobId=1982 in partition on gpu-cluster-1
[2016-10-07T20:26:28.194] job start: job_id = 1982	time = 1475843188

[2016-10-07T20:26:48.244] job_complete: JobID=1974 State=0x1 NodeCnt=1 WEXITSTATUS 255
[2016-10-07T20:26:48.244] job end: job_id = 1974	time = 1475843208

[2016-10-07T20:26:48.244] job_complete: JobID=1974 State=0x8005 NodeCnt=1 done
[2016-10-07T20:26:48.250] gres: gpu state for job 1976
[2016-10-07T20:26:48.250]   gres_cnt:7 node_cnt:3 type:(null)
[2016-10-07T20:26:48.250]   gres_bit_step_alloc:NULL
[2016-10-07T20:26:48.250]   gres_cnt_step_alloc:NULL
[2016-10-07T20:26:48.250]   gres_bit_alloc[0]:4-7
[2016-10-07T20:26:48.250]   gres_bit_alloc[1]:0,2
[2016-10-07T20:26:48.250]   gres_bit_alloc[2]:1
[2016-10-07T20:26:48.250] sched: Allocate JobID=1976 NodeList=gpu-cluster-1 #CPUs=1 Partition=partition
[2016-10-07T20:26:48.250] job start: job_id = 1976	time = 1475843208

[2016-10-07T20:26:51.799] job_complete: JobID=1976 State=0x1 NodeCnt=1 WEXITSTATUS 0
[2016-10-07T20:26:51.799] job end: job_id = 1976	time = 1475843211

[2016-10-07T20:26:51.799] job_complete: JobID=1976 State=0x8003 NodeCnt=1 done
[2016-10-07T20:26:51.804] gres: gpu state for job 1978
[2016-10-07T20:26:51.804]   gres_cnt:4 node_cnt:1 type:(null)
[2016-10-07T20:26:51.804]   gres_bit_step_alloc:NULL
[2016-10-07T20:26:51.804]   gres_cnt_step_alloc:NULL
[2016-10-07T20:26:51.804]   gres_bit_alloc[0]:4-7
[2016-10-07T20:26:51.804] sched: Allocate JobID=1978 NodeList=gpu-cluster-1 #CPUs=1 Partition=partition
[2016-10-07T20:26:51.804] job start: job_id = 1978	time = 1475843211

[2016-10-07T20:26:53.558] job_complete: JobID=1978 State=0x1 NodeCnt=1 WEXITSTATUS 0
[2016-10-07T20:26:53.558] job end: job_id = 1978	time = 1475843213

[2016-10-07T20:26:53.558] job_complete: JobID=1978 State=0x8003 NodeCnt=1 done
[2016-10-07T20:26:53.563] gres: gpu state for job 1979
[2016-10-07T20:26:53.563]   gres_cnt:5 node_cnt:2 type:(null)
[2016-10-07T20:26:53.563]   gres_bit_step_alloc:NULL
[2016-10-07T20:26:53.563]   gres_cnt_step_alloc:NULL
[2016-10-07T20:26:53.563]   gres_bit_alloc[0]:4-7
[2016-10-07T20:26:53.563]   gres_bit_alloc[1]:0
[2016-10-07T20:26:53.563] sched: Allocate JobID=1979 NodeList=gpu-cluster-1 #CPUs=1 Partition=partition
[2016-10-07T20:26:53.563] job start: job_id = 1979	time = 1475843213

[2016-10-07T20:26:58.203] gres: gpu state for job 1996
[2016-10-07T20:26:58.203]   gres_cnt:3 node_cnt:2 type:(null)
[2016-10-07T20:26:58.203]   gres_bit_step_alloc:NULL
[2016-10-07T20:26:58.203]   gres_cnt_step_alloc:NULL
[2016-10-07T20:26:58.203]   gres_bit_alloc[0]:2
[2016-10-07T20:26:58.203]   gres_bit_alloc[1]:1-2
[2016-10-07T20:26:58.203] backfill: Started JobId=1996 in partition on gpu-cluster-2
[2016-10-07T20:26:58.203] job start: job_id = 1996	time = 1475843218

[2016-10-07T20:30:44.874] job_complete: JobID=1979 State=0x1 NodeCnt=1 WEXITSTATUS 255
[2016-10-07T20:30:44.874] job end: job_id = 1979	time = 1475843444

[2016-10-07T20:30:44.874] job_complete: JobID=1979 State=0x8005 NodeCnt=1 done
[2016-10-07T20:30:44.880] gres: gpu state for job 1980
[2016-10-07T20:30:44.880]   gres_cnt:5 node_cnt:2 type:(null)
[2016-10-07T20:30:44.880]   gres_bit_step_alloc:NULL
[2016-10-07T20:30:44.880]   gres_cnt_step_alloc:NULL
[2016-10-07T20:30:44.880]   gres_bit_alloc[0]:4-7
[2016-10-07T20:30:44.880]   gres_bit_alloc[1]:0
[2016-10-07T20:30:44.880] sched: Allocate JobID=1980 NodeList=gpu-cluster-1 #CPUs=1 Partition=partition
[2016-10-07T20:30:44.880] job start: job_id = 1980	time = 1475843444

[2016-10-07T20:33:52.479] job_complete: JobID=1941 State=0x1 NodeCnt=1 WEXITSTATUS 0
[2016-10-07T20:33:52.479] job end: job_id = 1941	time = 1475843632

[2016-10-07T20:33:52.479] job_complete: JobID=1941 State=0x8003 NodeCnt=1 done
[2016-10-07T20:34:03.246] gres: gpu state for job 2007
[2016-10-07T20:34:03.246]   gres_cnt:1 node_cnt:1 type:(null)
[2016-10-07T20:34:03.246]   gres_bit_step_alloc:NULL
[2016-10-07T20:34:03.246]   gres_cnt_step_alloc:NULL
[2016-10-07T20:34:03.246]   gres_bit_alloc[0]:7
[2016-10-07T20:34:03.246] backfill: Started JobId=2007 in partition on gpu-cluster-1
[2016-10-07T20:34:03.246] job start: job_id = 2007	time = 1475843643

[2016-10-07T20:34:05.754] job_complete: JobID=2007 State=0x1 NodeCnt=1 WEXITSTATUS 0
[2016-10-07T20:34:05.754] job end: job_id = 2007	time = 1475843645

[2016-10-07T20:34:05.754] job_complete: JobID=2007 State=0x8003 NodeCnt=1 done
[2016-10-07T20:34:09.335] job_complete: JobID=1952 State=0x1 NodeCnt=1 WEXITSTATUS 0
[2016-10-07T20:34:09.335] job end: job_id = 1952	time = 1475843649

[2016-10-07T20:34:09.335] job_complete: JobID=1952 State=0x8003 NodeCnt=1 done
[2016-10-07T20:34:18.465] job_complete: JobID=1935 State=0x1 NodeCnt=1 WEXITSTATUS 0
[2016-10-07T20:34:18.465] job end: job_id = 1935	time = 1475843658

[2016-10-07T20:34:18.465] job_complete: JobID=1935 State=0x8003 NodeCnt=1 done
[2016-10-07T20:34:21.719] job_complete: JobID=1942 State=0x1 NodeCnt=1 WEXITSTATUS 0
[2016-10-07T20:34:21.719] job end: job_id = 1942	time = 1475843661

[2016-10-07T20:34:21.719] job_complete: JobID=1942 State=0x8003 NodeCnt=1 done
[2016-10-07T20:34:21.724] gres: gpu state for job 1981
[2016-10-07T20:34:21.724]   gres_cnt:6 node_cnt:3 type:(null)
[2016-10-07T20:34:21.724]   gres_bit_step_alloc:NULL
[2016-10-07T20:34:21.724]   gres_cnt_step_alloc:NULL
[2016-10-07T20:34:21.724]   gres_bit_alloc[0]:1
[2016-10-07T20:34:21.724]   gres_bit_alloc[1]:5-6
[2016-10-07T20:34:21.724]   gres_bit_alloc[2]:4-6
[2016-10-07T20:34:21.724] sched: Allocate JobID=1981 NodeList=gpu-cluster-2 #CPUs=1 Partition=partition
[2016-10-07T20:34:21.725] job start: job_id = 1981	time = 1475843661

[2016-10-07T20:34:35.121] job_complete: JobID=1980 State=0x1 NodeCnt=1 WEXITSTATUS 255
[2016-10-07T20:34:35.121] job end: job_id = 1980	time = 1475843675

[2016-10-07T20:34:35.121] job_complete: JobID=1980 State=0x8005 NodeCnt=1 done
[2016-10-07T20:34:35.126] gres: gpu state for job 1984
[2016-10-07T20:34:35.126]   gres_cnt:5 node_cnt:2 type:(null)
[2016-10-07T20:34:35.126]   gres_bit_step_alloc:NULL
[2016-10-07T20:34:35.126]   gres_cnt_step_alloc:NULL
[2016-10-07T20:34:35.126]   gres_bit_alloc[0]:4-7
[2016-10-07T20:34:35.126]   gres_bit_alloc[1]:0
[2016-10-07T20:34:35.126] sched: Allocate JobID=1984 NodeList=gpu-cluster-2 #CPUs=1 Partition=partition
[2016-10-07T20:34:35.127] job start: job_id = 1984	time = 1475843675

[2016-10-07T20:35:09.564] job_complete: JobID=1966 State=0x1 NodeCnt=1 WEXITSTATUS 0
[2016-10-07T20:35:09.564] job end: job_id = 1966	time = 1475843709

[2016-10-07T20:35:09.565] job_complete: JobID=1966 State=0x8003 NodeCnt=1 done
[2016-10-07T20:35:10.867] job_complete: JobID=1950 State=0x1 NodeCnt=1 WEXITSTATUS 0
[2016-10-07T20:35:10.867] job end: job_id = 1950	time = 1475843710

[2016-10-07T20:35:10.867] job_complete: JobID=1950 State=0x8003 NodeCnt=1 done
[2016-10-07T20:35:10.872] gres: gpu state for job 1986
[2016-10-07T20:35:10.872]   gres_cnt:6 node_cnt:3 type:(null)
[2016-10-07T20:35:10.872]   gres_bit_step_alloc:NULL
[2016-10-07T20:35:10.872]   gres_cnt_step_alloc:NULL
[2016-10-07T20:35:10.872]   gres_bit_alloc[0]:0-3
[2016-10-07T20:35:10.872]   gres_bit_alloc[1]:4
[2016-10-07T20:35:10.872]   gres_bit_alloc[2]:7
[2016-10-07T20:35:10.872] sched: Allocate JobID=1986 NodeList=gpu-cluster-2 #CPUs=1 Partition=partition
[2016-10-07T20:35:10.873] job start: job_id = 1986	time = 1475843710

[2016-10-07T20:35:13.790] job_complete: JobID=1986 State=0x1 NodeCnt=1 WEXITSTATUS 0
[2016-10-07T20:35:13.790] job end: job_id = 1986	time = 1475843713

[2016-10-07T20:35:13.790] job_complete: JobID=1986 State=0x8003 NodeCnt=1 done
[2016-10-07T20:35:13.796] gres: gpu state for job 1988
[2016-10-07T20:35:13.796]   gres_cnt:6 node_cnt:3 type:(null)
[2016-10-07T20:35:13.796]   gres_bit_step_alloc:NULL
[2016-10-07T20:35:13.796]   gres_cnt_step_alloc:NULL
[2016-10-07T20:35:13.796]   gres_bit_alloc[0]:0-3
[2016-10-07T20:35:13.796]   gres_bit_alloc[1]:4
[2016-10-07T20:35:13.796]   gres_bit_alloc[2]:7
[2016-10-07T20:35:13.796] sched: Allocate JobID=1988 NodeList=gpu-cluster-2 #CPUs=1 Partition=partition
[2016-10-07T20:35:13.796] job start: job_id = 1988	time = 1475843713

[2016-10-07T20:35:38.026] job_complete: JobID=1995 State=0x1 NodeCnt=1 WEXITSTATUS 0
[2016-10-07T20:35:38.026] job end: job_id = 1995	time = 1475843738

[2016-10-07T20:35:38.026] job_complete: JobID=1995 State=0x8003 NodeCnt=1 done
[2016-10-07T20:35:38.469] job_complete: JobID=1981 State=0x1 NodeCnt=1 WEXITSTATUS 255
[2016-10-07T20:35:38.469] job end: job_id = 1981	time = 1475843738

[2016-10-07T20:35:38.469] job_complete: JobID=1981 State=0x8005 NodeCnt=1 done
[2016-10-07T20:36:03.255] gres: gpu state for job 1991
[2016-10-07T20:36:03.255]   gres_cnt:5 node_cnt:3 type:(null)
[2016-10-07T20:36:03.255]   gres_bit_step_alloc:NULL
[2016-10-07T20:36:03.255]   gres_cnt_step_alloc:NULL
[2016-10-07T20:36:03.255]   gres_bit_alloc[0]:1
[2016-10-07T20:36:03.255]   gres_bit_alloc[1]:5-6
[2016-10-07T20:36:03.255]   gres_bit_alloc[2]:3-4
[2016-10-07T20:36:03.255] backfill: Started JobId=1991 in partition on gpu-cluster-2
[2016-10-07T20:36:03.256] job start: job_id = 1991	time = 1475843763

[2016-10-07T20:36:03.257] gres: gpu state for job 2008
[2016-10-07T20:36:03.257]   gres_cnt:2 node_cnt:1 type:(null)
[2016-10-07T20:36:03.257]   gres_bit_step_alloc:NULL
[2016-10-07T20:36:03.257]   gres_cnt_step_alloc:NULL
[2016-10-07T20:36:03.257]   gres_bit_alloc[0]:5-6
[2016-10-07T20:36:03.257] backfill: Started JobId=2008 in partition on gpu-cluster-2
[2016-10-07T20:36:03.257] job start: job_id = 2008	time = 1475843763

[2016-10-07T20:36:06.644] job_complete: JobID=1991 State=0x1 NodeCnt=1 WEXITSTATUS 0
[2016-10-07T20:36:06.644] job end: job_id = 1991	time = 1475843766

[2016-10-07T20:36:06.644] job_complete: JobID=1991 State=0x8003 NodeCnt=1 done
[2016-10-07T20:36:08.460] job_complete: JobID=2008 State=0x1 NodeCnt=1 WEXITSTATUS 0
[2016-10-07T20:36:08.460] job end: job_id = 2008	time = 1475843768

[2016-10-07T20:36:08.460] job_complete: JobID=2008 State=0x8003 NodeCnt=1 done
[2016-10-07T20:36:33.259] gres: gpu state for job 1992
[2016-10-07T20:36:33.259]   gres_cnt:7 node_cnt:3 type:(null)
[2016-10-07T20:36:33.259]   gres_bit_step_alloc:NULL
[2016-10-07T20:36:33.259]   gres_cnt_step_alloc:NULL
[2016-10-07T20:36:33.259]   gres_bit_alloc[0]:1
[2016-10-07T20:36:33.259]   gres_bit_alloc[1]:5-6
[2016-10-07T20:36:33.259]   gres_bit_alloc[2]:3-6
[2016-10-07T20:36:33.259] backfill: Started JobId=1992 in partition on gpu-cluster-2
[2016-10-07T20:36:33.259] job start: job_id = 1992	time = 1475843793

[2016-10-07T20:36:39.019] job_complete: JobID=1992 State=0x1 NodeCnt=1 WEXITSTATUS 0
[2016-10-07T20:36:39.019] job end: job_id = 1992	time = 1475843799

[2016-10-07T20:36:39.019] job_complete: JobID=1992 State=0x8003 NodeCnt=1 done
[2016-10-07T20:37:03.261] gres: gpu state for job 1993
[2016-10-07T20:37:03.261]   gres_cnt:7 node_cnt:3 type:(null)
[2016-10-07T20:37:03.261]   gres_bit_step_alloc:NULL
[2016-10-07T20:37:03.261]   gres_cnt_step_alloc:NULL
[2016-10-07T20:37:03.261]   gres_bit_alloc[0]:1
[2016-10-07T20:37:03.261]   gres_bit_alloc[1]:5-6
[2016-10-07T20:37:03.261]   gres_bit_alloc[2]:3-6
[2016-10-07T20:37:03.261] backfill: Started JobId=1993 in partition on gpu-cluster-2
[2016-10-07T20:37:03.262] job start: job_id = 1993	time = 1475843823

[2016-10-07T20:37:06.876] job_complete: JobID=1993 State=0x1 NodeCnt=1 WEXITSTATUS 0
[2016-10-07T20:37:06.876] job end: job_id = 1993	time = 1475843826

[2016-10-07T20:37:06.876] job_complete: JobID=1993 State=0x8003 NodeCnt=1 done
[2016-10-07T20:37:20.562] job_complete: JobID=1987 State=0x1 NodeCnt=1 WEXITSTATUS 0
[2016-10-07T20:37:20.562] job end: job_id = 1987	time = 1475843840

[2016-10-07T20:37:20.562] job_complete: JobID=1987 State=0x8003 NodeCnt=1 done
[2016-10-07T20:37:20.568] gres: gpu state for job 1989
[2016-10-07T20:37:20.568]   gres_cnt:8 node_cnt:3 type:(null)
[2016-10-07T20:37:20.568]   gres_bit_step_alloc:NULL
[2016-10-07T20:37:20.568]   gres_cnt_step_alloc:NULL
[2016-10-07T20:37:20.568]   gres_bit_alloc[0]:1
[2016-10-07T20:37:20.568]   gres_bit_alloc[1]:5-6
[2016-10-07T20:37:20.568]   gres_bit_alloc[2]:1-5
[2016-10-07T20:37:20.568] sched: Allocate JobID=1989 NodeList=gpu-cluster-2 #CPUs=1 Partition=partition
[2016-10-07T20:37:20.568] job start: job_id = 1989	time = 1475843840

[2016-10-07T20:37:24.306] job_complete: JobID=1989 State=0x1 NodeCnt=1 WEXITSTATUS 0
[2016-10-07T20:37:24.306] job end: job_id = 1989	time = 1475843844

[2016-10-07T20:37:24.306] job_complete: JobID=1989 State=0x8003 NodeCnt=1 done
[2016-10-07T20:37:24.312] gres: gpu state for job 1994
[2016-10-07T20:37:24.312]   gres_cnt:7 node_cnt:3 type:(null)
[2016-10-07T20:37:24.312]   gres_bit_step_alloc:NULL
[2016-10-07T20:37:24.312]   gres_cnt_step_alloc:NULL
[2016-10-07T20:37:24.312]   gres_bit_alloc[0]:1
[2016-10-07T20:37:24.312]   gres_bit_alloc[1]:5-6
[2016-10-07T20:37:24.312]   gres_bit_alloc[2]:1-4
[2016-10-07T20:37:24.312] sched: Allocate JobID=1994 NodeList=gpu-cluster-2 #CPUs=1 Partition=partition
[2016-10-07T20:37:24.312] job start: job_id = 1994	time = 1475843844

[2016-10-07T20:37:33.264] gres: gpu state for job 2011
[2016-10-07T20:37:33.264]   gres_cnt:2 node_cnt:1 type:(null)
[2016-10-07T20:37:33.264]   gres_bit_step_alloc:NULL
[2016-10-07T20:37:33.264]   gres_cnt_step_alloc:NULL
[2016-10-07T20:37:33.264]   gres_bit_alloc[0]:5-6
[2016-10-07T20:37:33.264] backfill: Started JobId=2011 in partition on gpu-cluster-2
[2016-10-07T20:37:33.265] job start: job_id = 2011	time = 1475843853

[2016-10-07T20:37:38.019] job_complete: JobID=2011 State=0x1 NodeCnt=1 WEXITSTATUS 0
[2016-10-07T20:37:38.019] job end: job_id = 2011	time = 1475843858

[2016-10-07T20:37:38.019] job_complete: JobID=2011 State=0x8003 NodeCnt=1 done
[2016-10-07T20:38:03.267] gres: gpu state for job 2016
[2016-10-07T20:38:03.267]   gres_cnt:2 node_cnt:1 type:(null)
[2016-10-07T20:38:03.267]   gres_bit_step_alloc:NULL
[2016-10-07T20:38:03.267]   gres_cnt_step_alloc:NULL
[2016-10-07T20:38:03.267]   gres_bit_alloc[0]:5-6
[2016-10-07T20:38:03.267] backfill: Started JobId=2016 in partition on gpu-cluster-2
[2016-10-07T20:38:03.267] job start: job_id = 2016	time = 1475843883

[2016-10-07T20:38:05.902] job_complete: JobID=2016 State=0x1 NodeCnt=1 WEXITSTATUS 0
[2016-10-07T20:38:05.902] job end: job_id = 2016	time = 1475843885

[2016-10-07T20:38:05.902] job_complete: JobID=2016 State=0x8003 NodeCnt=1 done
[2016-10-07T20:38:26.983] job_complete: JobID=1984 State=0x1 NodeCnt=1 WEXITSTATUS 255
[2016-10-07T20:38:26.983] job end: job_id = 1984	time = 1475843906

[2016-10-07T20:38:26.983] job_complete: JobID=1984 State=0x8005 NodeCnt=1 done
[2016-10-07T20:38:26.989] gres: gpu state for job 1997
[2016-10-07T20:38:26.989]   gres_cnt:7 node_cnt:3 type:(null)
[2016-10-07T20:38:26.989]   gres_bit_step_alloc:NULL
[2016-10-07T20:38:26.989]   gres_cnt_step_alloc:NULL
[2016-10-07T20:38:26.989]   gres_bit_alloc[0]:4-7
[2016-10-07T20:38:26.989]   gres_bit_alloc[1]:0
[2016-10-07T20:38:26.989]   gres_bit_alloc[2]:5-6
[2016-10-07T20:38:26.989] sched: Allocate JobID=1997 NodeList=gpu-cluster-2 #CPUs=1 Partition=partition
[2016-10-07T20:38:26.989] job start: job_id = 1997	time = 1475843906

[2016-10-07T20:38:29.668] job_complete: JobID=1997 State=0x1 NodeCnt=1 WEXITSTATUS 0
[2016-10-07T20:38:29.668] job end: job_id = 1997	time = 1475843909

[2016-10-07T20:38:29.668] job_complete: JobID=1997 State=0x8003 NodeCnt=1 done
[2016-10-07T20:38:33.268] gres: gpu state for job 1999
[2016-10-07T20:38:33.269]   gres_cnt:7 node_cnt:3 type:(null)
[2016-10-07T20:38:33.269]   gres_bit_step_alloc:NULL
[2016-10-07T20:38:33.269]   gres_cnt_step_alloc:NULL
[2016-10-07T20:38:33.269]   gres_bit_alloc[0]:4-7
[2016-10-07T20:38:33.269]   gres_bit_alloc[1]:0
[2016-10-07T20:38:33.269]   gres_bit_alloc[2]:5-6
[2016-10-07T20:38:33.269] backfill: Started JobId=1999 in partition on gpu-cluster-2
[2016-10-07T20:38:33.269] job start: job_id = 1999	time = 1475843913

[2016-10-07T20:38:36.464] job_complete: JobID=1999 State=0x1 NodeCnt=1 WEXITSTATUS 0
[2016-10-07T20:38:36.464] job end: job_id = 1999	time = 1475843916

[2016-10-07T20:38:36.464] job_complete: JobID=1999 State=0x8003 NodeCnt=1 done
[2016-10-07T20:38:38.098] job_complete: JobID=1977 State=0x1 NodeCnt=1 WEXITSTATUS 0
[2016-10-07T20:38:38.098] job end: job_id = 1977	time = 1475843918

[2016-10-07T20:38:38.098] job_complete: JobID=1977 State=0x8003 NodeCnt=1 done
[2016-10-07T20:38:38.104] gres: gpu state for job 1998
[2016-10-07T20:38:38.104]   gres_cnt:8 node_cnt:2 type:(null)
[2016-10-07T20:38:38.104]   gres_bit_step_alloc:NULL
[2016-10-07T20:38:38.104]   gres_cnt_step_alloc:NULL
[2016-10-07T20:38:38.104]   gres_bit_alloc[0]:4-7
[2016-10-07T20:38:38.104]   gres_bit_alloc[1]:0,5-7
[2016-10-07T20:38:38.104] sched: Allocate JobID=1998 NodeList=gpu-cluster-2 #CPUs=1 Partition=partition
[2016-10-07T20:38:38.105] job start: job_id = 1998	time = 1475843918

[2016-10-07T20:38:38.365] job_complete: JobID=2006 State=0x1 NodeCnt=1 WEXITSTATUS 0
[2016-10-07T20:38:38.365] job end: job_id = 2006	time = 1475843918

[2016-10-07T20:38:38.365] job_complete: JobID=2006 State=0x8003 NodeCnt=1 done
[2016-10-07T20:38:41.120] job_complete: JobID=1994 State=0x1 NodeCnt=1 WEXITSTATUS 255
[2016-10-07T20:38:41.120] job end: job_id = 1994	time = 1475843921

[2016-10-07T20:38:41.120] job_complete: JobID=1994 State=0x8005 NodeCnt=1 done
[2016-10-07T20:38:41.125] gres: gpu state for job 2000
[2016-10-07T20:38:41.126]   gres_cnt:5 node_cnt:3 type:(null)
[2016-10-07T20:38:41.126]   gres_bit_step_alloc:NULL
[2016-10-07T20:38:41.126]   gres_cnt_step_alloc:NULL
[2016-10-07T20:38:41.126]   gres_bit_alloc[0]:1
[2016-10-07T20:38:41.126]   gres_bit_alloc[1]:0,5-6
[2016-10-07T20:38:41.126]   gres_bit_alloc[2]:1
[2016-10-07T20:38:41.126] sched: Allocate JobID=2000 NodeList=gpu-cluster-2 #CPUs=1 Partition=partition
[2016-10-07T20:38:41.167] job start: job_id = 2000	time = 1475843921

[2016-10-07T20:38:46.710] job_complete: JobID=2000 State=0x1 NodeCnt=1 WEXITSTATUS 0
[2016-10-07T20:38:46.710] job end: job_id = 2000	time = 1475843926

[2016-10-07T20:38:46.710] job_complete: JobID=2000 State=0x8003 NodeCnt=1 done
[2016-10-07T20:38:46.715] gres: gpu state for job 2003
[2016-10-07T20:38:46.716]   gres_cnt:6 node_cnt:3 type:(null)
[2016-10-07T20:38:46.716]   gres_bit_step_alloc:NULL
[2016-10-07T20:38:46.716]   gres_cnt_step_alloc:NULL
[2016-10-07T20:38:46.716]   gres_bit_alloc[0]:1
[2016-10-07T20:38:46.716]   gres_bit_alloc[1]:0,5-6
[2016-10-07T20:38:46.716]   gres_bit_alloc[2]:1-2
[2016-10-07T20:38:46.716] sched: Allocate JobID=2003 NodeList=gpu-cluster-2 #CPUs=1 Partition=partition
[2016-10-07T20:38:46.716] job start: job_id = 2003	time = 1475843926

[2016-10-07T20:38:46.716] gres: gpu state for job 2004
[2016-10-07T20:38:46.716]   gres_cnt:4 node_cnt:1 type:(null)
[2016-10-07T20:38:46.716]   gres_bit_step_alloc:NULL
[2016-10-07T20:38:46.716]   gres_cnt_step_alloc:NULL
[2016-10-07T20:38:46.716]   gres_bit_alloc[0]:3-6
[2016-10-07T20:38:46.716] sched: Allocate JobID=2004 NodeList=gpu-cluster-2 #CPUs=1 Partition=partition
[2016-10-07T20:38:46.716] job start: job_id = 2004	time = 1475843926

[2016-10-07T20:38:50.393] job_complete: JobID=2003 State=0x1 NodeCnt=1 WEXITSTATUS 0
[2016-10-07T20:38:50.393] job end: job_id = 2003	time = 1475843930

[2016-10-07T20:38:50.393] job_complete: JobID=2003 State=0x8003 NodeCnt=1 done
[2016-10-07T20:38:50.542] job_complete: JobID=2004 State=0x1 NodeCnt=1 WEXITSTATUS 0
[2016-10-07T20:38:50.542] job end: job_id = 2004	time = 1475843930

[2016-10-07T20:38:50.542] job_complete: JobID=2004 State=0x8003 NodeCnt=1 done
[2016-10-07T20:38:50.548] gres: gpu state for job 2005
[2016-10-07T20:38:50.548]   gres_cnt:8 node_cnt:3 type:(null)
[2016-10-07T20:38:50.548]   gres_bit_step_alloc:NULL
[2016-10-07T20:38:50.548]   gres_cnt_step_alloc:NULL
[2016-10-07T20:38:50.548]   gres_bit_alloc[0]:1
[2016-10-07T20:38:50.548]   gres_bit_alloc[1]:0,5-6
[2016-10-07T20:38:50.548]   gres_bit_alloc[2]:1-4
[2016-10-07T20:38:50.548] sched: Allocate JobID=2005 NodeList=gpu-cluster-2 #CPUs=1 Partition=partition
[2016-10-07T20:38:50.548] job start: job_id = 2005	time = 1475843930

[2016-10-07T20:38:53.974] job_complete: JobID=2005 State=0x1 NodeCnt=1 WEXITSTATUS 0
[2016-10-07T20:38:53.974] job end: job_id = 2005	time = 1475843933

[2016-10-07T20:38:53.974] job_complete: JobID=2005 State=0x8003 NodeCnt=1 done
[2016-10-07T20:38:53.979] gres: gpu state for job 2009
[2016-10-07T20:38:53.979]   gres_cnt:8 node_cnt:3 type:(null)
[2016-10-07T20:38:53.979]   gres_bit_step_alloc:NULL
[2016-10-07T20:38:53.979]   gres_cnt_step_alloc:NULL
[2016-10-07T20:38:53.979]   gres_bit_alloc[0]:1
[2016-10-07T20:38:53.979]   gres_bit_alloc[1]:0,5-6
[2016-10-07T20:38:53.979]   gres_bit_alloc[2]:1-4
[2016-10-07T20:38:53.979] sched: Allocate JobID=2009 NodeList=gpu-cluster-2 #CPUs=1 Partition=partition
[2016-10-07T20:38:53.979] job start: job_id = 2009	time = 1475843933

[2016-10-07T20:38:58.549] job_complete: JobID=1998 State=0x1 NodeCnt=1 WEXITSTATUS 255
[2016-10-07T20:38:58.549] job end: job_id = 1998	time = 1475843938

[2016-10-07T20:38:58.549] job_complete: JobID=1998 State=0x8005 NodeCnt=1 done
[2016-10-07T20:38:58.555] gres: gpu state for job 2010
[2016-10-07T20:38:58.555]   gres_cnt:5 node_cnt:2 type:(null)
[2016-10-07T20:38:58.555]   gres_bit_step_alloc:NULL
[2016-10-07T20:38:58.555]   gres_cnt_step_alloc:NULL
[2016-10-07T20:38:58.555]   gres_bit_alloc[0]:4-7
[2016-10-07T20:38:58.555]   gres_bit_alloc[1]:0
[2016-10-07T20:38:58.555] sched: Allocate JobID=2010 NodeList=gpu-cluster-2 #CPUs=1 Partition=partition
[2016-10-07T20:38:58.555] job start: job_id = 2010	time = 1475843938

[2016-10-07T20:38:58.555] gres: gpu state for job 2012
[2016-10-07T20:38:58.555]   gres_cnt:5 node_cnt:2 type:(null)
[2016-10-07T20:38:58.555]   gres_bit_step_alloc:NULL
[2016-10-07T20:38:58.555]   gres_cnt_step_alloc:NULL
[2016-10-07T20:38:58.555]   gres_bit_alloc[0]:5-7
[2016-10-07T20:38:58.555]   gres_bit_alloc[1]:5-6
[2016-10-07T20:38:58.556] sched: Allocate JobID=2012 NodeList=gpu-cluster-2 #CPUs=1 Partition=partition
[2016-10-07T20:38:58.556] job start: job_id = 2012	time = 1475843938

[2016-10-07T20:39:02.459] job_complete: JobID=2012 State=0x1 NodeCnt=1 WEXITSTATUS 0
[2016-10-07T20:39:02.459] job end: job_id = 2012	time = 1475843942

[2016-10-07T20:39:02.459] job_complete: JobID=2012 State=0x8003 NodeCnt=1 done
[2016-10-07T20:39:03.271] gres: gpu state for job 2015
[2016-10-07T20:39:03.271]   gres_cnt:4 node_cnt:2 type:(null)
[2016-10-07T20:39:03.271]   gres_bit_step_alloc:NULL
[2016-10-07T20:39:03.271]   gres_cnt_step_alloc:NULL
[2016-10-07T20:39:03.271]   gres_bit_alloc[0]:5-7
[2016-10-07T20:39:03.271]   gres_bit_alloc[1]:5
[2016-10-07T20:39:03.271] backfill: Started JobId=2015 in partition on gpu-cluster-2
[2016-10-07T20:39:03.271] job start: job_id = 2015	time = 1475843943

[2016-10-07T20:39:12.409] job_complete: JobID=2009 State=0x1 NodeCnt=1 WEXITSTATUS 255
[2016-10-07T20:39:12.409] job end: job_id = 2009	time = 1475843952

[2016-10-07T20:39:12.409] job_complete: JobID=2009 State=0x8005 NodeCnt=1 done
[2016-10-07T20:39:12.415] gres: gpu state for job 2013
[2016-10-07T20:39:12.415]   gres_cnt:8 node_cnt:3 type:(null)
[2016-10-07T20:39:12.415]   gres_bit_step_alloc:NULL
[2016-10-07T20:39:12.415]   gres_cnt_step_alloc:NULL
[2016-10-07T20:39:12.415]   gres_bit_alloc[0]:1
[2016-10-07T20:39:12.415]   gres_bit_alloc[1]:0,5-6
[2016-10-07T20:39:12.415]   gres_bit_alloc[2]:1-4
[2016-10-07T20:39:12.415] sched: Allocate JobID=2013 NodeList=gpu-cluster-2 #CPUs=1 Partition=partition
[2016-10-07T20:39:12.415] job start: job_id = 2013	time = 1475843952

[2016-10-07T20:39:17.876] job_complete: JobID=2013 State=0x1 NodeCnt=1 WEXITSTATUS 0
[2016-10-07T20:39:17.876] job end: job_id = 2013	time = 1475843957

[2016-10-07T20:39:17.876] job_complete: JobID=2013 State=0x8003 NodeCnt=1 done
[2016-10-07T20:39:17.881] gres: gpu state for job 2014
[2016-10-07T20:39:17.881]   gres_cnt:8 node_cnt:3 type:(null)
[2016-10-07T20:39:17.881]   gres_bit_step_alloc:NULL
[2016-10-07T20:39:17.881]   gres_cnt_step_alloc:NULL
[2016-10-07T20:39:17.881]   gres_bit_alloc[0]:1
[2016-10-07T20:39:17.881]   gres_bit_alloc[1]:0,5-6
[2016-10-07T20:39:17.881]   gres_bit_alloc[2]:1-4
[2016-10-07T20:39:17.881] sched: Allocate JobID=2014 NodeList=gpu-cluster-2 #CPUs=1 Partition=partition
[2016-10-07T20:39:17.881] job start: job_id = 2014	time = 1475843957

[2016-10-07T20:39:23.158] job_complete: JobID=2002 State=0x1 NodeCnt=1 WEXITSTATUS 0
[2016-10-07T20:39:23.158] job end: job_id = 2002	time = 1475843963

[2016-10-07T20:39:23.158] job_complete: JobID=2002 State=0x8003 NodeCnt=1 done
[2016-10-07T20:39:33.273] gres: gpu state for job 2027
[2016-10-07T20:39:33.273]   gres_cnt:2 node_cnt:1 type:(null)
[2016-10-07T20:39:33.273]   gres_bit_step_alloc:NULL
[2016-10-07T20:39:33.273]   gres_cnt_step_alloc:NULL
[2016-10-07T20:39:33.273]   gres_bit_alloc[0]:3-4
[2016-10-07T20:39:33.273] backfill: Started JobId=2027 in partition on gpu-cluster-2
[2016-10-07T20:39:33.273] job start: job_id = 2027	time = 1475843973

[2016-10-07T20:39:35.829] job_complete: JobID=2014 State=0x1 NodeCnt=1 WEXITSTATUS 255
[2016-10-07T20:39:35.829] job end: job_id = 2014	time = 1475843975

[2016-10-07T20:39:35.829] job_complete: JobID=2014 State=0x8005 NodeCnt=1 done
[2016-10-07T20:39:35.834] gres: gpu state for job 2017
[2016-10-07T20:39:35.834]   gres_cnt:5 node_cnt:3 type:(null)
[2016-10-07T20:39:35.834]   gres_bit_step_alloc:NULL
[2016-10-07T20:39:35.834]   gres_cnt_step_alloc:NULL
[2016-10-07T20:39:35.834]   gres_bit_alloc[0]:1
[2016-10-07T20:39:35.834]   gres_bit_alloc[1]:0,5-6
[2016-10-07T20:39:35.834]   gres_bit_alloc[2]:1
[2016-10-07T20:39:35.834] sched: Allocate JobID=2017 NodeList=gpu-cluster-2 #CPUs=1 Partition=partition
[2016-10-07T20:39:35.835] job start: job_id = 2017	time = 1475843975

[2016-10-07T20:39:38.224] job_complete: JobID=2027 State=0x1 NodeCnt=1 WEXITSTATUS 0
[2016-10-07T20:39:38.224] job end: job_id = 2027	time = 1475843978

[2016-10-07T20:39:38.224] job_complete: JobID=2027 State=0x8003 NodeCnt=1 done
[2016-10-07T20:39:38.229] gres: gpu state for job 2018
[2016-10-07T20:39:38.229]   gres_cnt:6 node_cnt:2 type:(null)
[2016-10-07T20:39:38.229]   gres_bit_step_alloc:NULL
[2016-10-07T20:39:38.229]   gres_cnt_step_alloc:NULL
[2016-10-07T20:39:38.229]   gres_bit_alloc[0]:3-4
[2016-10-07T20:39:38.229]   gres_bit_alloc[1]:2-4,6
[2016-10-07T20:39:38.229] sched: Allocate JobID=2018 NodeList=gpu-cluster-2 #CPUs=1 Partition=partition
[2016-10-07T20:39:38.229] job start: job_id = 2018	time = 1475843978

[2016-10-07T20:39:43.609] job_complete: JobID=2018 State=0x1 NodeCnt=1 WEXITSTATUS 0
[2016-10-07T20:39:43.609] job end: job_id = 2018	time = 1475843983

[2016-10-07T20:39:43.609] job_complete: JobID=2018 State=0x8003 NodeCnt=1 done
[2016-10-07T20:39:43.615] gres: gpu state for job 2019
[2016-10-07T20:39:43.615]   gres_cnt:6 node_cnt:2 type:(null)
[2016-10-07T20:39:43.615]   gres_bit_step_alloc:NULL
[2016-10-07T20:39:43.615]   gres_cnt_step_alloc:NULL
[2016-10-07T20:39:43.615]   gres_bit_alloc[0]:3-4
[2016-10-07T20:39:43.615]   gres_bit_alloc[1]:2-4,6
[2016-10-07T20:39:43.615] sched: Allocate JobID=2019 NodeList=gpu-cluster-2 #CPUs=1 Partition=partition
[2016-10-07T20:39:43.615] job start: job_id = 2019	time = 1475843983

[2016-10-07T20:40:37.886] job_complete: JobID=1982 State=0x1 NodeCnt=1 WEXITSTATUS 0
[2016-10-07T20:40:37.886] job end: job_id = 1982	time = 1475844037

[2016-10-07T20:40:37.886] job_complete: JobID=1982 State=0x8003 NodeCnt=1 done
[2016-10-07T20:41:00.686] job_complete: JobID=2019 State=0x1 NodeCnt=1 WEXITSTATUS 255
[2016-10-07T20:41:00.686] job end: job_id = 2019	time = 1475844060

[2016-10-07T20:41:00.687] job_complete: JobID=2019 State=0x8005 NodeCnt=1 done
[2016-10-07T20:41:00.692] gres: gpu state for job 2020
[2016-10-07T20:41:00.692]   gres_cnt:7 node_cnt:3 type:(null)
[2016-10-07T20:41:00.692]   gres_bit_step_alloc:NULL
[2016-10-07T20:41:00.692]   gres_cnt_step_alloc:NULL
[2016-10-07T20:41:00.692]   gres_bit_alloc[0]:3-4
[2016-10-07T20:41:00.692]   gres_bit_alloc[1]:3,7
[2016-10-07T20:41:00.692]   gres_bit_alloc[2]:0,2-3
[2016-10-07T20:41:00.692] sched: Allocate JobID=2020 NodeList=gpu-cluster-2 #CPUs=1 Partition=partition
[2016-10-07T20:41:00.692] job start: job_id = 2020	time = 1475844060

[2016-10-07T20:41:06.189] job_complete: JobID=2020 State=0x1 NodeCnt=1 WEXITSTATUS 0
[2016-10-07T20:41:06.189] job end: job_id = 2020	time = 1475844066

[2016-10-07T20:41:06.189] job_complete: JobID=2020 State=0x8003 NodeCnt=1 done
[2016-10-07T20:41:06.194] gres: gpu state for job 2021
[2016-10-07T20:41:06.194]   gres_cnt:6 node_cnt:3 type:(null)
[2016-10-07T20:41:06.194]   gres_bit_step_alloc:NULL
[2016-10-07T20:41:06.194]   gres_cnt_step_alloc:NULL
[2016-10-07T20:41:06.194]   gres_bit_alloc[0]:3-4
[2016-10-07T20:41:06.194]   gres_bit_alloc[1]:3,7
[2016-10-07T20:41:06.194]   gres_bit_alloc[2]:0,2
[2016-10-07T20:41:06.194] sched: Allocate JobID=2021 NodeList=gpu-cluster-2 #CPUs=1 Partition=partition
[2016-10-07T20:41:06.194] job start: job_id = 2021	time = 1475844066

[2016-10-07T20:41:09.571] job_complete: JobID=2021 State=0x1 NodeCnt=1 WEXITSTATUS 0
[2016-10-07T20:41:09.571] job end: job_id = 2021	time = 1475844069

[2016-10-07T20:41:09.571] job_complete: JobID=2021 State=0x8003 NodeCnt=1 done
[2016-10-07T20:41:09.576] gres: gpu state for job 2022
[2016-10-07T20:41:09.576]   gres_cnt:8 node_cnt:3 type:(null)
[2016-10-07T20:41:09.576]   gres_bit_step_alloc:NULL
[2016-10-07T20:41:09.576]   gres_cnt_step_alloc:NULL
[2016-10-07T20:41:09.576]   gres_bit_alloc[0]:3-4
[2016-10-07T20:41:09.576]   gres_bit_alloc[1]:3,7
[2016-10-07T20:41:09.576]   gres_bit_alloc[2]:0,2-4
[2016-10-07T20:41:09.576] sched: Allocate JobID=2022 NodeList=gpu-cluster-2 #CPUs=1 Partition=partition
[2016-10-07T20:41:09.576] job start: job_id = 2022	time = 1475844069

[2016-10-07T20:41:11.265] job_complete: JobID=1996 State=0x1 NodeCnt=1 WEXITSTATUS 0
[2016-10-07T20:41:11.265] job end: job_id = 1996	time = 1475844071

[2016-10-07T20:41:11.265] job_complete: JobID=1996 State=0x8003 NodeCnt=1 done
[2016-10-07T20:41:28.047] job_complete: JobID=2022 State=0x1 NodeCnt=1 WEXITSTATUS 255
[2016-10-07T20:41:28.047] job end: job_id = 2022	time = 1475844088

[2016-10-07T20:41:28.047] job_complete: JobID=2022 State=0x8005 NodeCnt=1 done
[2016-10-07T20:41:28.052] gres: gpu state for job 2023
[2016-10-07T20:41:28.052]   gres_cnt:5 node_cnt:2 type:(null)
[2016-10-07T20:41:28.052]   gres_bit_step_alloc:NULL
[2016-10-07T20:41:28.052]   gres_cnt_step_alloc:NULL
[2016-10-07T20:41:28.052]   gres_bit_alloc[0]:2-4
[2016-10-07T20:41:28.052]   gres_bit_alloc[1]:1-2
[2016-10-07T20:41:28.052] sched: Allocate JobID=2023 NodeList=gpu-cluster-2 #CPUs=1 Partition=partition
[2016-10-07T20:41:28.052] job start: job_id = 2023	time = 1475844088

[2016-10-07T20:41:33.276] gres: gpu state for job 2025
[2016-10-07T20:41:33.276]   gres_cnt:4 node_cnt:2 type:(null)
[2016-10-07T20:41:33.276]   gres_bit_step_alloc:NULL
[2016-10-07T20:41:33.276]   gres_cnt_step_alloc:NULL
[2016-10-07T20:41:33.276]   gres_bit_alloc[0]:3,7
[2016-10-07T20:41:33.276]   gres_bit_alloc[1]:0,2
[2016-10-07T20:41:33.276] backfill: Started JobId=2025 in partition on gpu-cluster-2
[2016-10-07T20:41:33.276] job start: job_id = 2025	time = 1475844093

[2016-10-07T20:41:33.985] job_complete: JobID=2023 State=0x1 NodeCnt=1 WEXITSTATUS 0
[2016-10-07T20:41:33.985] job end: job_id = 2023	time = 1475844093

[2016-10-07T20:41:33.985] job_complete: JobID=2023 State=0x8003 NodeCnt=1 done
[2016-10-07T20:41:33.990] gres: gpu state for job 2024
[2016-10-07T20:41:33.990]   gres_cnt:8 node_cnt:3 type:(null)
[2016-10-07T20:41:33.990]   gres_bit_step_alloc:NULL
[2016-10-07T20:41:33.990]   gres_cnt_step_alloc:NULL
[2016-10-07T20:41:33.990]   gres_bit_alloc[0]:2-4
[2016-10-07T20:41:33.990]   gres_bit_alloc[1]:1-2
[2016-10-07T20:41:33.990]   gres_bit_alloc[2]:3-4,6
[2016-10-07T20:41:33.990] sched: Allocate JobID=2024 NodeList=gpu-cluster-2 #CPUs=1 Partition=partition
[2016-10-07T20:41:33.991] job start: job_id = 2024	time = 1475844093

[2016-10-07T20:41:37.634] job_complete: JobID=2024 State=0x1 NodeCnt=1 WEXITSTATUS 0
[2016-10-07T20:41:37.634] job end: job_id = 2024	time = 1475844097

[2016-10-07T20:41:37.634] job_complete: JobID=2024 State=0x8003 NodeCnt=1 done
[2016-10-07T20:41:37.639] gres: gpu state for job 2026
[2016-10-07T20:41:37.639]   gres_cnt:4 node_cnt:2 type:(null)
[2016-10-07T20:41:37.639]   gres_bit_step_alloc:NULL
[2016-10-07T20:41:37.639]   gres_cnt_step_alloc:NULL
[2016-10-07T20:41:37.639]   gres_bit_alloc[0]:2-4
[2016-10-07T20:41:37.639]   gres_bit_alloc[1]:1
[2016-10-07T20:41:37.639] sched: Allocate JobID=2026 NodeList=gpu-cluster-2 #CPUs=1 Partition=partition
[2016-10-07T20:41:37.640] job start: job_id = 2026	time = 1475844097

[2016-10-07T20:42:49.329] job_complete: JobID=2010 State=0x1 NodeCnt=1 WEXITSTATUS 255
[2016-10-07T20:42:49.329] job end: job_id = 2010	time = 1475844169

[2016-10-07T20:42:49.329] job_complete: JobID=2010 State=0x8005 NodeCnt=1 done
[2016-10-07T20:42:49.334] gres: gpu state for job 2028
[2016-10-07T20:42:49.335]   gres_cnt:8 node_cnt:4 type:(null)
[2016-10-07T20:42:49.335]   gres_bit_step_alloc:NULL
[2016-10-07T20:42:49.335]   gres_cnt_step_alloc:NULL
[2016-10-07T20:42:49.335]   gres_bit_alloc[0]:4-7
[2016-10-07T20:42:49.335]   gres_bit_alloc[1]:0
[2016-10-07T20:42:49.335]   gres_bit_alloc[2]:2
[2016-10-07T20:42:49.335]   gres_bit_alloc[3]:3-4
[2016-10-07T20:42:49.335] sched: Allocate JobID=2028 NodeList=gpu-cluster-2 #CPUs=1 Partition=partition
[2016-10-07T20:42:49.335] job start: job_id = 2028	time = 1475844169

[2016-10-07T20:42:54.755] job_complete: JobID=2028 State=0x1 NodeCnt=1 WEXITSTATUS 0
[2016-10-07T20:42:54.755] job end: job_id = 2028	time = 1475844174

[2016-10-07T20:42:54.755] job_complete: JobID=2028 State=0x8003 NodeCnt=1 done
[2016-10-07T20:42:54.761] gres: gpu state for job 2029
[2016-10-07T20:42:54.761]   gres_cnt:8 node_cnt:4 type:(null)
[2016-10-07T20:42:54.761]   gres_bit_step_alloc:NULL
[2016-10-07T20:42:54.761]   gres_cnt_step_alloc:NULL
[2016-10-07T20:42:54.761]   gres_bit_alloc[0]:4-7
[2016-10-07T20:42:54.761]   gres_bit_alloc[1]:0
[2016-10-07T20:42:54.761]   gres_bit_alloc[2]:2
[2016-10-07T20:42:54.761]   gres_bit_alloc[3]:3-4
[2016-10-07T20:42:54.761] sched: Allocate JobID=2029 NodeList=gpu-cluster-2 #CPUs=1 Partition=partition
[2016-10-07T20:42:54.762] job start: job_id = 2029	time = 1475844174

[2016-10-07T20:43:12.644] job_complete: JobID=2029 State=0x1 NodeCnt=1 WEXITSTATUS 255
[2016-10-07T20:43:12.644] job end: job_id = 2029	time = 1475844192

[2016-10-07T20:43:12.644] job_complete: JobID=2029 State=0x8005 NodeCnt=1 done
[2016-10-07T20:43:26.441] job_complete: JobID=2017 State=0x1 NodeCnt=1 WEXITSTATUS 255
[2016-10-07T20:43:26.441] job end: job_id = 2017	time = 1475844206

[2016-10-07T20:43:26.441] job_complete: JobID=2017 State=0x8005 NodeCnt=1 done
[2016-10-07T20:43:59.798] _slurm_rpc_kill_job2: REQUEST_KILL_JOB job 1988 uid 1001
[2016-10-07T20:43:59.799] job end: job_id = 1988	time = 1475844239

[2016-10-07T20:43:59.808] job_complete: JobID=1988 State=0x8004 NodeCnt=1 WTERMSIG 15
[2016-10-07T20:46:15.373] gres/gpu: state for gpu-cluster-3
[2016-10-07T20:46:15.373]   gres_cnt found:8 configured:8 avail:8 alloc:3
[2016-10-07T20:46:15.373]   gres_bit_alloc:1,3,7
[2016-10-07T20:46:15.373]   gres_used:(null)
[2016-10-07T20:46:15.373]   topo_cpus_bitmap[0]:0-7
[2016-10-07T20:46:15.373]   topo_gres_bitmap[0]:0-7
[2016-10-07T20:46:15.373]   topo_gres_cnt_alloc[0]:0
[2016-10-07T20:46:15.373]   topo_gres_cnt_avail[0]:8
[2016-10-07T20:46:15.373]   type[0]:tesla
[2016-10-07T20:46:15.373] gres/gpu: state for gpu-cluster-1
[2016-10-07T20:46:15.373]   gres_cnt found:8 configured:8 avail:8 alloc:0
[2016-10-07T20:46:15.373]   gres_bit_alloc:
[2016-10-07T20:46:15.373]   gres_used:(null)
[2016-10-07T20:46:15.373]   topo_cpus_bitmap[0]:0-7
[2016-10-07T20:46:15.373]   topo_gres_bitmap[0]:0-7
[2016-10-07T20:46:15.373]   topo_gres_cnt_alloc[0]:0
[2016-10-07T20:46:15.373]   topo_gres_cnt_avail[0]:8
[2016-10-07T20:46:15.373]   type[0]:tesla
[2016-10-07T20:46:15.373] gres/gpu: state for gpu-cluster-4
[2016-10-07T20:46:15.373]   gres_cnt found:8 configured:8 avail:8 alloc:3
[2016-10-07T20:46:15.373]   gres_bit_alloc:0,2,5
[2016-10-07T20:46:15.373]   gres_used:(null)
[2016-10-07T20:46:15.373]   topo_cpus_bitmap[0]:0-7
[2016-10-07T20:46:15.373]   topo_gres_bitmap[0]:0-7
[2016-10-07T20:46:15.373]   topo_gres_cnt_alloc[0]:0
[2016-10-07T20:46:15.373]   topo_gres_cnt_avail[0]:8
[2016-10-07T20:46:15.373]   type[0]:tesla
[2016-10-07T20:46:15.374] gres/gpu: state for gpu-cluster-2
[2016-10-07T20:46:15.374]   gres_cnt found:8 configured:8 avail:8 alloc:6
[2016-10-07T20:46:15.374]   gres_bit_alloc:2-7
[2016-10-07T20:46:15.374]   gres_used:(null)
[2016-10-07T20:46:15.374]   topo_cpus_bitmap[0]:0-7
[2016-10-07T20:46:15.374]   topo_gres_bitmap[0]:0-7
[2016-10-07T20:46:15.374]   topo_gres_cnt_alloc[0]:0
[2016-10-07T20:46:15.374]   topo_gres_cnt_avail[0]:8
[2016-10-07T20:46:15.374]   type[0]:tesla
[2016-10-07T20:53:37.285] job_complete: JobID=2015 State=0x1 NodeCnt=1 WEXITSTATUS 0
[2016-10-07T20:53:37.285] job end: job_id = 2015	time = 1475844817

[2016-10-07T20:53:37.285] job_complete: JobID=2015 State=0x8003 NodeCnt=1 done
[2016-10-07T20:56:10.968] job_complete: JobID=2025 State=0x1 NodeCnt=1 WEXITSTATUS 0
[2016-10-07T20:56:10.968] job end: job_id = 2025	time = 1475844970

[2016-10-07T20:56:10.968] job_complete: JobID=2025 State=0x8003 NodeCnt=1 done
[2016-10-07T20:56:19.929] job_complete: JobID=2026 State=0x1 NodeCnt=1 WEXITSTATUS 0
[2016-10-07T20:56:19.929] job end: job_id = 2026	time = 1475844979

[2016-10-07T20:56:19.929] job_complete: JobID=2026 State=0x8003 NodeCnt=1 done
[2016-10-07T21:19:35.179] gres/gpu: state for gpu-cluster-1
[2016-10-07T21:19:35.179]   gres_cnt found:8 configured:8 avail:8 alloc:0
[2016-10-07T21:19:35.179]   gres_bit_alloc:
[2016-10-07T21:19:35.179]   gres_used:(null)
[2016-10-07T21:19:35.179]   topo_cpus_bitmap[0]:0-7
[2016-10-07T21:19:35.179]   topo_gres_bitmap[0]:0-7
[2016-10-07T21:19:35.179]   topo_gres_cnt_alloc[0]:0
[2016-10-07T21:19:35.179]   topo_gres_cnt_avail[0]:8
[2016-10-07T21:19:35.179]   type[0]:tesla
[2016-10-07T21:19:35.180] gres/gpu: state for gpu-cluster-3
[2016-10-07T21:19:35.180]   gres_cnt found:8 configured:8 avail:8 alloc:0
[2016-10-07T21:19:35.180]   gres_bit_alloc:
[2016-10-07T21:19:35.180]   gres_used:(null)
[2016-10-07T21:19:35.180]   topo_cpus_bitmap[0]:0-7
[2016-10-07T21:19:35.180]   topo_gres_bitmap[0]:0-7
[2016-10-07T21:19:35.180]   topo_gres_cnt_alloc[0]:0
[2016-10-07T21:19:35.180]   topo_gres_cnt_avail[0]:8
[2016-10-07T21:19:35.180]   type[0]:tesla
[2016-10-07T21:19:35.180] gres/gpu: state for gpu-cluster-4
[2016-10-07T21:19:35.180]   gres_cnt found:8 configured:8 avail:8 alloc:0
[2016-10-07T21:19:35.180]   gres_bit_alloc:
[2016-10-07T21:19:35.180]   gres_used:(null)
[2016-10-07T21:19:35.180]   topo_cpus_bitmap[0]:0-7
[2016-10-07T21:19:35.180]   topo_gres_bitmap[0]:0-7
[2016-10-07T21:19:35.180]   topo_gres_cnt_alloc[0]:0
[2016-10-07T21:19:35.180]   topo_gres_cnt_avail[0]:8
[2016-10-07T21:19:35.180]   type[0]:tesla
[2016-10-07T21:19:35.180] gres/gpu: state for gpu-cluster-2
[2016-10-07T21:19:35.180]   gres_cnt found:8 configured:8 avail:8 alloc:0
[2016-10-07T21:19:35.180]   gres_bit_alloc:
[2016-10-07T21:19:35.180]   gres_used:(null)
[2016-10-07T21:19:35.180]   topo_cpus_bitmap[0]:0-7
[2016-10-07T21:19:35.181]   topo_gres_bitmap[0]:0-7
[2016-10-07T21:19:35.181]   topo_gres_cnt_alloc[0]:0
[2016-10-07T21:19:35.181]   topo_gres_cnt_avail[0]:8
[2016-10-07T21:19:35.181]   type[0]:tesla
[2016-10-07T21:52:55.715] gres/gpu: state for gpu-cluster-1
[2016-10-07T21:52:55.715]   gres_cnt found:8 configured:8 avail:8 alloc:0
[2016-10-07T21:52:55.715]   gres_bit_alloc:
[2016-10-07T21:52:55.715]   gres_used:(null)
[2016-10-07T21:52:55.716]   topo_cpus_bitmap[0]:0-7
[2016-10-07T21:52:55.716]   topo_gres_bitmap[0]:0-7
[2016-10-07T21:52:55.716]   topo_gres_cnt_alloc[0]:0
[2016-10-07T21:52:55.716]   topo_gres_cnt_avail[0]:8
[2016-10-07T21:52:55.716]   type[0]:tesla
[2016-10-07T21:52:55.716] gres/gpu: state for gpu-cluster-3
[2016-10-07T21:52:55.716]   gres_cnt found:8 configured:8 avail:8 alloc:0
[2016-10-07T21:52:55.716]   gres_bit_alloc:
[2016-10-07T21:52:55.716]   gres_used:(null)
[2016-10-07T21:52:55.716]   topo_cpus_bitmap[0]:0-7
[2016-10-07T21:52:55.716]   topo_gres_bitmap[0]:0-7
[2016-10-07T21:52:55.716]   topo_gres_cnt_alloc[0]:0
[2016-10-07T21:52:55.716]   topo_gres_cnt_avail[0]:8
[2016-10-07T21:52:55.716]   type[0]:tesla
[2016-10-07T21:52:55.716] gres/gpu: state for gpu-cluster-4
[2016-10-07T21:52:55.716]   gres_cnt found:8 configured:8 avail:8 alloc:0
[2016-10-07T21:52:55.716]   gres_bit_alloc:
[2016-10-07T21:52:55.716]   gres_used:(null)
[2016-10-07T21:52:55.716]   topo_cpus_bitmap[0]:0-7
[2016-10-07T21:52:55.716]   topo_gres_bitmap[0]:0-7
[2016-10-07T21:52:55.716]   topo_gres_cnt_alloc[0]:0
[2016-10-07T21:52:55.716]   topo_gres_cnt_avail[0]:8
[2016-10-07T21:52:55.716]   type[0]:tesla
[2016-10-07T21:52:55.716] gres/gpu: state for gpu-cluster-2
[2016-10-07T21:52:55.717]   gres_cnt found:8 configured:8 avail:8 alloc:0
[2016-10-07T21:52:55.717]   gres_bit_alloc:
[2016-10-07T21:52:55.717]   gres_used:(null)
[2016-10-07T21:52:55.717]   topo_cpus_bitmap[0]:0-7
[2016-10-07T21:52:55.717]   topo_gres_bitmap[0]:0-7
[2016-10-07T21:52:55.717]   topo_gres_cnt_alloc[0]:0
[2016-10-07T21:52:55.717]   topo_gres_cnt_avail[0]:8
[2016-10-07T21:52:55.717]   type[0]:tesla
[2016-10-07T22:26:15.499] gres/gpu: state for gpu-cluster-1
[2016-10-07T22:26:15.499]   gres_cnt found:8 configured:8 avail:8 alloc:0
[2016-10-07T22:26:15.499]   gres_bit_alloc:
[2016-10-07T22:26:15.499]   gres_used:(null)
[2016-10-07T22:26:15.499]   topo_cpus_bitmap[0]:0-7
[2016-10-07T22:26:15.499]   topo_gres_bitmap[0]:0-7
[2016-10-07T22:26:15.499]   topo_gres_cnt_alloc[0]:0
[2016-10-07T22:26:15.499]   topo_gres_cnt_avail[0]:8
[2016-10-07T22:26:15.499]   type[0]:tesla
[2016-10-07T22:26:15.500] gres/gpu: state for gpu-cluster-3
[2016-10-07T22:26:15.500]   gres_cnt found:8 configured:8 avail:8 alloc:0
[2016-10-07T22:26:15.500]   gres_bit_alloc:
[2016-10-07T22:26:15.500]   gres_used:(null)
[2016-10-07T22:26:15.500]   topo_cpus_bitmap[0]:0-7
[2016-10-07T22:26:15.500]   topo_gres_bitmap[0]:0-7
[2016-10-07T22:26:15.500]   topo_gres_cnt_alloc[0]:0
[2016-10-07T22:26:15.500]   topo_gres_cnt_avail[0]:8
[2016-10-07T22:26:15.500]   type[0]:tesla
[2016-10-07T22:26:15.500] gres/gpu: state for gpu-cluster-4
[2016-10-07T22:26:15.500]   gres_cnt found:8 configured:8 avail:8 alloc:0
[2016-10-07T22:26:15.500]   gres_bit_alloc:
[2016-10-07T22:26:15.500]   gres_used:(null)
[2016-10-07T22:26:15.500]   topo_cpus_bitmap[0]:0-7
[2016-10-07T22:26:15.500]   topo_gres_bitmap[0]:0-7
[2016-10-07T22:26:15.500]   topo_gres_cnt_alloc[0]:0
[2016-10-07T22:26:15.500]   topo_gres_cnt_avail[0]:8
[2016-10-07T22:26:15.500]   type[0]:tesla
[2016-10-07T22:26:15.501] gres/gpu: state for gpu-cluster-2
[2016-10-07T22:26:15.501]   gres_cnt found:8 configured:8 avail:8 alloc:0
[2016-10-07T22:26:15.501]   gres_bit_alloc:
[2016-10-07T22:26:15.501]   gres_used:(null)
[2016-10-07T22:26:15.501]   topo_cpus_bitmap[0]:0-7
[2016-10-07T22:26:15.501]   topo_gres_bitmap[0]:0-7
[2016-10-07T22:26:15.501]   topo_gres_cnt_alloc[0]:0
[2016-10-07T22:26:15.501]   topo_gres_cnt_avail[0]:8
[2016-10-07T22:26:15.501]   type[0]:tesla
[2016-10-07T22:59:35.280] gres/gpu: state for gpu-cluster-1
[2016-10-07T22:59:35.280]   gres_cnt found:8 configured:8 avail:8 alloc:0
[2016-10-07T22:59:35.280]   gres_bit_alloc:
[2016-10-07T22:59:35.280]   gres_used:(null)
[2016-10-07T22:59:35.280]   topo_cpus_bitmap[0]:0-7
[2016-10-07T22:59:35.280]   topo_gres_bitmap[0]:0-7
[2016-10-07T22:59:35.280]   topo_gres_cnt_alloc[0]:0
[2016-10-07T22:59:35.280]   topo_gres_cnt_avail[0]:8
[2016-10-07T22:59:35.280]   type[0]:tesla
[2016-10-07T22:59:35.280] gres/gpu: state for gpu-cluster-3
[2016-10-07T22:59:35.280]   gres_cnt found:8 configured:8 avail:8 alloc:0
[2016-10-07T22:59:35.280]   gres_bit_alloc:
[2016-10-07T22:59:35.280]   gres_used:(null)
[2016-10-07T22:59:35.280]   topo_cpus_bitmap[0]:0-7
[2016-10-07T22:59:35.280]   topo_gres_bitmap[0]:0-7
[2016-10-07T22:59:35.280]   topo_gres_cnt_alloc[0]:0
[2016-10-07T22:59:35.281]   topo_gres_cnt_avail[0]:8
[2016-10-07T22:59:35.281]   type[0]:tesla
[2016-10-07T22:59:35.281] gres/gpu: state for gpu-cluster-2
[2016-10-07T22:59:35.281]   gres_cnt found:8 configured:8 avail:8 alloc:0
[2016-10-07T22:59:35.281]   gres_bit_alloc:
[2016-10-07T22:59:35.281]   gres_used:(null)
[2016-10-07T22:59:35.281]   topo_cpus_bitmap[0]:0-7
[2016-10-07T22:59:35.281]   topo_gres_bitmap[0]:0-7
[2016-10-07T22:59:35.281]   topo_gres_cnt_alloc[0]:0
[2016-10-07T22:59:35.281]   topo_gres_cnt_avail[0]:8
[2016-10-07T22:59:35.281]   type[0]:tesla
[2016-10-07T22:59:35.281] gres/gpu: state for gpu-cluster-4
[2016-10-07T22:59:35.281]   gres_cnt found:8 configured:8 avail:8 alloc:0
[2016-10-07T22:59:35.281]   gres_bit_alloc:
[2016-10-07T22:59:35.281]   gres_used:(null)
[2016-10-07T22:59:35.281]   topo_cpus_bitmap[0]:0-7
[2016-10-07T22:59:35.281]   topo_gres_bitmap[0]:0-7
[2016-10-07T22:59:35.281]   topo_gres_cnt_alloc[0]:0
[2016-10-07T22:59:35.281]   topo_gres_cnt_avail[0]:8
[2016-10-07T22:59:35.281]   type[0]:tesla
[2016-10-07T23:32:55.822] gres/gpu: state for gpu-cluster-1
[2016-10-07T23:32:55.822]   gres_cnt found:8 configured:8 avail:8 alloc:0
[2016-10-07T23:32:55.822]   gres_bit_alloc:
[2016-10-07T23:32:55.822]   gres_used:(null)
[2016-10-07T23:32:55.822]   topo_cpus_bitmap[0]:0-7
[2016-10-07T23:32:55.822]   topo_gres_bitmap[0]:0-7
[2016-10-07T23:32:55.822]   topo_gres_cnt_alloc[0]:0
[2016-10-07T23:32:55.823]   topo_gres_cnt_avail[0]:8
[2016-10-07T23:32:55.823]   type[0]:tesla
[2016-10-07T23:32:55.823] gres/gpu: state for gpu-cluster-3
[2016-10-07T23:32:55.823]   gres_cnt found:8 configured:8 avail:8 alloc:0
[2016-10-07T23:32:55.823]   gres_bit_alloc:
[2016-10-07T23:32:55.823]   gres_used:(null)
[2016-10-07T23:32:55.823]   topo_cpus_bitmap[0]:0-7
[2016-10-07T23:32:55.823]   topo_gres_bitmap[0]:0-7
[2016-10-07T23:32:55.823]   topo_gres_cnt_alloc[0]:0
[2016-10-07T23:32:55.823]   topo_gres_cnt_avail[0]:8
[2016-10-07T23:32:55.823]   type[0]:tesla
[2016-10-07T23:32:55.823] gres/gpu: state for gpu-cluster-2
[2016-10-07T23:32:55.823]   gres_cnt found:8 configured:8 avail:8 alloc:0
[2016-10-07T23:32:55.823]   gres_bit_alloc:
[2016-10-07T23:32:55.823]   gres_used:(null)
[2016-10-07T23:32:55.823]   topo_cpus_bitmap[0]:0-7
[2016-10-07T23:32:55.823]   topo_gres_bitmap[0]:0-7
[2016-10-07T23:32:55.823]   topo_gres_cnt_alloc[0]:0
[2016-10-07T23:32:55.824]   topo_gres_cnt_avail[0]:8
[2016-10-07T23:32:55.824]   type[0]:tesla
[2016-10-07T23:32:55.824] gres/gpu: state for gpu-cluster-4
[2016-10-07T23:32:55.824]   gres_cnt found:8 configured:8 avail:8 alloc:0
[2016-10-07T23:32:55.824]   gres_bit_alloc:
[2016-10-07T23:32:55.824]   gres_used:(null)
[2016-10-07T23:32:55.824]   topo_cpus_bitmap[0]:0-7
[2016-10-07T23:32:55.824]   topo_gres_bitmap[0]:0-7
[2016-10-07T23:32:55.824]   topo_gres_cnt_alloc[0]:0
[2016-10-07T23:32:55.824]   topo_gres_cnt_avail[0]:8
[2016-10-07T23:32:55.824]   type[0]:tesla
[2016-10-08T00:06:15.614] gres/gpu: state for gpu-cluster-1
[2016-10-08T00:06:15.614]   gres_cnt found:8 configured:8 avail:8 alloc:0
[2016-10-08T00:06:15.614]   gres_bit_alloc:
[2016-10-08T00:06:15.614]   gres_used:(null)
[2016-10-08T00:06:15.614]   topo_cpus_bitmap[0]:0-7
[2016-10-08T00:06:15.614]   topo_gres_bitmap[0]:0-7
[2016-10-08T00:06:15.614]   topo_gres_cnt_alloc[0]:0
[2016-10-08T00:06:15.614]   topo_gres_cnt_avail[0]:8
[2016-10-08T00:06:15.614]   type[0]:tesla
[2016-10-08T00:06:15.614] gres/gpu: state for gpu-cluster-3
[2016-10-08T00:06:15.615]   gres_cnt found:8 configured:8 avail:8 alloc:0
[2016-10-08T00:06:15.615]   gres_bit_alloc:
[2016-10-08T00:06:15.615]   gres_used:(null)
[2016-10-08T00:06:15.615]   topo_cpus_bitmap[0]:0-7
[2016-10-08T00:06:15.615]   topo_gres_bitmap[0]:0-7
[2016-10-08T00:06:15.615]   topo_gres_cnt_alloc[0]:0
[2016-10-08T00:06:15.615]   topo_gres_cnt_avail[0]:8
[2016-10-08T00:06:15.615]   type[0]:tesla
[2016-10-08T00:06:15.615] gres/gpu: state for gpu-cluster-2
[2016-10-08T00:06:15.615]   gres_cnt found:8 configured:8 avail:8 alloc:0
[2016-10-08T00:06:15.615]   gres_bit_alloc:
[2016-10-08T00:06:15.615]   gres_used:(null)
[2016-10-08T00:06:15.615]   topo_cpus_bitmap[0]:0-7
[2016-10-08T00:06:15.615]   topo_gres_bitmap[0]:0-7
[2016-10-08T00:06:15.615]   topo_gres_cnt_alloc[0]:0
[2016-10-08T00:06:15.615]   topo_gres_cnt_avail[0]:8
[2016-10-08T00:06:15.615]   type[0]:tesla
[2016-10-08T00:06:15.615] gres/gpu: state for gpu-cluster-4
[2016-10-08T00:06:15.615]   gres_cnt found:8 configured:8 avail:8 alloc:0
[2016-10-08T00:06:15.615]   gres_bit_alloc:
[2016-10-08T00:06:15.615]   gres_used:(null)
[2016-10-08T00:06:15.615]   topo_cpus_bitmap[0]:0-7
[2016-10-08T00:06:15.615]   topo_gres_bitmap[0]:0-7
[2016-10-08T00:06:15.615]   topo_gres_cnt_alloc[0]:0
[2016-10-08T00:06:15.615]   topo_gres_cnt_avail[0]:8
[2016-10-08T00:06:15.615]   type[0]:tesla
[2016-10-08T00:39:35.402] gres/gpu: state for gpu-cluster-1
[2016-10-08T00:39:35.402]   gres_cnt found:8 configured:8 avail:8 alloc:0
[2016-10-08T00:39:35.402]   gres_bit_alloc:
[2016-10-08T00:39:35.402]   gres_used:(null)
[2016-10-08T00:39:35.402]   topo_cpus_bitmap[0]:0-7
[2016-10-08T00:39:35.402]   topo_gres_bitmap[0]:0-7
[2016-10-08T00:39:35.402]   topo_gres_cnt_alloc[0]:0
[2016-10-08T00:39:35.402]   topo_gres_cnt_avail[0]:8
[2016-10-08T00:39:35.402]   type[0]:tesla
[2016-10-08T00:39:35.403] gres/gpu: state for gpu-cluster-3
[2016-10-08T00:39:35.403]   gres_cnt found:8 configured:8 avail:8 alloc:0
[2016-10-08T00:39:35.403]   gres_bit_alloc:
[2016-10-08T00:39:35.403]   gres_used:(null)
[2016-10-08T00:39:35.403]   topo_cpus_bitmap[0]:0-7
[2016-10-08T00:39:35.403]   topo_gres_bitmap[0]:0-7
[2016-10-08T00:39:35.403]   topo_gres_cnt_alloc[0]:0
[2016-10-08T00:39:35.403]   topo_gres_cnt_avail[0]:8
[2016-10-08T00:39:35.403]   type[0]:tesla
[2016-10-08T00:39:35.403] gres/gpu: state for gpu-cluster-4
[2016-10-08T00:39:35.403]   gres_cnt found:8 configured:8 avail:8 alloc:0
[2016-10-08T00:39:35.403]   gres_bit_alloc:
[2016-10-08T00:39:35.403]   gres_used:(null)
[2016-10-08T00:39:35.403]   topo_cpus_bitmap[0]:0-7
[2016-10-08T00:39:35.403]   topo_gres_bitmap[0]:0-7
[2016-10-08T00:39:35.403]   topo_gres_cnt_alloc[0]:0
[2016-10-08T00:39:35.403]   topo_gres_cnt_avail[0]:8
[2016-10-08T00:39:35.403]   type[0]:tesla
[2016-10-08T00:39:35.403] gres/gpu: state for gpu-cluster-2
[2016-10-08T00:39:35.403]   gres_cnt found:8 configured:8 avail:8 alloc:0
[2016-10-08T00:39:35.403]   gres_bit_alloc:
[2016-10-08T00:39:35.403]   gres_used:(null)
[2016-10-08T00:39:35.403]   topo_cpus_bitmap[0]:0-7
[2016-10-08T00:39:35.403]   topo_gres_bitmap[0]:0-7
[2016-10-08T00:39:35.403]   topo_gres_cnt_alloc[0]:0
[2016-10-08T00:39:35.403]   topo_gres_cnt_avail[0]:8
[2016-10-08T00:39:35.403]   type[0]:tesla
[2016-10-08T01:12:55.948] gres/gpu: state for gpu-cluster-1
[2016-10-08T01:12:55.948]   gres_cnt found:8 configured:8 avail:8 alloc:0
[2016-10-08T01:12:55.948]   gres_bit_alloc:
[2016-10-08T01:12:55.948]   gres_used:(null)
[2016-10-08T01:12:55.948]   topo_cpus_bitmap[0]:0-7
[2016-10-08T01:12:55.948]   topo_gres_bitmap[0]:0-7
[2016-10-08T01:12:55.948]   topo_gres_cnt_alloc[0]:0
[2016-10-08T01:12:55.948]   topo_gres_cnt_avail[0]:8
[2016-10-08T01:12:55.948]   type[0]:tesla
[2016-10-08T01:12:55.948] gres/gpu: state for gpu-cluster-2
[2016-10-08T01:12:55.948]   gres_cnt found:8 configured:8 avail:8 alloc:0
[2016-10-08T01:12:55.948]   gres_bit_alloc:
[2016-10-08T01:12:55.948]   gres_used:(null)
[2016-10-08T01:12:55.948]   topo_cpus_bitmap[0]:0-7
[2016-10-08T01:12:55.949]   topo_gres_bitmap[0]:0-7
[2016-10-08T01:12:55.949]   topo_gres_cnt_alloc[0]:0
[2016-10-08T01:12:55.949]   topo_gres_cnt_avail[0]:8
[2016-10-08T01:12:55.949]   type[0]:tesla
[2016-10-08T01:12:55.949] gres/gpu: state for gpu-cluster-4
[2016-10-08T01:12:55.949]   gres_cnt found:8 configured:8 avail:8 alloc:0
[2016-10-08T01:12:55.949]   gres_bit_alloc:
[2016-10-08T01:12:55.949]   gres_used:(null)
[2016-10-08T01:12:55.949]   topo_cpus_bitmap[0]:0-7
[2016-10-08T01:12:55.949]   topo_gres_bitmap[0]:0-7
[2016-10-08T01:12:55.949]   topo_gres_cnt_alloc[0]:0
[2016-10-08T01:12:55.949]   topo_gres_cnt_avail[0]:8
[2016-10-08T01:12:55.949]   type[0]:tesla
[2016-10-08T01:12:55.949] gres/gpu: state for gpu-cluster-3
[2016-10-08T01:12:55.949]   gres_cnt found:8 configured:8 avail:8 alloc:0
[2016-10-08T01:12:55.949]   gres_bit_alloc:
[2016-10-08T01:12:55.949]   gres_used:(null)
[2016-10-08T01:12:55.949]   topo_cpus_bitmap[0]:0-7
[2016-10-08T01:12:55.949]   topo_gres_bitmap[0]:0-7
[2016-10-08T01:12:55.949]   topo_gres_cnt_alloc[0]:0
[2016-10-08T01:12:55.949]   topo_gres_cnt_avail[0]:8
[2016-10-08T01:12:55.949]   type[0]:tesla
[2016-10-08T01:46:15.760] gres/gpu: state for gpu-cluster-1
[2016-10-08T01:46:15.760]   gres_cnt found:8 configured:8 avail:8 alloc:0
[2016-10-08T01:46:15.760]   gres_bit_alloc:
[2016-10-08T01:46:15.760]   gres_used:(null)
[2016-10-08T01:46:15.760]   topo_cpus_bitmap[0]:0-7
[2016-10-08T01:46:15.760]   topo_gres_bitmap[0]:0-7
[2016-10-08T01:46:15.760]   topo_gres_cnt_alloc[0]:0
[2016-10-08T01:46:15.760]   topo_gres_cnt_avail[0]:8
[2016-10-08T01:46:15.760]   type[0]:tesla
[2016-10-08T01:46:15.760] gres/gpu: state for gpu-cluster-3
[2016-10-08T01:46:15.760]   gres_cnt found:8 configured:8 avail:8 alloc:0
[2016-10-08T01:46:15.760]   gres_bit_alloc:
[2016-10-08T01:46:15.760]   gres_used:(null)
[2016-10-08T01:46:15.760]   topo_cpus_bitmap[0]:0-7
[2016-10-08T01:46:15.760]   topo_gres_bitmap[0]:0-7
[2016-10-08T01:46:15.760]   topo_gres_cnt_alloc[0]:0
[2016-10-08T01:46:15.760]   topo_gres_cnt_avail[0]:8
[2016-10-08T01:46:15.760]   type[0]:tesla
[2016-10-08T01:46:15.761] gres/gpu: state for gpu-cluster-4
[2016-10-08T01:46:15.761]   gres_cnt found:8 configured:8 avail:8 alloc:0
[2016-10-08T01:46:15.761]   gres_bit_alloc:
[2016-10-08T01:46:15.761]   gres_used:(null)
[2016-10-08T01:46:15.761]   topo_cpus_bitmap[0]:0-7
[2016-10-08T01:46:15.761]   topo_gres_bitmap[0]:0-7
[2016-10-08T01:46:15.761]   topo_gres_cnt_alloc[0]:0
[2016-10-08T01:46:15.761]   topo_gres_cnt_avail[0]:8
[2016-10-08T01:46:15.761]   type[0]:tesla
[2016-10-08T01:46:15.761] gres/gpu: state for gpu-cluster-2
[2016-10-08T01:46:15.761]   gres_cnt found:8 configured:8 avail:8 alloc:0
[2016-10-08T01:46:15.761]   gres_bit_alloc:
[2016-10-08T01:46:15.761]   gres_used:(null)
[2016-10-08T01:46:15.761]   topo_cpus_bitmap[0]:0-7
[2016-10-08T01:46:15.761]   topo_gres_bitmap[0]:0-7
[2016-10-08T01:46:15.761]   topo_gres_cnt_alloc[0]:0
[2016-10-08T01:46:15.761]   topo_gres_cnt_avail[0]:8
[2016-10-08T01:46:15.761]   type[0]:tesla
[2016-10-08T02:19:35.550] gres/gpu: state for gpu-cluster-1
[2016-10-08T02:19:35.550]   gres_cnt found:8 configured:8 avail:8 alloc:0
[2016-10-08T02:19:35.550]   gres_bit_alloc:
[2016-10-08T02:19:35.550]   gres_used:(null)
[2016-10-08T02:19:35.550]   topo_cpus_bitmap[0]:0-7
[2016-10-08T02:19:35.550]   topo_gres_bitmap[0]:0-7
[2016-10-08T02:19:35.550]   topo_gres_cnt_alloc[0]:0
[2016-10-08T02:19:35.550]   topo_gres_cnt_avail[0]:8
[2016-10-08T02:19:35.550]   type[0]:tesla
[2016-10-08T02:19:35.550] gres/gpu: state for gpu-cluster-3
[2016-10-08T02:19:35.550]   gres_cnt found:8 configured:8 avail:8 alloc:0
[2016-10-08T02:19:35.550]   gres_bit_alloc:
[2016-10-08T02:19:35.550]   gres_used:(null)
[2016-10-08T02:19:35.550]   topo_cpus_bitmap[0]:0-7
[2016-10-08T02:19:35.551]   topo_gres_bitmap[0]:0-7
[2016-10-08T02:19:35.551]   topo_gres_cnt_alloc[0]:0
[2016-10-08T02:19:35.551]   topo_gres_cnt_avail[0]:8
[2016-10-08T02:19:35.551]   type[0]:tesla
[2016-10-08T02:19:35.551] gres/gpu: state for gpu-cluster-2
[2016-10-08T02:19:35.551]   gres_cnt found:8 configured:8 avail:8 alloc:0
[2016-10-08T02:19:35.551]   gres_bit_alloc:
[2016-10-08T02:19:35.551]   gres_used:(null)
[2016-10-08T02:19:35.551]   topo_cpus_bitmap[0]:0-7
[2016-10-08T02:19:35.551]   topo_gres_bitmap[0]:0-7
[2016-10-08T02:19:35.551]   topo_gres_cnt_alloc[0]:0
[2016-10-08T02:19:35.551]   topo_gres_cnt_avail[0]:8
[2016-10-08T02:19:35.551]   type[0]:tesla
[2016-10-08T02:19:35.551] gres/gpu: state for gpu-cluster-4
[2016-10-08T02:19:35.551]   gres_cnt found:8 configured:8 avail:8 alloc:0
[2016-10-08T02:19:35.551]   gres_bit_alloc:
[2016-10-08T02:19:35.551]   gres_used:(null)
[2016-10-08T02:19:35.551]   topo_cpus_bitmap[0]:0-7
[2016-10-08T02:19:35.551]   topo_gres_bitmap[0]:0-7
[2016-10-08T02:19:35.551]   topo_gres_cnt_alloc[0]:0
[2016-10-08T02:19:35.551]   topo_gres_cnt_avail[0]:8
[2016-10-08T02:19:35.551]   type[0]:tesla
[2016-10-08T02:52:55.100] gres/gpu: state for gpu-cluster-1
[2016-10-08T02:52:55.100]   gres_cnt found:8 configured:8 avail:8 alloc:0
[2016-10-08T02:52:55.100]   gres_bit_alloc:
[2016-10-08T02:52:55.100]   gres_used:(null)
[2016-10-08T02:52:55.100]   topo_cpus_bitmap[0]:0-7
[2016-10-08T02:52:55.100]   topo_gres_bitmap[0]:0-7
[2016-10-08T02:52:55.100]   topo_gres_cnt_alloc[0]:0
[2016-10-08T02:52:55.100]   topo_gres_cnt_avail[0]:8
[2016-10-08T02:52:55.100]   type[0]:tesla
[2016-10-08T02:52:55.100] gres/gpu: state for gpu-cluster-3
[2016-10-08T02:52:55.100]   gres_cnt found:8 configured:8 avail:8 alloc:0
[2016-10-08T02:52:55.100]   gres_bit_alloc:
[2016-10-08T02:52:55.100]   gres_used:(null)
[2016-10-08T02:52:55.100]   topo_cpus_bitmap[0]:0-7
[2016-10-08T02:52:55.101]   topo_gres_bitmap[0]:0-7
[2016-10-08T02:52:55.101]   topo_gres_cnt_alloc[0]:0
[2016-10-08T02:52:55.101]   topo_gres_cnt_avail[0]:8
[2016-10-08T02:52:55.101]   type[0]:tesla
[2016-10-08T02:52:55.101] gres/gpu: state for gpu-cluster-4
[2016-10-08T02:52:55.101]   gres_cnt found:8 configured:8 avail:8 alloc:0
[2016-10-08T02:52:55.101]   gres_bit_alloc:
[2016-10-08T02:52:55.101]   gres_used:(null)
[2016-10-08T02:52:55.101]   topo_cpus_bitmap[0]:0-7
[2016-10-08T02:52:55.101]   topo_gres_bitmap[0]:0-7
[2016-10-08T02:52:55.101]   topo_gres_cnt_alloc[0]:0
[2016-10-08T02:52:55.101]   topo_gres_cnt_avail[0]:8
[2016-10-08T02:52:55.101]   type[0]:tesla
[2016-10-08T02:52:55.101] gres/gpu: state for gpu-cluster-2
[2016-10-08T02:52:55.101]   gres_cnt found:8 configured:8 avail:8 alloc:0
[2016-10-08T02:52:55.101]   gres_bit_alloc:
[2016-10-08T02:52:55.101]   gres_used:(null)
[2016-10-08T02:52:55.101]   topo_cpus_bitmap[0]:0-7
[2016-10-08T02:52:55.101]   topo_gres_bitmap[0]:0-7
[2016-10-08T02:52:55.101]   topo_gres_cnt_alloc[0]:0
[2016-10-08T02:52:55.101]   topo_gres_cnt_avail[0]:8
[2016-10-08T02:52:55.101]   type[0]:tesla
[2016-10-08T03:26:15.909] gres/gpu: state for gpu-cluster-1
[2016-10-08T03:26:15.909]   gres_cnt found:8 configured:8 avail:8 alloc:0
[2016-10-08T03:26:15.909]   gres_bit_alloc:
[2016-10-08T03:26:15.909]   gres_used:(null)
[2016-10-08T03:26:15.909]   topo_cpus_bitmap[0]:0-7
[2016-10-08T03:26:15.909]   topo_gres_bitmap[0]:0-7
[2016-10-08T03:26:15.909]   topo_gres_cnt_alloc[0]:0
[2016-10-08T03:26:15.909]   topo_gres_cnt_avail[0]:8
[2016-10-08T03:26:15.909]   type[0]:tesla
[2016-10-08T03:26:15.909] gres/gpu: state for gpu-cluster-3
[2016-10-08T03:26:15.909]   gres_cnt found:8 configured:8 avail:8 alloc:0
[2016-10-08T03:26:15.909]   gres_bit_alloc:
[2016-10-08T03:26:15.909]   gres_used:(null)
[2016-10-08T03:26:15.910]   topo_cpus_bitmap[0]:0-7
[2016-10-08T03:26:15.910]   topo_gres_bitmap[0]:0-7
[2016-10-08T03:26:15.910]   topo_gres_cnt_alloc[0]:0
[2016-10-08T03:26:15.910]   topo_gres_cnt_avail[0]:8
[2016-10-08T03:26:15.910]   type[0]:tesla
[2016-10-08T03:26:15.910] gres/gpu: state for gpu-cluster-4
[2016-10-08T03:26:15.910]   gres_cnt found:8 configured:8 avail:8 alloc:0
[2016-10-08T03:26:15.910]   gres_bit_alloc:
[2016-10-08T03:26:15.910]   gres_used:(null)
[2016-10-08T03:26:15.910]   topo_cpus_bitmap[0]:0-7
[2016-10-08T03:26:15.910]   topo_gres_bitmap[0]:0-7
[2016-10-08T03:26:15.910]   topo_gres_cnt_alloc[0]:0
[2016-10-08T03:26:15.910]   topo_gres_cnt_avail[0]:8
[2016-10-08T03:26:15.910]   type[0]:tesla
[2016-10-08T03:26:15.910] gres/gpu: state for gpu-cluster-2
[2016-10-08T03:26:15.910]   gres_cnt found:8 configured:8 avail:8 alloc:0
[2016-10-08T03:26:15.910]   gres_bit_alloc:
[2016-10-08T03:26:15.910]   gres_used:(null)
[2016-10-08T03:26:15.910]   topo_cpus_bitmap[0]:0-7
[2016-10-08T03:26:15.910]   topo_gres_bitmap[0]:0-7
[2016-10-08T03:26:15.910]   topo_gres_cnt_alloc[0]:0
[2016-10-08T03:26:15.910]   topo_gres_cnt_avail[0]:8
[2016-10-08T03:26:15.910]   type[0]:tesla
[2016-10-08T03:59:35.708] gres/gpu: state for gpu-cluster-1
[2016-10-08T03:59:35.708]   gres_cnt found:8 configured:8 avail:8 alloc:0
[2016-10-08T03:59:35.708]   gres_bit_alloc:
[2016-10-08T03:59:35.708]   gres_used:(null)
[2016-10-08T03:59:35.708]   topo_cpus_bitmap[0]:0-7
[2016-10-08T03:59:35.708]   topo_gres_bitmap[0]:0-7
[2016-10-08T03:59:35.708]   topo_gres_cnt_alloc[0]:0
[2016-10-08T03:59:35.708]   topo_gres_cnt_avail[0]:8
[2016-10-08T03:59:35.708]   type[0]:tesla
[2016-10-08T03:59:35.709] gres/gpu: state for gpu-cluster-3
[2016-10-08T03:59:35.709]   gres_cnt found:8 configured:8 avail:8 alloc:0
[2016-10-08T03:59:35.709]   gres_bit_alloc:
[2016-10-08T03:59:35.709]   gres_used:(null)
[2016-10-08T03:59:35.709]   topo_cpus_bitmap[0]:0-7
[2016-10-08T03:59:35.709]   topo_gres_bitmap[0]:0-7
[2016-10-08T03:59:35.709]   topo_gres_cnt_alloc[0]:0
[2016-10-08T03:59:35.709]   topo_gres_cnt_avail[0]:8
[2016-10-08T03:59:35.709]   type[0]:tesla
[2016-10-08T03:59:35.709] gres/gpu: state for gpu-cluster-4
[2016-10-08T03:59:35.709]   gres_cnt found:8 configured:8 avail:8 alloc:0
[2016-10-08T03:59:35.709]   gres_bit_alloc:
[2016-10-08T03:59:35.709]   gres_used:(null)
[2016-10-08T03:59:35.709]   topo_cpus_bitmap[0]:0-7
[2016-10-08T03:59:35.709]   topo_gres_bitmap[0]:0-7
[2016-10-08T03:59:35.709]   topo_gres_cnt_alloc[0]:0
[2016-10-08T03:59:35.709]   topo_gres_cnt_avail[0]:8
[2016-10-08T03:59:35.709]   type[0]:tesla
[2016-10-08T03:59:35.710] gres/gpu: state for gpu-cluster-2
[2016-10-08T03:59:35.710]   gres_cnt found:8 configured:8 avail:8 alloc:0
[2016-10-08T03:59:35.710]   gres_bit_alloc:
[2016-10-08T03:59:35.710]   gres_used:(null)
[2016-10-08T03:59:35.710]   topo_cpus_bitmap[0]:0-7
[2016-10-08T03:59:35.710]   topo_gres_bitmap[0]:0-7
[2016-10-08T03:59:35.710]   topo_gres_cnt_alloc[0]:0
[2016-10-08T03:59:35.710]   topo_gres_cnt_avail[0]:8
[2016-10-08T03:59:35.710]   type[0]:tesla
[2016-10-08T04:32:55.274] gres/gpu: state for gpu-cluster-1
[2016-10-08T04:32:55.274]   gres_cnt found:8 configured:8 avail:8 alloc:0
[2016-10-08T04:32:55.274]   gres_bit_alloc:
[2016-10-08T04:32:55.274]   gres_used:(null)
[2016-10-08T04:32:55.274]   topo_cpus_bitmap[0]:0-7
[2016-10-08T04:32:55.274]   topo_gres_bitmap[0]:0-7
[2016-10-08T04:32:55.274]   topo_gres_cnt_alloc[0]:0
[2016-10-08T04:32:55.274]   topo_gres_cnt_avail[0]:8
[2016-10-08T04:32:55.274]   type[0]:tesla
[2016-10-08T04:32:55.274] gres/gpu: state for gpu-cluster-3
[2016-10-08T04:32:55.274]   gres_cnt found:8 configured:8 avail:8 alloc:0
[2016-10-08T04:32:55.274]   gres_bit_alloc:
[2016-10-08T04:32:55.274]   gres_used:(null)
[2016-10-08T04:32:55.274]   topo_cpus_bitmap[0]:0-7
[2016-10-08T04:32:55.274]   topo_gres_bitmap[0]:0-7
[2016-10-08T04:32:55.275]   topo_gres_cnt_alloc[0]:0
[2016-10-08T04:32:55.275]   topo_gres_cnt_avail[0]:8
[2016-10-08T04:32:55.275]   type[0]:tesla
[2016-10-08T04:32:55.275] gres/gpu: state for gpu-cluster-2
[2016-10-08T04:32:55.275]   gres_cnt found:8 configured:8 avail:8 alloc:0
[2016-10-08T04:32:55.275]   gres_bit_alloc:
[2016-10-08T04:32:55.275]   gres_used:(null)
[2016-10-08T04:32:55.275]   topo_cpus_bitmap[0]:0-7
[2016-10-08T04:32:55.275]   topo_gres_bitmap[0]:0-7
[2016-10-08T04:32:55.275]   topo_gres_cnt_alloc[0]:0
[2016-10-08T04:32:55.275]   topo_gres_cnt_avail[0]:8
[2016-10-08T04:32:55.275]   type[0]:tesla
[2016-10-08T04:32:55.275] gres/gpu: state for gpu-cluster-4
[2016-10-08T04:32:55.275]   gres_cnt found:8 configured:8 avail:8 alloc:0
[2016-10-08T04:32:55.275]   gres_bit_alloc:
[2016-10-08T04:32:55.275]   gres_used:(null)
[2016-10-08T04:32:55.275]   topo_cpus_bitmap[0]:0-7
[2016-10-08T04:32:55.275]   topo_gres_bitmap[0]:0-7
[2016-10-08T04:32:55.275]   topo_gres_cnt_alloc[0]:0
[2016-10-08T04:32:55.275]   topo_gres_cnt_avail[0]:8
[2016-10-08T04:32:55.275]   type[0]:tesla
[2016-10-08T05:06:15.057] gres/gpu: state for gpu-cluster-1
[2016-10-08T05:06:15.057]   gres_cnt found:8 configured:8 avail:8 alloc:0
[2016-10-08T05:06:15.057]   gres_bit_alloc:
[2016-10-08T05:06:15.057]   gres_used:(null)
[2016-10-08T05:06:15.057]   topo_cpus_bitmap[0]:0-7
[2016-10-08T05:06:15.057]   topo_gres_bitmap[0]:0-7
[2016-10-08T05:06:15.057]   topo_gres_cnt_alloc[0]:0
[2016-10-08T05:06:15.057]   topo_gres_cnt_avail[0]:8
[2016-10-08T05:06:15.057]   type[0]:tesla
[2016-10-08T05:06:15.057] gres/gpu: state for gpu-cluster-3
[2016-10-08T05:06:15.057]   gres_cnt found:8 configured:8 avail:8 alloc:0
[2016-10-08T05:06:15.058]   gres_bit_alloc:
[2016-10-08T05:06:15.058]   gres_used:(null)
[2016-10-08T05:06:15.058]   topo_cpus_bitmap[0]:0-7
[2016-10-08T05:06:15.058]   topo_gres_bitmap[0]:0-7
[2016-10-08T05:06:15.058]   topo_gres_cnt_alloc[0]:0
[2016-10-08T05:06:15.058]   topo_gres_cnt_avail[0]:8
[2016-10-08T05:06:15.058]   type[0]:tesla
[2016-10-08T05:06:15.058] gres/gpu: state for gpu-cluster-4
[2016-10-08T05:06:15.058]   gres_cnt found:8 configured:8 avail:8 alloc:0
[2016-10-08T05:06:15.058]   gres_bit_alloc:
[2016-10-08T05:06:15.058]   gres_used:(null)
[2016-10-08T05:06:15.058]   topo_cpus_bitmap[0]:0-7
[2016-10-08T05:06:15.058]   topo_gres_bitmap[0]:0-7
[2016-10-08T05:06:15.058]   topo_gres_cnt_alloc[0]:0
[2016-10-08T05:06:15.058]   topo_gres_cnt_avail[0]:8
[2016-10-08T05:06:15.058]   type[0]:tesla
[2016-10-08T05:06:15.058] gres/gpu: state for gpu-cluster-2
[2016-10-08T05:06:15.058]   gres_cnt found:8 configured:8 avail:8 alloc:0
[2016-10-08T05:06:15.058]   gres_bit_alloc:
[2016-10-08T05:06:15.058]   gres_used:(null)
[2016-10-08T05:06:15.058]   topo_cpus_bitmap[0]:0-7
[2016-10-08T05:06:15.058]   topo_gres_bitmap[0]:0-7
[2016-10-08T05:06:15.058]   topo_gres_cnt_alloc[0]:0
[2016-10-08T05:06:15.058]   topo_gres_cnt_avail[0]:8
[2016-10-08T05:06:15.058]   type[0]:tesla
[2016-10-08T05:39:35.860] gres/gpu: state for gpu-cluster-1
[2016-10-08T05:39:35.860]   gres_cnt found:8 configured:8 avail:8 alloc:0
[2016-10-08T05:39:35.860]   gres_bit_alloc:
[2016-10-08T05:39:35.860]   gres_used:(null)
[2016-10-08T05:39:35.860]   topo_cpus_bitmap[0]:0-7
[2016-10-08T05:39:35.860]   topo_gres_bitmap[0]:0-7
[2016-10-08T05:39:35.860]   topo_gres_cnt_alloc[0]:0
[2016-10-08T05:39:35.860]   topo_gres_cnt_avail[0]:8
[2016-10-08T05:39:35.860]   type[0]:tesla
[2016-10-08T05:39:35.860] gres/gpu: state for gpu-cluster-3
[2016-10-08T05:39:35.861]   gres_cnt found:8 configured:8 avail:8 alloc:0
[2016-10-08T05:39:35.861]   gres_bit_alloc:
[2016-10-08T05:39:35.861]   gres_used:(null)
[2016-10-08T05:39:35.861]   topo_cpus_bitmap[0]:0-7
[2016-10-08T05:39:35.861]   topo_gres_bitmap[0]:0-7
[2016-10-08T05:39:35.861]   topo_gres_cnt_alloc[0]:0
[2016-10-08T05:39:35.861]   topo_gres_cnt_avail[0]:8
[2016-10-08T05:39:35.861]   type[0]:tesla
[2016-10-08T05:39:35.861] gres/gpu: state for gpu-cluster-2
[2016-10-08T05:39:35.861]   gres_cnt found:8 configured:8 avail:8 alloc:0
[2016-10-08T05:39:35.861]   gres_bit_alloc:
[2016-10-08T05:39:35.861]   gres_used:(null)
[2016-10-08T05:39:35.861]   topo_cpus_bitmap[0]:0-7
[2016-10-08T05:39:35.861]   topo_gres_bitmap[0]:0-7
[2016-10-08T05:39:35.861]   topo_gres_cnt_alloc[0]:0
[2016-10-08T05:39:35.861]   topo_gres_cnt_avail[0]:8
[2016-10-08T05:39:35.861]   type[0]:tesla
[2016-10-08T05:39:35.861] gres/gpu: state for gpu-cluster-4
[2016-10-08T05:39:35.861]   gres_cnt found:8 configured:8 avail:8 alloc:0
[2016-10-08T05:39:35.861]   gres_bit_alloc:
[2016-10-08T05:39:35.861]   gres_used:(null)
[2016-10-08T05:39:35.861]   topo_cpus_bitmap[0]:0-7
[2016-10-08T05:39:35.861]   topo_gres_bitmap[0]:0-7
[2016-10-08T05:39:35.861]   topo_gres_cnt_alloc[0]:0
[2016-10-08T05:39:35.861]   topo_gres_cnt_avail[0]:8
[2016-10-08T05:39:35.861]   type[0]:tesla
[2016-10-08T06:12:55.415] gres/gpu: state for gpu-cluster-1
[2016-10-08T06:12:55.415]   gres_cnt found:8 configured:8 avail:8 alloc:0
[2016-10-08T06:12:55.415]   gres_bit_alloc:
[2016-10-08T06:12:55.415]   gres_used:(null)
[2016-10-08T06:12:55.415]   topo_cpus_bitmap[0]:0-7
[2016-10-08T06:12:55.415]   topo_gres_bitmap[0]:0-7
[2016-10-08T06:12:55.416]   topo_gres_cnt_alloc[0]:0
[2016-10-08T06:12:55.416]   topo_gres_cnt_avail[0]:8
[2016-10-08T06:12:55.416]   type[0]:tesla
[2016-10-08T06:12:55.416] gres/gpu: state for gpu-cluster-3
[2016-10-08T06:12:55.416]   gres_cnt found:8 configured:8 avail:8 alloc:0
[2016-10-08T06:12:55.416]   gres_bit_alloc:
[2016-10-08T06:12:55.416]   gres_used:(null)
[2016-10-08T06:12:55.416]   topo_cpus_bitmap[0]:0-7
[2016-10-08T06:12:55.416]   topo_gres_bitmap[0]:0-7
[2016-10-08T06:12:55.416]   topo_gres_cnt_alloc[0]:0
[2016-10-08T06:12:55.416]   topo_gres_cnt_avail[0]:8
[2016-10-08T06:12:55.416]   type[0]:tesla
[2016-10-08T06:12:55.416] gres/gpu: state for gpu-cluster-4
[2016-10-08T06:12:55.416]   gres_cnt found:8 configured:8 avail:8 alloc:0
[2016-10-08T06:12:55.416]   gres_bit_alloc:
[2016-10-08T06:12:55.416]   gres_used:(null)
[2016-10-08T06:12:55.416]   topo_cpus_bitmap[0]:0-7
[2016-10-08T06:12:55.416]   topo_gres_bitmap[0]:0-7
[2016-10-08T06:12:55.416]   topo_gres_cnt_alloc[0]:0
[2016-10-08T06:12:55.416]   topo_gres_cnt_avail[0]:8
[2016-10-08T06:12:55.416]   type[0]:tesla
[2016-10-08T06:12:55.416] gres/gpu: state for gpu-cluster-2
[2016-10-08T06:12:55.416]   gres_cnt found:8 configured:8 avail:8 alloc:0
[2016-10-08T06:12:55.416]   gres_bit_alloc:
[2016-10-08T06:12:55.416]   gres_used:(null)
[2016-10-08T06:12:55.417]   topo_cpus_bitmap[0]:0-7
[2016-10-08T06:12:55.417]   topo_gres_bitmap[0]:0-7
[2016-10-08T06:12:55.417]   topo_gres_cnt_alloc[0]:0
[2016-10-08T06:12:55.417]   topo_gres_cnt_avail[0]:8
[2016-10-08T06:12:55.417]   type[0]:tesla
[2016-10-08T06:46:15.210] gres/gpu: state for gpu-cluster-1
[2016-10-08T06:46:15.210]   gres_cnt found:8 configured:8 avail:8 alloc:0
[2016-10-08T06:46:15.210]   gres_bit_alloc:
[2016-10-08T06:46:15.210]   gres_used:(null)
[2016-10-08T06:46:15.210]   topo_cpus_bitmap[0]:0-7
[2016-10-08T06:46:15.210]   topo_gres_bitmap[0]:0-7
[2016-10-08T06:46:15.210]   topo_gres_cnt_alloc[0]:0
[2016-10-08T06:46:15.210]   topo_gres_cnt_avail[0]:8
[2016-10-08T06:46:15.210]   type[0]:tesla
[2016-10-08T06:46:15.210] gres/gpu: state for gpu-cluster-3
[2016-10-08T06:46:15.210]   gres_cnt found:8 configured:8 avail:8 alloc:0
[2016-10-08T06:46:15.210]   gres_bit_alloc:
[2016-10-08T06:46:15.210]   gres_used:(null)
[2016-10-08T06:46:15.210]   topo_cpus_bitmap[0]:0-7
[2016-10-08T06:46:15.210]   topo_gres_bitmap[0]:0-7
[2016-10-08T06:46:15.210]   topo_gres_cnt_alloc[0]:0
[2016-10-08T06:46:15.210]   topo_gres_cnt_avail[0]:8
[2016-10-08T06:46:15.210]   type[0]:tesla
[2016-10-08T06:46:15.210] gres/gpu: state for gpu-cluster-4
[2016-10-08T06:46:15.210]   gres_cnt found:8 configured:8 avail:8 alloc:0
[2016-10-08T06:46:15.210]   gres_bit_alloc:
[2016-10-08T06:46:15.210]   gres_used:(null)
[2016-10-08T06:46:15.210]   topo_cpus_bitmap[0]:0-7
[2016-10-08T06:46:15.210]   topo_gres_bitmap[0]:0-7
[2016-10-08T06:46:15.210]   topo_gres_cnt_alloc[0]:0
[2016-10-08T06:46:15.210]   topo_gres_cnt_avail[0]:8
[2016-10-08T06:46:15.210]   type[0]:tesla
[2016-10-08T06:46:15.211] gres/gpu: state for gpu-cluster-2
[2016-10-08T06:46:15.211]   gres_cnt found:8 configured:8 avail:8 alloc:0
[2016-10-08T06:46:15.211]   gres_bit_alloc:
[2016-10-08T06:46:15.211]   gres_used:(null)
[2016-10-08T06:46:15.211]   topo_cpus_bitmap[0]:0-7
[2016-10-08T06:46:15.211]   topo_gres_bitmap[0]:0-7
[2016-10-08T06:46:15.211]   topo_gres_cnt_alloc[0]:0
[2016-10-08T06:46:15.211]   topo_gres_cnt_avail[0]:8
[2016-10-08T06:46:15.211]   type[0]:tesla
[2016-10-08T07:19:35.999] gres/gpu: state for gpu-cluster-1
[2016-10-08T07:19:35.999]   gres_cnt found:8 configured:8 avail:8 alloc:0
[2016-10-08T07:19:35.999]   gres_bit_alloc:
[2016-10-08T07:19:35.999]   gres_used:(null)
[2016-10-08T07:19:35.999]   topo_cpus_bitmap[0]:0-7
[2016-10-08T07:19:35.999]   topo_gres_bitmap[0]:0-7
[2016-10-08T07:19:35.999]   topo_gres_cnt_alloc[0]:0
[2016-10-08T07:19:35.999]   topo_gres_cnt_avail[0]:8
[2016-10-08T07:19:35.999]   type[0]:tesla
[2016-10-08T07:19:35.999] gres/gpu: state for gpu-cluster-3
[2016-10-08T07:19:35.999]   gres_cnt found:8 configured:8 avail:8 alloc:0
[2016-10-08T07:19:35.999]   gres_bit_alloc:
[2016-10-08T07:19:36.000]   gres_used:(null)
[2016-10-08T07:19:36.000]   topo_cpus_bitmap[0]:0-7
[2016-10-08T07:19:36.000]   topo_gres_bitmap[0]:0-7
[2016-10-08T07:19:36.000]   topo_gres_cnt_alloc[0]:0
[2016-10-08T07:19:36.000]   topo_gres_cnt_avail[0]:8
[2016-10-08T07:19:36.000]   type[0]:tesla
[2016-10-08T07:19:36.000] gres/gpu: state for gpu-cluster-2
[2016-10-08T07:19:36.000]   gres_cnt found:8 configured:8 avail:8 alloc:0
[2016-10-08T07:19:36.000]   gres_bit_alloc:
[2016-10-08T07:19:36.000]   gres_used:(null)
[2016-10-08T07:19:36.000]   topo_cpus_bitmap[0]:0-7
[2016-10-08T07:19:36.000]   topo_gres_bitmap[0]:0-7
[2016-10-08T07:19:36.000]   topo_gres_cnt_alloc[0]:0
[2016-10-08T07:19:36.000]   topo_gres_cnt_avail[0]:8
[2016-10-08T07:19:36.000]   type[0]:tesla
[2016-10-08T07:19:36.000] gres/gpu: state for gpu-cluster-4
[2016-10-08T07:19:36.000]   gres_cnt found:8 configured:8 avail:8 alloc:0
[2016-10-08T07:19:36.000]   gres_bit_alloc:
[2016-10-08T07:19:36.000]   gres_used:(null)
[2016-10-08T07:19:36.000]   topo_cpus_bitmap[0]:0-7
[2016-10-08T07:19:36.000]   topo_gres_bitmap[0]:0-7
[2016-10-08T07:19:36.000]   topo_gres_cnt_alloc[0]:0
[2016-10-08T07:19:36.000]   topo_gres_cnt_avail[0]:8
[2016-10-08T07:19:36.000]   type[0]:tesla
[2016-10-08T07:52:55.577] gres/gpu: state for gpu-cluster-1
[2016-10-08T07:52:55.577]   gres_cnt found:8 configured:8 avail:8 alloc:0
[2016-10-08T07:52:55.577]   gres_bit_alloc:
[2016-10-08T07:52:55.577]   gres_used:(null)
[2016-10-08T07:52:55.577]   topo_cpus_bitmap[0]:0-7
[2016-10-08T07:52:55.577]   topo_gres_bitmap[0]:0-7
[2016-10-08T07:52:55.577]   topo_gres_cnt_alloc[0]:0
[2016-10-08T07:52:55.577]   topo_gres_cnt_avail[0]:8
[2016-10-08T07:52:55.577]   type[0]:tesla
[2016-10-08T07:52:55.578] gres/gpu: state for gpu-cluster-3
[2016-10-08T07:52:55.578]   gres_cnt found:8 configured:8 avail:8 alloc:0
[2016-10-08T07:52:55.578]   gres_bit_alloc:
[2016-10-08T07:52:55.578]   gres_used:(null)
[2016-10-08T07:52:55.578]   topo_cpus_bitmap[0]:0-7
[2016-10-08T07:52:55.578]   topo_gres_bitmap[0]:0-7
[2016-10-08T07:52:55.578]   topo_gres_cnt_alloc[0]:0
[2016-10-08T07:52:55.578]   topo_gres_cnt_avail[0]:8
[2016-10-08T07:52:55.578]   type[0]:tesla
[2016-10-08T07:52:55.578] gres/gpu: state for gpu-cluster-2
[2016-10-08T07:52:55.578]   gres_cnt found:8 configured:8 avail:8 alloc:0
[2016-10-08T07:52:55.578]   gres_bit_alloc:
[2016-10-08T07:52:55.578]   gres_used:(null)
[2016-10-08T07:52:55.578]   topo_cpus_bitmap[0]:0-7
[2016-10-08T07:52:55.578]   topo_gres_bitmap[0]:0-7
[2016-10-08T07:52:55.578]   topo_gres_cnt_alloc[0]:0
[2016-10-08T07:52:55.578]   topo_gres_cnt_avail[0]:8
[2016-10-08T07:52:55.579]   type[0]:tesla
[2016-10-08T07:52:55.579] gres/gpu: state for gpu-cluster-4
[2016-10-08T07:52:55.579]   gres_cnt found:8 configured:8 avail:8 alloc:0
[2016-10-08T07:52:55.579]   gres_bit_alloc:
[2016-10-08T07:52:55.579]   gres_used:(null)
[2016-10-08T07:52:55.579]   topo_cpus_bitmap[0]:0-7
[2016-10-08T07:52:55.579]   topo_gres_bitmap[0]:0-7
[2016-10-08T07:52:55.579]   topo_gres_cnt_alloc[0]:0
[2016-10-08T07:52:55.579]   topo_gres_cnt_avail[0]:8
[2016-10-08T07:52:55.579]   type[0]:tesla
[2016-10-08T08:26:15.397] gres/gpu: state for gpu-cluster-1
[2016-10-08T08:26:15.397]   gres_cnt found:8 configured:8 avail:8 alloc:0
[2016-10-08T08:26:15.397]   gres_bit_alloc:
[2016-10-08T08:26:15.397]   gres_used:(null)
[2016-10-08T08:26:15.397]   topo_cpus_bitmap[0]:0-7
[2016-10-08T08:26:15.397]   topo_gres_bitmap[0]:0-7
[2016-10-08T08:26:15.397]   topo_gres_cnt_alloc[0]:0
[2016-10-08T08:26:15.397]   topo_gres_cnt_avail[0]:8
[2016-10-08T08:26:15.397]   type[0]:tesla
[2016-10-08T08:26:15.398] gres/gpu: state for gpu-cluster-3
[2016-10-08T08:26:15.398]   gres_cnt found:8 configured:8 avail:8 alloc:0
[2016-10-08T08:26:15.398]   gres_bit_alloc:
[2016-10-08T08:26:15.398]   gres_used:(null)
[2016-10-08T08:26:15.398]   topo_cpus_bitmap[0]:0-7
[2016-10-08T08:26:15.398]   topo_gres_bitmap[0]:0-7
[2016-10-08T08:26:15.398]   topo_gres_cnt_alloc[0]:0
[2016-10-08T08:26:15.398]   topo_gres_cnt_avail[0]:8
[2016-10-08T08:26:15.398]   type[0]:tesla
[2016-10-08T08:26:15.398] gres/gpu: state for gpu-cluster-2
[2016-10-08T08:26:15.398]   gres_cnt found:8 configured:8 avail:8 alloc:0
[2016-10-08T08:26:15.398]   gres_bit_alloc:
[2016-10-08T08:26:15.398]   gres_used:(null)
[2016-10-08T08:26:15.398]   topo_cpus_bitmap[0]:0-7
[2016-10-08T08:26:15.398]   topo_gres_bitmap[0]:0-7
[2016-10-08T08:26:15.398]   topo_gres_cnt_alloc[0]:0
[2016-10-08T08:26:15.398]   topo_gres_cnt_avail[0]:8
[2016-10-08T08:26:15.398]   type[0]:tesla
[2016-10-08T08:26:15.398] gres/gpu: state for gpu-cluster-4
[2016-10-08T08:26:15.399]   gres_cnt found:8 configured:8 avail:8 alloc:0
[2016-10-08T08:26:15.399]   gres_bit_alloc:
[2016-10-08T08:26:15.399]   gres_used:(null)
[2016-10-08T08:26:15.399]   topo_cpus_bitmap[0]:0-7
[2016-10-08T08:26:15.399]   topo_gres_bitmap[0]:0-7
[2016-10-08T08:26:15.399]   topo_gres_cnt_alloc[0]:0
[2016-10-08T08:26:15.399]   topo_gres_cnt_avail[0]:8
[2016-10-08T08:26:15.399]   type[0]:tesla
[2016-10-08T08:59:35.215] gres/gpu: state for gpu-cluster-1
[2016-10-08T08:59:35.215]   gres_cnt found:8 configured:8 avail:8 alloc:0
[2016-10-08T08:59:35.215]   gres_bit_alloc:
[2016-10-08T08:59:35.215]   gres_used:(null)
[2016-10-08T08:59:35.215]   topo_cpus_bitmap[0]:0-7
[2016-10-08T08:59:35.215]   topo_gres_bitmap[0]:0-7
[2016-10-08T08:59:35.215]   topo_gres_cnt_alloc[0]:0
[2016-10-08T08:59:35.215]   topo_gres_cnt_avail[0]:8
[2016-10-08T08:59:35.215]   type[0]:tesla
[2016-10-08T08:59:35.216] gres/gpu: state for gpu-cluster-3
[2016-10-08T08:59:35.216]   gres_cnt found:8 configured:8 avail:8 alloc:0
[2016-10-08T08:59:35.216]   gres_bit_alloc:
[2016-10-08T08:59:35.216]   gres_used:(null)
[2016-10-08T08:59:35.216]   topo_cpus_bitmap[0]:0-7
[2016-10-08T08:59:35.216]   topo_gres_bitmap[0]:0-7
[2016-10-08T08:59:35.216]   topo_gres_cnt_alloc[0]:0
[2016-10-08T08:59:35.216]   topo_gres_cnt_avail[0]:8
[2016-10-08T08:59:35.216]   type[0]:tesla
[2016-10-08T08:59:35.216] gres/gpu: state for gpu-cluster-2
[2016-10-08T08:59:35.216]   gres_cnt found:8 configured:8 avail:8 alloc:0
[2016-10-08T08:59:35.216]   gres_bit_alloc:
[2016-10-08T08:59:35.216]   gres_used:(null)
[2016-10-08T08:59:35.216]   topo_cpus_bitmap[0]:0-7
[2016-10-08T08:59:35.216]   topo_gres_bitmap[0]:0-7
[2016-10-08T08:59:35.216]   topo_gres_cnt_alloc[0]:0
[2016-10-08T08:59:35.216]   topo_gres_cnt_avail[0]:8
[2016-10-08T08:59:35.217]   type[0]:tesla
[2016-10-08T08:59:35.217] gres/gpu: state for gpu-cluster-4
[2016-10-08T08:59:35.217]   gres_cnt found:8 configured:8 avail:8 alloc:0
[2016-10-08T08:59:35.217]   gres_bit_alloc:
[2016-10-08T08:59:35.217]   gres_used:(null)
[2016-10-08T08:59:35.217]   topo_cpus_bitmap[0]:0-7
[2016-10-08T08:59:35.217]   topo_gres_bitmap[0]:0-7
[2016-10-08T08:59:35.217]   topo_gres_cnt_alloc[0]:0
[2016-10-08T08:59:35.217]   topo_gres_cnt_avail[0]:8
[2016-10-08T08:59:35.217]   type[0]:tesla
[2016-10-08T09:32:55.771] gres/gpu: state for gpu-cluster-1
[2016-10-08T09:32:55.771]   gres_cnt found:8 configured:8 avail:8 alloc:0
[2016-10-08T09:32:55.771]   gres_bit_alloc:
[2016-10-08T09:32:55.771]   gres_used:(null)
[2016-10-08T09:32:55.771]   topo_cpus_bitmap[0]:0-7
[2016-10-08T09:32:55.771]   topo_gres_bitmap[0]:0-7
[2016-10-08T09:32:55.771]   topo_gres_cnt_alloc[0]:0
[2016-10-08T09:32:55.771]   topo_gres_cnt_avail[0]:8
[2016-10-08T09:32:55.771]   type[0]:tesla
[2016-10-08T09:32:55.772] gres/gpu: state for gpu-cluster-3
[2016-10-08T09:32:55.772]   gres_cnt found:8 configured:8 avail:8 alloc:0
[2016-10-08T09:32:55.772]   gres_bit_alloc:
[2016-10-08T09:32:55.772]   gres_used:(null)
[2016-10-08T09:32:55.772]   topo_cpus_bitmap[0]:0-7
[2016-10-08T09:32:55.772]   topo_gres_bitmap[0]:0-7
[2016-10-08T09:32:55.772]   topo_gres_cnt_alloc[0]:0
[2016-10-08T09:32:55.772]   topo_gres_cnt_avail[0]:8
[2016-10-08T09:32:55.772]   type[0]:tesla
[2016-10-08T09:32:55.772] gres/gpu: state for gpu-cluster-2
[2016-10-08T09:32:55.772]   gres_cnt found:8 configured:8 avail:8 alloc:0
[2016-10-08T09:32:55.772]   gres_bit_alloc:
[2016-10-08T09:32:55.772]   gres_used:(null)
[2016-10-08T09:32:55.772]   topo_cpus_bitmap[0]:0-7
[2016-10-08T09:32:55.772]   topo_gres_bitmap[0]:0-7
[2016-10-08T09:32:55.772]   topo_gres_cnt_alloc[0]:0
[2016-10-08T09:32:55.772]   topo_gres_cnt_avail[0]:8
[2016-10-08T09:32:55.772]   type[0]:tesla
[2016-10-08T09:32:55.772] gres/gpu: state for gpu-cluster-4
[2016-10-08T09:32:55.772]   gres_cnt found:8 configured:8 avail:8 alloc:0
[2016-10-08T09:32:55.772]   gres_bit_alloc:
[2016-10-08T09:32:55.772]   gres_used:(null)
[2016-10-08T09:32:55.772]   topo_cpus_bitmap[0]:0-7
[2016-10-08T09:32:55.772]   topo_gres_bitmap[0]:0-7
[2016-10-08T09:32:55.772]   topo_gres_cnt_alloc[0]:0
[2016-10-08T09:32:55.772]   topo_gres_cnt_avail[0]:8
[2016-10-08T09:32:55.773]   type[0]:tesla
[2016-10-08T10:06:15.573] gres/gpu: state for gpu-cluster-1
[2016-10-08T10:06:15.574]   gres_cnt found:8 configured:8 avail:8 alloc:0
[2016-10-08T10:06:15.574]   gres_bit_alloc:
[2016-10-08T10:06:15.574]   gres_used:(null)
[2016-10-08T10:06:15.574]   topo_cpus_bitmap[0]:0-7
[2016-10-08T10:06:15.574]   topo_gres_bitmap[0]:0-7
[2016-10-08T10:06:15.574]   topo_gres_cnt_alloc[0]:0
[2016-10-08T10:06:15.574]   topo_gres_cnt_avail[0]:8
[2016-10-08T10:06:15.574]   type[0]:tesla
[2016-10-08T10:06:15.574] gres/gpu: state for gpu-cluster-3
[2016-10-08T10:06:15.574]   gres_cnt found:8 configured:8 avail:8 alloc:0
[2016-10-08T10:06:15.574]   gres_bit_alloc:
[2016-10-08T10:06:15.574]   gres_used:(null)
[2016-10-08T10:06:15.574]   topo_cpus_bitmap[0]:0-7
[2016-10-08T10:06:15.574]   topo_gres_bitmap[0]:0-7
[2016-10-08T10:06:15.574]   topo_gres_cnt_alloc[0]:0
[2016-10-08T10:06:15.574]   topo_gres_cnt_avail[0]:8
[2016-10-08T10:06:15.574]   type[0]:tesla
[2016-10-08T10:06:15.574] gres/gpu: state for gpu-cluster-2
[2016-10-08T10:06:15.574]   gres_cnt found:8 configured:8 avail:8 alloc:0
[2016-10-08T10:06:15.574]   gres_bit_alloc:
[2016-10-08T10:06:15.574]   gres_used:(null)
[2016-10-08T10:06:15.574]   topo_cpus_bitmap[0]:0-7
[2016-10-08T10:06:15.574]   topo_gres_bitmap[0]:0-7
[2016-10-08T10:06:15.574]   topo_gres_cnt_alloc[0]:0
[2016-10-08T10:06:15.574]   topo_gres_cnt_avail[0]:8
[2016-10-08T10:06:15.574]   type[0]:tesla
[2016-10-08T10:06:15.575] gres/gpu: state for gpu-cluster-4
[2016-10-08T10:06:15.575]   gres_cnt found:8 configured:8 avail:8 alloc:0
[2016-10-08T10:06:15.575]   gres_bit_alloc:
[2016-10-08T10:06:15.575]   gres_used:(null)
[2016-10-08T10:06:15.575]   topo_cpus_bitmap[0]:0-7
[2016-10-08T10:06:15.575]   topo_gres_bitmap[0]:0-7
[2016-10-08T10:06:15.575]   topo_gres_cnt_alloc[0]:0
[2016-10-08T10:06:15.575]   topo_gres_cnt_avail[0]:8
[2016-10-08T10:06:15.575]   type[0]:tesla
[2016-10-08T10:39:35.360] gres/gpu: state for gpu-cluster-1
[2016-10-08T10:39:35.360]   gres_cnt found:8 configured:8 avail:8 alloc:0
[2016-10-08T10:39:35.360]   gres_bit_alloc:
[2016-10-08T10:39:35.360]   gres_used:(null)
[2016-10-08T10:39:35.360]   topo_cpus_bitmap[0]:0-7
[2016-10-08T10:39:35.360]   topo_gres_bitmap[0]:0-7
[2016-10-08T10:39:35.360]   topo_gres_cnt_alloc[0]:0
[2016-10-08T10:39:35.360]   topo_gres_cnt_avail[0]:8
[2016-10-08T10:39:35.360]   type[0]:tesla
[2016-10-08T10:39:35.361] gres/gpu: state for gpu-cluster-3
[2016-10-08T10:39:35.361]   gres_cnt found:8 configured:8 avail:8 alloc:0
[2016-10-08T10:39:35.361]   gres_bit_alloc:
[2016-10-08T10:39:35.361]   gres_used:(null)
[2016-10-08T10:39:35.361]   topo_cpus_bitmap[0]:0-7
[2016-10-08T10:39:35.361]   topo_gres_bitmap[0]:0-7
[2016-10-08T10:39:35.361]   topo_gres_cnt_alloc[0]:0
[2016-10-08T10:39:35.361]   topo_gres_cnt_avail[0]:8
[2016-10-08T10:39:35.361]   type[0]:tesla
[2016-10-08T10:39:35.361] gres/gpu: state for gpu-cluster-4
[2016-10-08T10:39:35.361]   gres_cnt found:8 configured:8 avail:8 alloc:0
[2016-10-08T10:39:35.361]   gres_bit_alloc:
[2016-10-08T10:39:35.361]   gres_used:(null)
[2016-10-08T10:39:35.361]   topo_cpus_bitmap[0]:0-7
[2016-10-08T10:39:35.362]   topo_gres_bitmap[0]:0-7
[2016-10-08T10:39:35.362]   topo_gres_cnt_alloc[0]:0
[2016-10-08T10:39:35.362]   topo_gres_cnt_avail[0]:8
[2016-10-08T10:39:35.362]   type[0]:tesla
[2016-10-08T10:39:35.362] gres/gpu: state for gpu-cluster-2
[2016-10-08T10:39:35.362]   gres_cnt found:8 configured:8 avail:8 alloc:0
[2016-10-08T10:39:35.362]   gres_bit_alloc:
[2016-10-08T10:39:35.362]   gres_used:(null)
[2016-10-08T10:39:35.362]   topo_cpus_bitmap[0]:0-7
[2016-10-08T10:39:35.362]   topo_gres_bitmap[0]:0-7
[2016-10-08T10:39:35.362]   topo_gres_cnt_alloc[0]:0
[2016-10-08T10:39:35.362]   topo_gres_cnt_avail[0]:8
[2016-10-08T10:39:35.362]   type[0]:tesla
[2016-10-08T11:12:55.993] gres/gpu: state for gpu-cluster-1
[2016-10-08T11:12:55.993]   gres_cnt found:8 configured:8 avail:8 alloc:0
[2016-10-08T11:12:55.993]   gres_bit_alloc:
[2016-10-08T11:12:55.993]   gres_used:(null)
[2016-10-08T11:12:55.993]   topo_cpus_bitmap[0]:0-7
[2016-10-08T11:12:55.993]   topo_gres_bitmap[0]:0-7
[2016-10-08T11:12:55.993]   topo_gres_cnt_alloc[0]:0
[2016-10-08T11:12:55.993]   topo_gres_cnt_avail[0]:8
[2016-10-08T11:12:55.993]   type[0]:tesla
[2016-10-08T11:12:55.993] gres/gpu: state for gpu-cluster-3
[2016-10-08T11:12:55.993]   gres_cnt found:8 configured:8 avail:8 alloc:0
[2016-10-08T11:12:55.993]   gres_bit_alloc:
[2016-10-08T11:12:55.994]   gres_used:(null)
[2016-10-08T11:12:55.994]   topo_cpus_bitmap[0]:0-7
[2016-10-08T11:12:55.994]   topo_gres_bitmap[0]:0-7
[2016-10-08T11:12:55.994]   topo_gres_cnt_alloc[0]:0
[2016-10-08T11:12:55.994]   topo_gres_cnt_avail[0]:8
[2016-10-08T11:12:55.994]   type[0]:tesla
[2016-10-08T11:12:55.994] gres/gpu: state for gpu-cluster-4
[2016-10-08T11:12:55.994]   gres_cnt found:8 configured:8 avail:8 alloc:0
[2016-10-08T11:12:55.994]   gres_bit_alloc:
[2016-10-08T11:12:55.994]   gres_used:(null)
[2016-10-08T11:12:55.994]   topo_cpus_bitmap[0]:0-7
[2016-10-08T11:12:55.994]   topo_gres_bitmap[0]:0-7
[2016-10-08T11:12:55.994]   topo_gres_cnt_alloc[0]:0
[2016-10-08T11:12:55.994]   topo_gres_cnt_avail[0]:8
[2016-10-08T11:12:55.994]   type[0]:tesla
[2016-10-08T11:12:55.994] gres/gpu: state for gpu-cluster-2
[2016-10-08T11:12:55.994]   gres_cnt found:8 configured:8 avail:8 alloc:0
[2016-10-08T11:12:55.994]   gres_bit_alloc:
[2016-10-08T11:12:55.994]   gres_used:(null)
[2016-10-08T11:12:55.994]   topo_cpus_bitmap[0]:0-7
[2016-10-08T11:12:55.994]   topo_gres_bitmap[0]:0-7
[2016-10-08T11:12:55.994]   topo_gres_cnt_alloc[0]:0
[2016-10-08T11:12:55.994]   topo_gres_cnt_avail[0]:8
[2016-10-08T11:12:55.994]   type[0]:tesla
[2016-10-08T11:46:15.798] gres/gpu: state for gpu-cluster-1
[2016-10-08T11:46:15.798]   gres_cnt found:8 configured:8 avail:8 alloc:0
[2016-10-08T11:46:15.798]   gres_bit_alloc:
[2016-10-08T11:46:15.798]   gres_used:(null)
[2016-10-08T11:46:15.798]   topo_cpus_bitmap[0]:0-7
[2016-10-08T11:46:15.798]   topo_gres_bitmap[0]:0-7
[2016-10-08T11:46:15.798]   topo_gres_cnt_alloc[0]:0
[2016-10-08T11:46:15.798]   topo_gres_cnt_avail[0]:8
[2016-10-08T11:46:15.798]   type[0]:tesla
[2016-10-08T11:46:15.798] gres/gpu: state for gpu-cluster-3
[2016-10-08T11:46:15.798]   gres_cnt found:8 configured:8 avail:8 alloc:0
[2016-10-08T11:46:15.799]   gres_bit_alloc:
[2016-10-08T11:46:15.799]   gres_used:(null)
[2016-10-08T11:46:15.799]   topo_cpus_bitmap[0]:0-7
[2016-10-08T11:46:15.799]   topo_gres_bitmap[0]:0-7
[2016-10-08T11:46:15.799]   topo_gres_cnt_alloc[0]:0
[2016-10-08T11:46:15.799]   topo_gres_cnt_avail[0]:8
[2016-10-08T11:46:15.799]   type[0]:tesla
[2016-10-08T11:46:15.799] gres/gpu: state for gpu-cluster-4
[2016-10-08T11:46:15.799]   gres_cnt found:8 configured:8 avail:8 alloc:0
[2016-10-08T11:46:15.799]   gres_bit_alloc:
[2016-10-08T11:46:15.799]   gres_used:(null)
[2016-10-08T11:46:15.799]   topo_cpus_bitmap[0]:0-7
[2016-10-08T11:46:15.799]   topo_gres_bitmap[0]:0-7
[2016-10-08T11:46:15.799]   topo_gres_cnt_alloc[0]:0
[2016-10-08T11:46:15.799]   topo_gres_cnt_avail[0]:8
[2016-10-08T11:46:15.799]   type[0]:tesla
[2016-10-08T11:46:15.799] gres/gpu: state for gpu-cluster-2
[2016-10-08T11:46:15.799]   gres_cnt found:8 configured:8 avail:8 alloc:0
[2016-10-08T11:46:15.799]   gres_bit_alloc:
[2016-10-08T11:46:15.799]   gres_used:(null)
[2016-10-08T11:46:15.799]   topo_cpus_bitmap[0]:0-7
[2016-10-08T11:46:15.799]   topo_gres_bitmap[0]:0-7
[2016-10-08T11:46:15.799]   topo_gres_cnt_alloc[0]:0
[2016-10-08T11:46:15.799]   topo_gres_cnt_avail[0]:8
[2016-10-08T11:46:15.800]   type[0]:tesla
[2016-10-08T12:19:35.568] gres/gpu: state for gpu-cluster-1
[2016-10-08T12:19:35.568]   gres_cnt found:8 configured:8 avail:8 alloc:0
[2016-10-08T12:19:35.568]   gres_bit_alloc:
[2016-10-08T12:19:35.568]   gres_used:(null)
[2016-10-08T12:19:35.568]   topo_cpus_bitmap[0]:0-7
[2016-10-08T12:19:35.568]   topo_gres_bitmap[0]:0-7
[2016-10-08T12:19:35.568]   topo_gres_cnt_alloc[0]:0
[2016-10-08T12:19:35.568]   topo_gres_cnt_avail[0]:8
[2016-10-08T12:19:35.569]   type[0]:tesla
[2016-10-08T12:19:35.569] gres/gpu: state for gpu-cluster-3
[2016-10-08T12:19:35.569]   gres_cnt found:8 configured:8 avail:8 alloc:0
[2016-10-08T12:19:35.569]   gres_bit_alloc:
[2016-10-08T12:19:35.569]   gres_used:(null)
[2016-10-08T12:19:35.569]   topo_cpus_bitmap[0]:0-7
[2016-10-08T12:19:35.569]   topo_gres_bitmap[0]:0-7
[2016-10-08T12:19:35.569]   topo_gres_cnt_alloc[0]:0
[2016-10-08T12:19:35.569]   topo_gres_cnt_avail[0]:8
[2016-10-08T12:19:35.569]   type[0]:tesla
[2016-10-08T12:19:35.569] gres/gpu: state for gpu-cluster-4
[2016-10-08T12:19:35.569]   gres_cnt found:8 configured:8 avail:8 alloc:0
[2016-10-08T12:19:35.569]   gres_bit_alloc:
[2016-10-08T12:19:35.569]   gres_used:(null)
[2016-10-08T12:19:35.569]   topo_cpus_bitmap[0]:0-7
[2016-10-08T12:19:35.569]   topo_gres_bitmap[0]:0-7
[2016-10-08T12:19:35.569]   topo_gres_cnt_alloc[0]:0
[2016-10-08T12:19:35.569]   topo_gres_cnt_avail[0]:8
[2016-10-08T12:19:35.569]   type[0]:tesla
[2016-10-08T12:19:35.570] gres/gpu: state for gpu-cluster-2
[2016-10-08T12:19:35.570]   gres_cnt found:8 configured:8 avail:8 alloc:0
[2016-10-08T12:19:35.570]   gres_bit_alloc:
[2016-10-08T12:19:35.570]   gres_used:(null)
[2016-10-08T12:19:35.570]   topo_cpus_bitmap[0]:0-7
[2016-10-08T12:19:35.570]   topo_gres_bitmap[0]:0-7
[2016-10-08T12:19:35.570]   topo_gres_cnt_alloc[0]:0
[2016-10-08T12:19:35.570]   topo_gres_cnt_avail[0]:8
[2016-10-08T12:19:35.570]   type[0]:tesla
[2016-10-08T12:52:55.112] gres/gpu: state for gpu-cluster-1
[2016-10-08T12:52:55.112]   gres_cnt found:8 configured:8 avail:8 alloc:0
[2016-10-08T12:52:55.112]   gres_bit_alloc:
[2016-10-08T12:52:55.112]   gres_used:(null)
[2016-10-08T12:52:55.112]   topo_cpus_bitmap[0]:0-7
[2016-10-08T12:52:55.112]   topo_gres_bitmap[0]:0-7
[2016-10-08T12:52:55.112]   topo_gres_cnt_alloc[0]:0
[2016-10-08T12:52:55.112]   topo_gres_cnt_avail[0]:8
[2016-10-08T12:52:55.112]   type[0]:tesla
[2016-10-08T12:52:55.113] gres/gpu: state for gpu-cluster-3
[2016-10-08T12:52:55.113]   gres_cnt found:8 configured:8 avail:8 alloc:0
[2016-10-08T12:52:55.113]   gres_bit_alloc:
[2016-10-08T12:52:55.113]   gres_used:(null)
[2016-10-08T12:52:55.113]   topo_cpus_bitmap[0]:0-7
[2016-10-08T12:52:55.113]   topo_gres_bitmap[0]:0-7
[2016-10-08T12:52:55.113]   topo_gres_cnt_alloc[0]:0
[2016-10-08T12:52:55.113]   topo_gres_cnt_avail[0]:8
[2016-10-08T12:52:55.113]   type[0]:tesla
[2016-10-08T12:52:55.113] gres/gpu: state for gpu-cluster-2
[2016-10-08T12:52:55.113]   gres_cnt found:8 configured:8 avail:8 alloc:0
[2016-10-08T12:52:55.113]   gres_bit_alloc:
[2016-10-08T12:52:55.113]   gres_used:(null)
[2016-10-08T12:52:55.113]   topo_cpus_bitmap[0]:0-7
[2016-10-08T12:52:55.114]   topo_gres_bitmap[0]:0-7
[2016-10-08T12:52:55.114]   topo_gres_cnt_alloc[0]:0
[2016-10-08T12:52:55.114]   topo_gres_cnt_avail[0]:8
[2016-10-08T12:52:55.114]   type[0]:tesla
[2016-10-08T12:52:55.114] gres/gpu: state for gpu-cluster-4
[2016-10-08T12:52:55.114]   gres_cnt found:8 configured:8 avail:8 alloc:0
[2016-10-08T12:52:55.114]   gres_bit_alloc:
[2016-10-08T12:52:55.114]   gres_used:(null)
[2016-10-08T12:52:55.114]   topo_cpus_bitmap[0]:0-7
[2016-10-08T12:52:55.114]   topo_gres_bitmap[0]:0-7
[2016-10-08T12:52:55.114]   topo_gres_cnt_alloc[0]:0
[2016-10-08T12:52:55.114]   topo_gres_cnt_avail[0]:8
[2016-10-08T12:52:55.114]   type[0]:tesla
[2016-10-08T13:26:15.883] gres/gpu: state for gpu-cluster-1
[2016-10-08T13:26:15.883]   gres_cnt found:8 configured:8 avail:8 alloc:0
[2016-10-08T13:26:15.883]   gres_bit_alloc:
[2016-10-08T13:26:15.883]   gres_used:(null)
[2016-10-08T13:26:15.883]   topo_cpus_bitmap[0]:0-7
[2016-10-08T13:26:15.883]   topo_gres_bitmap[0]:0-7
[2016-10-08T13:26:15.883]   topo_gres_cnt_alloc[0]:0
[2016-10-08T13:26:15.883]   topo_gres_cnt_avail[0]:8
[2016-10-08T13:26:15.883]   type[0]:tesla
[2016-10-08T13:26:15.884] gres/gpu: state for gpu-cluster-3
[2016-10-08T13:26:15.884]   gres_cnt found:8 configured:8 avail:8 alloc:0
[2016-10-08T13:26:15.884]   gres_bit_alloc:
[2016-10-08T13:26:15.884]   gres_used:(null)
[2016-10-08T13:26:15.884]   topo_cpus_bitmap[0]:0-7
[2016-10-08T13:26:15.884]   topo_gres_bitmap[0]:0-7
[2016-10-08T13:26:15.884]   topo_gres_cnt_alloc[0]:0
[2016-10-08T13:26:15.884]   topo_gres_cnt_avail[0]:8
[2016-10-08T13:26:15.884]   type[0]:tesla
[2016-10-08T13:26:15.884] gres/gpu: state for gpu-cluster-4
[2016-10-08T13:26:15.884]   gres_cnt found:8 configured:8 avail:8 alloc:0
[2016-10-08T13:26:15.884]   gres_bit_alloc:
[2016-10-08T13:26:15.884]   gres_used:(null)
[2016-10-08T13:26:15.884]   topo_cpus_bitmap[0]:0-7
[2016-10-08T13:26:15.884]   topo_gres_bitmap[0]:0-7
[2016-10-08T13:26:15.884]   topo_gres_cnt_alloc[0]:0
[2016-10-08T13:26:15.884]   topo_gres_cnt_avail[0]:8
[2016-10-08T13:26:15.884]   type[0]:tesla
[2016-10-08T13:26:15.884] gres/gpu: state for gpu-cluster-2
[2016-10-08T13:26:15.884]   gres_cnt found:8 configured:8 avail:8 alloc:0
[2016-10-08T13:26:15.884]   gres_bit_alloc:
[2016-10-08T13:26:15.885]   gres_used:(null)
[2016-10-08T13:26:15.885]   topo_cpus_bitmap[0]:0-7
[2016-10-08T13:26:15.885]   topo_gres_bitmap[0]:0-7
[2016-10-08T13:26:15.885]   topo_gres_cnt_alloc[0]:0
[2016-10-08T13:26:15.885]   topo_gres_cnt_avail[0]:8
[2016-10-08T13:26:15.885]   type[0]:tesla
[2016-10-08T13:59:35.676] gres/gpu: state for gpu-cluster-1
[2016-10-08T13:59:35.676]   gres_cnt found:8 configured:8 avail:8 alloc:0
[2016-10-08T13:59:35.676]   gres_bit_alloc:
[2016-10-08T13:59:35.676]   gres_used:(null)
[2016-10-08T13:59:35.676]   topo_cpus_bitmap[0]:0-7
[2016-10-08T13:59:35.676]   topo_gres_bitmap[0]:0-7
[2016-10-08T13:59:35.676]   topo_gres_cnt_alloc[0]:0
[2016-10-08T13:59:35.676]   topo_gres_cnt_avail[0]:8
[2016-10-08T13:59:35.676]   type[0]:tesla
[2016-10-08T13:59:35.676] gres/gpu: state for gpu-cluster-3
[2016-10-08T13:59:35.676]   gres_cnt found:8 configured:8 avail:8 alloc:0
[2016-10-08T13:59:35.676]   gres_bit_alloc:
[2016-10-08T13:59:35.677]   gres_used:(null)
[2016-10-08T13:59:35.677]   topo_cpus_bitmap[0]:0-7
[2016-10-08T13:59:35.677]   topo_gres_bitmap[0]:0-7
[2016-10-08T13:59:35.677]   topo_gres_cnt_alloc[0]:0
[2016-10-08T13:59:35.677]   topo_gres_cnt_avail[0]:8
[2016-10-08T13:59:35.677]   type[0]:tesla
[2016-10-08T13:59:35.677] gres/gpu: state for gpu-cluster-2
[2016-10-08T13:59:35.677]   gres_cnt found:8 configured:8 avail:8 alloc:0
[2016-10-08T13:59:35.677]   gres_bit_alloc:
[2016-10-08T13:59:35.677]   gres_used:(null)
[2016-10-08T13:59:35.677]   topo_cpus_bitmap[0]:0-7
[2016-10-08T13:59:35.677]   topo_gres_bitmap[0]:0-7
[2016-10-08T13:59:35.677]   topo_gres_cnt_alloc[0]:0
[2016-10-08T13:59:35.677]   topo_gres_cnt_avail[0]:8
[2016-10-08T13:59:35.677]   type[0]:tesla
[2016-10-08T13:59:35.677] gres/gpu: state for gpu-cluster-4
[2016-10-08T13:59:35.677]   gres_cnt found:8 configured:8 avail:8 alloc:0
[2016-10-08T13:59:35.677]   gres_bit_alloc:
[2016-10-08T13:59:35.677]   gres_used:(null)
[2016-10-08T13:59:35.677]   topo_cpus_bitmap[0]:0-7
[2016-10-08T13:59:35.677]   topo_gres_bitmap[0]:0-7
[2016-10-08T13:59:35.677]   topo_gres_cnt_alloc[0]:0
[2016-10-08T13:59:35.677]   topo_gres_cnt_avail[0]:8
[2016-10-08T13:59:35.677]   type[0]:tesla
[2016-10-08T14:32:55.247] gres/gpu: state for gpu-cluster-1
[2016-10-08T14:32:55.247]   gres_cnt found:8 configured:8 avail:8 alloc:0
[2016-10-08T14:32:55.247]   gres_bit_alloc:
[2016-10-08T14:32:55.247]   gres_used:(null)
[2016-10-08T14:32:55.247]   topo_cpus_bitmap[0]:0-7
[2016-10-08T14:32:55.247]   topo_gres_bitmap[0]:0-7
[2016-10-08T14:32:55.247]   topo_gres_cnt_alloc[0]:0
[2016-10-08T14:32:55.247]   topo_gres_cnt_avail[0]:8
[2016-10-08T14:32:55.247]   type[0]:tesla
[2016-10-08T14:32:55.247] gres/gpu: state for gpu-cluster-4
[2016-10-08T14:32:55.247]   gres_cnt found:8 configured:8 avail:8 alloc:0
[2016-10-08T14:32:55.247]   gres_bit_alloc:
[2016-10-08T14:32:55.247]   gres_used:(null)
[2016-10-08T14:32:55.247]   topo_cpus_bitmap[0]:0-7
[2016-10-08T14:32:55.247]   topo_gres_bitmap[0]:0-7
[2016-10-08T14:32:55.247]   topo_gres_cnt_alloc[0]:0
[2016-10-08T14:32:55.247]   topo_gres_cnt_avail[0]:8
[2016-10-08T14:32:55.247]   type[0]:tesla
[2016-10-08T14:32:55.248] gres/gpu: state for gpu-cluster-3
[2016-10-08T14:32:55.248]   gres_cnt found:8 configured:8 avail:8 alloc:0
[2016-10-08T14:32:55.248]   gres_bit_alloc:
[2016-10-08T14:32:55.248]   gres_used:(null)
[2016-10-08T14:32:55.248]   topo_cpus_bitmap[0]:0-7
[2016-10-08T14:32:55.248]   topo_gres_bitmap[0]:0-7
[2016-10-08T14:32:55.248]   topo_gres_cnt_alloc[0]:0
[2016-10-08T14:32:55.248]   topo_gres_cnt_avail[0]:8
[2016-10-08T14:32:55.248]   type[0]:tesla
[2016-10-08T14:32:55.248] gres/gpu: state for gpu-cluster-2
[2016-10-08T14:32:55.248]   gres_cnt found:8 configured:8 avail:8 alloc:0
[2016-10-08T14:32:55.248]   gres_bit_alloc:
[2016-10-08T14:32:55.248]   gres_used:(null)
[2016-10-08T14:32:55.248]   topo_cpus_bitmap[0]:0-7
[2016-10-08T14:32:55.248]   topo_gres_bitmap[0]:0-7
[2016-10-08T14:32:55.248]   topo_gres_cnt_alloc[0]:0
[2016-10-08T14:32:55.248]   topo_gres_cnt_avail[0]:8
[2016-10-08T14:32:55.248]   type[0]:tesla
[2016-10-08T15:06:15.030] gres/gpu: state for gpu-cluster-1
[2016-10-08T15:06:15.030]   gres_cnt found:8 configured:8 avail:8 alloc:0
[2016-10-08T15:06:15.030]   gres_bit_alloc:
[2016-10-08T15:06:15.030]   gres_used:(null)
[2016-10-08T15:06:15.031]   topo_cpus_bitmap[0]:0-7
[2016-10-08T15:06:15.031]   topo_gres_bitmap[0]:0-7
[2016-10-08T15:06:15.031]   topo_gres_cnt_alloc[0]:0
[2016-10-08T15:06:15.031]   topo_gres_cnt_avail[0]:8
[2016-10-08T15:06:15.031]   type[0]:tesla
[2016-10-08T15:06:15.031] gres/gpu: state for gpu-cluster-3
[2016-10-08T15:06:15.031]   gres_cnt found:8 configured:8 avail:8 alloc:0
[2016-10-08T15:06:15.031]   gres_bit_alloc:
[2016-10-08T15:06:15.031]   gres_used:(null)
[2016-10-08T15:06:15.031]   topo_cpus_bitmap[0]:0-7
[2016-10-08T15:06:15.031]   topo_gres_bitmap[0]:0-7
[2016-10-08T15:06:15.031]   topo_gres_cnt_alloc[0]:0
[2016-10-08T15:06:15.031]   topo_gres_cnt_avail[0]:8
[2016-10-08T15:06:15.031]   type[0]:tesla
[2016-10-08T15:06:15.031] gres/gpu: state for gpu-cluster-4
[2016-10-08T15:06:15.031]   gres_cnt found:8 configured:8 avail:8 alloc:0
[2016-10-08T15:06:15.032]   gres_bit_alloc:
[2016-10-08T15:06:15.032]   gres_used:(null)
[2016-10-08T15:06:15.032]   topo_cpus_bitmap[0]:0-7
[2016-10-08T15:06:15.032]   topo_gres_bitmap[0]:0-7
[2016-10-08T15:06:15.032]   topo_gres_cnt_alloc[0]:0
[2016-10-08T15:06:15.032]   topo_gres_cnt_avail[0]:8
[2016-10-08T15:06:15.032]   type[0]:tesla
[2016-10-08T15:06:15.032] gres/gpu: state for gpu-cluster-2
[2016-10-08T15:06:15.032]   gres_cnt found:8 configured:8 avail:8 alloc:0
[2016-10-08T15:06:15.032]   gres_bit_alloc:
[2016-10-08T15:06:15.032]   gres_used:(null)
[2016-10-08T15:06:15.032]   topo_cpus_bitmap[0]:0-7
[2016-10-08T15:06:15.032]   topo_gres_bitmap[0]:0-7
[2016-10-08T15:06:15.032]   topo_gres_cnt_alloc[0]:0
[2016-10-08T15:06:15.032]   topo_gres_cnt_avail[0]:8
[2016-10-08T15:06:15.032]   type[0]:tesla
[2016-10-08T15:39:35.823] gres/gpu: state for gpu-cluster-1
[2016-10-08T15:39:35.823]   gres_cnt found:8 configured:8 avail:8 alloc:0
[2016-10-08T15:39:35.823]   gres_bit_alloc:
[2016-10-08T15:39:35.823]   gres_used:(null)
[2016-10-08T15:39:35.823]   topo_cpus_bitmap[0]:0-7
[2016-10-08T15:39:35.823]   topo_gres_bitmap[0]:0-7
[2016-10-08T15:39:35.823]   topo_gres_cnt_alloc[0]:0
[2016-10-08T15:39:35.824]   topo_gres_cnt_avail[0]:8
[2016-10-08T15:39:35.824]   type[0]:tesla
[2016-10-08T15:39:35.824] gres/gpu: state for gpu-cluster-3
[2016-10-08T15:39:35.824]   gres_cnt found:8 configured:8 avail:8 alloc:0
[2016-10-08T15:39:35.824]   gres_bit_alloc:
[2016-10-08T15:39:35.824]   gres_used:(null)
[2016-10-08T15:39:35.824]   topo_cpus_bitmap[0]:0-7
[2016-10-08T15:39:35.824]   topo_gres_bitmap[0]:0-7
[2016-10-08T15:39:35.824]   topo_gres_cnt_alloc[0]:0
[2016-10-08T15:39:35.824]   topo_gres_cnt_avail[0]:8
[2016-10-08T15:39:35.824]   type[0]:tesla
[2016-10-08T15:39:35.824] gres/gpu: state for gpu-cluster-4
[2016-10-08T15:39:35.825]   gres_cnt found:8 configured:8 avail:8 alloc:0
[2016-10-08T15:39:35.825]   gres_bit_alloc:
[2016-10-08T15:39:35.825]   gres_used:(null)
[2016-10-08T15:39:35.825]   topo_cpus_bitmap[0]:0-7
[2016-10-08T15:39:35.825]   topo_gres_bitmap[0]:0-7
[2016-10-08T15:39:35.825]   topo_gres_cnt_alloc[0]:0
[2016-10-08T15:39:35.825]   topo_gres_cnt_avail[0]:8
[2016-10-08T15:39:35.825]   type[0]:tesla
[2016-10-08T15:39:35.825] gres/gpu: state for gpu-cluster-2
[2016-10-08T15:39:35.825]   gres_cnt found:8 configured:8 avail:8 alloc:0
[2016-10-08T15:39:35.825]   gres_bit_alloc:
[2016-10-08T15:39:35.825]   gres_used:(null)
[2016-10-08T15:39:35.825]   topo_cpus_bitmap[0]:0-7
[2016-10-08T15:39:35.825]   topo_gres_bitmap[0]:0-7
[2016-10-08T15:39:35.825]   topo_gres_cnt_alloc[0]:0
[2016-10-08T15:39:35.825]   topo_gres_cnt_avail[0]:8
[2016-10-08T15:39:35.825]   type[0]:tesla
[2016-10-08T16:12:55.398] gres/gpu: state for gpu-cluster-1
[2016-10-08T16:12:55.399]   gres_cnt found:8 configured:8 avail:8 alloc:0
[2016-10-08T16:12:55.399]   gres_bit_alloc:
[2016-10-08T16:12:55.399]   gres_used:(null)
[2016-10-08T16:12:55.399]   topo_cpus_bitmap[0]:0-7
[2016-10-08T16:12:55.399]   topo_gres_bitmap[0]:0-7
[2016-10-08T16:12:55.399]   topo_gres_cnt_alloc[0]:0
[2016-10-08T16:12:55.399]   topo_gres_cnt_avail[0]:8
[2016-10-08T16:12:55.399]   type[0]:tesla
[2016-10-08T16:12:55.399] gres/gpu: state for gpu-cluster-3
[2016-10-08T16:12:55.399]   gres_cnt found:8 configured:8 avail:8 alloc:0
[2016-10-08T16:12:55.399]   gres_bit_alloc:
[2016-10-08T16:12:55.399]   gres_used:(null)
[2016-10-08T16:12:55.399]   topo_cpus_bitmap[0]:0-7
[2016-10-08T16:12:55.399]   topo_gres_bitmap[0]:0-7
[2016-10-08T16:12:55.399]   topo_gres_cnt_alloc[0]:0
[2016-10-08T16:12:55.399]   topo_gres_cnt_avail[0]:8
[2016-10-08T16:12:55.399]   type[0]:tesla
[2016-10-08T16:12:55.399] gres/gpu: state for gpu-cluster-2
[2016-10-08T16:12:55.400]   gres_cnt found:8 configured:8 avail:8 alloc:0
[2016-10-08T16:12:55.400]   gres_bit_alloc:
[2016-10-08T16:12:55.400]   gres_used:(null)
[2016-10-08T16:12:55.400]   topo_cpus_bitmap[0]:0-7
[2016-10-08T16:12:55.400]   topo_gres_bitmap[0]:0-7
[2016-10-08T16:12:55.400]   topo_gres_cnt_alloc[0]:0
[2016-10-08T16:12:55.400]   topo_gres_cnt_avail[0]:8
[2016-10-08T16:12:55.400]   type[0]:tesla
[2016-10-08T16:12:55.400] gres/gpu: state for gpu-cluster-4
[2016-10-08T16:12:55.400]   gres_cnt found:8 configured:8 avail:8 alloc:0
[2016-10-08T16:12:55.400]   gres_bit_alloc:
[2016-10-08T16:12:55.400]   gres_used:(null)
[2016-10-08T16:12:55.400]   topo_cpus_bitmap[0]:0-7
[2016-10-08T16:12:55.400]   topo_gres_bitmap[0]:0-7
[2016-10-08T16:12:55.400]   topo_gres_cnt_alloc[0]:0
[2016-10-08T16:12:55.400]   topo_gres_cnt_avail[0]:8
[2016-10-08T16:12:55.400]   type[0]:tesla
[2016-10-08T16:46:15.189] gres/gpu: state for gpu-cluster-1
[2016-10-08T16:46:15.189]   gres_cnt found:8 configured:8 avail:8 alloc:0
[2016-10-08T16:46:15.189]   gres_bit_alloc:
[2016-10-08T16:46:15.189]   gres_used:(null)
[2016-10-08T16:46:15.189]   topo_cpus_bitmap[0]:0-7
[2016-10-08T16:46:15.189]   topo_gres_bitmap[0]:0-7
[2016-10-08T16:46:15.189]   topo_gres_cnt_alloc[0]:0
[2016-10-08T16:46:15.189]   topo_gres_cnt_avail[0]:8
[2016-10-08T16:46:15.189]   type[0]:tesla
[2016-10-08T16:46:15.189] gres/gpu: state for gpu-cluster-3
[2016-10-08T16:46:15.189]   gres_cnt found:8 configured:8 avail:8 alloc:0
[2016-10-08T16:46:15.190]   gres_bit_alloc:
[2016-10-08T16:46:15.190]   gres_used:(null)
[2016-10-08T16:46:15.190]   topo_cpus_bitmap[0]:0-7
[2016-10-08T16:46:15.190]   topo_gres_bitmap[0]:0-7
[2016-10-08T16:46:15.190]   topo_gres_cnt_alloc[0]:0
[2016-10-08T16:46:15.190]   topo_gres_cnt_avail[0]:8
[2016-10-08T16:46:15.190]   type[0]:tesla
[2016-10-08T16:46:15.190] gres/gpu: state for gpu-cluster-2
[2016-10-08T16:46:15.190]   gres_cnt found:8 configured:8 avail:8 alloc:0
[2016-10-08T16:46:15.190]   gres_bit_alloc:
[2016-10-08T16:46:15.190]   gres_used:(null)
[2016-10-08T16:46:15.190]   topo_cpus_bitmap[0]:0-7
[2016-10-08T16:46:15.190]   topo_gres_bitmap[0]:0-7
[2016-10-08T16:46:15.190]   topo_gres_cnt_alloc[0]:0
[2016-10-08T16:46:15.190]   topo_gres_cnt_avail[0]:8
[2016-10-08T16:46:15.190]   type[0]:tesla
[2016-10-08T16:46:15.190] gres/gpu: state for gpu-cluster-4
[2016-10-08T16:46:15.190]   gres_cnt found:8 configured:8 avail:8 alloc:0
[2016-10-08T16:46:15.190]   gres_bit_alloc:
[2016-10-08T16:46:15.190]   gres_used:(null)
[2016-10-08T16:46:15.190]   topo_cpus_bitmap[0]:0-7
[2016-10-08T16:46:15.190]   topo_gres_bitmap[0]:0-7
[2016-10-08T16:46:15.190]   topo_gres_cnt_alloc[0]:0
[2016-10-08T16:46:15.190]   topo_gres_cnt_avail[0]:8
[2016-10-08T16:46:15.190]   type[0]:tesla
[2016-10-08T17:19:35.982] gres/gpu: state for gpu-cluster-1
[2016-10-08T17:19:35.982]   gres_cnt found:8 configured:8 avail:8 alloc:0
[2016-10-08T17:19:35.982]   gres_bit_alloc:
[2016-10-08T17:19:35.982]   gres_used:(null)
[2016-10-08T17:19:35.982]   topo_cpus_bitmap[0]:0-7
[2016-10-08T17:19:35.982]   topo_gres_bitmap[0]:0-7
[2016-10-08T17:19:35.982]   topo_gres_cnt_alloc[0]:0
[2016-10-08T17:19:35.982]   topo_gres_cnt_avail[0]:8
[2016-10-08T17:19:35.982]   type[0]:tesla
[2016-10-08T17:19:35.982] gres/gpu: state for gpu-cluster-3
[2016-10-08T17:19:35.982]   gres_cnt found:8 configured:8 avail:8 alloc:0
[2016-10-08T17:19:35.982]   gres_bit_alloc:
[2016-10-08T17:19:35.982]   gres_used:(null)
[2016-10-08T17:19:35.982]   topo_cpus_bitmap[0]:0-7
[2016-10-08T17:19:35.982]   topo_gres_bitmap[0]:0-7
[2016-10-08T17:19:35.982]   topo_gres_cnt_alloc[0]:0
[2016-10-08T17:19:35.982]   topo_gres_cnt_avail[0]:8
[2016-10-08T17:19:35.982]   type[0]:tesla
[2016-10-08T17:19:35.982] gres/gpu: state for gpu-cluster-4
[2016-10-08T17:19:35.982]   gres_cnt found:8 configured:8 avail:8 alloc:0
[2016-10-08T17:19:35.982]   gres_bit_alloc:
[2016-10-08T17:19:35.982]   gres_used:(null)
[2016-10-08T17:19:35.983]   topo_cpus_bitmap[0]:0-7
[2016-10-08T17:19:35.983]   topo_gres_bitmap[0]:0-7
[2016-10-08T17:19:35.983]   topo_gres_cnt_alloc[0]:0
[2016-10-08T17:19:35.983]   topo_gres_cnt_avail[0]:8
[2016-10-08T17:19:35.983]   type[0]:tesla
[2016-10-08T17:19:35.983] gres/gpu: state for gpu-cluster-2
[2016-10-08T17:19:35.983]   gres_cnt found:8 configured:8 avail:8 alloc:0
[2016-10-08T17:19:35.983]   gres_bit_alloc:
[2016-10-08T17:19:35.983]   gres_used:(null)
[2016-10-08T17:19:35.983]   topo_cpus_bitmap[0]:0-7
[2016-10-08T17:19:35.983]   topo_gres_bitmap[0]:0-7
[2016-10-08T17:19:35.983]   topo_gres_cnt_alloc[0]:0
[2016-10-08T17:19:35.983]   topo_gres_cnt_avail[0]:8
[2016-10-08T17:19:35.983]   type[0]:tesla
[2016-10-08T17:52:55.561] gres/gpu: state for gpu-cluster-1
[2016-10-08T17:52:55.561]   gres_cnt found:8 configured:8 avail:8 alloc:0
[2016-10-08T17:52:55.561]   gres_bit_alloc:
[2016-10-08T17:52:55.561]   gres_used:(null)
[2016-10-08T17:52:55.561]   topo_cpus_bitmap[0]:0-7
[2016-10-08T17:52:55.561]   topo_gres_bitmap[0]:0-7
[2016-10-08T17:52:55.561]   topo_gres_cnt_alloc[0]:0
[2016-10-08T17:52:55.561]   topo_gres_cnt_avail[0]:8
[2016-10-08T17:52:55.561]   type[0]:tesla
[2016-10-08T17:52:55.561] gres/gpu: state for gpu-cluster-3
[2016-10-08T17:52:55.561]   gres_cnt found:8 configured:8 avail:8 alloc:0
[2016-10-08T17:52:55.561]   gres_bit_alloc:
[2016-10-08T17:52:55.561]   gres_used:(null)
[2016-10-08T17:52:55.561]   topo_cpus_bitmap[0]:0-7
[2016-10-08T17:52:55.561]   topo_gres_bitmap[0]:0-7
[2016-10-08T17:52:55.561]   topo_gres_cnt_alloc[0]:0
[2016-10-08T17:52:55.561]   topo_gres_cnt_avail[0]:8
[2016-10-08T17:52:55.561]   type[0]:tesla
[2016-10-08T17:52:55.562] gres/gpu: state for gpu-cluster-2
[2016-10-08T17:52:55.562]   gres_cnt found:8 configured:8 avail:8 alloc:0
[2016-10-08T17:52:55.562]   gres_bit_alloc:
[2016-10-08T17:52:55.562]   gres_used:(null)
[2016-10-08T17:52:55.562]   topo_cpus_bitmap[0]:0-7
[2016-10-08T17:52:55.562]   topo_gres_bitmap[0]:0-7
[2016-10-08T17:52:55.562]   topo_gres_cnt_alloc[0]:0
[2016-10-08T17:52:55.562]   topo_gres_cnt_avail[0]:8
[2016-10-08T17:52:55.562]   type[0]:tesla
[2016-10-08T17:52:55.562] gres/gpu: state for gpu-cluster-4
[2016-10-08T17:52:55.562]   gres_cnt found:8 configured:8 avail:8 alloc:0
[2016-10-08T17:52:55.562]   gres_bit_alloc:
[2016-10-08T17:52:55.562]   gres_used:(null)
[2016-10-08T17:52:55.562]   topo_cpus_bitmap[0]:0-7
[2016-10-08T17:52:55.562]   topo_gres_bitmap[0]:0-7
[2016-10-08T17:52:55.562]   topo_gres_cnt_alloc[0]:0
[2016-10-08T17:52:55.562]   topo_gres_cnt_avail[0]:8
[2016-10-08T17:52:55.562]   type[0]:tesla
[2016-10-08T18:26:15.354] gres/gpu: state for gpu-cluster-1
[2016-10-08T18:26:15.354]   gres_cnt found:8 configured:8 avail:8 alloc:0
[2016-10-08T18:26:15.354]   gres_bit_alloc:
[2016-10-08T18:26:15.354]   gres_used:(null)
[2016-10-08T18:26:15.354]   topo_cpus_bitmap[0]:0-7
[2016-10-08T18:26:15.354]   topo_gres_bitmap[0]:0-7
[2016-10-08T18:26:15.354]   topo_gres_cnt_alloc[0]:0
[2016-10-08T18:26:15.354]   topo_gres_cnt_avail[0]:8
[2016-10-08T18:26:15.354]   type[0]:tesla
[2016-10-08T18:26:15.355] gres/gpu: state for gpu-cluster-3
[2016-10-08T18:26:15.355]   gres_cnt found:8 configured:8 avail:8 alloc:0
[2016-10-08T18:26:15.355]   gres_bit_alloc:
[2016-10-08T18:26:15.355]   gres_used:(null)
[2016-10-08T18:26:15.355]   topo_cpus_bitmap[0]:0-7
[2016-10-08T18:26:15.355]   topo_gres_bitmap[0]:0-7
[2016-10-08T18:26:15.355]   topo_gres_cnt_alloc[0]:0
[2016-10-08T18:26:15.355]   topo_gres_cnt_avail[0]:8
[2016-10-08T18:26:15.355]   type[0]:tesla
[2016-10-08T18:26:15.355] gres/gpu: state for gpu-cluster-2
[2016-10-08T18:26:15.355]   gres_cnt found:8 configured:8 avail:8 alloc:0
[2016-10-08T18:26:15.355]   gres_bit_alloc:
[2016-10-08T18:26:15.355]   gres_used:(null)
[2016-10-08T18:26:15.355]   topo_cpus_bitmap[0]:0-7
[2016-10-08T18:26:15.355]   topo_gres_bitmap[0]:0-7
[2016-10-08T18:26:15.355]   topo_gres_cnt_alloc[0]:0
[2016-10-08T18:26:15.355]   topo_gres_cnt_avail[0]:8
[2016-10-08T18:26:15.355]   type[0]:tesla
[2016-10-08T18:26:15.356] gres/gpu: state for gpu-cluster-4
[2016-10-08T18:26:15.356]   gres_cnt found:8 configured:8 avail:8 alloc:0
[2016-10-08T18:26:15.356]   gres_bit_alloc:
[2016-10-08T18:26:15.356]   gres_used:(null)
[2016-10-08T18:26:15.356]   topo_cpus_bitmap[0]:0-7
[2016-10-08T18:26:15.356]   topo_gres_bitmap[0]:0-7
[2016-10-08T18:26:15.356]   topo_gres_cnt_alloc[0]:0
[2016-10-08T18:26:15.356]   topo_gres_cnt_avail[0]:8
[2016-10-08T18:26:15.356]   type[0]:tesla
[2016-10-08T18:59:35.151] gres/gpu: state for gpu-cluster-1
[2016-10-08T18:59:35.151]   gres_cnt found:8 configured:8 avail:8 alloc:0
[2016-10-08T18:59:35.151]   gres_bit_alloc:
[2016-10-08T18:59:35.151]   gres_used:(null)
[2016-10-08T18:59:35.151]   topo_cpus_bitmap[0]:0-7
[2016-10-08T18:59:35.151]   topo_gres_bitmap[0]:0-7
[2016-10-08T18:59:35.151]   topo_gres_cnt_alloc[0]:0
[2016-10-08T18:59:35.151]   topo_gres_cnt_avail[0]:8
[2016-10-08T18:59:35.151]   type[0]:tesla
[2016-10-08T18:59:35.152] gres/gpu: state for gpu-cluster-3
[2016-10-08T18:59:35.152]   gres_cnt found:8 configured:8 avail:8 alloc:0
[2016-10-08T18:59:35.152]   gres_bit_alloc:
[2016-10-08T18:59:35.152]   gres_used:(null)
[2016-10-08T18:59:35.152]   topo_cpus_bitmap[0]:0-7
[2016-10-08T18:59:35.152]   topo_gres_bitmap[0]:0-7
[2016-10-08T18:59:35.152]   topo_gres_cnt_alloc[0]:0
[2016-10-08T18:59:35.152]   topo_gres_cnt_avail[0]:8
[2016-10-08T18:59:35.152]   type[0]:tesla
[2016-10-08T18:59:35.152] gres/gpu: state for gpu-cluster-2
[2016-10-08T18:59:35.152]   gres_cnt found:8 configured:8 avail:8 alloc:0
[2016-10-08T18:59:35.152]   gres_bit_alloc:
[2016-10-08T18:59:35.152]   gres_used:(null)
[2016-10-08T18:59:35.152]   topo_cpus_bitmap[0]:0-7
[2016-10-08T18:59:35.152]   topo_gres_bitmap[0]:0-7
[2016-10-08T18:59:35.152]   topo_gres_cnt_alloc[0]:0
[2016-10-08T18:59:35.152]   topo_gres_cnt_avail[0]:8
[2016-10-08T18:59:35.152]   type[0]:tesla
[2016-10-08T18:59:35.152] gres/gpu: state for gpu-cluster-4
[2016-10-08T18:59:35.152]   gres_cnt found:8 configured:8 avail:8 alloc:0
[2016-10-08T18:59:35.152]   gres_bit_alloc:
[2016-10-08T18:59:35.152]   gres_used:(null)
[2016-10-08T18:59:35.152]   topo_cpus_bitmap[0]:0-7
[2016-10-08T18:59:35.153]   topo_gres_bitmap[0]:0-7
[2016-10-08T18:59:35.153]   topo_gres_cnt_alloc[0]:0
[2016-10-08T18:59:35.153]   topo_gres_cnt_avail[0]:8
[2016-10-08T18:59:35.153]   type[0]:tesla
[2016-10-08T19:32:55.708] gres/gpu: state for gpu-cluster-1
[2016-10-08T19:32:55.708]   gres_cnt found:8 configured:8 avail:8 alloc:0
[2016-10-08T19:32:55.708]   gres_bit_alloc:
[2016-10-08T19:32:55.708]   gres_used:(null)
[2016-10-08T19:32:55.708]   topo_cpus_bitmap[0]:0-7
[2016-10-08T19:32:55.708]   topo_gres_bitmap[0]:0-7
[2016-10-08T19:32:55.708]   topo_gres_cnt_alloc[0]:0
[2016-10-08T19:32:55.708]   topo_gres_cnt_avail[0]:8
[2016-10-08T19:32:55.708]   type[0]:tesla
[2016-10-08T19:32:55.709] gres/gpu: state for gpu-cluster-3
[2016-10-08T19:32:55.709]   gres_cnt found:8 configured:8 avail:8 alloc:0
[2016-10-08T19:32:55.709]   gres_bit_alloc:
[2016-10-08T19:32:55.709]   gres_used:(null)
[2016-10-08T19:32:55.709]   topo_cpus_bitmap[0]:0-7
[2016-10-08T19:32:55.709]   topo_gres_bitmap[0]:0-7
[2016-10-08T19:32:55.709]   topo_gres_cnt_alloc[0]:0
[2016-10-08T19:32:55.709]   topo_gres_cnt_avail[0]:8
[2016-10-08T19:32:55.709]   type[0]:tesla
[2016-10-08T19:32:55.709] gres/gpu: state for gpu-cluster-4
[2016-10-08T19:32:55.709]   gres_cnt found:8 configured:8 avail:8 alloc:0
[2016-10-08T19:32:55.709]   gres_bit_alloc:
[2016-10-08T19:32:55.709]   gres_used:(null)
[2016-10-08T19:32:55.709]   topo_cpus_bitmap[0]:0-7
[2016-10-08T19:32:55.710]   topo_gres_bitmap[0]:0-7
[2016-10-08T19:32:55.710]   topo_gres_cnt_alloc[0]:0
[2016-10-08T19:32:55.710]   topo_gres_cnt_avail[0]:8
[2016-10-08T19:32:55.710]   type[0]:tesla
[2016-10-08T19:32:55.710] gres/gpu: state for gpu-cluster-2
[2016-10-08T19:32:55.710]   gres_cnt found:8 configured:8 avail:8 alloc:0
[2016-10-08T19:32:55.710]   gres_bit_alloc:
[2016-10-08T19:32:55.710]   gres_used:(null)
[2016-10-08T19:32:55.710]   topo_cpus_bitmap[0]:0-7
[2016-10-08T19:32:55.710]   topo_gres_bitmap[0]:0-7
[2016-10-08T19:32:55.710]   topo_gres_cnt_alloc[0]:0
[2016-10-08T19:32:55.710]   topo_gres_cnt_avail[0]:8
[2016-10-08T19:32:55.710]   type[0]:tesla
[2016-10-08T20:06:15.515] gres/gpu: state for gpu-cluster-1
[2016-10-08T20:06:15.515]   gres_cnt found:8 configured:8 avail:8 alloc:0
[2016-10-08T20:06:15.515]   gres_bit_alloc:
[2016-10-08T20:06:15.515]   gres_used:(null)
[2016-10-08T20:06:15.515]   topo_cpus_bitmap[0]:0-7
[2016-10-08T20:06:15.515]   topo_gres_bitmap[0]:0-7
[2016-10-08T20:06:15.515]   topo_gres_cnt_alloc[0]:0
[2016-10-08T20:06:15.515]   topo_gres_cnt_avail[0]:8
[2016-10-08T20:06:15.515]   type[0]:tesla
[2016-10-08T20:06:15.516] gres/gpu: state for gpu-cluster-3
[2016-10-08T20:06:15.516]   gres_cnt found:8 configured:8 avail:8 alloc:0
[2016-10-08T20:06:15.516]   gres_bit_alloc:
[2016-10-08T20:06:15.516]   gres_used:(null)
[2016-10-08T20:06:15.516]   topo_cpus_bitmap[0]:0-7
[2016-10-08T20:06:15.516]   topo_gres_bitmap[0]:0-7
[2016-10-08T20:06:15.516]   topo_gres_cnt_alloc[0]:0
[2016-10-08T20:06:15.516]   topo_gres_cnt_avail[0]:8
[2016-10-08T20:06:15.516]   type[0]:tesla
[2016-10-08T20:06:15.516] gres/gpu: state for gpu-cluster-4
[2016-10-08T20:06:15.516]   gres_cnt found:8 configured:8 avail:8 alloc:0
[2016-10-08T20:06:15.516]   gres_bit_alloc:
[2016-10-08T20:06:15.516]   gres_used:(null)
[2016-10-08T20:06:15.516]   topo_cpus_bitmap[0]:0-7
[2016-10-08T20:06:15.516]   topo_gres_bitmap[0]:0-7
[2016-10-08T20:06:15.516]   topo_gres_cnt_alloc[0]:0
[2016-10-08T20:06:15.516]   topo_gres_cnt_avail[0]:8
[2016-10-08T20:06:15.516]   type[0]:tesla
[2016-10-08T20:06:15.517] gres/gpu: state for gpu-cluster-2
[2016-10-08T20:06:15.517]   gres_cnt found:8 configured:8 avail:8 alloc:0
[2016-10-08T20:06:15.517]   gres_bit_alloc:
[2016-10-08T20:06:15.517]   gres_used:(null)
[2016-10-08T20:06:15.517]   topo_cpus_bitmap[0]:0-7
[2016-10-08T20:06:15.517]   topo_gres_bitmap[0]:0-7
[2016-10-08T20:06:15.517]   topo_gres_cnt_alloc[0]:0
[2016-10-08T20:06:15.517]   topo_gres_cnt_avail[0]:8
[2016-10-08T20:06:15.517]   type[0]:tesla
[2016-10-08T20:39:35.129] gres/gpu: state for gpu-cluster-1
[2016-10-08T20:39:35.129]   gres_cnt found:8 configured:8 avail:8 alloc:0
[2016-10-08T20:39:35.129]   gres_bit_alloc:
[2016-10-08T20:39:35.129]   gres_used:(null)
[2016-10-08T20:39:35.129]   topo_cpus_bitmap[0]:0-7
[2016-10-08T20:39:35.129]   topo_gres_bitmap[0]:0-7
[2016-10-08T20:39:35.129]   topo_gres_cnt_alloc[0]:0
[2016-10-08T20:39:35.129]   topo_gres_cnt_avail[0]:8
[2016-10-08T20:39:35.129]   type[0]:tesla
[2016-10-08T20:39:35.129] gres/gpu: state for gpu-cluster-3
[2016-10-08T20:39:35.129]   gres_cnt found:8 configured:8 avail:8 alloc:0
[2016-10-08T20:39:35.130]   gres_bit_alloc:
[2016-10-08T20:39:35.130]   gres_used:(null)
[2016-10-08T20:39:35.130]   topo_cpus_bitmap[0]:0-7
[2016-10-08T20:39:35.130]   topo_gres_bitmap[0]:0-7
[2016-10-08T20:39:35.130]   topo_gres_cnt_alloc[0]:0
[2016-10-08T20:39:35.130]   topo_gres_cnt_avail[0]:8
[2016-10-08T20:39:35.130]   type[0]:tesla
[2016-10-08T20:39:35.130] gres/gpu: state for gpu-cluster-2
[2016-10-08T20:39:35.130]   gres_cnt found:8 configured:8 avail:8 alloc:0
[2016-10-08T20:39:35.130]   gres_bit_alloc:
[2016-10-08T20:39:35.130]   gres_used:(null)
[2016-10-08T20:39:35.130]   topo_cpus_bitmap[0]:0-7
[2016-10-08T20:39:35.130]   topo_gres_bitmap[0]:0-7
[2016-10-08T20:39:35.130]   topo_gres_cnt_alloc[0]:0
[2016-10-08T20:39:35.130]   topo_gres_cnt_avail[0]:8
[2016-10-08T20:39:35.130]   type[0]:tesla
[2016-10-08T20:39:35.130] gres/gpu: state for gpu-cluster-4
[2016-10-08T20:39:35.130]   gres_cnt found:8 configured:8 avail:8 alloc:0
[2016-10-08T20:39:35.130]   gres_bit_alloc:
[2016-10-08T20:39:35.130]   gres_used:(null)
[2016-10-08T20:39:35.130]   topo_cpus_bitmap[0]:0-7
[2016-10-08T20:39:35.130]   topo_gres_bitmap[0]:0-7
[2016-10-08T20:39:35.130]   topo_gres_cnt_alloc[0]:0
[2016-10-08T20:39:35.130]   topo_gres_cnt_avail[0]:8
[2016-10-08T20:39:35.130]   type[0]:tesla
[2016-10-08T20:40:54.113] Performing RPC: REQUEST_SHUTDOWN
[2016-10-08T20:40:54.123] Terminate signal (SIGINT or SIGTERM) received
[2016-10-08T20:40:54.212] Saving all slurm state
[2016-10-08T20:40:54.333] layouts: all layouts are now unloaded.
